Workbook

Sheet Start here
A1: Keyword Mapping Template
A2: Keyword → URL with intent, priority and cannibalisation flags · by Lazarina Stoy · MLforSEO
A4: What it does
A5: Maps every keyword (or cluster) to one existing or planned URL, labels its search intent, scores priority, and flags
A6: the problems that cause cannibalisation: a keyword mapped to two pages, a page with too many primary keywords, a page
A7: spanning several clusters, a keyword whose intent doesn't fit the page type, and a ranking URL that isn't the one you chose.
A8: It is the step between keyword clustering and content briefs.
A10: How to use it
A11: 1. Settings: replace the Navigational words with your brand and product names. Check the page types and the intent-fit grid.
A12: 2. Keyword Map: delete the sample rows (columns A-L only), then paste your clustered keywords: keyword, cluster, volume, KD.
A13: Optional: current ranking URL and position from Search Console or your rank tracker, and an intent label from a classifier.
A14: 3. For each keyword pick a Target URL, Page status, Page type and Keyword role (one Primary per URL, the rest Secondary).
... A29: Legend
A30: Dark header | B30: Input column: paste or type here.
A31: Purple header | B31: Calculated column: formulas, please don't type over them.
A32: Lavender band | B32: Readability banding and paste zones.
A33: Yellow cell | B33: A flag that needs a human look, or an editable setting.
A34: Soft red | B34: A stronger warning (for example cannibalisation or a prune decision).
A35: Good to know
A36: Works in Google Sheets and Excel: formulas are INDEX/MATCH, COUNTIFS, SUMIFS, SUMPRODUCT and IF. Room for 1,000 keywords
A37: (copy the last formula row down for more). Rule-based intent is a first pass, not ground truth. COUNTIFS ignores case.
A39: Credits
A40: Template by Lazarina Stoy · MLforSEO (mlforseo.com). Free to use and adapt; please keep this credit.
A41: Read: How to turn semantic keyword research into an actionable SEO workflow (MLforSEO)
A42: Course: Semantic ML-enabled Keyword Research (MLforSEO Academy)
A43: Free intent classifier (code): github.com/lazarinastoy/mlforseo-code/search-intent-regex-classifier

Sheet Keyword Map
A1: PASTE OR TYPE HERE (keyword research export + your mapping decisions) | M1: SAMPLE DATA rows 3-29 (synthetic site stride-example.com). Clear columns A-L and paste your own.
A2: Keyword | B2: Cluster | C2: Search volume | D2: Keyword difficulty | E2: Current ranking URL | F2: Current position | G2: Target URL | H2: Page status | I2: Page type | J2: Keyword role | K2: Intent (pasted, optional) | L2: Notes | M2: Keyword (clean) | N2: Rule-based intent | O2: Final intent | P2: Priority score | Q2: Other URLs for this keyword | R2: Cannibalisation | S2: Primary keywords on target URL | T2: Too many primaries on URL | U2: URL spans 2+ clusters | V2: Intent fit (page type) | W2: Intent mismatch | X2: Ranking URL is not the target | Y2: Flag count | Z2: Flags | AA2: URL index (helper) | AB2: Cluster index (helper)
A3: trail running shoes | B3: Trail shoes | C3: 9900 | D3: 54 | E3: https://www.stride-example.com/trail-running-shoes/ | F3: 14 | G3: https://www.stride-example.com/trail-running-shoes/ | H3: Existing | I3: Category / collection | J3: Primary | K3: Commercial | L3: Intent pasted from a SERP-based classifier | M3: =IF(A3="","",LOWER(TRIM(SUBSTITUTE(SUBSTITUTE(A3,"?",""),"*","")))) | N3: =IF(M3="","",IF(SUMPRODUCT(ISNUMBER(SEARCH(" "&Settings!$L$5:$L$124&" "," "&M3&" "))*(Settings!$K$5:$K$124="Navigational")*(Settings!$L$5:$L$124<>""))>0,"Navigational",IF(SUMPRODUCT(ISNUMBER(SEARCH(" "&Settings!$L$5:$L$124&" "," "&M3&" "))*(Settings!$K$5:$K$124="Transactional")*(Settings!$L$5:$L$124<>""))>0,"Transactional",IF(SUMPRODUCT(ISNUMBER(SEARCH(" "&Settings!$L$5:$L$124&" "," "&M3&" "))*(Settings!$K$5:$K$124="Commercial")*(Settings!$L$5:$L$124<>""))>0,"Commercial",IF(SUMPRODUCT(ISNUMBER(SEARCH(" "&Settings!$L$5:$L$124&" "," "&M3&" "))*(Settings!$K$5:$K$124="Informational")*(Settings!$L$5:$L$124<>""))>0,"Informational","Unclassified"))))) | O3: =IF(A3="","",IF(K3<>"",PROPER(K3),N3)) | P3: =IF(A3="","",ROUND(Settings!$B$5*MIN(1,LOG10(N(C3)+1)/LOG10(Settings!$B$7+1))+Settings!$B$6*(1-MIN(100,IF(D3="",50,N(D3)))/100)+IFERROR(INDEX(Settings!$B$10:$B$14,MATCH(O3,Settings!$A$10:$A$14,0)),0),0)) | Q3: =IF(OR(A3="",G3=""),"",COUNTIFS($M$3:$M$1002,M3,$G$3:$G$1002,"<>"&SUBSTITUTE(SUBSTITUTE(G3,"?","~?"),"*","~*"),$G$3:$G$1002,"?*")) | R3: =IF(Q3="","",IF(Q3>0,"Yes","No")) | S3: =IF(G3="","",COUNTIFS($G$3:$G$1002,SUBSTITUTE(SUBSTITUTE(G3,"?","~?"),"*","~*"),$J$3:$J$1002,"Primary")) | T3: =IF(S3="","",IF(S3>Settings!$B$4,"Yes","No")) | U3: =IF(OR(G3="",B3=""),"",IF(COUNTIFS($G$3:$G$1002,SUBSTITUTE(SUBSTITUTE(G3,"?","~?"),"*","~*"),$B$3:$B$1002,"<>"&SUBSTITUTE(SUBSTITUTE(B3,"?","~?"),"*","~*"),$B$3:$B$1002,"?*")>0,"Yes","No")) | V3: =IF(OR(G3="",I3="",O3="",O3="Unclassified"),"",IFERROR(INDEX(Settings!$E$5:$H$16,MATCH(I3,Settings!$D$5:$D$16,0),MATCH(O3,Settings!$E$4:$H$4,0)),"Check")) | W3: =IF(V3="","",IF(V3="No","Yes","No")) | X3: =IF(OR(E3="",G3=""),"",IF(LOWER(IF(RIGHT(TRIM(E3),1)="/",LEFT(TRIM(E3),LEN(TRIM(E3))-1),TRIM(E3)))<>LOWER(IF(RIGHT(TRIM(G3),1)="/",LEFT(TRIM(G3),LEN(TRIM(G3))-1),TRIM(G3))),"Yes","No")) | Y3: =IF(A3="","",(N(Q3)>0)+(T3="Yes")+(U3="Yes")+(W3="Yes")+(X3="Yes")) | Z3: =IF(A3="","",IF(G3="","Not mapped",IF(Y3=0,"OK",MID(IF(N(Q3)>0,"; Cannibalisation","")&IF(T3="Yes","; Too many primary keywords on URL","")&IF(U3="Yes","; URL spans 2+ clusters","")&IF(W3="Yes","; Intent mismatch","")&IF(X3="Yes","; Ranking URL is not the target",""),3,300)))) | AA3: =IF(G3="","",IF(COUNTIF($G$3:G3,SUBSTITUTE(SUBSTITUTE(G3,"?","~?"),"*","~*"))=1,MAX($AA$2:AA2)+1,"")) | AB3: =IF(B3="","",IF(COUNTIF($B$3:B3,SUBSTITUTE(SUBSTITUTE(B3,"?","~?"),"*","~*"))=1,MAX($AB$2:AB2)+1,""))
A4: best trail running shoes | B4: Trail shoes | C4: 4400 | D4: 61 | E4: https://www.stride-example.com/blog/best-trail-running-shoes/ | F4: 9 | G4: https://www.stride-example.com/blog/best-trail-running-shoes/ | H4: Existing | I4: Comparison / review | J4: Primary | M4: =IF(A4="","",LOWER(TRIM(SUBSTITUTE(SUBSTITUTE(A4,"?",""),"*","")))) | N4: =IF(M4="","",IF(SUMPRODUCT(ISNUMBER(SEARCH(" "&Settings!$L$5:$L$124&" "," "&M4&" "))*(Settings!$K$5:$K$124="Navigational")*(Settings!$L$5:$L$124<>""))>0,"Navigational",IF(SUMPRODUCT(ISNUMBER(SEARCH(" "&Settings!$L$5:$L$124&" "," "&M4&" "))*(Settings!$K$5:$K$124="Transactional")*(Settings!$L$5:$L$124<>""))>0,"Transactional",IF(SUMPRODUCT(ISNUMBER(SEARCH(" "&Settings!$L$5:$L$124&" "," "&M4&" "))*(Settings!$K$5:$K$124="Commercial")*(Settings!$L$5:$L$124<>""))>0,"Commercial",IF(SUMPRODUCT(ISNUMBER(SEARCH(" "&Settings!$L$5:$L$124&" "," "&M4&" "))*(Settings!$K$5:$K$124="Informational")*(Settings!$L$5:$L$124<>""))>0,"Informational","Unclassified"))))) | O4: =IF(A4="","",IF(K4<>"",PROPER(K4),N4)) | P4: =IF(A4="","",ROUND(Settings!$B$5*MIN(1,LOG10(N(C4)+1)/LOG10(Settings!$B$7+1))+Settings!$B$6*(1-MIN(100,IF(D4="",50,N(D4)))/100)+IFERROR(INDEX(Settings!$B$10:$B$14,MATCH(O4,Settings!$A$10:$A$14,0)),0),0)) | Q4: =IF(OR(A4="",G4=""),"",COUNTIFS($M$3:$M$1002,M4,$G$3:$G$1002,"<>"&SUBSTITUTE(SUBSTITUTE(G4,"?","~?"),"*","~*"),$G$3:$G$1002,"?*")) | R4: =IF(Q4="","",IF(Q4>0,"Yes","No")) | S4: =IF(G4="","",COUNTIFS($G$3:$G$1002,SUBSTITUTE(SUBSTITUTE(G4,"?","~?"),"*","~*"),$J$3:$J$1002,"Primary")) | T4: =IF(S4="","",IF(S4>Settings!$B$4,"Yes","No")) | U4: =IF(OR(G4="",B4=""),"",IF(COUNTIFS($G$3:$G$1002,SUBSTITUTE(SUBSTITUTE(G4,"?","~?"),"*","~*"),$B$3:$B$1002,"<>"&SUBSTITUTE(SUBSTITUTE(B4,"?","~?"),"*","~*"),$B$3:$B$1002,"?*")>0,"Yes","No")) | V4: =IF(OR(G4="",I4="",O4="",O4="Unclassified"),"",IFERROR(INDEX(Settings!$E$5:$H$16,MATCH(I4,Settings!$D$5:$D$16,0),MATCH(O4,Settings!$E$4:$H$4,0)),"Check")) | W4: =IF(V4="","",IF(V4="No","Yes","No")) | X4: =IF(OR(E4="",G4=""),"",IF(LOWER(IF(RIGHT(TRIM(E4),1)="/",LEFT(TRIM(E4),LEN(TRIM(E4))-1),TRIM(E4)))<>LOWER(IF(RIGHT(TRIM(G4),1)="/",LEFT(TRIM(G4),LEN(TRIM(G4))-1),TRIM(G4))),"Yes","No")) | Y4: =IF(A4="","",(N(Q4)>0)+(T4="Yes")+(U4="Yes")+(W4="Yes")+(X4="Yes")) | Z4: =IF(A4="","",IF(G4="","Not mapped",IF(Y4=0,"OK",MID(IF(N(Q4)>0,"; Cannibalisation","")&IF(T4="Yes","; Too many primary keywords on URL","")&IF(U4="Yes","; URL spans 2+ clusters","")&IF(W4="Yes","; Intent mismatch","")&IF(X4="Yes","; Ranking URL is not the target",""),3,300)))) | AA4: =IF(G4="","",IF(COUNTIF($G$3:G4,SUBSTITUTE(SUBSTITUTE(G4,"?","~?"),"*","~*"))=1,MAX($AA$2:AA3)+1,"")) | AB4: =IF(B4="","",IF(COUNTIF($B$3:B4,SUBSTITUTE(SUBSTITUTE(B4,"?","~?"),"*","~*"))=1,MAX($AB$2:AB3)+1,""))
A5: trail running shoes for beginners | B5: Trail shoes | C5: 590 | D5: 22 | E5: https://www.stride-example.com/blog/best-trail-running-shoes/ | F5: 18 | G5: https://www.stride-example.com/blog/trail-running-for-beginners/ | H5: Planned | I5: Blog post / guide | J5: Primary | L5: New guide planned | M5: =IF(A5="","",LOWER(TRIM(SUBSTITUTE(SUBSTITUTE(A5,"?",""),"*","")))) | N5: =IF(M5="","",IF(SUMPRODUCT(ISNUMBER(SEARCH(" "&Settings!$L$5:$L$124&" "," "&M5&" "))*(Settings!$K$5:$K$124="Navigational")*(Settings!$L$5:$L$124<>""))>0,"Navigational",IF(SUMPRODUCT(ISNUMBER(SEARCH(" "&Settings!$L$5:$L$124&" "," "&M5&" "))*(Settings!$K$5:$K$124="Transactional")*(Settings!$L$5:$L$124<>""))>0,"Transactional",IF(SUMPRODUCT(ISNUMBER(SEARCH(" "&Settings!$L$5:$L$124&" "," "&M5&" "))*(Settings!$K$5:$K$124="Commercial")*(Settings!$L$5:$L$124<>""))>0,"Commercial",IF(SUMPRODUCT(ISNUMBER(SEARCH(" "&Settings!$L$5:$L$124&" "," "&M5&" "))*(Settings!$K$5:$K$124="Informational")*(Settings!$L$5:$L$124<>""))>0,"Informational","Unclassified"))))) | O5: =IF(A5="","",IF(K5<>"",PROPER(K5),N5)) | P5: =IF(A5="","",ROUND(Settings!$B$5*MIN(1,LOG10(N(C5)+1)/LOG10(Settings!$B$7+1))+Settings!$B$6*(1-MIN(100,IF(D5="",50,N(D5)))/100)+IFERROR(INDEX(Settings!$B$10:$B$14,MATCH(O5,Settings!$A$10:$A$14,0)),0),0)) | Q5: =IF(OR(A5="",G5=""),"",COUNTIFS($M$3:$M$1002,M5,$G$3:$G$1002,"<>"&SUBSTITUTE(SUBSTITUTE(G5,"?","~?"),"*","~*"),$G$3:$G$1002,"?*")) | R5: =IF(Q5="","",IF(Q5>0,"Yes","No")) | S5: =IF(G5="","",COUNTIFS($G$3:$G$1002,SUBSTITUTE(SUBSTITUTE(G5,"?","~?"),"*","~*"),$J$3:$J$1002,"Primary")) | T5: =IF(S5="","",IF(S5>Settings!$B$4,"Yes","No")) | U5: =IF(OR(G5="",B5=""),"",IF(COUNTIFS($G$3:$G$1002,SUBSTITUTE(SUBSTITUTE(G5,"?","~?"),"*","~*"),$B$3:$B$1002,"<>"&SUBSTITUTE(SUBSTITUTE(B5,"?","~?"),"*","~*"),$B$3:$B$1002,"?*")>0,"Yes","No")) | V5: =IF(OR(G5="",I5="",O5="",O5="Unclassified"),"",IFERROR(INDEX(Settings!$E$5:$H$16,MATCH(I5,Settings!$D$5:$D$16,0),MATCH(O5,Settings!$E$4:$H$4,0)),"Check")) | W5: =IF(V5="","",IF(V5="No","Yes","No")) | X5: =IF(OR(E5="",G5=""),"",IF(LOWER(IF(RIGHT(TRIM(E5),1)="/",LEFT(TRIM(E5),LEN(TRIM(E5))-1),TRIM(E5)))<>LOWER(IF(RIGHT(TRIM(G5),1)="/",LEFT(TRIM(G5),LEN(TRIM(G5))-1),TRIM(G5))),"Yes","No")) | Y5: =IF(A5="","",(N(Q5)>0)+(T5="Yes")+(U5="Yes")+(W5="Yes")+(X5="Yes")) | Z5: =IF(A5="","",IF(G5="","Not mapped",IF(Y5=0,"OK",MID(IF(N(Q5)>0,"; Cannibalisation","")&IF(T5="Yes","; Too many primary keywords on URL","")&IF(U5="Yes","; URL spans 2+ clusters","")&IF(W5="Yes","; Intent mismatch","")&IF(X5="Yes","; Ranking URL is not the target",""),3,300)))) | AA5: =IF(G5="","",IF(COUNTIF($G$3:G5,SUBSTITUTE(SUBSTITUTE(G5,"?","~?"),"*","~*"))=1,MAX($AA$2:AA4)+1,"")) | AB5: =IF(B5="","",IF(COUNTIF($B$3:B5,SUBSTITUTE(SUBSTITUTE(B5,"?","~?"),"*","~*"))=1,MAX($AB$2:AB4)+1,""))
A6: waterproof trail running shoes | B6: Trail shoes | C6: 1300 | D6: 35 | E6: https://www.stride-example.com/trail-running-shoes/ | F6: 21 | G6: https://www.stride-example.com/trail-running-shoes/waterproof/ | H6: Planned | I6: Category / collection | J6: Primary | M6: =IF(A6="","",LOWER(TRIM(SUBSTITUTE(SUBSTITUTE(A6,"?",""),"*","")))) | N6: =IF(M6="","",IF(SUMPRODUCT(ISNUMBER(SEARCH(" "&Settings!$L$5:$L$124&" "," "&M6&" "))*(Settings!$K$5:$K$124="Navigational")*(Settings!$L$5:$L$124<>""))>0,"Navigational",IF(SUMPRODUCT(ISNUMBER(SEARCH(" "&Settings!$L$5:$L$124&" "," "&M6&" "))*(Settings!$K$5:$K$124="Transactional")*(Settings!$L$5:$L$124<>""))>0,"Transactional",IF(SUMPRODUCT(ISNUMBER(SEARCH(" "&Settings!$L$5:$L$124&" "," "&M6&" "))*(Settings!$K$5:$K$124="Commercial")*(Settings!$L$5:$L$124<>""))>0,"Commercial",IF(SUMPRODUCT(ISNUMBER(SEARCH(" "&Settings!$L$5:$L$124&" "," "&M6&" "))*(Settings!$K$5:$K$124="Informational")*(Settings!$L$5:$L$124<>""))>0,"Informational","Unclassified"))))) | O6: =IF(A6="","",IF(K6<>"",PROPER(K6),N6)) | P6: =IF(A6="","",ROUND(Settings!$B$5*MIN(1,LOG10(N(C6)+1)/LOG10(Settings!$B$7+1))+Settings!$B$6*(1-MIN(100,IF(D6="",50,N(D6)))/100)+IFERROR(INDEX(Settings!$B$10:$B$14,MATCH(O6,Settings!$A$10:$A$14,0)),0),0)) | Q6: =IF(OR(A6="",G6=""),"",COUNTIFS($M$3:$M$1002,M6,$G$3:$G$1002,"<>"&SUBSTITUTE(SUBSTITUTE(G6,"?","~?"),"*","~*"),$G$3:$G$1002,"?*")) | R6: =IF(Q6="","",IF(Q6>0,"Yes","No")) | S6: =IF(G6="","",COUNTIFS($G$3:$G$1002,SUBSTITUTE(SUBSTITUTE(G6,"?","~?"),"*","~*"),$J$3:$J$1002,"Primary")) | T6: =IF(S6="","",IF(S6>Settings!$B$4,"Yes","No")) | U6: =IF(OR(G6="",B6=""),"",IF(COUNTIFS($G$3:$G$1002,SUBSTITUTE(SUBSTITUTE(G6,"?","~?"),"*","~*"),$B$3:$B$1002,"<>"&SUBSTITUTE(SUBSTITUTE(B6,"?","~?"),"*","~*"),$B$3:$B$1002,"?*")>0,"Yes","No")) | V6: =IF(OR(G6="",I6="",O6="",O6="Unclassified"),"",IFERROR(INDEX(Settings!$E$5:$H$16,MATCH(I6,Settings!$D$5:$D$16,0),MATCH(O6,Settings!$E$4:$H$4,0)),"Check")) | W6: =IF(V6="","",IF(V6="No","Yes","No")) | X6: =IF(OR(E6="",G6=""),"",IF(LOWER(IF(RIGHT(TRIM(E6),1)="/",LEFT(TRIM(E6),LEN(TRIM(E6))-1),TRIM(E6)))<>LOWER(IF(RIGHT(TRIM(G6),1)="/",LEFT(TRIM(G6),LEN(TRIM(G6))-1),TRIM(G6))),"Yes","No")) | Y6: =IF(A6="","",(N(Q6)>0)+(T6="Yes")+(U6="Yes")+(W6="Yes")+(X6="Yes")) | Z6: =IF(A6="","",IF(G6="","Not mapped",IF(Y6=0,"OK",MID(IF(N(Q6)>0,"; Cannibalisation","")&IF(T6="Yes","; Too many primary keywords on URL","")&IF(U6="Yes","; URL spans 2+ clusters","")&IF(W6="Yes","; Intent mismatch","")&IF(X6="Yes","; Ranking URL is not the target",""),3,300)))) | AA6: =IF(G6="","",IF(COUNTIF($G$3:G6,SUBSTITUTE(SUBSTITUTE(G6,"?","~?"),"*","~*"))=1,MAX($AA$2:AA5)+1,"")) | AB6: =IF(B6="","",IF(COUNTIF($B$3:B6,SUBSTITUTE(SUBSTITUTE(B6,"?","~?"),"*","~*"))=1,MAX($AB$2:AB5)+1,""))
A7: buy trail running shoes | B7: Trail shoes | C7: 210 | D7: 40 | G7: https://www.stride-example.com/blog/trail-running-for-beginners/ | H7: Planned | I7: Blog post / guide | J7: Secondary | M7: =IF(A7="","",LOWER(TRIM(SUBSTITUTE(SUBSTITUTE(A7,"?",""),"*","")))) | N7: =IF(M7="","",IF(SUMPRODUCT(ISNUMBER(SEARCH(" "&Settings!$L$5:$L$124&" "," "&M7&" "))*(Settings!$K$5:$K$124="Navigational")*(Settings!$L$5:$L$124<>""))>0,"Navigational",IF(SUMPRODUCT(ISNUMBER(SEARCH(" "&Settings!$L$5:$L$124&" "," "&M7&" "))*(Settings!$K$5:$K$124="Transactional")*(Settings!$L$5:$L$124<>""))>0,"Transactional",IF(SUMPRODUCT(ISNUMBER(SEARCH(" "&Settings!$L$5:$L$124&" "," "&M7&" "))*(Settings!$K$5:$K$124="Commercial")*(Settings!$L$5:$L$124<>""))>0,"Commercial",IF(SUMPRODUCT(ISNUMBER(SEARCH(" "&Settings!$L$5:$L$124&" "," "&M7&" "))*(Settings!$K$5:$K$124="Informational")*(Settings!$L$5:$L$124<>""))>0,"Informational","Unclassified"))))) | O7: =IF(A7="","",IF(K7<>"",PROPER(K7),N7)) | P7: =IF(A7="","",ROUND(Settings!$B$5*MIN(1,LOG10(N(C7)+1)/LOG10(Settings!$B$7+1))+Settings!$B$6*(1-MIN(100,IF(D7="",50,N(D7)))/100)+IFERROR(INDEX(Settings!$B$10:$B$14,MATCH(O7,Settings!$A$10:$A$14,0)),0),0)) | Q7: =IF(OR(A7="",G7=""),"",COUNTIFS($M$3:$M$1002,M7,$G$3:$G$1002,"<>"&SUBSTITUTE(SUBSTITUTE(G7,"?","~?"),"*","~*"),$G$3:$G$1002,"?*")) | R7: =IF(Q7="","",IF(Q7>0,"Yes","No")) | S7: =IF(G7="","",COUNTIFS($G$3:$G$1002,SUBSTITUTE(SUBSTITUTE(G7,"?","~?"),"*","~*"),$J$3:$J$1002,"Primary")) | T7: =IF(S7="","",IF(S7>Settings!$B$4,"Yes","No")) | U7: =IF(OR(G7="",B7=""),"",IF(COUNTIFS($G$3:$G$1002,SUBSTITUTE(SUBSTITUTE(G7,"?","~?"),"*","~*"),$B$3:$B$1002,"<>"&SUBSTITUTE(SUBSTITUTE(B7,"?","~?"),"*","~*"),$B$3:$B$1002,"?*")>0,"Yes","No")) | V7: =IF(OR(G7="",I7="",O7="",O7="Unclassified"),"",IFERROR(INDEX(Settings!$E$5:$H$16,MATCH(I7,Settings!$D$5:$D$16,0),MATCH(O7,Settings!$E$4:$H$4,0)),"Check")) | W7: =IF(V7="","",IF(V7="No","Yes","No")) | X7: =IF(OR(E7="",G7=""),"",IF(LOWER(IF(RIGHT(TRIM(E7),1)="/",LEFT(TRIM(E7),LEN(TRIM(E7))-1),TRIM(E7)))<>LOWER(IF(RIGHT(TRIM(G7),1)="/",LEFT(TRIM(G7),LEN(TRIM(G7))-1),TRIM(G7))),"Yes","No")) | Y7: =IF(A7="","",(N(Q7)>0)+(T7="Yes")+(U7="Yes")+(W7="Yes")+(X7="Yes")) | Z7: =IF(A7="","",IF(G7="","Not mapped",IF(Y7=0,"OK",MID(IF(N(Q7)>0,"; Cannibalisation","")&IF(T7="Yes","; Too many primary keywords on URL","")&IF(U7="Yes","; URL spans 2+ clusters","")&IF(W7="Yes","; Intent mismatch","")&IF(X7="Yes","; Ranking URL is not the target",""),3,300)))) | AA7: =IF(G7="","",IF(COUNTIF($G$3:G7,SUBSTITUTE(SUBSTITUTE(G7,"?","~?"),"*","~*"))=1,MAX($AA$2:AA6)+1,"")) | AB7: =IF(B7="","",IF(COUNTIF($B$3:B7,SUBSTITUTE(SUBSTITUTE(B7,"?","~?"),"*","~*"))=1,MAX($AB$2:AB6)+1,""))
A8: wide running shoes | B8: Wide fit | C8: 2900 | D8: 30 | E8: https://www.stride-example.com/wide-fit-running-shoes/ | F8: 7 | G8: https://www.stride-example.com/wide-fit-running-shoes/ | H8: Existing | I8: Category / collection | J8: Primary | K8: Commercial | M8: =IF(A8="","",LOWER(TRIM(SUBSTITUTE(SUBSTITUTE(A8,"?",""),"*","")))) | N8: =IF(M8="","",IF(SUMPRODUCT(ISNUMBER(SEARCH(" "&Settings!$L$5:$L$124&" "," "&M8&" "))*(Settings!$K$5:$K$124="Navigational")*(Settings!$L$5:$L$124<>""))>0,"Navigational",IF(SUMPRODUCT(ISNUMBER(SEARCH(" "&Settings!$L$5:$L$124&" "," "&M8&" "))*(Settings!$K$5:$K$124="Transactional")*(Settings!$L$5:$L$124<>""))>0,"Transactional",IF(SUMPRODUCT(ISNUMBER(SEARCH(" "&Settings!$L$5:$L$124&" "," "&M8&" "))*(Settings!$K$5:$K$124="Commercial")*(Settings!$L$5:$L$124<>""))>0,"Commercial",IF(SUMPRODUCT(ISNUMBER(SEARCH(" "&Settings!$L$5:$L$124&" "," "&M8&" "))*(Settings!$K$5:$K$124="Informational")*(Settings!$L$5:$L$124<>""))>0,"Informational","Unclassified"))))) | O8: =IF(A8="","",IF(K8<>"",PROPER(K8),N8)) | P8: =IF(A8="","",ROUND(Settings!$B$5*MIN(1,LOG10(N(C8)+1)/LOG10(Settings!$B$7+1))+Settings!$B$6*(1-MIN(100,IF(D8="",50,N(D8)))/100)+IFERROR(INDEX(Settings!$B$10:$B$14,MATCH(O8,Settings!$A$10:$A$14,0)),0),0)) | Q8: =IF(OR(A8="",G8=""),"",COUNTIFS($M$3:$M$1002,M8,$G$3:$G$1002,"<>"&SUBSTITUTE(SUBSTITUTE(G8,"?","~?"),"*","~*"),$G$3:$G$1002,"?*")) | R8: =IF(Q8="","",IF(Q8>0,"Yes","No")) | S8: =IF(G8="","",COUNTIFS($G$3:$G$1002,SUBSTITUTE(SUBSTITUTE(G8,"?","~?"),"*","~*"),$J$3:$J$1002,"Primary")) | T8: =IF(S8="","",IF(S8>Settings!$B$4,"Yes","No")) | U8: =IF(OR(G8="",B8=""),"",IF(COUNTIFS($G$3:$G$1002,SUBSTITUTE(SUBSTITUTE(G8,"?","~?"),"*","~*"),$B$3:$B$1002,"<>"&SUBSTITUTE(SUBSTITUTE(B8,"?","~?"),"*","~*"),$B$3:$B$1002,"?*")>0,"Yes","No")) | V8: =IF(OR(G8="",I8="",O8="",O8="Unclassified"),"",IFERROR(INDEX(Settings!$E$5:$H$16,MATCH(I8,Settings!$D$5:$D$16,0),MATCH(O8,Settings!$E$4:$H$4,0)),"Check")) | W8: =IF(V8="","",IF(V8="No","Yes","No")) | X8: =IF(OR(E8="",G8=""),"",IF(LOWER(IF(RIGHT(TRIM(E8),1)="/",LEFT(TRIM(E8),LEN(TRIM(E8))-1),TRIM(E8)))<>LOWER(IF(RIGHT(TRIM(G8),1)="/",LEFT(TRIM(G8),LEN(TRIM(G8))-1),TRIM(G8))),"Yes","No")) | Y8: =IF(A8="","",(N(Q8)>0)+(T8="Yes")+(U8="Yes")+(W8="Yes")+(X8="Yes")) | Z8: =IF(A8="","",IF(G8="","Not mapped",IF(Y8=0,"OK",MID(IF(N(Q8)>0,"; Cannibalisation","")&IF(T8="Yes","; Too many primary keywords on URL","")&IF(U8="Yes","; URL spans 2+ clusters","")&IF(W8="Yes","; Intent mismatch","")&IF(X8="Yes","; Ranking URL is not the target",""),3,300)))) | AA8: =IF(G8="","",IF(COUNTIF($G$3:G8,SUBSTITUTE(SUBSTITUTE(G8,"?","~?"),"*","~*"))=1,MAX($AA$2:AA7)+1,"")) | AB8: =IF(B8="","",IF(COUNTIF($B$3:B8,SUBSTITUTE(SUBSTITUTE(B8,"?","~?"),"*","~*"))=1,MAX($AB$2:AB7)+1,""))
A9: running shoes for wide feet | B9: Wide fit | C9: 1900 | D9: 28 | E9: https://www.stride-example.com/blog/wide-feet-guide/ | F9: 11 | G9: https://www.stride-example.com/wide-fit-running-shoes/ | H9: Existing | I9: Category / collection | J9: Secondary | M9: =IF(A9="","",LOWER(TRIM(SUBSTITUTE(SUBSTITUTE(A9,"?",""),"*","")))) | N9: =IF(M9="","",IF(SUMPRODUCT(ISNUMBER(SEARCH(" "&Settings!$L$5:$L$124&" "," "&M9&" "))*(Settings!$K$5:$K$124="Navigational")*(Settings!$L$5:$L$124<>""))>0,"Navigational",IF(SUMPRODUCT(ISNUMBER(SEARCH(" "&Settings!$L$5:$L$124&" "," "&M9&" "))*(Settings!$K$5:$K$124="Transactional")*(Settings!$L$5:$L$124<>""))>0,"Transactional",IF(SUMPRODUCT(ISNUMBER(SEARCH(" "&Settings!$L$5:$L$124&" "," "&M9&" "))*(Settings!$K$5:$K$124="Commercial")*(Settings!$L$5:$L$124<>""))>0,"Commercial",IF(SUMPRODUCT(ISNUMBER(SEARCH(" "&Settings!$L$5:$L$124&" "," "&M9&" "))*(Settings!$K$5:$K$124="Informational")*(Settings!$L$5:$L$124<>""))>0,"Informational","Unclassified"))))) | O9: =IF(A9="","",IF(K9<>"",PROPER(K9),N9)) | P9: =IF(A9="","",ROUND(Settings!$B$5*MIN(1,LOG10(N(C9)+1)/LOG10(Settings!$B$7+1))+Settings!$B$6*(1-MIN(100,IF(D9="",50,N(D9)))/100)+IFERROR(INDEX(Settings!$B$10:$B$14,MATCH(O9,Settings!$A$10:$A$14,0)),0),0)) | Q9: =IF(OR(A9="",G9=""),"",COUNTIFS($M$3:$M$1002,M9,$G$3:$G$1002,"<>"&SUBSTITUTE(SUBSTITUTE(G9,"?","~?"),"*","~*"),$G$3:$G$1002,"?*")) | R9: =IF(Q9="","",IF(Q9>0,"Yes","No")) | S9: =IF(G9="","",COUNTIFS($G$3:$G$1002,SUBSTITUTE(SUBSTITUTE(G9,"?","~?"),"*","~*"),$J$3:$J$1002,"Primary")) | T9: =IF(S9="","",IF(S9>Settings!$B$4,"Yes","No")) | U9: =IF(OR(G9="",B9=""),"",IF(COUNTIFS($G$3:$G$1002,SUBSTITUTE(SUBSTITUTE(G9,"?","~?"),"*","~*"),$B$3:$B$1002,"<>"&SUBSTITUTE(SUBSTITUTE(B9,"?","~?"),"*","~*"),$B$3:$B$1002,"?*")>0,"Yes","No")) | V9: =IF(OR(G9="",I9="",O9="",O9="Unclassified"),"",IFERROR(INDEX(Settings!$E$5:$H$16,MATCH(I9,Settings!$D$5:$D$16,0),MATCH(O9,Settings!$E$4:$H$4,0)),"Check")) | W9: =IF(V9="","",IF(V9="No","Yes","No")) | X9: =IF(OR(E9="",G9=""),"",IF(LOWER(IF(RIGHT(TRIM(E9),1)="/",LEFT(TRIM(E9),LEN(TRIM(E9))-1),TRIM(E9)))<>LOWER(IF(RIGHT(TRIM(G9),1)="/",LEFT(TRIM(G9),LEN(TRIM(G9))-1),TRIM(G9))),"Yes","No")) | Y9: =IF(A9="","",(N(Q9)>0)+(T9="Yes")+(U9="Yes")+(W9="Yes")+(X9="Yes")) | Z9: =IF(A9="","",IF(G9="","Not mapped",IF(Y9=0,"OK",MID(IF(N(Q9)>0,"; Cannibalisation","")&IF(T9="Yes","; Too many primary keywords on URL","")&IF(U9="Yes","; URL spans 2+ clusters","")&IF(W9="Yes","; Intent mismatch","")&IF(X9="Yes","; Ranking URL is not the target",""),3,300)))) | AA9: =IF(G9="","",IF(COUNTIF($G$3:G9,SUBSTITUTE(SUBSTITUTE(G9,"?","~?"),"*","~*"))=1,MAX($AA$2:AA8)+1,"")) | AB9: =IF(B9="","",IF(COUNTIF($B$3:B9,SUBSTITUTE(SUBSTITUTE(B9,"?","~?"),"*","~*"))=1,MAX($AB$2:AB8)+1,""))
A10: running shoes for wide feet | B10: Wide fit | C10: 1900 | D10: 28 | E10: https://www.stride-example.com/blog/wide-feet-guide/ | F10: 11 | G10: https://www.stride-example.com/blog/wide-feet-guide/ | H10: Existing | I10: Blog post / guide | J10: Primary | L10: Also mapped to the category page | M10: =IF(A10="","",LOWER(TRIM(SUBSTITUTE(SUBSTITUTE(A10,"?",""),"*","")))) | N10: =IF(M10="","",IF(SUMPRODUCT(ISNUMBER(SEARCH(" "&Settings!$L$5:$L$124&" "," "&M10&" "))*(Settings!$K$5:$K$124="Navigational")*(Settings!$L$5:$L$124<>""))>0,"Navigational",IF(SUMPRODUCT(ISNUMBER(SEARCH(" "&Settings!$L$5:$L$124&" "," "&M10&" "))*(Settings!$K$5:$K$124="Transactional")*(Settings!$L$5:$L$124<>""))>0,"Transactional",IF(SUMPRODUCT(ISNUMBER(SEARCH(" "&Settings!$L$5:$L$124&" "," "&M10&" "))*(Settings!$K$5:$K$124="Commercial")*(Settings!$L$5:$L$124<>""))>0,"Commercial",IF(SUMPRODUCT(ISNUMBER(SEARCH(" "&Settings!$L$5:$L$124&" "," "&M10&" "))*(Settings!$K$5:$K$124="Informational")*(Settings!$L$5:$L$124<>""))>0,"Informational","Unclassified"))))) | O10: =IF(A10="","",IF(K10<>"",PROPER(K10),N10)) | P10: =IF(A10="","",ROUND(Settings!$B$5*MIN(1,LOG10(N(C10)+1)/LOG10(Settings!$B$7+1))+Settings!$B$6*(1-MIN(100,IF(D10="",50,N(D10)))/100)+IFERROR(INDEX(Settings!$B$10:$B$14,MATCH(O10,Settings!$A$10:$A$14,0)),0),0)) | Q10: =IF(OR(A10="",G10=""),"",COUNTIFS($M$3:$M$1002,M10,$G$3:$G$1002,"<>"&SUBSTITUTE(SUBSTITUTE(G10,"?","~?"),"*","~*"),$G$3:$G$1002,"?*")) | R10: =IF(Q10="","",IF(Q10>0,"Yes","No")) | S10: =IF(G10="","",COUNTIFS($G$3:$G$1002,SUBSTITUTE(SUBSTITUTE(G10,"?","~?"),"*","~*"),$J$3:$J$1002,"Primary")) | T10: =IF(S10="","",IF(S10>Settings!$B$4,"Yes","No")) | U10: =IF(OR(G10="",B10=""),"",IF(COUNTIFS($G$3:$G$1002,SUBSTITUTE(SUBSTITUTE(G10,"?","~?"),"*","~*"),$B$3:$B$1002,"<>"&SUBSTITUTE(SUBSTITUTE(B10,"?","~?"),"*","~*"),$B$3:$B$1002,"?*")>0,"Yes","No")) | V10: =IF(OR(G10="",I10="",O10="",O10="Unclassified"),"",IFERROR(INDEX(Settings!$E$5:$H$16,MATCH(I10,Settings!$D$5:$D$16,0),MATCH(O10,Settings!$E$4:$H$4,0)),"Check")) | W10: =IF(V10="","",IF(V10="No","Yes","No")) | X10: =IF(OR(E10="",G10=""),"",IF(LOWER(IF(RIGHT(TRIM(E10),1)="/",LEFT(TRIM(E10),LEN(TRIM(E10))-1),TRIM(E10)))<>LOWER(IF(RIGHT(TRIM(G10),1)="/",LEFT(TRIM(G10),LEN(TRIM(G10))-1),TRIM(G10))),"Yes","No")) | Y10: =IF(A10="","",(N(Q10)>0)+(T10="Yes")+(U10="Yes")+(W10="Yes")+(X10="Yes")) | Z10: =IF(A10="","",IF(G10="","Not mapped",IF(Y10=0,"OK",MID(IF(N(Q10)>0,"; Cannibalisation","")&IF(T10="Yes","; Too many primary keywords on URL","")&IF(U10="Yes","; URL spans 2+ clusters","")&IF(W10="Yes","; Intent mismatch","")&IF(X10="Yes","; Ranking URL is not the target",""),3,300)))) | AA10: =IF(G10="","",IF(COUNTIF($G$3:G10,SUBSTITUTE(SUBSTITUTE(G10,"?","~?"),"*","~*"))=1,MAX($AA$2:AA9)+1,"")) | AB10: =IF(B10="","",IF(COUNTIF($B$3:B10,SUBSTITUTE(SUBSTITUTE(B10,"?","~?"),"*","~*"))=1,MAX($AB$2:AB9)+1,""))
A11: how to choose running shoes for wide feet | B11: Wide fit | C11: 320 | D11: 12 | E11: https://www.stride-example.com/blog/wide-feet-guide/ | F11: 4 | G11: https://www.stride-example.com/blog/wide-feet-guide/ | H11: Existing | I11: Blog post / guide | J11: Secondary | M11: =IF(A11="","",LOWER(TRIM(SUBSTITUTE(SUBSTITUTE(A11,"?",""),"*","")))) | N11: =IF(M11="","",IF(SUMPRODUCT(ISNUMBER(SEARCH(" "&Settings!$L$5:$L$124&" "," "&M11&" "))*(Settings!$K$5:$K$124="Navigational")*(Settings!$L$5:$L$124<>""))>0,"Navigational",IF(SUMPRODUCT(ISNUMBER(SEARCH(" "&Settings!$L$5:$L$124&" "," "&M11&" "))*(Settings!$K$5:$K$124="Transactional")*(Settings!$L$5:$L$124<>""))>0,"Transactional",IF(SUMPRODUCT(ISNUMBER(SEARCH(" "&Settings!$L$5:$L$124&" "," "&M11&" "))*(Settings!$K$5:$K$124="Commercial")*(Settings!$L$5:$L$124<>""))>0,"Commercial",IF(SUMPRODUCT(ISNUMBER(SEARCH(" "&Settings!$L$5:$L$124&" "," "&M11&" "))*(Settings!$K$5:$K$124="Informational")*(Settings!$L$5:$L$124<>""))>0,"Informational","Unclassified"))))) | O11: =IF(A11="","",IF(K11<>"",PROPER(K11),N11)) | P11: =IF(A11="","",ROUND(Settings!$B$5*MIN(1,LOG10(N(C11)+1)/LOG10(Settings!$B$7+1))+Settings!$B$6*(1-MIN(100,IF(D11="",50,N(D11)))/100)+IFERROR(INDEX(Settings!$B$10:$B$14,MATCH(O11,Settings!$A$10:$A$14,0)),0),0)) | Q11: =IF(OR(A11="",G11=""),"",COUNTIFS($M$3:$M$1002,M11,$G$3:$G$1002,"<>"&SUBSTITUTE(SUBSTITUTE(G11,"?","~?"),"*","~*"),$G$3:$G$1002,"?*")) | R11: =IF(Q11="","",IF(Q11>0,"Yes","No")) | S11: =IF(G11="","",COUNTIFS($G$3:$G$1002,SUBSTITUTE(SUBSTITUTE(G11,"?","~?"),"*","~*"),$J$3:$J$1002,"Primary")) | T11: =IF(S11="","",IF(S11>Settings!$B$4,"Yes","No")) | U11: =IF(OR(G11="",B11=""),"",IF(COUNTIFS($G$3:$G$1002,SUBSTITUTE(SUBSTITUTE(G11,"?","~?"),"*","~*"),$B$3:$B$1002,"<>"&SUBSTITUTE(SUBSTITUTE(B11,"?","~?"),"*","~*"),$B$3:$B$1002,"?*")>0,"Yes","No")) | V11: =IF(OR(G11="",I11="",O11="",O11="Unclassified"),"",IFERROR(INDEX(Settings!$E$5:$H$16,MATCH(I11,Settings!$D$5:$D$16,0),MATCH(O11,Settings!$E$4:$H$4,0)),"Check")) | W11: =IF(V11="","",IF(V11="No","Yes","No")) | X11: =IF(OR(E11="",G11=""),"",IF(LOWER(IF(RIGHT(TRIM(E11),1)="/",LEFT(TRIM(E11),LEN(TRIM(E11))-1),TRIM(E11)))<>LOWER(IF(RIGHT(TRIM(G11),1)="/",LEFT(TRIM(G11),LEN(TRIM(G11))-1),TRIM(G11))),"Yes","No")) | Y11: =IF(A11="","",(N(Q11)>0)+(T11="Yes")+(U11="Yes")+(W11="Yes")+(X11="Yes")) | Z11: =IF(A11="","",IF(G11="","Not mapped",IF(Y11=0,"OK",MID(IF(N(Q11)>0,"; Cannibalisation","")&IF(T11="Yes","; Too many primary keywords on URL","")&IF(U11="Yes","; URL spans 2+ clusters","")&IF(W11="Yes","; Intent mismatch","")&IF(X11="Yes","; Ranking URL is not the target",""),3,300)))) | AA11: =IF(G11="","",IF(COUNTIF($G$3:G11,SUBSTITUTE(SUBSTITUTE(G11,"?","~?"),"*","~*"))=1,MAX($AA$2:AA10)+1,"")) | AB11: =IF(B11="","",IF(COUNTIF($B$3:B11,SUBSTITUTE(SUBSTITUTE(B11,"?","~?"),"*","~*"))=1,MAX($AB$2:AB10)+1,""))
A12: marathon running shoes | B12: Marathon | C12: 2400 | D12: 48 | E12: https://www.stride-example.com/marathon-running-shoes/ | F12: 16 | G12: https://www.stride-example.com/marathon-running-shoes/ | H12: Existing | I12: Category / collection | J12: Primary | K12: Commercial | M12: =IF(A12="","",LOWER(TRIM(SUBSTITUTE(SUBSTITUTE(A12,"?",""),"*","")))) | N12: =IF(M12="","",IF(SUMPRODUCT(ISNUMBER(SEARCH(" "&Settings!$L$5:$L$124&" "," "&M12&" "))*(Settings!$K$5:$K$124="Navigational")*(Settings!$L$5:$L$124<>""))>0,"Navigational",IF(SUMPRODUCT(ISNUMBER(SEARCH(" "&Settings!$L$5:$L$124&" "," "&M12&" "))*(Settings!$K$5:$K$124="Transactional")*(Settings!$L$5:$L$124<>""))>0,"Transactional",IF(SUMPRODUCT(ISNUMBER(SEARCH(" "&Settings!$L$5:$L$124&" "," "&M12&" "))*(Settings!$K$5:$K$124="Commercial")*(Settings!$L$5:$L$124<>""))>0,"Commercial",IF(SUMPRODUCT(ISNUMBER(SEARCH(" "&Settings!$L$5:$L$124&" "," "&M12&" "))*(Settings!$K$5:$K$124="Informational")*(Settings!$L$5:$L$124<>""))>0,"Informational","Unclassified"))))) | O12: =IF(A12="","",IF(K12<>"",PROPER(K12),N12)) | P12: =IF(A12="","",ROUND(Settings!$B$5*MIN(1,LOG10(N(C12)+1)/LOG10(Settings!$B$7+1))+Settings!$B$6*(1-MIN(100,IF(D12="",50,N(D12)))/100)+IFERROR(INDEX(Settings!$B$10:$B$14,MATCH(O12,Settings!$A$10:$A$14,0)),0),0)) | Q12: =IF(OR(A12="",G12=""),"",COUNTIFS($M$3:$M$1002,M12,$G$3:$G$1002,"<>"&SUBSTITUTE(SUBSTITUTE(G12,"?","~?"),"*","~*"),$G$3:$G$1002,"?*")) | R12: =IF(Q12="","",IF(Q12>0,"Yes","No")) | S12: =IF(G12="","",COUNTIFS($G$3:$G$1002,SUBSTITUTE(SUBSTITUTE(G12,"?","~?"),"*","~*"),$J$3:$J$1002,"Primary")) | T12: =IF(S12="","",IF(S12>Settings!$B$4,"Yes","No")) | U12: =IF(OR(G12="",B12=""),"",IF(COUNTIFS($G$3:$G$1002,SUBSTITUTE(SUBSTITUTE(G12,"?","~?"),"*","~*"),$B$3:$B$1002,"<>"&SUBSTITUTE(SUBSTITUTE(B12,"?","~?"),"*","~*"),$B$3:$B$1002,"?*")>0,"Yes","No")) | V12: =IF(OR(G12="",I12="",O12="",O12="Unclassified"),"",IFERROR(INDEX(Settings!$E$5:$H$16,MATCH(I12,Settings!$D$5:$D$16,0),MATCH(O12,Settings!$E$4:$H$4,0)),"Check")) | W12: =IF(V12="","",IF(V12="No","Yes","No")) | X12: =IF(OR(E12="",G12=""),"",IF(LOWER(IF(RIGHT(TRIM(E12),1)="/",LEFT(TRIM(E12),LEN(TRIM(E12))-1),TRIM(E12)))<>LOWER(IF(RIGHT(TRIM(G12),1)="/",LEFT(TRIM(G12),LEN(TRIM(G12))-1),TRIM(G12))),"Yes","No")) | Y12: =IF(A12="","",(N(Q12)>0)+(T12="Yes")+(U12="Yes")+(W12="Yes")+(X12="Yes")) | Z12: =IF(A12="","",IF(G12="","Not mapped",IF(Y12=0,"OK",MID(IF(N(Q12)>0,"; Cannibalisation","")&IF(T12="Yes","; Too many primary keywords on URL","")&IF(U12="Yes","; URL spans 2+ clusters","")&IF(W12="Yes","; Intent mismatch","")&IF(X12="Yes","; Ranking URL is not the target",""),3,300)))) | AA12: =IF(G12="","",IF(COUNTIF($G$3:G12,SUBSTITUTE(SUBSTITUTE(G12,"?","~?"),"*","~*"))=1,MAX($AA$2:AA11)+1,"")) | AB12: =IF(B12="","",IF(COUNTIF($B$3:B12,SUBSTITUTE(SUBSTITUTE(B12,"?","~?"),"*","~*"))=1,MAX($AB$2:AB11)+1,""))
A13: best marathon shoes | B13: Marathon | C13: 1600 | D13: 52 | E13: https://www.stride-example.com/marathon-running-shoes/ | F13: 19 | G13: https://www.stride-example.com/marathon-running-shoes/ | H13: Existing | I13: Category / collection | J13: Primary | M13: =IF(A13="","",LOWER(TRIM(SUBSTITUTE(SUBSTITUTE(A13,"?",""),"*","")))) | N13: =IF(M13="","",IF(SUMPRODUCT(ISNUMBER(SEARCH(" "&Settings!$L$5:$L$124&" "," "&M13&" "))*(Settings!$K$5:$K$124="Navigational")*(Settings!$L$5:$L$124<>""))>0,"Navigational",IF(SUMPRODUCT(ISNUMBER(SEARCH(" "&Settings!$L$5:$L$124&" "," "&M13&" "))*(Settings!$K$5:$K$124="Transactional")*(Settings!$L$5:$L$124<>""))>0,"Transactional",IF(SUMPRODUCT(ISNUMBER(SEARCH(" "&Settings!$L$5:$L$124&" "," "&M13&" "))*(Settings!$K$5:$K$124="Commercial")*(Settings!$L$5:$L$124<>""))>0,"Commercial",IF(SUMPRODUCT(ISNUMBER(SEARCH(" "&Settings!$L$5:$L$124&" "," "&M13&" "))*(Settings!$K$5:$K$124="Informational")*(Settings!$L$5:$L$124<>""))>0,"Informational","Unclassified"))))) | O13: =IF(A13="","",IF(K13<>"",PROPER(K13),N13)) | P13: =IF(A13="","",ROUND(Settings!$B$5*MIN(1,LOG10(N(C13)+1)/LOG10(Settings!$B$7+1))+Settings!$B$6*(1-MIN(100,IF(D13="",50,N(D13)))/100)+IFERROR(INDEX(Settings!$B$10:$B$14,MATCH(O13,Settings!$A$10:$A$14,0)),0),0)) | Q13: =IF(OR(A13="",G13=""),"",COUNTIFS($M$3:$M$1002,M13,$G$3:$G$1002,"<>"&SUBSTITUTE(SUBSTITUTE(G13,"?","~?"),"*","~*"),$G$3:$G$1002,"?*")) | R13: =IF(Q13="","",IF(Q13>0,"Yes","No")) | S13: =IF(G13="","",COUNTIFS($G$3:$G$1002,SUBSTITUTE(SUBSTITUTE(G13,"?","~?"),"*","~*"),$J$3:$J$1002,"Primary")) | T13: =IF(S13="","",IF(S13>Settings!$B$4,"Yes","No")) | U13: =IF(OR(G13="",B13=""),"",IF(COUNTIFS($G$3:$G$1002,SUBSTITUTE(SUBSTITUTE(G13,"?","~?"),"*","~*"),$B$3:$B$1002,"<>"&SUBSTITUTE(SUBSTITUTE(B13,"?","~?"),"*","~*"),$B$3:$B$1002,"?*")>0,"Yes","No")) | V13: =IF(OR(G13="",I13="",O13="",O13="Unclassified"),"",IFERROR(INDEX(Settings!$E$5:$H$16,MATCH(I13,Settings!$D$5:$D$16,0),MATCH(O13,Settings!$E$4:$H$4,0)),"Check")) | W13: =IF(V13="","",IF(V13="No","Yes","No")) | X13: =IF(OR(E13="",G13=""),"",IF(LOWER(IF(RIGHT(TRIM(E13),1)="/",LEFT(TRIM(E13),LEN(TRIM(E13))-1),TRIM(E13)))<>LOWER(IF(RIGHT(TRIM(G13),1)="/",LEFT(TRIM(G13),LEN(TRIM(G13))-1),TRIM(G13))),"Yes","No")) | Y13: =IF(A13="","",(N(Q13)>0)+(T13="Yes")+(U13="Yes")+(W13="Yes")+(X13="Yes")) | Z13: =IF(A13="","",IF(G13="","Not mapped",IF(Y13=0,"OK",MID(IF(N(Q13)>0,"; Cannibalisation","")&IF(T13="Yes","; Too many primary keywords on URL","")&IF(U13="Yes","; URL spans 2+ clusters","")&IF(W13="Yes","; Intent mismatch","")&IF(X13="Yes","; Ranking URL is not the target",""),3,300)))) | AA13: =IF(G13="","",IF(COUNTIF($G$3:G13,SUBSTITUTE(SUBSTITUTE(G13,"?","~?"),"*","~*"))=1,MAX($AA$2:AA12)+1,"")) | AB13: =IF(B13="","",IF(COUNTIF($B$3:B13,SUBSTITUTE(SUBSTITUTE(B13,"?","~?"),"*","~*"))=1,MAX($AB$2:AB12)+1,""))
A14: carbon plate running shoes | B14: Marathon | C14: 1000 | D14: 44 | G14: https://www.stride-example.com/marathon-running-shoes/carbon-plate/ | H14: Planned | I14: Category / collection | J14: Primary | M14: =IF(A14="","",LOWER(TRIM(SUBSTITUTE(SUBSTITUTE(A14,"?",""),"*","")))) | N14: =IF(M14="","",IF(SUMPRODUCT(ISNUMBER(SEARCH(" "&Settings!$L$5:$L$124&" "," "&M14&" "))*(Settings!$K$5:$K$124="Navigational")*(Settings!$L$5:$L$124<>""))>0,"Navigational",IF(SUMPRODUCT(ISNUMBER(SEARCH(" "&Settings!$L$5:$L$124&" "," "&M14&" "))*(Settings!$K$5:$K$124="Transactional")*(Settings!$L$5:$L$124<>""))>0,"Transactional",IF(SUMPRODUCT(ISNUMBER(SEARCH(" "&Settings!$L$5:$L$124&" "," "&M14&" "))*(Settings!$K$5:$K$124="Commercial")*(Settings!$L$5:$L$124<>""))>0,"Commercial",IF(SUMPRODUCT(ISNUMBER(SEARCH(" "&Settings!$L$5:$L$124&" "," "&M14&" "))*(Settings!$K$5:$K$124="Informational")*(Settings!$L$5:$L$124<>""))>0,"Informational","Unclassified"))))) | O14: =IF(A14="","",IF(K14<>"",PROPER(K14),N14)) | P14: =IF(A14="","",ROUND(Settings!$B$5*MIN(1,LOG10(N(C14)+1)/LOG10(Settings!$B$7+1))+Settings!$B$6*(1-MIN(100,IF(D14="",50,N(D14)))/100)+IFERROR(INDEX(Settings!$B$10:$B$14,MATCH(O14,Settings!$A$10:$A$14,0)),0),0)) | Q14: =IF(OR(A14="",G14=""),"",COUNTIFS($M$3:$M$1002,M14,$G$3:$G$1002,"<>"&SUBSTITUTE(SUBSTITUTE(G14,"?","~?"),"*","~*"),$G$3:$G$1002,"?*")) | R14: =IF(Q14="","",IF(Q14>0,"Yes","No")) | S14: =IF(G14="","",COUNTIFS($G$3:$G$1002,SUBSTITUTE(SUBSTITUTE(G14,"?","~?"),"*","~*"),$J$3:$J$1002,"Primary")) | T14: =IF(S14="","",IF(S14>Settings!$B$4,"Yes","No")) | U14: =IF(OR(G14="",B14=""),"",IF(COUNTIFS($G$3:$G$1002,SUBSTITUTE(SUBSTITUTE(G14,"?","~?"),"*","~*"),$B$3:$B$1002,"<>"&SUBSTITUTE(SUBSTITUTE(B14,"?","~?"),"*","~*"),$B$3:$B$1002,"?*")>0,"Yes","No")) | V14: =IF(OR(G14="",I14="",O14="",O14="Unclassified"),"",IFERROR(INDEX(Settings!$E$5:$H$16,MATCH(I14,Settings!$D$5:$D$16,0),MATCH(O14,Settings!$E$4:$H$4,0)),"Check")) | W14: =IF(V14="","",IF(V14="No","Yes","No")) | X14: =IF(OR(E14="",G14=""),"",IF(LOWER(IF(RIGHT(TRIM(E14),1)="/",LEFT(TRIM(E14),LEN(TRIM(E14))-1),TRIM(E14)))<>LOWER(IF(RIGHT(TRIM(G14),1)="/",LEFT(TRIM(G14),LEN(TRIM(G14))-1),TRIM(G14))),"Yes","No")) | Y14: =IF(A14="","",(N(Q14)>0)+(T14="Yes")+(U14="Yes")+(W14="Yes")+(X14="Yes")) | Z14: =IF(A14="","",IF(G14="","Not mapped",IF(Y14=0,"OK",MID(IF(N(Q14)>0,"; Cannibalisation","")&IF(T14="Yes","; Too many primary keywords on URL","")&IF(U14="Yes","; URL spans 2+ clusters","")&IF(W14="Yes","; Intent mismatch","")&IF(X14="Yes","; Ranking URL is not the target",""),3,300)))) | AA14: =IF(G14="","",IF(COUNTIF($G$3:G14,SUBSTITUTE(SUBSTITUTE(G14,"?","~?"),"*","~*"))=1,MAX($AA$2:AA13)+1,"")) | AB14: =IF(B14="","",IF(COUNTIF($B$3:B14,SUBSTITUTE(SUBSTITUTE(B14,"?","~?"),"*","~*"))=1,MAX($AB$2:AB13)+1,""))
A15: what are carbon plate shoes | B15: Marathon | C15: 480 | D15: 18 | G15: https://www.stride-example.com/glossary/carbon-plate/ | H15: Planned | I15: Glossary / definition | J15: Primary | M15: =IF(A15="","",LOWER(TRIM(SUBSTITUTE(SUBSTITUTE(A15,"?",""),"*","")))) | N15: =IF(M15="","",IF(SUMPRODUCT(ISNUMBER(SEARCH(" "&Settings!$L$5:$L$124&" "," "&M15&" "))*(Settings!$K$5:$K$124="Navigational")*(Settings!$L$5:$L$124<>""))>0,"Navigational",IF(SUMPRODUCT(ISNUMBER(SEARCH(" "&Settings!$L$5:$L$124&" "," "&M15&" "))*(Settings!$K$5:$K$124="Transactional")*(Settings!$L$5:$L$124<>""))>0,"Transactional",IF(SUMPRODUCT(ISNUMBER(SEARCH(" "&Settings!$L$5:$L$124&" "," "&M15&" "))*(Settings!$K$5:$K$124="Commercial")*(Settings!$L$5:$L$124<>""))>0,"Commercial",IF(SUMPRODUCT(ISNUMBER(SEARCH(" "&Settings!$L$5:$L$124&" "," "&M15&" "))*(Settings!$K$5:$K$124="Informational")*(Settings!$L$5:$L$124<>""))>0,"Informational","Unclassified"))))) | O15: =IF(A15="","",IF(K15<>"",PROPER(K15),N15)) | P15: =IF(A15="","",ROUND(Settings!$B$5*MIN(1,LOG10(N(C15)+1)/LOG10(Settings!$B$7+1))+Settings!$B$6*(1-MIN(100,IF(D15="",50,N(D15)))/100)+IFERROR(INDEX(Settings!$B$10:$B$14,MATCH(O15,Settings!$A$10:$A$14,0)),0),0)) | Q15: =IF(OR(A15="",G15=""),"",COUNTIFS($M$3:$M$1002,M15,$G$3:$G$1002,"<>"&SUBSTITUTE(SUBSTITUTE(G15,"?","~?"),"*","~*"),$G$3:$G$1002,"?*")) | R15: =IF(Q15="","",IF(Q15>0,"Yes","No")) | S15: =IF(G15="","",COUNTIFS($G$3:$G$1002,SUBSTITUTE(SUBSTITUTE(G15,"?","~?"),"*","~*"),$J$3:$J$1002,"Primary")) | T15: =IF(S15="","",IF(S15>Settings!$B$4,"Yes","No")) | U15: =IF(OR(G15="",B15=""),"",IF(COUNTIFS($G$3:$G$1002,SUBSTITUTE(SUBSTITUTE(G15,"?","~?"),"*","~*"),$B$3:$B$1002,"<>"&SUBSTITUTE(SUBSTITUTE(B15,"?","~?"),"*","~*"),$B$3:$B$1002,"?*")>0,"Yes","No")) | V15: =IF(OR(G15="",I15="",O15="",O15="Unclassified"),"",IFERROR(INDEX(Settings!$E$5:$H$16,MATCH(I15,Settings!$D$5:$D$16,0),MATCH(O15,Settings!$E$4:$H$4,0)),"Check")) | W15: =IF(V15="","",IF(V15="No","Yes","No")) | X15: =IF(OR(E15="",G15=""),"",IF(LOWER(IF(RIGHT(TRIM(E15),1)="/",LEFT(TRIM(E15),LEN(TRIM(E15))-1),TRIM(E15)))<>LOWER(IF(RIGHT(TRIM(G15),1)="/",LEFT(TRIM(G15),LEN(TRIM(G15))-1),TRIM(G15))),"Yes","No")) | Y15: =IF(A15="","",(N(Q15)>0)+(T15="Yes")+(U15="Yes")+(W15="Yes")+(X15="Yes")) | Z15: =IF(A15="","",IF(G15="","Not mapped",IF(Y15=0,"OK",MID(IF(N(Q15)>0,"; Cannibalisation","")&IF(T15="Yes","; Too many primary keywords on URL","")&IF(U15="Yes","; URL spans 2+ clusters","")&IF(W15="Yes","; Intent mismatch","")&IF(X15="Yes","; Ranking URL is not the target",""),3,300)))) | AA15: =IF(G15="","",IF(COUNTIF($G$3:G15,SUBSTITUTE(SUBSTITUTE(G15,"?","~?"),"*","~*"))=1,MAX($AA$2:AA14)+1,"")) | AB15: =IF(B15="","",IF(COUNTIF($B$3:B15,SUBSTITUTE(SUBSTITUTE(B15,"?","~?"),"*","~*"))=1,MAX($AB$2:AB14)+1,""))
A16: hoka vs brooks | B16: Brand comparisons | C16: 880 | D16: 26 | E16: https://www.stride-example.com/blog/hoka-vs-brooks/ | F16: 6 | G16: https://www.stride-example.com/blog/hoka-vs-brooks/ | H16: Existing | I16: Comparison / review | J16: Primary | M16: =IF(A16="","",LOWER(TRIM(SUBSTITUTE(SUBSTITUTE(A16,"?",""),"*","")))) | N16: =IF(M16="","",IF(SUMPRODUCT(ISNUMBER(SEARCH(" "&Settings!$L$5:$L$124&" "," "&M16&" "))*(Settings!$K$5:$K$124="Navigational")*(Settings!$L$5:$L$124<>""))>0,"Navigational",IF(SUMPRODUCT(ISNUMBER(SEARCH(" "&Settings!$L$5:$L$124&" "," "&M16&" "))*(Settings!$K$5:$K$124="Transactional")*(Settings!$L$5:$L$124<>""))>0,"Transactional",IF(SUMPRODUCT(ISNUMBER(SEARCH(" "&Settings!$L$5:$L$124&" "," "&M16&" "))*(Settings!$K$5:$K$124="Commercial")*(Settings!$L$5:$L$124<>""))>0,"Commercial",IF(SUMPRODUCT(ISNUMBER(SEARCH(" "&Settings!$L$5:$L$124&" "," "&M16&" "))*(Settings!$K$5:$K$124="Informational")*(Settings!$L$5:$L$124<>""))>0,"Informational","Unclassified"))))) | O16: =IF(A16="","",IF(K16<>"",PROPER(K16),N16)) | P16: =IF(A16="","",ROUND(Settings!$B$5*MIN(1,LOG10(N(C16)+1)/LOG10(Settings!$B$7+1))+Settings!$B$6*(1-MIN(100,IF(D16="",50,N(D16)))/100)+IFERROR(INDEX(Settings!$B$10:$B$14,MATCH(O16,Settings!$A$10:$A$14,0)),0),0)) | Q16: =IF(OR(A16="",G16=""),"",COUNTIFS($M$3:$M$1002,M16,$G$3:$G$1002,"<>"&SUBSTITUTE(SUBSTITUTE(G16,"?","~?"),"*","~*"),$G$3:$G$1002,"?*")) | R16: =IF(Q16="","",IF(Q16>0,"Yes","No")) | S16: =IF(G16="","",COUNTIFS($G$3:$G$1002,SUBSTITUTE(SUBSTITUTE(G16,"?","~?"),"*","~*"),$J$3:$J$1002,"Primary")) | T16: =IF(S16="","",IF(S16>Settings!$B$4,"Yes","No")) | U16: =IF(OR(G16="",B16=""),"",IF(COUNTIFS($G$3:$G$1002,SUBSTITUTE(SUBSTITUTE(G16,"?","~?"),"*","~*"),$B$3:$B$1002,"<>"&SUBSTITUTE(SUBSTITUTE(B16,"?","~?"),"*","~*"),$B$3:$B$1002,"?*")>0,"Yes","No")) | V16: =IF(OR(G16="",I16="",O16="",O16="Unclassified"),"",IFERROR(INDEX(Settings!$E$5:$H$16,MATCH(I16,Settings!$D$5:$D$16,0),MATCH(O16,Settings!$E$4:$H$4,0)),"Check")) | W16: =IF(V16="","",IF(V16="No","Yes","No")) | X16: =IF(OR(E16="",G16=""),"",IF(LOWER(IF(RIGHT(TRIM(E16),1)="/",LEFT(TRIM(E16),LEN(TRIM(E16))-1),TRIM(E16)))<>LOWER(IF(RIGHT(TRIM(G16),1)="/",LEFT(TRIM(G16),LEN(TRIM(G16))-1),TRIM(G16))),"Yes","No")) | Y16: =IF(A16="","",(N(Q16)>0)+(T16="Yes")+(U16="Yes")+(W16="Yes")+(X16="Yes")) | Z16: =IF(A16="","",IF(G16="","Not mapped",IF(Y16=0,"OK",MID(IF(N(Q16)>0,"; Cannibalisation","")&IF(T16="Yes","; Too many primary keywords on URL","")&IF(U16="Yes","; URL spans 2+ clusters","")&IF(W16="Yes","; Intent mismatch","")&IF(X16="Yes","; Ranking URL is not the target",""),3,300)))) | AA16: =IF(G16="","",IF(COUNTIF($G$3:G16,SUBSTITUTE(SUBSTITUTE(G16,"?","~?"),"*","~*"))=1,MAX($AA$2:AA15)+1,"")) | AB16: =IF(B16="","",IF(COUNTIF($B$3:B16,SUBSTITUTE(SUBSTITUTE(B16,"?","~?"),"*","~*"))=1,MAX($AB$2:AB15)+1,""))
A17: hoka clifton vs brooks ghost | B17: Brand comparisons | C17: 720 | D17: 21 | E17: https://www.stride-example.com/blog/hoka-vs-brooks/ | F17: 8 | G17: https://www.stride-example.com/blog/hoka-vs-brooks/ | H17: Existing | I17: Comparison / review | J17: Secondary | M17: =IF(A17="","",LOWER(TRIM(SUBSTITUTE(SUBSTITUTE(A17,"?",""),"*","")))) | N17: =IF(M17="","",IF(SUMPRODUCT(ISNUMBER(SEARCH(" "&Settings!$L$5:$L$124&" "," "&M17&" "))*(Settings!$K$5:$K$124="Navigational")*(Settings!$L$5:$L$124<>""))>0,"Navigational",IF(SUMPRODUCT(ISNUMBER(SEARCH(" "&Settings!$L$5:$L$124&" "," "&M17&" "))*(Settings!$K$5:$K$124="Transactional")*(Settings!$L$5:$L$124<>""))>0,"Transactional",IF(SUMPRODUCT(ISNUMBER(SEARCH(" "&Settings!$L$5:$L$124&" "," "&M17&" "))*(Settings!$K$5:$K$124="Commercial")*(Settings!$L$5:$L$124<>""))>0,"Commercial",IF(SUMPRODUCT(ISNUMBER(SEARCH(" "&Settings!$L$5:$L$124&" "," "&M17&" "))*(Settings!$K$5:$K$124="Informational")*(Settings!$L$5:$L$124<>""))>0,"Informational","Unclassified"))))) | O17: =IF(A17="","",IF(K17<>"",PROPER(K17),N17)) | P17: =IF(A17="","",ROUND(Settings!$B$5*MIN(1,LOG10(N(C17)+1)/LOG10(Settings!$B$7+1))+Settings!$B$6*(1-MIN(100,IF(D17="",50,N(D17)))/100)+IFERROR(INDEX(Settings!$B$10:$B$14,MATCH(O17,Settings!$A$10:$A$14,0)),0),0)) | Q17: =IF(OR(A17="",G17=""),"",COUNTIFS($M$3:$M$1002,M17,$G$3:$G$1002,"<>"&SUBSTITUTE(SUBSTITUTE(G17,"?","~?"),"*","~*"),$G$3:$G$1002,"?*")) | R17: =IF(Q17="","",IF(Q17>0,"Yes","No")) | S17: =IF(G17="","",COUNTIFS($G$3:$G$1002,SUBSTITUTE(SUBSTITUTE(G17,"?","~?"),"*","~*"),$J$3:$J$1002,"Primary")) | T17: =IF(S17="","",IF(S17>Settings!$B$4,"Yes","No")) | U17: =IF(OR(G17="",B17=""),"",IF(COUNTIFS($G$3:$G$1002,SUBSTITUTE(SUBSTITUTE(G17,"?","~?"),"*","~*"),$B$3:$B$1002,"<>"&SUBSTITUTE(SUBSTITUTE(B17,"?","~?"),"*","~*"),$B$3:$B$1002,"?*")>0,"Yes","No")) | V17: =IF(OR(G17="",I17="",O17="",O17="Unclassified"),"",IFERROR(INDEX(Settings!$E$5:$H$16,MATCH(I17,Settings!$D$5:$D$16,0),MATCH(O17,Settings!$E$4:$H$4,0)),"Check")) | W17: =IF(V17="","",IF(V17="No","Yes","No")) | X17: =IF(OR(E17="",G17=""),"",IF(LOWER(IF(RIGHT(TRIM(E17),1)="/",LEFT(TRIM(E17),LEN(TRIM(E17))-1),TRIM(E17)))<>LOWER(IF(RIGHT(TRIM(G17),1)="/",LEFT(TRIM(G17),LEN(TRIM(G17))-1),TRIM(G17))),"Yes","No")) | Y17: =IF(A17="","",(N(Q17)>0)+(T17="Yes")+(U17="Yes")+(W17="Yes")+(X17="Yes")) | Z17: =IF(A17="","",IF(G17="","Not mapped",IF(Y17=0,"OK",MID(IF(N(Q17)>0,"; Cannibalisation","")&IF(T17="Yes","; Too many primary keywords on URL","")&IF(U17="Yes","; URL spans 2+ clusters","")&IF(W17="Yes","; Intent mismatch","")&IF(X17="Yes","; Ranking URL is not the target",""),3,300)))) | AA17: =IF(G17="","",IF(COUNTIF($G$3:G17,SUBSTITUTE(SUBSTITUTE(G17,"?","~?"),"*","~*"))=1,MAX($AA$2:AA16)+1,"")) | AB17: =IF(B17="","",IF(COUNTIF($B$3:B17,SUBSTITUTE(SUBSTITUTE(B17,"?","~?"),"*","~*"))=1,MAX($AB$2:AB16)+1,""))
A18: asics gel nimbus review | B18: Brand comparisons | C18: 1300 | D18: 33 | G18: https://www.stride-example.com/reviews/asics-gel-nimbus/ | H18: Planned | I18: Comparison / review | J18: Primary | M18: =IF(A18="","",LOWER(TRIM(SUBSTITUTE(SUBSTITUTE(A18,"?",""),"*","")))) | N18: =IF(M18="","",IF(SUMPRODUCT(ISNUMBER(SEARCH(" "&Settings!$L$5:$L$124&" "," "&M18&" "))*(Settings!$K$5:$K$124="Navigational")*(Settings!$L$5:$L$124<>""))>0,"Navigational",IF(SUMPRODUCT(ISNUMBER(SEARCH(" "&Settings!$L$5:$L$124&" "," "&M18&" "))*(Settings!$K$5:$K$124="Transactional")*(Settings!$L$5:$L$124<>""))>0,"Transactional",IF(SUMPRODUCT(ISNUMBER(SEARCH(" "&Settings!$L$5:$L$124&" "," "&M18&" "))*(Settings!$K$5:$K$124="Commercial")*(Settings!$L$5:$L$124<>""))>0,"Commercial",IF(SUMPRODUCT(ISNUMBER(SEARCH(" "&Settings!$L$5:$L$124&" "," "&M18&" "))*(Settings!$K$5:$K$124="Informational")*(Settings!$L$5:$L$124<>""))>0,"Informational","Unclassified"))))) | O18: =IF(A18="","",IF(K18<>"",PROPER(K18),N18)) | P18: =IF(A18="","",ROUND(Settings!$B$5*MIN(1,LOG10(N(C18)+1)/LOG10(Settings!$B$7+1))+Settings!$B$6*(1-MIN(100,IF(D18="",50,N(D18)))/100)+IFERROR(INDEX(Settings!$B$10:$B$14,MATCH(O18,Settings!$A$10:$A$14,0)),0),0)) | Q18: =IF(OR(A18="",G18=""),"",COUNTIFS($M$3:$M$1002,M18,$G$3:$G$1002,"<>"&SUBSTITUTE(SUBSTITUTE(G18,"?","~?"),"*","~*"),$G$3:$G$1002,"?*")) | R18: =IF(Q18="","",IF(Q18>0,"Yes","No")) | S18: =IF(G18="","",COUNTIFS($G$3:$G$1002,SUBSTITUTE(SUBSTITUTE(G18,"?","~?"),"*","~*"),$J$3:$J$1002,"Primary")) | T18: =IF(S18="","",IF(S18>Settings!$B$4,"Yes","No")) | U18: =IF(OR(G18="",B18=""),"",IF(COUNTIFS($G$3:$G$1002,SUBSTITUTE(SUBSTITUTE(G18,"?","~?"),"*","~*"),$B$3:$B$1002,"<>"&SUBSTITUTE(SUBSTITUTE(B18,"?","~?"),"*","~*"),$B$3:$B$1002,"?*")>0,"Yes","No")) | V18: =IF(OR(G18="",I18="",O18="",O18="Unclassified"),"",IFERROR(INDEX(Settings!$E$5:$H$16,MATCH(I18,Settings!$D$5:$D$16,0),MATCH(O18,Settings!$E$4:$H$4,0)),"Check")) | W18: =IF(V18="","",IF(V18="No","Yes","No")) | X18: =IF(OR(E18="",G18=""),"",IF(LOWER(IF(RIGHT(TRIM(E18),1)="/",LEFT(TRIM(E18),LEN(TRIM(E18))-1),TRIM(E18)))<>LOWER(IF(RIGHT(TRIM(G18),1)="/",LEFT(TRIM(G18),LEN(TRIM(G18))-1),TRIM(G18))),"Yes","No")) | Y18: =IF(A18="","",(N(Q18)>0)+(T18="Yes")+(U18="Yes")+(W18="Yes")+(X18="Yes")) | Z18: =IF(A18="","",IF(G18="","Not mapped",IF(Y18=0,"OK",MID(IF(N(Q18)>0,"; Cannibalisation","")&IF(T18="Yes","; Too many primary keywords on URL","")&IF(U18="Yes","; URL spans 2+ clusters","")&IF(W18="Yes","; Intent mismatch","")&IF(X18="Yes","; Ranking URL is not the target",""),3,300)))) | AA18: =IF(G18="","",IF(COUNTIF($G$3:G18,SUBSTITUTE(SUBSTITUTE(G18,"?","~?"),"*","~*"))=1,MAX($AA$2:AA17)+1,"")) | AB18: =IF(B18="","",IF(COUNTIF($B$3:B18,SUBSTITUTE(SUBSTITUTE(B18,"?","~?"),"*","~*"))=1,MAX($AB$2:AB17)+1,""))
A19: stride and co discount code | B19: Brand & store | C19: 390 | D19: 5 | E19: https://www.stride-example.com/offers/ | F19: 2 | G19: https://www.stride-example.com/offers/ | H19: Existing | I19: Landing page | J19: Primary | M19: =IF(A19="","",LOWER(TRIM(SUBSTITUTE(SUBSTITUTE(A19,"?",""),"*","")))) | N19: =IF(M19="","",IF(SUMPRODUCT(ISNUMBER(SEARCH(" "&Settings!$L$5:$L$124&" "," "&M19&" "))*(Settings!$K$5:$K$124="Navigational")*(Settings!$L$5:$L$124<>""))>0,"Navigational",IF(SUMPRODUCT(ISNUMBER(SEARCH(" "&Settings!$L$5:$L$124&" "," "&M19&" "))*(Settings!$K$5:$K$124="Transactional")*(Settings!$L$5:$L$124<>""))>0,"Transactional",IF(SUMPRODUCT(ISNUMBER(SEARCH(" "&Settings!$L$5:$L$124&" "," "&M19&" "))*(Settings!$K$5:$K$124="Commercial")*(Settings!$L$5:$L$124<>""))>0,"Commercial",IF(SUMPRODUCT(ISNUMBER(SEARCH(" "&Settings!$L$5:$L$124&" "," "&M19&" "))*(Settings!$K$5:$K$124="Informational")*(Settings!$L$5:$L$124<>""))>0,"Informational","Unclassified"))))) | O19: =IF(A19="","",IF(K19<>"",PROPER(K19),N19)) | P19: =IF(A19="","",ROUND(Settings!$B$5*MIN(1,LOG10(N(C19)+1)/LOG10(Settings!$B$7+1))+Settings!$B$6*(1-MIN(100,IF(D19="",50,N(D19)))/100)+IFERROR(INDEX(Settings!$B$10:$B$14,MATCH(O19,Settings!$A$10:$A$14,0)),0),0)) | Q19: =IF(OR(A19="",G19=""),"",COUNTIFS($M$3:$M$1002,M19,$G$3:$G$1002,"<>"&SUBSTITUTE(SUBSTITUTE(G19,"?","~?"),"*","~*"),$G$3:$G$1002,"?*")) | R19: =IF(Q19="","",IF(Q19>0,"Yes","No")) | S19: =IF(G19="","",COUNTIFS($G$3:$G$1002,SUBSTITUTE(SUBSTITUTE(G19,"?","~?"),"*","~*"),$J$3:$J$1002,"Primary")) | T19: =IF(S19="","",IF(S19>Settings!$B$4,"Yes","No")) | U19: =IF(OR(G19="",B19=""),"",IF(COUNTIFS($G$3:$G$1002,SUBSTITUTE(SUBSTITUTE(G19,"?","~?"),"*","~*"),$B$3:$B$1002,"<>"&SUBSTITUTE(SUBSTITUTE(B19,"?","~?"),"*","~*"),$B$3:$B$1002,"?*")>0,"Yes","No")) | V19: =IF(OR(G19="",I19="",O19="",O19="Unclassified"),"",IFERROR(INDEX(Settings!$E$5:$H$16,MATCH(I19,Settings!$D$5:$D$16,0),MATCH(O19,Settings!$E$4:$H$4,0)),"Check")) | W19: =IF(V19="","",IF(V19="No","Yes","No")) | X19: =IF(OR(E19="",G19=""),"",IF(LOWER(IF(RIGHT(TRIM(E19),1)="/",LEFT(TRIM(E19),LEN(TRIM(E19))-1),TRIM(E19)))<>LOWER(IF(RIGHT(TRIM(G19),1)="/",LEFT(TRIM(G19),LEN(TRIM(G19))-1),TRIM(G19))),"Yes","No")) | Y19: =IF(A19="","",(N(Q19)>0)+(T19="Yes")+(U19="Yes")+(W19="Yes")+(X19="Yes")) | Z19: =IF(A19="","",IF(G19="","Not mapped",IF(Y19=0,"OK",MID(IF(N(Q19)>0,"; Cannibalisation","")&IF(T19="Yes","; Too many primary keywords on URL","")&IF(U19="Yes","; URL spans 2+ clusters","")&IF(W19="Yes","; Intent mismatch","")&IF(X19="Yes","; Ranking URL is not the target",""),3,300)))) | AA19: =IF(G19="","",IF(COUNTIF($G$3:G19,SUBSTITUTE(SUBSTITUTE(G19,"?","~?"),"*","~*"))=1,MAX($AA$2:AA18)+1,"")) | AB19: =IF(B19="","",IF(COUNTIF($B$3:B19,SUBSTITUTE(SUBSTITUTE(B19,"?","~?"),"*","~*"))=1,MAX($AB$2:AB18)+1,""))
A20: stride and co returns | B20: Brand & store | C20: 170 | D20: 3 | E20: https://www.stride-example.com/help/returns/ | F20: 1 | G20: https://www.stride-example.com/help/returns/ | H20: Existing | I20: Support / docs | J20: Primary | M20: =IF(A20="","",LOWER(TRIM(SUBSTITUTE(SUBSTITUTE(A20,"?",""),"*","")))) | N20: =IF(M20="","",IF(SUMPRODUCT(ISNUMBER(SEARCH(" "&Settings!$L$5:$L$124&" "," "&M20&" "))*(Settings!$K$5:$K$124="Navigational")*(Settings!$L$5:$L$124<>""))>0,"Navigational",IF(SUMPRODUCT(ISNUMBER(SEARCH(" "&Settings!$L$5:$L$124&" "," "&M20&" "))*(Settings!$K$5:$K$124="Transactional")*(Settings!$L$5:$L$124<>""))>0,"Transactional",IF(SUMPRODUCT(ISNUMBER(SEARCH(" "&Settings!$L$5:$L$124&" "," "&M20&" "))*(Settings!$K$5:$K$124="Commercial")*(Settings!$L$5:$L$124<>""))>0,"Commercial",IF(SUMPRODUCT(ISNUMBER(SEARCH(" "&Settings!$L$5:$L$124&" "," "&M20&" "))*(Settings!$K$5:$K$124="Informational")*(Settings!$L$5:$L$124<>""))>0,"Informational","Unclassified"))))) | O20: =IF(A20="","",IF(K20<>"",PROPER(K20),N20)) | P20: =IF(A20="","",ROUND(Settings!$B$5*MIN(1,LOG10(N(C20)+1)/LOG10(Settings!$B$7+1))+Settings!$B$6*(1-MIN(100,IF(D20="",50,N(D20)))/100)+IFERROR(INDEX(Settings!$B$10:$B$14,MATCH(O20,Settings!$A$10:$A$14,0)),0),0)) | Q20: =IF(OR(A20="",G20=""),"",COUNTIFS($M$3:$M$1002,M20,$G$3:$G$1002,"<>"&SUBSTITUTE(SUBSTITUTE(G20,"?","~?"),"*","~*"),$G$3:$G$1002,"?*")) | R20: =IF(Q20="","",IF(Q20>0,"Yes","No")) | S20: =IF(G20="","",COUNTIFS($G$3:$G$1002,SUBSTITUTE(SUBSTITUTE(G20,"?","~?"),"*","~*"),$J$3:$J$1002,"Primary")) | T20: =IF(S20="","",IF(S20>Settings!$B$4,"Yes","No")) | U20: =IF(OR(G20="",B20=""),"",IF(COUNTIFS($G$3:$G$1002,SUBSTITUTE(SUBSTITUTE(G20,"?","~?"),"*","~*"),$B$3:$B$1002,"<>"&SUBSTITUTE(SUBSTITUTE(B20,"?","~?"),"*","~*"),$B$3:$B$1002,"?*")>0,"Yes","No")) | V20: =IF(OR(G20="",I20="",O20="",O20="Unclassified"),"",IFERROR(INDEX(Settings!$E$5:$H$16,MATCH(I20,Settings!$D$5:$D$16,0),MATCH(O20,Settings!$E$4:$H$4,0)),"Check")) | W20: =IF(V20="","",IF(V20="No","Yes","No")) | X20: =IF(OR(E20="",G20=""),"",IF(LOWER(IF(RIGHT(TRIM(E20),1)="/",LEFT(TRIM(E20),LEN(TRIM(E20))-1),TRIM(E20)))<>LOWER(IF(RIGHT(TRIM(G20),1)="/",LEFT(TRIM(G20),LEN(TRIM(G20))-1),TRIM(G20))),"Yes","No")) | Y20: =IF(A20="","",(N(Q20)>0)+(T20="Yes")+(U20="Yes")+(W20="Yes")+(X20="Yes")) | Z20: =IF(A20="","",IF(G20="","Not mapped",IF(Y20=0,"OK",MID(IF(N(Q20)>0,"; Cannibalisation","")&IF(T20="Yes","; Too many primary keywords on URL","")&IF(U20="Yes","; URL spans 2+ clusters","")&IF(W20="Yes","; Intent mismatch","")&IF(X20="Yes","; Ranking URL is not the target",""),3,300)))) | AA20: =IF(G20="","",IF(COUNTIF($G$3:G20,SUBSTITUTE(SUBSTITUTE(G20,"?","~?"),"*","~*"))=1,MAX($AA$2:AA19)+1,"")) | AB20: =IF(B20="","",IF(COUNTIF($B$3:B20,SUBSTITUTE(SUBSTITUTE(B20,"?","~?"),"*","~*"))=1,MAX($AB$2:AB19)+1,""))
A21: running shoe shop london | B21: Brand & store | C21: 880 | D21: 38 | E21: https://www.stride-example.com/stores/london/ | F21: 5 | G21: https://www.stride-example.com/stores/london/ | H21: Existing | I21: Store / location page | J21: Primary | M21: =IF(A21="","",LOWER(TRIM(SUBSTITUTE(SUBSTITUTE(A21,"?",""),"*","")))) | N21: =IF(M21="","",IF(SUMPRODUCT(ISNUMBER(SEARCH(" "&Settings!$L$5:$L$124&" "," "&M21&" "))*(Settings!$K$5:$K$124="Navigational")*(Settings!$L$5:$L$124<>""))>0,"Navigational",IF(SUMPRODUCT(ISNUMBER(SEARCH(" "&Settings!$L$5:$L$124&" "," "&M21&" "))*(Settings!$K$5:$K$124="Transactional")*(Settings!$L$5:$L$124<>""))>0,"Transactional",IF(SUMPRODUCT(ISNUMBER(SEARCH(" "&Settings!$L$5:$L$124&" "," "&M21&" "))*(Settings!$K$5:$K$124="Commercial")*(Settings!$L$5:$L$124<>""))>0,"Commercial",IF(SUMPRODUCT(ISNUMBER(SEARCH(" "&Settings!$L$5:$L$124&" "," "&M21&" "))*(Settings!$K$5:$K$124="Informational")*(Settings!$L$5:$L$124<>""))>0,"Informational","Unclassified"))))) | O21: =IF(A21="","",IF(K21<>"",PROPER(K21),N21)) | P21: =IF(A21="","",ROUND(Settings!$B$5*MIN(1,LOG10(N(C21)+1)/LOG10(Settings!$B$7+1))+Settings!$B$6*(1-MIN(100,IF(D21="",50,N(D21)))/100)+IFERROR(INDEX(Settings!$B$10:$B$14,MATCH(O21,Settings!$A$10:$A$14,0)),0),0)) | Q21: =IF(OR(A21="",G21=""),"",COUNTIFS($M$3:$M$1002,M21,$G$3:$G$1002,"<>"&SUBSTITUTE(SUBSTITUTE(G21,"?","~?"),"*","~*"),$G$3:$G$1002,"?*")) | R21: =IF(Q21="","",IF(Q21>0,"Yes","No")) | S21: =IF(G21="","",COUNTIFS($G$3:$G$1002,SUBSTITUTE(SUBSTITUTE(G21,"?","~?"),"*","~*"),$J$3:$J$1002,"Primary")) | T21: =IF(S21="","",IF(S21>Settings!$B$4,"Yes","No")) | U21: =IF(OR(G21="",B21=""),"",IF(COUNTIFS($G$3:$G$1002,SUBSTITUTE(SUBSTITUTE(G21,"?","~?"),"*","~*"),$B$3:$B$1002,"<>"&SUBSTITUTE(SUBSTITUTE(B21,"?","~?"),"*","~*"),$B$3:$B$1002,"?*")>0,"Yes","No")) | V21: =IF(OR(G21="",I21="",O21="",O21="Unclassified"),"",IFERROR(INDEX(Settings!$E$5:$H$16,MATCH(I21,Settings!$D$5:$D$16,0),MATCH(O21,Settings!$E$4:$H$4,0)),"Check")) | W21: =IF(V21="","",IF(V21="No","Yes","No")) | X21: =IF(OR(E21="",G21=""),"",IF(LOWER(IF(RIGHT(TRIM(E21),1)="/",LEFT(TRIM(E21),LEN(TRIM(E21))-1),TRIM(E21)))<>LOWER(IF(RIGHT(TRIM(G21),1)="/",LEFT(TRIM(G21),LEN(TRIM(G21))-1),TRIM(G21))),"Yes","No")) | Y21: =IF(A21="","",(N(Q21)>0)+(T21="Yes")+(U21="Yes")+(W21="Yes")+(X21="Yes")) | Z21: =IF(A21="","",IF(G21="","Not mapped",IF(Y21=0,"OK",MID(IF(N(Q21)>0,"; Cannibalisation","")&IF(T21="Yes","; Too many primary keywords on URL","")&IF(U21="Yes","; URL spans 2+ clusters","")&IF(W21="Yes","; Intent mismatch","")&IF(X21="Yes","; Ranking URL is not the target",""),3,300)))) | AA21: =IF(G21="","",IF(COUNTIF($G$3:G21,SUBSTITUTE(SUBSTITUTE(G21,"?","~?"),"*","~*"))=1,MAX($AA$2:AA20)+1,"")) | AB21: =IF(B21="","",IF(COUNTIF($B$3:B21,SUBSTITUTE(SUBSTITUTE(B21,"?","~?"),"*","~*"))=1,MAX($AB$2:AB20)+1,""))
A22: gait analysis near me | B22: Gait analysis | C22: 1000 | D22: 30 | E22: https://www.stride-example.com/stores/london/ | F22: 7 | G22: https://www.stride-example.com/stores/london/ | H22: Existing | I22: Store / location page | J22: Secondary | M22: =IF(A22="","",LOWER(TRIM(SUBSTITUTE(SUBSTITUTE(A22,"?",""),"*","")))) | N22: =IF(M22="","",IF(SUMPRODUCT(ISNUMBER(SEARCH(" "&Settings!$L$5:$L$124&" "," "&M22&" "))*(Settings!$K$5:$K$124="Navigational")*(Settings!$L$5:$L$124<>""))>0,"Navigational",IF(SUMPRODUCT(ISNUMBER(SEARCH(" "&Settings!$L$5:$L$124&" "," "&M22&" "))*(Settings!$K$5:$K$124="Transactional")*(Settings!$L$5:$L$124<>""))>0,"Transactional",IF(SUMPRODUCT(ISNUMBER(SEARCH(" "&Settings!$L$5:$L$124&" "," "&M22&" "))*(Settings!$K$5:$K$124="Commercial")*(Settings!$L$5:$L$124<>""))>0,"Commercial",IF(SUMPRODUCT(ISNUMBER(SEARCH(" "&Settings!$L$5:$L$124&" "," "&M22&" "))*(Settings!$K$5:$K$124="Informational")*(Settings!$L$5:$L$124<>""))>0,"Informational","Unclassified"))))) | O22: =IF(A22="","",IF(K22<>"",PROPER(K22),N22)) | P22: =IF(A22="","",ROUND(Settings!$B$5*MIN(1,LOG10(N(C22)+1)/LOG10(Settings!$B$7+1))+Settings!$B$6*(1-MIN(100,IF(D22="",50,N(D22)))/100)+IFERROR(INDEX(Settings!$B$10:$B$14,MATCH(O22,Settings!$A$10:$A$14,0)),0),0)) | Q22: =IF(OR(A22="",G22=""),"",COUNTIFS($M$3:$M$1002,M22,$G$3:$G$1002,"<>"&SUBSTITUTE(SUBSTITUTE(G22,"?","~?"),"*","~*"),$G$3:$G$1002,"?*")) | R22: =IF(Q22="","",IF(Q22>0,"Yes","No")) | S22: =IF(G22="","",COUNTIFS($G$3:$G$1002,SUBSTITUTE(SUBSTITUTE(G22,"?","~?"),"*","~*"),$J$3:$J$1002,"Primary")) | T22: =IF(S22="","",IF(S22>Settings!$B$4,"Yes","No")) | U22: =IF(OR(G22="",B22=""),"",IF(COUNTIFS($G$3:$G$1002,SUBSTITUTE(SUBSTITUTE(G22,"?","~?"),"*","~*"),$B$3:$B$1002,"<>"&SUBSTITUTE(SUBSTITUTE(B22,"?","~?"),"*","~*"),$B$3:$B$1002,"?*")>0,"Yes","No")) | V22: =IF(OR(G22="",I22="",O22="",O22="Unclassified"),"",IFERROR(INDEX(Settings!$E$5:$H$16,MATCH(I22,Settings!$D$5:$D$16,0),MATCH(O22,Settings!$E$4:$H$4,0)),"Check")) | W22: =IF(V22="","",IF(V22="No","Yes","No")) | X22: =IF(OR(E22="",G22=""),"",IF(LOWER(IF(RIGHT(TRIM(E22),1)="/",LEFT(TRIM(E22),LEN(TRIM(E22))-1),TRIM(E22)))<>LOWER(IF(RIGHT(TRIM(G22),1)="/",LEFT(TRIM(G22),LEN(TRIM(G22))-1),TRIM(G22))),"Yes","No")) | Y22: =IF(A22="","",(N(Q22)>0)+(T22="Yes")+(U22="Yes")+(W22="Yes")+(X22="Yes")) | Z22: =IF(A22="","",IF(G22="","Not mapped",IF(Y22=0,"OK",MID(IF(N(Q22)>0,"; Cannibalisation","")&IF(T22="Yes","; Too many primary keywords on URL","")&IF(U22="Yes","; URL spans 2+ clusters","")&IF(W22="Yes","; Intent mismatch","")&IF(X22="Yes","; Ranking URL is not the target",""),3,300)))) | AA22: =IF(G22="","",IF(COUNTIF($G$3:G22,SUBSTITUTE(SUBSTITUTE(G22,"?","~?"),"*","~*"))=1,MAX($AA$2:AA21)+1,"")) | AB22: =IF(B22="","",IF(COUNTIF($B$3:B22,SUBSTITUTE(SUBSTITUTE(B22,"?","~?"),"*","~*"))=1,MAX($AB$2:AB21)+1,""))
