Workbook

Sheet Start here
B2: Generative Engine Optimisation (GEO) Checklist
B3: 44 checks to help AI search systems find, understand, trust and cite your content. Free from MLforSEO, October 2026.
B5: What this is
B6: A working checklist for getting content into AI answers (Google AI Overviews and AI Mode, ChatGPT, Perplexity, Claude, Gemini, Copilot). It runs in the order AI systems process content: can they reach it, can they find and recognise it, can they lift a clean passage out of it, do they believe it, and can you see the result. Every check links to the MLforSEO article that explains it, plus the official documentation where one exists.
B7: Generative engine optimisation (GEO) is mostly good SEO done with a different reader in mind. Google says there are no extra requirements to appear in its AI features beyond being indexed and eligible for a snippet, so the foundations come first. Each check carries an Evidence label so you can see which items platforms document, which come from research, and which are MLforSEO practice.
B9: How to use it
B10: Step 1 | C10: Make your own copy (File > Make a copy in Google Sheets). Don't request edit access to the original.
B11: Step 2 | C11: Work through the Checklist tab area by area. Set Status for each check, add an Owner and write what you found in Notes.
B12: Step 3 | C12: Mark checks that don't apply as N/A. They are left out of the % complete.
B13: Step 4 | C13: Use the filter arrows in the header row, for example Priority = High and Status = Not started, to build your first sprint.
B14: Step 5 | C14: Fill in the AI crawlers tab while you work on area 1, and start the Prompt tracker for area 8. The Progress tab calculates everything.
B15: Step 6 | C15: Rerun the Prompt tracker monthly. AI answers change between runs, so look at the trend, not one result.
B17: Tabs
B18: Checklist | C18: The 44 checks, with why each matters, how to check it, priority, evidence level, status, owner, notes and links. Blank rows at the bottom are for your own checks.
B19: AI crawlers | C19: Every major AI crawler and user-agent token, what it does, what blocking it does, and a column for your decision. Checked against each provider's documentation in October 2026.
B20: Prompt tracker | C20: Log the customer questions you test in each assistant and whether you were mentioned, cited and described accurately.
B21: Progress | C21: Completion by area and priority, open High-priority checks, and mention, citation and accuracy rates from the Prompt tracker.
B23: Status
B24: Not started | C24: Default for every check.
B25: In progress | C25: Someone is working on it.
B26: Done | C26: Checked, and fixed if it needed fixing.
B27: N/A | C27: Does not apply to this site. N/A rows are left out of the % complete.
B29: Priority
B30: High | C30: Fix first. Blocks access, eligibility or entity recognition, or misrepresents you.
B31: Medium | C31: Do next. Improves how often and how well you are selected.
B32: Low | C32: Nice to have, or an early-warning signal to monitor.
B34: Evidence levels
B35: Google-documented | C35: Stated in Google Search Central or Google Help documentation.
B36: Platform-documented | C36: Stated in another platform's own documentation (OpenAI, Anthropic, Perplexity, Microsoft Bing, Apple, Meta, Wikidata / Wikimedia, schema.org).
B37: Research-backed | C37: Supported by published research or a large public dataset. Results come from specific test conditions and may not carry over to every site.
B38: MLforSEO practice | C38: What we teach in MLforSEO courses and use in audits, based on how retrieval and entity systems work. Sensible and low-risk, but not confirmed by the platforms.
B39: Unconfirmed (optional) | C39: A cheap extra that no major platform has confirmed using. Do it last, if at all.
B41: What this checklist can't promise
B42: No checklist guarantees citations. AI answers vary by prompt wording, location, account and run, and providers change their systems often. Use the checks to remove the reasons you would be skipped, then measure what happens. Facts were checked in October 2026; recheck the official sources linked in each row before big decisions.
B44: Credits
B45: Created by | C45: =HYPERLINK("https://www.mlforseo.com/experts/lazarina-stoy/","Lazarina Stoy · MLforSEO")
B46: Built on | C46: =HYPERLINK("https://www.mlforseo.com/experts/beatrice-gamba/","Beatrice Gamba's AI search series on MLforSEO")
B47: Go deeper | C47: =HYPERLINK("https://www.mlforseo.com/courses/ai-search-optimisation-agentic-seo/","AI Search Optimisation & Agentic SEO course")
B48: More free resources | C48: =HYPERLINK("https://www.mlforseo.com/resources-library/","MLforSEO resources library")
B49: Source files | C49: =HYPERLINK("https://github.com/lazarinastoy/mlforseo-code/tree/main/geo-checklist","GitHub: lazarinastoy/mlforseo-code")
...

Sheet Checklist
A1: ID | B1: Area | C1: Check | D1: Why it matters | E1: How to check (tool / where) | F1: Priority | G1: Evidence | H1: Status | I1: Owner | J1: Notes | K1: Learn more | L1: Official source
A2: G01 | B2: 1. Crawl access | C2: Googlebot can crawl every page you want in Google's AI Overviews and AI Mode | D2: Google's AI features use the normal Search index and follow your robots.txt rules for Googlebot. There is no separate AI crawler to allow for them. | E2: Search Console > Settings > robots.txt report, then URL Inspection on your key templates. Look for Disallow rules that catch important folders. | F2: High | G2: Google-documented | H2: Not started | K2: =HYPERLINK("https://www.mlforseo.com/machine-learning-implementation-guides/ai-search-optimisation/robots-txt-silent-killer-ai-traffic/","Your robots.txt might be the silent killer of your AI traffic") | L2: =HYPERLINK("https://developers.google.com/search/docs/appearance/ai-features","Google: AI features and your website")
A3: G02 | B3: 1. Crawl access | C3: AI search crawlers are allowed in robots.txt: OAI-SearchBot, Claude-SearchBot, PerplexityBot and Bingbot | D3: These bots decide whether you can be shown and linked in ChatGPT search, Claude's web search, Perplexity and Bing / Copilot answers. OpenAI says sites that block OAI-SearchBot won't be shown in ChatGPT search answers. | E3: Open yourdomain.com/robots.txt. Check for a User-agent group per bot, or a catch-all (User-agent: *) group that blocks them. The 'AI crawlers' tab lists every token with its docs. | F3: High | G3: Platform-documented | H3: Not started | K3: =HYPERLINK("https://www.mlforseo.com/machine-learning-implementation-guides/ai-search-optimisation/robots-txt-silent-killer-ai-traffic/","Your robots.txt might be the silent killer of your AI traffic") | L3: =HYPERLINK("https://platform.openai.com/docs/bots","OpenAI: crawlers and user agents")
A4: G03 | B4: 1. Crawl access | C4: Training crawlers are a deliberate business decision: GPTBot, ClaudeBot, Google-Extended, Applebot-Extended, Meta-ExternalAgent, CCBot | D4: Blocking training crawlers is separate from search visibility. Google-Extended does not affect inclusion in Google Search, including AI Overviews. Make the choice on purpose, and write down why. | E4: Agree the policy with legal / leadership, record it in the 'AI crawlers' tab (Your decision column), then match robots.txt to it. | F4: Medium | G4: Platform-documented | H4: Not started | K4: =HYPERLINK("https://www.mlforseo.com/machine-learning-implementation-guides/ai-search-optimisation/robots-txt-silent-killer-ai-traffic/","Your robots.txt might be the silent killer of your AI traffic") | L4: =HYPERLINK("https://developers.google.com/search/docs/crawling-indexing/google-common-crawlers","Google: common crawlers (Google-Extended)")
A5: G04 | B5: 1. Crawl access | C5: Your CDN, firewall or bot-management settings aren't blocking the crawlers you allowed | D5: A robots.txt Allow means nothing if a WAF rule, a 'block AI bots' toggle or a rate limit returns 403, 429 or a challenge page. Google lists CDN and hosting blocks among the things to check. | E5: Check your CDN / WAF dashboard (for example Cloudflare's AI crawler and bot settings). In server logs, filter for the bot user agents and look for 403, 429 and 503 responses. Verify bots against their published IP ranges. | F5: High | G5: Google-documented | H5: Not started | K5: =HYPERLINK("https://www.mlforseo.com/machine-learning-implementation-guides/ai-search-optimisation/robots-txt-silent-killer-ai-traffic/","Your robots.txt might be the silent killer of your AI traffic") | L5: =HYPERLINK("https://docs.perplexity.ai/guides/bots","Perplexity: crawlers")
A6: G05 | B6: 1. Crawl access | C6: Fetching a key page with an AI user-agent string returns the real content | D6: Agents fail silently: no error, just a skipped page. A quick fetch shows whether they get your content or a block page, cookie wall or empty shell. | E6: From a terminal: curl -A "ClaudeBot" https://yourdomain.com/key-page | head (repeat with OAI-SearchBot and PerplexityBot). Some firewalls also check IP ranges, so confirm in logs too. | F6: High | G6: MLforSEO practice | H6: Not started | K6: =HYPERLINK("https://www.mlforseo.com/machine-learning-implementation-guides/ai-search-optimisation/robots-txt-silent-killer-ai-traffic/","Your robots.txt might be the silent killer of your AI traffic")
A7: G06 | B7: 1. Crawl access | C7: Main content, links and JSON-LD are in the raw HTML, not only added by JavaScript | D7: Google renders JavaScript, but the major AI crawlers studied in 2024 (GPTBot, ClaudeBot, PerplexityBot and others) fetched JavaScript files without executing them. Content that only appears after rendering may be invisible to them. | E7: Compare View Source (raw HTML) with Inspect / rendered DOM on each template, or crawl with JavaScript rendering off. Anything missing from the raw HTML is at risk. | F7: High | G7: Research-backed | H7: Not started | K7: =HYPERLINK("https://www.mlforseo.com/machine-learning-implementation-guides/ai-search-optimisation/consistency-beats-completeness-structured-data/","Consistency beats completeness") | L7: =HYPERLINK("https://vercel.com/blog/the-rise-of-the-ai-crawler","Vercel and MERJ: the rise of the AI crawler")
A8: G07 | B8: 1. Crawl access | C8: Key facts sit near the top of the page and priority pages aren't bloated | D8: Agents read against a token budget, so facts buried deep in long pages can be cut. Our working budget is under about 15,000 tokens for product and category pages (roughly 60,000 characters of text). | E8: Copy the page text into a text editor, divide the character count by four for an approximate token count. Check that the answer, price or policy appears in the first screen of text. | F8: Medium | G8: MLforSEO practice | H8: Not started | K8: =HYPERLINK("https://www.mlforseo.com/machine-learning-implementation-guides/ai-search-optimisation/robots-txt-silent-killer-ai-traffic/","Your robots.txt might be the silent killer of your AI traffic")
A9: G08 | B9: 1. Crawl access | C9: Optional: an llms.txt file, if you want one, lists your most useful pages with short descriptions | D9: llms.txt is a proposed standard. No major AI provider has confirmed that its crawlers read it, and Google says you don't need AI text files to appear in its AI features. Treat it as a cheap extra after everything above. | E9: If you publish one, keep it short, Markdown, at yourdomain.com/llms.txt, organised by task, and keep it in sync with the site. Don't block it in robots.txt. | F9: Low | G9: Unconfirmed (optional) | H9: Not started | K9: =HYPERLINK("https://www.mlforseo.com/machine-learning-implementation-guides/ai-search-optimisation/robots-txt-silent-killer-ai-traffic/","Your robots.txt might be the silent killer of your AI traffic") | L9: =HYPERLINK("https://llmstxt.org/","llmstxt.org proposal")
A10: G09 | B10: 1. Crawl access | C10: AI crawler activity is visible in your server logs | D10: Logs show which pages the AI bots fetch, how often, and whether they get errors. A page crawled heavily but never cited points to an extraction or selection problem rather than an access one. | E10: Export logs (host, CDN or log analyser such as Screaming Frog Log File Analyser) and segment by user agent. Verify genuine bots against the IP lists each provider publishes. | F10: Medium | G10: MLforSEO practice | H10: Not started | K10: =HYPERLINK("https://www.mlforseo.com/machine-learning-implementation-guides/ai-search-optimisation/rank-tracker-ai-search-measurement/","Your rank tracker is lying to you about AI search") | L10: =HYPERLINK("https://platform.openai.com/docs/bots","OpenAI: crawlers and user agents")
A11: G10 | B11: 2. Indexing & eligibility | C11: Priority pages are indexed in Google and eligible for a snippet | D11: To be a supporting link in AI Overviews or AI Mode, a page must be indexed and eligible to show with a snippet. nosnippet, max-snippet:0 or data-nosnippet on the main content removes that eligibility. | E11: Search Console > URL Inspection for each priority URL; check the page source and HTTP headers for noindex, nosnippet, max-snippet and data-nosnippet. | F11: High | G11: Google-documented | H11: Not started | K11: =HYPERLINK("https://www.mlforseo.com/machine-learning-implementation-guides/ai-search-optimisation/indexed-is-not-selected/","Indexed is not selected (Beatrice Gamba)") | L11: =HYPERLINK("https://developers.google.com/search/docs/appearance/ai-features","Google: AI features and your website")
A12: G11 | B12: 2. Indexing & eligibility | C12: Priority pages are indexed in Bing, and changes are pushed with IndexNow | D12: Bing's index feeds Bing results and Microsoft Copilot answers. IndexNow tells Bing (and other participating engines) about new and updated URLs within minutes. | E12: Bing Webmaster Tools > URL Inspection; set up IndexNow through your CMS, CDN or a script. | F12: Medium | G12: Platform-documented | H12: Not started | K12: =HYPERLINK("https://www.mlforseo.com/machine-learning-implementation-guides/indexnow-api-python/","The IndexNow API guide") | L12: =HYPERLINK("https://www.bing.com/webmasters/","Bing Webmaster Tools")
A13: G12 | B13: 2. Indexing & eligibility | C13: Priority pages are reachable through internal links (no orphans) within a few clicks | D13: Google lists internal links among the SEO basics that still matter for AI features, and crawlers of every kind discover pages through links. | E13: Crawl the site and compare crawled URLs with your sitemap and analytics landing pages. Check click depth for priority pages. | F13: Medium | G13: Google-documented | H13: Not started | K13: =HYPERLINK("https://www.mlforseo.com/machine-learning-implementation-guides/ai-search-optimisation/blog-site-architecture-ai-search/","Blog and site architecture in the AI search era") | L13: =HYPERLINK("https://developers.google.com/search/docs/appearance/ai-features","Google: AI features and your website")
A14: G13 | B14: 3. Entity clarity | C14: Your organisation (or person) is described in Organization / Person markup on the home or about page | D14: This is how you state who you are in a format machines parse directly: name, URL, logo, description and the profiles that confirm you. Google recommends placing it on the home page or a single page about the organisation. | E14: View Source on the home and about pages, then run the Rich Results Test and the Schema Markup Validator. Check name, url, logo, description and sameAs are present. | F14: High | G14: Google-documented | H14: Not started | K14: =HYPERLINK("https://www.mlforseo.com/machine-learning-implementation-guides/structured-data-audit/how-structured-data-reinforces-entity-understanding-in-ai-search/","Structured data and entity understanding") | L14: =HYPERLINK("https://developers.google.com/search/docs/appearance/structured-data/organization","Google: Organization structured data")
A15: G14 | B15: 3. Entity clarity | C15: One canonical brand name is used, character for character, everywhere | D15: 'Acme', 'Acme Corp' and 'Acme Corporation' can be read as three different entities. Consistent naming stops your entity fragmenting across the site, profiles and knowledge bases. | E15: Write the canonical form into your style guide. Search the site (and your schema) for variants; compare with LinkedIn, Crunchbase, Wikidata and directory listings. | F15: High | G15: MLforSEO practice | H15: Not started | K15: =HYPERLINK("https://www.mlforseo.com/machine-learning-implementation-guides/ai-search-optimisation/consistency-beats-completeness-structured-data/","Consistency beats completeness")
A16: G15 | B16: 3. Entity clarity | C16: Core entities have a stable @id that other markup points to | D16: A stable @id turns separate Organization, Person and Article blocks into one connected graph: the publisher of every article, the employer of every author, the brand of every product. | E16: In the JSON-LD on several page types, check that the Organization has an @id that never changes, and that publisher, author, worksFor and brand reference those @id values. | F16: Medium | G16: MLforSEO practice | H16: Not started | K16: =HYPERLINK("https://www.mlforseo.com/machine-learning-implementation-guides/structured-data-audit/what-schema-org-id-does-and-why-your-entity-graph-falls-apart-without-it/","What schema.org @id does") | L16: =HYPERLINK("https://www.mlforseo.com/machine-learning-implementation-guides/structured-data-audit/structured-data-automation-python/","Structured data automation with Python")
A17: G16 | B17: 3. Entity clarity | C17: Every sameAs link works and shows the same name as your markup | D17: schema.org defines sameAs as a page that unambiguously indicates the item's identity. A broken link, or a profile showing a different name, gives systems a contradiction instead of a confirmation. | E17: Open each sameAs URL. Record the status code and the displayed name. Remove or fix anything that 404s, redirects somewhere unrelated or shows a different name. | F17: High | G17: MLforSEO practice | H17: Not started | K17: =HYPERLINK("https://www.mlforseo.com/machine-learning-implementation-guides/ai-search-optimisation/consistency-beats-completeness-structured-data/","Consistency beats completeness") | L17: =HYPERLINK("https://schema.org/sameAs","schema.org: sameAs")
A18: G17 | B18: 3. Entity clarity | C18: On its own page, your main entity is the most prominent entity (navigation isn't drowning it) | D18: Entity extraction weighs the whole page. Repeated menu and footer labels can outscore your brand or topic on the very page meant to define it. | E18: Run Google's Natural Language API (or the MLforSEO no-code template) on the full page, then on the main content only. Check the brand or topic leads on salience. Wrap layout in <nav>, <main>, <aside> and <footer>. | F18: Medium | G18: MLforSEO practice | H18: Not started | K18: =HYPERLINK("https://www.mlforseo.com/machine-learning-tutorials/entity-analysis/why-navigation-elements-outrank-your-brand-in-entity-analysis/","Why navigation outranks your brand")
A19: G18 | B19: 3. Entity clarity | C19: If your brand name is shared with something else, it's disambiguated | D19: When systems can't tell which entity you mean, your content gets attributed elsewhere or not at all. Full names plus category context and sameAs links resolve the collision. | E19: Query your brand in the Knowledge Graph Search API and in AI assistants. If another entity dominates, use the full name with a category descriptor in the H1, intro, meta description and schema description. | F19: Medium | G19: MLforSEO practice | H19: Not started | K19: =HYPERLINK("https://www.mlforseo.com/machine-learning-tutorials/entity-analysis/entity-disambiguation-in-practice/","Entity disambiguation in practice") | L19: =HYPERLINK("https://developers.google.com/knowledge-graph","Google: Knowledge Graph Search API")
A20: G19 | B20: 3. Entity clarity | C20: Content covers the sub-questions your key topics fan out into | D20: Google says AI Overviews and AI Mode may use query fan-out: several related searches across subtopics. Pages that answer one sub-question clearly can be picked for that slice of the answer. | E20: For each priority topic, list the sub-questions a real buyer asks (People Also Ask, sales calls, support tickets, AI follow-up suggestions). Map each to a page or section; mark gaps. | F20: Medium | G20: Google-documented | H20: Not started | K20: =HYPERLINK("https://www.mlforseo.com/machine-learning-implementation-guides/ai-search-optimisation/how-entities-power-query-fan-out-in-ai-search/","How entities power query fan-out") | L20: =HYPERLINK("https://developers.google.com/search/docs/appearance/ai-features","Google: AI features and your website")
A21: G20 | B21: 4. Chunk extractability | C21: Headings say what the section answers, in the words a person would search | D21: Retrieval systems cut pages into passages and judge each on its own. A heading like 'What does X cost for small teams?' is a strong signal for that passage; 'A closer look' carries none. | E21: Read every H2 and H3 out of context. Could each stand alone as a search query or a clear label? Rewrite the vague ones. | F21: High | G21: MLforSEO practice | H21: Not started | K21: =HYPERLINK("https://www.mlforseo.com/machine-learning-implementation-guides/ai-search-optimisation/chunk-not-the-page/","The chunk, not the page")
A22: G21 | B22: 4. Chunk extractability | C22: Every section makes sense on its own (no 'as noted above', no orphan 'it' or 'this') | D22: An extracted passage carries no memory of the rest of the page. Back-references and pronouns without a named subject become broken references once the chunk is lifted out. | E22: Search the page for 'as mentioned', 'as noted above', 'see below', 'as we discussed' and drive them to zero. Name the subject in the first sentence of each section. | F22: High | G22: MLforSEO practice | H22: Not started | K22: =HYPERLINK("https://www.mlforseo.com/machine-learning-implementation-guides/ai-search-optimisation/chunk-not-the-page/","The chunk, not the page")
A23: G22 | B23: 4. Chunk extractability | C23: One main idea per headed section | D23: A paragraph that mixes problem, cause and fix is a blend that matches no single query well. Separate sections give each idea its own sharp passage. | E23: Skim each long section: if it answers more than one question, split it under separate headings. | F23: Medium | G23: MLforSEO practice | H23: Not started | K23: =HYPERLINK("https://www.mlforseo.com/machine-learning-implementation-guides/ai-search-optimisation/chunk-not-the-page/","The chunk, not the page")
A24: G23 | B24: 4. Chunk extractability | C24: Each section leads with the direct answer, then the detail | D24: Answer-first writing puts the extractable claim where both readers and machines find it first. Detail and nuance can follow. | E24: Check the first one or two sentences under each heading. Do they answer the heading directly? If the answer appears three paragraphs in, move it up. | F24: Medium | G24: MLforSEO practice | H24: Not started | K24: =HYPERLINK("https://www.mlforseo.com/machine-learning-implementation-guides/ai-search-optimisation/chunk-not-the-page/","The chunk, not the page")
A25: G24 | B25: 4. Chunk extractability | C25: Comparisons, specs and prices are in HTML tables with a sentence explaining them | D25: Tables pack structured facts into far fewer tokens than prose. The explanatory sentence keeps the meaning attached if the table is extracted on its own. | E25: Find prose that lists attributes, plans, sizes or specs. Convert to a real <table> (not an image), with a one-sentence summary directly above it. | F25: Medium | G25: MLforSEO practice | H25: Not started | K25: =HYPERLINK("https://www.mlforseo.com/machine-learning-implementation-guides/ai-search-optimisation/robots-txt-silent-killer-ai-traffic/","Your robots.txt might be the silent killer of your AI traffic")
A26: G25 | B26: 4. Chunk extractability | C26: Sources, dates and named entities sit in the same sentence as the statistic | D26: Bylines, footnotes and reference lists don't travel with an extracted chunk. In the GEO study, adding citations, quotations and statistics raised source visibility in generative answers by up to 40% on their benchmark. | E26: For every number or claim you want cited, check the sentence names the source, the scope and the date. Replace 'our research found' with the named organisation and study. | F26: High | G26: Research-backed | H26: Not started | K26: =HYPERLINK("https://www.mlforseo.com/machine-learning-implementation-guides/ai-search-optimisation/chunk-not-the-page/","The chunk, not the page") | L26: =HYPERLINK("https://arxiv.org/abs/2311.09735","Aggarwal et al., GEO: Generative Engine Optimization (KDD 2024)")
A27: G26 | B27: 5. Claim quality | C27: Key claims pass the three-property test: extract-friendly, verifiable, specific | D27: A claim with no value to lift, nothing to cross-check and no exact detail gives a system nothing to select. Vague sentences are skipped, not ranked lower. | E27: List the 5 to 10 claims you most want cited (price, use case, size, founding year, key results). Score each against the three properties and rewrite failures. | F27: High | G27: MLforSEO practice | H27: Not started | K27: =HYPERLINK("https://www.mlforseo.com/machine-learning-implementation-guides/ai-search-optimisation/vagueness-is-a-disqualifier/","Vagueness is a disqualifier")
A28: G27 | B28: 5. Claim quality | C28: Marketing phrases are backed by the exact fact underneath | D28: 'Flexible pricing' and 'many integrations' name nothing. '£25 per user per month' and '50 integrations including Slack and Jira' can be extracted and checked. Keep the persuasive line if you like, but add the fact. | E28: Search priority pages for 'leading', 'world-class', 'many', 'flexible', 'affordable', 'best-in-class'. Add the number, name or date behind each. | F28: High | G28: MLforSEO practice | H28: Not started | K28: =HYPERLINK("https://www.mlforseo.com/machine-learning-implementation-guides/ai-search-optimisation/vagueness-is-a-disqualifier/","Vagueness is a disqualifier") | L28: =HYPERLINK("https://arxiv.org/abs/2311.09735","Aggarwal et al., GEO: Generative Engine Optimization (KDD 2024)")
A29: G28 | B29: 5. Claim quality | C29: Time-sensitive facts carry a date ('as of October 2026') and the page shows when it was updated | D29: Words like 'current' and 'latest' decay and give no fixed point. A date lets systems and readers judge freshness. | E29: Check prices, stats, product details and policies for an 'as of' date. Make sure the visible updated date is real (changed content, not a cosmetic bump). | F29: Medium | G29: MLforSEO practice | H29: Not started | K29: =HYPERLINK("https://www.mlforseo.com/machine-learning-implementation-guides/ai-search-optimisation/vagueness-is-a-disqualifier/","Vagueness is a disqualifier")
A30: G29 | B30: 5. Claim quality | C30: Each priority page offers something others don't: original data, first-hand experience or a clear point of view | D30: If ten sources say the same thing, any one of them will do. Google's helpful content guidance asks whether content provides original information, reporting or analysis. | E30: Compare your page with the top results and AI answers for its main query. Note what only you can say (data, examples, tests, expert input) and make it prominent. | F30: Medium | G30: Google-documented | H30: Not started | K30: =HYPERLINK("https://www.mlforseo.com/ml-fundamentals/what-is-information-gain-in-seo/","What is information gain in SEO?") | L30: =HYPERLINK("https://developers.google.com/search/docs/fundamentals/creating-helpful-content","Google: creating helpful content")
A31: G30 | B31: 6. Structured data | C31: Structured data matches the visible text on the page | D31: Google lists this among the SEO basics for AI features. Markup that disagrees with the page is a contradiction, and it breaks Google's structured data policies. | E31: Spot-check prices, ratings, dates, names and FAQs in the JSON-LD against the rendered page. | F31: High | G31: Google-documented | H31: Not started | K31: =HYPERLINK("https://www.mlforseo.com/machine-learning-implementation-guides/ai-search-optimisation/consistency-beats-completeness-structured-data/","Consistency beats completeness") | L31: =HYPERLINK("https://developers.google.com/search/docs/appearance/structured-data/sd-policies","Google: structured data policies")
A32: G31 | B32: 6. Structured data | C32: Each page uses the type that matches what it is | D32: A CMS that stamps Organization on every URL tells systems your blog posts are the company. Article, Product, Service, ProfilePage and Organization each belong on their own kind of page. | E32: Crawl with structured data extraction on (for example Screaming Frog), then pivot schema types by page template. | F32: Medium | G32: MLforSEO practice | H32: Not started | K32: =HYPERLINK("https://www.mlforseo.com/machine-learning-implementation-guides/ai-search-optimisation/consistency-beats-completeness-structured-data/","Consistency beats completeness") | L32: =HYPERLINK("https://www.mlforseo.com/machine-learning-implementation-guides/structured-data-audit/structured-data-automation-python/","Structured data automation with Python")
A33: G32 | B33: 6. Structured data | C33: Commercial facts are machine-readable: price, currency, availability, returns, shipping, opening hours | D33: Recommendation and shopping agents compare typed fields. If a returns policy or price exists only in prose, an agent may treat it as unknown. Google also asks you to keep Merchant Center and Business Profile up to date. | E33: Check Product / Offer markup (price, priceCurrency, availability), MerchantReturnPolicy and shipping details, LocalBusiness openingHoursSpecification. Compare with Merchant Center and Business Profile. | F33: Medium | G33: Google-documented | H33: Not started | K33: =HYPERLINK("https://www.mlforseo.com/machine-learning-implementation-guides/ai-search-optimisation/audience-no-longer-only-human-agentic-seo/","Your audience is no longer only human") | L33: =HYPERLINK("https://developers.google.com/search/docs/appearance/ai-features","Google: AI features and your website")
A34: G33 | B34: 6. Structured data | C34: The same fact has the same value across every page, schema block and profile | D34: Gaps are neutral; contradictions are negative. A founding year of 2011 in schema, 2013 in a press release and 2012 on LinkedIn gives systems a conflict they can't resolve. | E34: Pull the values for name, founding date, employee count, address, prices and leadership from schema, about page, press kit and profiles. Use ranges (QuantitativeValue) for figures that change. | F34: Medium | G34: MLforSEO practice | H34: Not started | K34: =HYPERLINK("https://www.mlforseo.com/machine-learning-implementation-guides/ai-search-optimisation/consistency-beats-completeness-structured-data/","Consistency beats completeness")
A35: G34 | B35: 7. Trust & corroboration | C35: Your three most important facts are confirmed by independent sources, with the same values | D35: Claims that appear only on your own site are self-assertion. When an assistant cross-checks sources at answer time, independently confirmed claims are the ones that survive. | E35: Pick three facts (price, ideal customer, company size, founding year). Search each and count independent, non-promotional sources that state the same value. Zero is a gap to close. | F35: High | G35: MLforSEO practice | H35: Not started | K35: =HYPERLINK("https://www.mlforseo.com/machine-learning-implementation-guides/ai-search-optimisation/trust-is-not-a-schema-field/","Trust isn't a schema field")
A36: G35 | B36: 7. Trust & corroboration | C36: Canonical facts match across LinkedIn, Crunchbase, Wikidata, Business Profile, review sites and directories | D36: Every platform holding facts about you is a verification point. Consistent points add confidence; inconsistent ones subtract it. | E36: Keep a single source of truth (the Knowledge Panel checklist has a fact sheet tab). Audit each profile against it and fix mismatches, contradictions first. | F36: High | G36: MLforSEO practice | H36: Not started | K36: =HYPERLINK("https://www.mlforseo.com/machine-learning-implementation-guides/ai-search-optimisation/cross-platform-entity-consistency-the-llm-era/","Cross-platform entity consistency")
A37: G36 | B37: 7. Trust & corroboration | C37: Authors are real, identifiable people with consistent profiles | D37: Google's guidance asks you to make clear who created content and why they're qualified. Author pages, Person markup with sameAs, and a consistent external footprint (talks, publications, LinkedIn) let systems check that. | E37: Check bylines link to author pages; author pages state expertise in plain text and link to external profiles; Person markup uses a stable @id referenced from Article author. | F37: Medium | G37: Google-documented | H37: Not started | K37: =HYPERLINK("https://www.mlforseo.com/machine-learning-implementation-guides/ai-search-optimisation/trust-is-not-a-schema-field/","Trust isn't a schema field") | L37: =HYPERLINK("https://developers.google.com/search/docs/fundamentals/creating-helpful-content","Google: creating helpful content")
A38: G37 | B38: 7. Trust & corroboration | C38: You are present in the third-party places your category is discussed | D38: Assistants build answers from many sources. Reviews, comparisons, trade press, podcasts and conference programmes that name you next to your category and peers give them independent material to cite. | E38: Ask assistants for 'best [category] for [use case]' and list the sources they cite. Check which mention you, which don't, and whether the facts about you are right. | F38: Medium | G38: MLforSEO practice | H38: Not started | K38: =HYPERLINK("https://www.mlforseo.com/machine-learning-implementation-guides/ai-search-optimisation/how-llms-co-cite-building-authority-by-association/","How LLMs co-cite")
A39: G38 | B39: 7. Trust & corroboration | C39: If you qualify, your organisation has an accurate, referenced Wikidata item | D39: Wikidata is openly licensed, widely reused and a common reference for entity systems. Items need serious, publicly available references, and editing your own item is a conflict of interest to declare. | E39: Search Wikidata for an existing item first. Check label, description, instance of, official website and that statements have external references. See the Knowledge Panel checklist for the full audit. | F39: Medium | G39: Platform-documented | H39: Not started | K39: =HYPERLINK("https://www.mlforseo.com/knowledge-graph-strategy/wikidata-for-brands-notability-criteria-and-a-realistic-path/","Wikidata for brands") | L39: =HYPERLINK("https://www.wikidata.org/wiki/Wikidata:Notability","Wikidata: notability policy")
A40: G39 | B40: 8. Measurement | C40: You have a fixed set of 10 to 50 real customer questions to test in AI assistants | D40: Rankings measure visibility to people scanning a results page; they can't show whether an assistant selected you. A fixed prompt set, rerun on a schedule, gives you a citation-rate baseline. | E40: Use the 'Prompt tracker' tab. Pull questions from sales calls, support tickets, Search Console queries and People Also Ask. Keep the wording fixed between runs. | F40: High | G40: MLforSEO practice | H40: Not started | K40: =HYPERLINK("https://www.mlforseo.com/machine-learning-implementation-guides/ai-search-optimisation/rank-tracker-ai-search-measurement/","Your rank tracker is lying to you about AI search")
...

Sheet AI crawlers
A1: Tokens and behaviour as documented by each provider, checked October 2026. Search and user-fetch bots affect whether you can be shown in AI answers; training bots don't. Record your policy in 'Your decision' and what robots.txt actually says in the next column.
A2: User-agent token | B2: Company | C2: What it does | D2: What blocking it does | E2: robots.txt | F2: Docs | G2: Your decision | H2: In your robots.txt now | I2: Notes
A3: Googlebot | B3: Google | C3: Google Search, including AI Overviews and AI Mode | D3: Blocking removes pages from Google Search and its AI features. | E3: Respects robots.txt | F3: =HYPERLINK("https://developers.google.com/search/docs/appearance/ai-features","Google: AI features and your website")
A4: Google-Extended | B4: Google | C4: Control token only (no separate crawler) for Gemini Apps and Vertex AI training and grounding | D4: Does not affect Google Search or AI Overviews. | E4: robots.txt token | F4: =HYPERLINK("https://developers.google.com/search/docs/crawling-indexing/google-common-crawlers","Google: common crawlers (Google-Extended)")
A5: Bingbot | B5: Microsoft | C5: Bing search; Bing's index also grounds Microsoft Copilot answers | D5: Blocking removes pages from Bing and the answers built on it. | E5: Respects robots.txt | F5: =HYPERLINK("https://www.bing.com/webmasters/help/which-crawlers-does-bing-use-8c184ec0","Bing: which crawlers Bing uses")
A6: OAI-SearchBot | B6: OpenAI | C6: Shows and links sites in ChatGPT search | D6: Sites opted out won't be shown in ChatGPT search answers (may still appear as navigational links). | E6: Respects robots.txt; changes take about 24 hours | F6: =HYPERLINK("https://platform.openai.com/docs/bots","OpenAI: crawlers and user agents")
A7: GPTBot | B7: OpenAI | C7: Crawls content that may be used to train OpenAI's foundation models | D7: Signals content should not be used for training. Independent of OAI-SearchBot. | E7: Respects robots.txt | F7: =HYPERLINK("https://platform.openai.com/docs/bots","OpenAI: crawlers and user agents")
A8: ChatGPT-User | B8: OpenAI | C8: Visits pages when a ChatGPT user or Custom GPT asks it to | D8: User-initiated; OpenAI says robots.txt rules may not apply. Not used for search inclusion. | E8: May not apply | F8: =HYPERLINK("https://platform.openai.com/docs/bots","OpenAI: crawlers and user agents")
A9: Claude-SearchBot | B9: Anthropic | C9: Indexes content to improve Claude's search results | D9: Blocking may reduce visibility in Claude's search answers. | E9: Respects robots.txt | F9: =HYPERLINK("https://support.claude.com/en/articles/8896518-does-anthropic-crawl-data-from-the-web-and-how-can-site-owners-block-the-crawler","Anthropic: crawlers and opt-out")
A10: ClaudeBot | B10: Anthropic | C10: Collects content that could contribute to model training | D10: Signals future content should be excluded from training. | E10: Respects robots.txt | F10: =HYPERLINK("https://support.claude.com/en/articles/8896518-does-anthropic-crawl-data-from-the-web-and-how-can-site-owners-block-the-crawler","Anthropic: crawlers and opt-out")
A11: Claude-User | B11: Anthropic | C11: Fetches pages when a Claude user asks a question | D11: Blocking stops Claude retrieving your pages for users. | E11: Respects robots.txt | F11: =HYPERLINK("https://support.claude.com/en/articles/8896518-does-anthropic-crawl-data-from-the-web-and-how-can-site-owners-block-the-crawler","Anthropic: crawlers and opt-out")
A12: PerplexityBot | B12: Perplexity | C12: Surfaces and links sites in Perplexity search; not used for foundation-model training | D12: Blocking removes you from Perplexity's search results. | E12: Respects robots.txt; up to 24 hours to update | F12: =HYPERLINK("https://docs.perplexity.ai/guides/bots","Perplexity: crawlers")
A13: Perplexity-User | B13: Perplexity | C13: Fetches pages for a user's question | D13: User-initiated; Perplexity says it generally ignores robots.txt. | E13: Generally ignores robots.txt | F13: =HYPERLINK("https://docs.perplexity.ai/guides/bots","Perplexity: crawlers")
A14: Applebot | B14: Apple | C14: Siri, Spotlight and other Apple search features | D14: Blocking removes pages from Apple's search features. | E14: Respects robots.txt | F14: =HYPERLINK("https://support.apple.com/en-us/119829","Apple: about Applebot")
A15: Applebot-Extended | B15: Apple | C15: Control token for using Applebot-crawled content to train Apple's generative models | D15: Opts out of training only. | E15: robots.txt token | F15: =HYPERLINK("https://support.apple.com/en-us/119829","Apple: about Applebot")
A16: Meta-ExternalAgent | B16: Meta | C16: Crawls for uses such as training AI models or indexing content | D16: Opts out of that crawling. | E16: Check Meta's docs | F16: =HYPERLINK("https://developers.facebook.com/docs/sharing/webmasters/web-crawlers","Meta: web crawlers")
A17: CCBot | B17: Common Crawl | C17: Builds the open Common Crawl dataset, widely used in model training | D17: Keeps new content out of future Common Crawl snapshots. | E17: Respects robots.txt | F17: =HYPERLINK("https://commoncrawl.org/ccbot","Common Crawl: CCBot")

Sheet Prompt tracker
A1: One row per prompt, per assistant, per run. Use 10 to 50 real customer questions and rerun them monthly with the same wording, logged out where possible. Delete the two example rows before you start.
A2: Date | B2: Prompt (keep wording fixed) | C2: Topic / intent | D2: Assistant | E2: Mentioned? | F2: Cited with link? | G2: Cited URL | H2: Described accurately? | I2: How you appear | J2: Competitors named | K2: Notes
A3: 2026-10-01 | B3: What is the best tool for [your category] for small teams? | C3: Commercial | D3: ChatGPT | E3: Yes | F3: No | H3: Partly | I3: Listed among several | J3: Competitor A, Competitor B | K3: EXAMPLE ROW: delete. Price quoted was last year's.
A4: 2026-10-01 | B4: What is the best tool for [your category] for small teams? | C4: Commercial | D4: Perplexity | E4: Yes | F4: Yes | G4: https://www.example.com/pricing/ | H4: Yes | I4: Primary recommendation | J4: Competitor A | K4: EXAMPLE ROW: delete.

Sheet Progress
B2: Progress
B3: Updates automatically as you change the Status column. Formulas use COUNTIF / COUNTIFS, so they work in Google Sheets and Excel.
B5: Checks | C5: =COUNTA('Checklist'!$C$2:$C$60)
B6: Done | C6: =COUNTIF('Checklist'!$H$2:$H$60,"Done")
B7: In progress | C7: =COUNTIF('Checklist'!$H$2:$H$60,"In progress")
B8: Not started | C8: =COUNTIF('Checklist'!$H$2:$H$60,"Not started")
B9: N/A | C9: =COUNTIF('Checklist'!$H$2:$H$60,"N/A")
B10: % complete (Done / applicable) | C10: =IFERROR(C6/(C5-C9),0) | D10: =REPT("█",ROUND(C10*20,0))&REPT("░",20-ROUND(C10*20,0))
B11: Open High-priority checks | C11: =COUNTIFS('Checklist'!$F$2:$F$60,"High",'Checklist'!$H$2:$H$60,"<>Done",'Checklist'!$H$2:$H$60,"<>N/A")
B13: Area | C13: Checks | D13: Done | E13: In progress | F13: Not started | G13: N/A | H13: % done | I13: Open High
B14: 1. Crawl access | C14: =COUNTIF('Checklist'!$B$2:$B$60,$B14) | D14: =COUNTIFS('Checklist'!$B$2:$B$60,$B14,'Checklist'!$H$2:$H$60,"Done") | E14: =COUNTIFS('Checklist'!$B$2:$B$60,$B14,'Checklist'!$H$2:$H$60,"In progress") | F14: =COUNTIFS('Checklist'!$B$2:$B$60,$B14,'Checklist'!$H$2:$H$60,"Not started") | G14: =COUNTIFS('Checklist'!$B$2:$B$60,$B14,'Checklist'!$H$2:$H$60,"N/A") | H14: =IFERROR(D14/(C14-G14),0) | I14: =COUNTIFS('Checklist'!$B$2:$B$60,$B14,'Checklist'!$F$2:$F$60,"High",'Checklist'!$H$2:$H$60,"<>Done",'Checklist'!$H$2:$H$60,"<>N/A") | J14: =REPT("█",ROUND(H14*10,0))&REPT("░",10-ROUND(H14*10,0))
B15: 2. Indexing & eligibility | C15: =COUNTIF('Checklist'!$B$2:$B$60,$B15) | D15: =COUNTIFS('Checklist'!$B$2:$B$60,$B15,'Checklist'!$H$2:$H$60,"Done") | E15: =COUNTIFS('Checklist'!$B$2:$B$60,$B15,'Checklist'!$H$2:$H$60,"In progress") | F15: =COUNTIFS('Checklist'!$B$2:$B$60,$B15,'Checklist'!$H$2:$H$60,"Not started") | G15: =COUNTIFS('Checklist'!$B$2:$B$60,$B15,'Checklist'!$H$2:$H$60,"N/A") | H15: =IFERROR(D15/(C15-G15),0) | I15: =COUNTIFS('Checklist'!$B$2:$B$60,$B15,'Checklist'!$F$2:$F$60,"High",'Checklist'!$H$2:$H$60,"<>Done",'Checklist'!$H$2:$H$60,"<>N/A") | J15: =REPT("█",ROUND(H15*10,0))&REPT("░",10-ROUND(H15*10,0))
B16: 3. Entity clarity | C16: =COUNTIF('Checklist'!$B$2:$B$60,$B16) | D16: =COUNTIFS('Checklist'!$B$2:$B$60,$B16,'Checklist'!$H$2:$H$60,"Done") | E16: =COUNTIFS('Checklist'!$B$2:$B$60,$B16,'Checklist'!$H$2:$H$60,"In progress") | F16: =COUNTIFS('Checklist'!$B$2:$B$60,$B16,'Checklist'!$H$2:$H$60,"Not started") | G16: =COUNTIFS('Checklist'!$B$2:$B$60,$B16,'Checklist'!$H$2:$H$60,"N/A") | H16: =IFERROR(D16/(C16-G16),0) | I16: =COUNTIFS('Checklist'!$B$2:$B$60,$B16,'Checklist'!$F$2:$F$60,"High",'Checklist'!$H$2:$H$60,"<>Done",'Checklist'!$H$2:$H$60,"<>N/A") | J16: =REPT("█",ROUND(H16*10,0))&REPT("░",10-ROUND(H16*10,0))
B17: 4. Chunk extractability | C17: =COUNTIF('Checklist'!$B$2:$B$60,$B17) | D17: =COUNTIFS('Checklist'!$B$2:$B$60,$B17,'Checklist'!$H$2:$H$60,"Done") | E17: =COUNTIFS('Checklist'!$B$2:$B$60,$B17,'Checklist'!$H$2:$H$60,"In progress") | F17: =COUNTIFS('Checklist'!$B$2:$B$60,$B17,'Checklist'!$H$2:$H$60,"Not started") | G17: =COUNTIFS('Checklist'!$B$2:$B$60,$B17,'Checklist'!$H$2:$H$60,"N/A") | H17: =IFERROR(D17/(C17-G17),0) | I17: =COUNTIFS('Checklist'!$B$2:$B$60,$B17,'Checklist'!$F$2:$F$60,"High",'Checklist'!$H$2:$H$60,"<>Done",'Checklist'!$H$2:$H$60,"<>N/A") | J17: =REPT("█",ROUND(H17*10,0))&REPT("░",10-ROUND(H17*10,0))
B18: 5. Claim quality | C18: =COUNTIF('Checklist'!$B$2:$B$60,$B18) | D18: =COUNTIFS('Checklist'!$B$2:$B$60,$B18,'Checklist'!$H$2:$H$60,"Done") | E18: =COUNTIFS('Checklist'!$B$2:$B$60,$B18,'Checklist'!$H$2:$H$60,"In progress") | F18: =COUNTIFS('Checklist'!$B$2:$B$60,$B18,'Checklist'!$H$2:$H$60,"Not started") | G18: =COUNTIFS('Checklist'!$B$2:$B$60,$B18,'Checklist'!$H$2:$H$60,"N/A") | H18: =IFERROR(D18/(C18-G18),0) | I18: =COUNTIFS('Checklist'!$B$2:$B$60,$B18,'Checklist'!$F$2:$F$60,"High",'Checklist'!$H$2:$H$60,"<>Done",'Checklist'!$H$2:$H$60,"<>N/A") | J18: =REPT("█",ROUND(H18*10,0))&REPT("░",10-ROUND(H18*10,0))
B19: 6. Structured data | C19: =COUNTIF('Checklist'!$B$2:$B$60,$B19) | D19: =COUNTIFS('Checklist'!$B$2:$B$60,$B19,'Checklist'!$H$2:$H$60,"Done") | E19: =COUNTIFS('Checklist'!$B$2:$B$60,$B19,'Checklist'!$H$2:$H$60,"In progress") | F19: =COUNTIFS('Checklist'!$B$2:$B$60,$B19,'Checklist'!$H$2:$H$60,"Not started") | G19: =COUNTIFS('Checklist'!$B$2:$B$60,$B19,'Checklist'!$H$2:$H$60,"N/A") | H19: =IFERROR(D19/(C19-G19),0) | I19: =COUNTIFS('Checklist'!$B$2:$B$60,$B19,'Checklist'!$F$2:$F$60,"High",'Checklist'!$H$2:$H$60,"<>Done",'Checklist'!$H$2:$H$60,"<>N/A") | J19: =REPT("█",ROUND(H19*10,0))&REPT("░",10-ROUND(H19*10,0))
B20: 7. Trust & corroboration | C20: =COUNTIF('Checklist'!$B$2:$B$60,$B20) | D20: =COUNTIFS('Checklist'!$B$2:$B$60,$B20,'Checklist'!$H$2:$H$60,"Done") | E20: =COUNTIFS('Checklist'!$B$2:$B$60,$B20,'Checklist'!$H$2:$H$60,"In progress") | F20: =COUNTIFS('Checklist'!$B$2:$B$60,$B20,'Checklist'!$H$2:$H$60,"Not started") | G20: =COUNTIFS('Checklist'!$B$2:$B$60,$B20,'Checklist'!$H$2:$H$60,"N/A") | H20: =IFERROR(D20/(C20-G20),0) | I20: =COUNTIFS('Checklist'!$B$2:$B$60,$B20,'Checklist'!$F$2:$F$60,"High",'Checklist'!$H$2:$H$60,"<>Done",'Checklist'!$H$2:$H$60,"<>N/A") | J20: =REPT("█",ROUND(H20*10,0))&REPT("░",10-ROUND(H20*10,0))
B21: 8. Measurement | C21: =COUNTIF('Checklist'!$B$2:$B$60,$B21) | D21: =COUNTIFS('Checklist'!$B$2:$B$60,$B21,'Checklist'!$H$2:$H$60,"Done") | E21: =COUNTIFS('Checklist'!$B$2:$B$60,$B21,'Checklist'!$H$2:$H$60,"In progress") | F21: =COUNTIFS('Checklist'!$B$2:$B$60,$B21,'Checklist'!$H$2:$H$60,"Not started") | G21: =COUNTIFS('Checklist'!$B$2:$B$60,$B21,'Checklist'!$H$2:$H$60,"N/A") | H21: =IFERROR(D21/(C21-G21),0) | I21: =COUNTIFS('Checklist'!$B$2:$B$60,$B21,'Checklist'!$F$2:$F$60,"High",'Checklist'!$H$2:$H$60,"<>Done",'Checklist'!$H$2:$H$60,"<>N/A") | J21: =REPT("█",ROUND(H21*10,0))&REPT("░",10-ROUND(H21*10,0))
B23: Priority | C23: Checks | D23: Done | E23: Open | F23: % done
B24: High | C24: =COUNTIF('Checklist'!$F$2:$F$60,$B24) | D24: =COUNTIFS('Checklist'!$F$2:$F$60,$B24,'Checklist'!$H$2:$H$60,"Done") | E24: =COUNTIFS('Checklist'!$F$2:$F$60,$B24,'Checklist'!$H$2:$H$60,"<>Done",'Checklist'!$H$2:$H$60,"<>N/A") | F24: =IFERROR(D24/(C24-COUNTIFS('Checklist'!$F$2:$F$60,$B24,'Checklist'!$H$2:$H$60,"N/A")),0)
B25: Medium | C25: =COUNTIF('Checklist'!$F$2:$F$60,$B25) | D25: =COUNTIFS('Checklist'!$F$2:$F$60,$B25,'Checklist'!$H$2:$H$60,"Done") | E25: =COUNTIFS('Checklist'!$F$2:$F$60,$B25,'Checklist'!$H$2:$H$60,"<>Done",'Checklist'!$H$2:$H$60,"<>N/A") | F25: =IFERROR(D25/(C25-COUNTIFS('Checklist'!$F$2:$F$60,$B25,'Checklist'!$H$2:$H$60,"N/A")),0)
B26: Low | C26: =COUNTIF('Checklist'!$F$2:$F$60,$B26) | D26: =COUNTIFS('Checklist'!$F$2:$F$60,$B26,'Checklist'!$H$2:$H$60,"Done") | E26: =COUNTIFS('Checklist'!$F$2:$F$60,$B26,'Checklist'!$H$2:$H$60,"<>Done",'Checklist'!$H$2:$H$60,"<>N/A") | F26: =IFERROR(D26/(C26-COUNTIFS('Checklist'!$F$2:$F$60,$B26,'Checklist'!$H$2:$H$60,"N/A")),0)
B28: AI visibility (from the Prompt tracker)
B29: Assistant | C29: Runs logged | D29: Mentioned | E29: Mention rate | F29: Cited with link | G29: Citation rate | H29: Accurate | I29: Accuracy rate
B30: All assistants | C30: =COUNTIF('Prompt tracker'!$E$3:$E$302,"Yes")+COUNTIF('Prompt tracker'!$E$3:$E$302,"No") | D30: =COUNTIF('Prompt tracker'!$E$3:$E$302,"Yes") | E30: =IFERROR(D30/C30,0) | F30: =COUNTIF('Prompt tracker'!$F$3:$F$302,"Yes") | G30: =IFERROR(F30/C30,0) | H30: =COUNTIF('Prompt tracker'!$H$3:$H$302,"Yes") | I30: =IFERROR(H30/D30,0)
B31: ChatGPT | C31: =COUNTIFS('Prompt tracker'!$D$3:$D$302,$B31,'Prompt tracker'!$E$3:$E$302,"Yes")+COUNTIFS('Prompt tracker'!$D$3:$D$302,$B31,'Prompt tracker'!$E$3:$E$302,"No") | D31: =COUNTIFS('Prompt tracker'!$D$3:$D$302,$B31,'Prompt tracker'!$E$3:$E$302,"Yes") | E31: =IFERROR(D31/C31,0) | F31: =COUNTIFS('Prompt tracker'!$D$3:$D$302,$B31,'Prompt tracker'!$F$3:$F$302,"Yes") | G31: =IFERROR(F31/C31,0) | H31: =COUNTIFS('Prompt tracker'!$D$3:$D$302,$B31,'Prompt tracker'!$H$3:$H$302,"Yes") | I31: =IFERROR(H31/D31,0)
B32: Perplexity | C32: =COUNTIFS('Prompt tracker'!$D$3:$D$302,$B32,'Prompt tracker'!$E$3:$E$302,"Yes")+COUNTIFS('Prompt tracker'!$D$3:$D$302,$B32,'Prompt tracker'!$E$3:$E$302,"No") | D32: =COUNTIFS('Prompt tracker'!$D$3:$D$302,$B32,'Prompt tracker'!$E$3:$E$302,"Yes") | E32: =IFERROR(D32/C32,0) | F32: =COUNTIFS('Prompt tracker'!$D$3:$D$302,$B32,'Prompt tracker'!$F$3:$F$302,"Yes") | G32: =IFERROR(F32/C32,0) | H32: =COUNTIFS('Prompt tracker'!$D$3:$D$302,$B32,'Prompt tracker'!$H$3:$H$302,"Yes") | I32: =IFERROR(H32/D32,0)
B33: Claude | C33: =COUNTIFS('Prompt tracker'!$D$3:$D$302,$B33,'Prompt tracker'!$E$3:$E$302,"Yes")+COUNTIFS('Prompt tracker'!$D$3:$D$302,$B33,'Prompt tracker'!$E$3:$E$302,"No") | D33: =COUNTIFS('Prompt tracker'!$D$3:$D$302,$B33,'Prompt tracker'!$E$3:$E$302,"Yes") | E33: =IFERROR(D33/C33,0) | F33: =COUNTIFS('Prompt tracker'!$D$3:$D$302,$B33,'Prompt tracker'!$F$3:$F$302,"Yes") | G33: =IFERROR(F33/C33,0) | H33: =COUNTIFS('Prompt tracker'!$D$3:$D$302,$B33,'Prompt tracker'!$H$3:$H$302,"Yes") | I33: =IFERROR(H33/D33,0)
B34: Gemini | C34: =COUNTIFS('Prompt tracker'!$D$3:$D$302,$B34,'Prompt tracker'!$E$3:$E$302,"Yes")+COUNTIFS('Prompt tracker'!$D$3:$D$302,$B34,'Prompt tracker'!$E$3:$E$302,"No") | D34: =COUNTIFS('Prompt tracker'!$D$3:$D$302,$B34,'Prompt tracker'!$E$3:$E$302,"Yes") | E34: =IFERROR(D34/C34,0) | F34: =COUNTIFS('Prompt tracker'!$D$3:$D$302,$B34,'Prompt tracker'!$F$3:$F$302,"Yes") | G34: =IFERROR(F34/C34,0) | H34: =COUNTIFS('Prompt tracker'!$D$3:$D$302,$B34,'Prompt tracker'!$H$3:$H$302,"Yes") | I34: =IFERROR(H34/D34,0)
B35: Google AI Mode | C35: =COUNTIFS('Prompt tracker'!$D$3:$D$302,$B35,'Prompt tracker'!$E$3:$E$302,"Yes")+COUNTIFS('Prompt tracker'!$D$3:$D$302,$B35,'Prompt tracker'!$E$3:$E$302,"No") | D35: =COUNTIFS('Prompt tracker'!$D$3:$D$302,$B35,'Prompt tracker'!$E$3:$E$302,"Yes") | E35: =IFERROR(D35/C35,0) | F35: =COUNTIFS('Prompt tracker'!$D$3:$D$302,$B35,'Prompt tracker'!$F$3:$F$302,"Yes") | G35: =IFERROR(F35/C35,0) | H35: =COUNTIFS('Prompt tracker'!$D$3:$D$302,$B35,'Prompt tracker'!$H$3:$H$302,"Yes") | I35: =IFERROR(H35/D35,0)
B36: Google AI Overview | C36: =COUNTIFS('Prompt tracker'!$D$3:$D$302,$B36,'Prompt tracker'!$E$3:$E$302,"Yes")+COUNTIFS('Prompt tracker'!$D$3:$D$302,$B36,'Prompt tracker'!$E$3:$E$302,"No") | D36: =COUNTIFS('Prompt tracker'!$D$3:$D$302,$B36,'Prompt tracker'!$E$3:$E$302,"Yes") | E36: =IFERROR(D36/C36,0) | F36: =COUNTIFS('Prompt tracker'!$D$3:$D$302,$B36,'Prompt tracker'!$F$3:$F$302,"Yes") | G36: =IFERROR(F36/C36,0) | H36: =COUNTIFS('Prompt tracker'!$D$3:$D$302,$B36,'Prompt tracker'!$H$3:$H$302,"Yes") | I36: =IFERROR(H36/D36,0)
B37: Microsoft Copilot | C37: =COUNTIFS('Prompt tracker'!$D$3:$D$302,$B37,'Prompt tracker'!$E$3:$E$302,"Yes")+COUNTIFS('Prompt tracker'!$D$3:$D$302,$B37,'Prompt tracker'!$E$3:$E$302,"No") | D37: =COUNTIFS('Prompt tracker'!$D$3:$D$302,$B37,'Prompt tracker'!$E$3:$E$302,"Yes") | E37: =IFERROR(D37/C37,0) | F37: =COUNTIFS('Prompt tracker'!$D$3:$D$302,$B37,'Prompt tracker'!$F$3:$F$302,"Yes") | G37: =IFERROR(F37/C37,0) | H37: =COUNTIFS('Prompt tracker'!$D$3:$D$302,$B37,'Prompt tracker'!$H$3:$H$302,"Yes") | I37: =IFERROR(H37/D37,0)
B38: Other | C38: =COUNTIFS('Prompt tracker'!$D$3:$D$302,$B38,'Prompt tracker'!$E$3:$E$302,"Yes")+COUNTIFS('Prompt tracker'!$D$3:$D$302,$B38,'Prompt tracker'!$E$3:$E$302,"No") | D38: =COUNTIFS('Prompt tracker'!$D$3:$D$302,$B38,'Prompt tracker'!$E$3:$E$302,"Yes") | E38: =IFERROR(D38/C38,0) | F38: =COUNTIFS('Prompt tracker'!$D$3:$D$302,$B38,'Prompt tracker'!$F$3:$F$302,"Yes") | G38: =IFERROR(F38/C38,0) | H38: =COUNTIFS('Prompt tracker'!$D$3:$D$302,$B38,'Prompt tracker'!$H$3:$H$302,"Yes") | I38: =IFERROR(H38/D38,0)
B39: Mention rate = runs where you were named / runs logged. Citation rate = runs with a link to your site / runs logged. Accuracy rate = accurate descriptions / runs where you were named.
