Workbook

Sheet Start here
A1: Content Audit Template
A2: Search Console + GA4 + Screaming Frog → Keep / Update / Merge / Prune / Redirect · by Lazarina Stoy · MLforSEO
A4: What it does
A5: Joins your crawl, Search Console and GA4 data per URL, checks each page for decay, striking distance, thin content,
A6: overlap with another page and conversions, and suggests a decision with a plain-English reason. Every threshold sits on
A7: the Rules tab, so you can see (and change) exactly why a page got its label. Your Override column always wins.
A9: How to use it
A10: 1. Crawl: run Screaming Frog (turn on near-duplicates and, if you can, embeddings for semantic similarity), then
A11: Internal > HTML > Export. Paste the whole file into the Crawl tab from cell A1, headers included.
A12: 2. GSC current: Search Console > Performance > last 3 months > Pages tab > Export > CSV. Paste Pages.csv from A1.
A13: 3. GSC previous: the same export for the 3 months before (Date > Custom). Optional, but decay needs it.
A14: 4. GA4: Reports > Engagement > Landing page, same dates > Share > Download CSV. Delete the lines starting with #, paste from A1.
... A29: Legend
A30: Dark header | B30: Input column: paste or type here.
A31: Purple header | B31: Calculated column: formulas, please don't type over them.
A32: Lavender band | B32: Readability banding and paste zones.
A33: Yellow cell | B33: A flag that needs a human look, or an editable setting.
A34: Soft red | B34: A stronger warning (for example cannibalisation or a prune decision).
A35: Credits
A36: Template by Lazarina Stoy · MLforSEO (mlforseo.com). Free to use and adapt; please keep this credit.
A37: Read: Blog and site architecture for SEO and conversions in the AI search era (MLforSEO)
A38: Course: Introduction to Machine Learning for SEO (MLforSEO Academy)
A39: Code and helper script: github.com/lazarinastoy/mlforseo-code/content-audit-template

Sheet Audit
A1: FROM THE CRAWL | K1: SEARCH CONSOLE + GA4 | T1: SIGNALS AND DECISION | AC1: YOUR INPUT | AF1: SAMPLE DATA (synthetic site). Clear the input tabs to start.
A2: URL | B2: Key | C2: Status code | D2: Indexability | E2: Indexability status | F2: Word count | G2: Unique inlinks | H2: Near duplicates | I2: Overlapping page | J2: Semantic similarity | K2: Clicks | L2: Impressions | M2: CTR | N2: Avg position | O2: Clicks (previous period) | P2: Click change | Q2: Sessions | R2: Avg engagement time (s) | S2: Key events | T2: Thin? | U2: Decaying? | V2: Striking distance? | W2: Overlaps another page? | X2: Overlap has more clicks? | Y2: Converts? | Z2: Low value? | AA2: Suggested decision | AB2: Reason | AC2: Referring domains (optional) | AD2: Override | AE2: Final decision | AF2: Notes
A3: =IF(Crawl!A2="","",Crawl!A2) | B3: =IF(A3="","",Crawl!EC2) | C3: =IF(A3="","",IFERROR(INDEX(Crawl!$A2:$DZ2,1,Rules!$H$6),"")) | D3: =IF(A3="","",IFERROR(INDEX(Crawl!$A2:$DZ2,1,Rules!$H$7),"")&"") | E3: =IF(A3="","",IFERROR(INDEX(Crawl!$A2:$DZ2,1,Rules!$H$8),"")&"") | F3: =IF(A3="","",IFERROR(INDEX(Crawl!$A2:$DZ2,1,Rules!$H$9),"")) | G3: =IF(A3="","",IFERROR(INDEX(Crawl!$A2:$DZ2,1,Rules!$H$10),"")) | H3: =IF(A3="","",IFERROR(INDEX(Crawl!$A2:$DZ2,1,Rules!$H$12),"")) | I3: =IF(A3="","",IF(AND(N(H3)>0,IFERROR(INDEX(Crawl!$A2:$DZ2,1,Rules!$H$11),"")&""<>""),IFERROR(INDEX(Crawl!$A2:$DZ2,1,Rules!$H$11),"")&"",IF(AND(ISNUMBER(J3),N(J3)>=Rules!$B$12,IFERROR(INDEX(Crawl!$A2:$DZ2,1,Rules!$H$13),"")&""<>""),IFERROR(INDEX(Crawl!$A2:$DZ2,1,Rules!$H$13),"")&"",""))) | J3: =IF(A3="","",IF(IFERROR(INDEX(Crawl!$A2:$DZ2,1,Rules!$H$14),"")&""="","",IFERROR(INDEX(Crawl!$A2:$DZ2,1,Rules!$H$14),""))) | K3: =IF(A3="","",IFERROR(SUMIFS('GSC current'!$J$2:$J$2001,'GSC current'!$I$2:$I$2001,B3),0)) | L3: =IF(A3="","",IFERROR(SUMIFS('GSC current'!$K$2:$K$2001,'GSC current'!$I$2:$I$2001,B3),0)) | M3: =IF(A3="","",IF(N(L3)>0,K3/L3,"")) | N3: =IF(A3="","",IF(N(L3)>0,SUMIFS('GSC current'!$L$2:$L$2001,'GSC current'!$I$2:$I$2001,B3)/L3,"")) | O3: =IF(A3="","",IFERROR(SUMIFS('GSC previous'!$J$2:$J$2001,'GSC previous'!$I$2:$I$2001,B3),0)) | P3: =IF(A3="","",IF(N(O3)>0,(K3-O3)/O3,"")) | Q3: =IF(A3="","",IFERROR(SUMIFS(GA4!$P$2:$P$2001,GA4!$O$2:$O$2001,B3),0)) | R3: =IF(A3="","",IF(N(Q3)>0,SUMIFS(GA4!$Q$2:$Q$2001,GA4!$O$2:$O$2001,B3)/Q3,"")) | S3: =IF(A3="","",IFERROR(SUMIFS(GA4!$R$2:$R$2001,GA4!$O$2:$O$2001,B3),0)) | T3: =IF(A3="","",IF(AND(ISNUMBER(F3),LEFT(C3&"",1)="2"),IF(F3<Rules!$B$9,"Yes","No"),"No")) | U3: =IF(A3="","",IF(AND(N(O3)>=Rules!$B$8,ISNUMBER(P3)),IF(P3<=-Rules!$B$7,"Yes","No"),"No")) | V3: =IF(A3="","",IF(AND(N(L3)>=Rules!$B$6,ISNUMBER(N3)),IF(AND(N3>=Rules!$B$10,N3<=Rules!$B$11),"Yes","No"),"No")) | W3: =IF(A3="","",IF(I3<>"","Yes","No")) | X3: =IF(I3="","",IF(SUMIFS($K$3:$K$2002,$A$3:$A$2002,SUBSTITUTE(SUBSTITUTE(I3,"?","~?"),"*","~*"))>N(K3),"Yes","No")) | Y3: =IF(A3="","",IF(N(S3)>0,"Yes","No")) | Z3: =IF(A3="","",IF(AND(N(K3)<Rules!$B$5,N(L3)<Rules!$B$6,N(Q3)<Rules!$B$13,Y3="No"),"Yes","No")) | AA3: =IF(A3="","",IF(LEFT(C3&"",1)="3","Redirect",IF(OR(LEFT(C3&"",1)="4",LEFT(C3&"",1)="5"),IF(OR(N(K3)>0,N(AC3)>=Rules!$B$14),"Redirect","Prune"),IF(D3="Non-Indexable","Keep",IF(AND(W3="Yes",X3="Yes",Y3="No"),"Merge",IF(OR(U3="Yes",V3="Yes",AND(T3="Yes",N(L3)>=Rules!$B$6)),"Update",IF(Z3="Yes",IF(N(AC3)>=Rules!$B$14,"Redirect","Prune"),"Keep"))))))) | AB3: =IF(A3="","",IF(LEFT(C3&"",1)="3","Already redirects ("&C3&"). Update internal links to point at the final URL.",IF(OR(LEFT(C3&"",1)="4",LEFT(C3&"",1)="5"),IF(AA3="Redirect","Returns "&C3&" but still has "&N(K3)&" clicks and "&N(AC3)&" referring domains. 301 it to the closest live page.","Returns "&C3&" with no clicks or links. Remove internal links and let it 404 or 410."),IF(D3="Non-Indexable","Non-indexable ("&E3&"). Keep if that is intentional; otherwise fix the canonical or noindex.",IF(AA3="Merge","Overlaps with "&I3&IF(N(J3)>0," (similarity "&TEXT(J3,"0.00")&")","")&", which gets more clicks. Merge the useful parts into it and 301 this URL.",IF(AA3="Update",MID(IF(U3="Yes","; Clicks down "&TEXT(-P3,"0%")&" on the previous period","")&IF(V3="Yes","; Average position "&TEXT(N3,"0.0")&" on "&TEXT(L3,"#,##0")&" impressions (striking distance)","")&IF(AND(T3="Yes",N(L3)>=Rules!$B$6),"; Thin ("&F3&" words) but has search demand",""),3,400),IF(AA3="Prune","Low value: "&N(K3)&" clicks, "&N(L3)&" impressions, "&N(Q3)&" sessions, no key events. Remove or noindex it and update internal links.",IF(AA3="Redirect","Low value but "&N(AC3)&" referring domains. 301 it to the closest relevant page to keep those links.",IF(AND(Z3="No",Y3="Yes",N(K3)<Rules!$B$5),"Low search traffic but it converts (key events: "&S3&"). Keep it and link to it.",IF(W3="Yes","Stronger than the page it overlaps ("&I3&"). Keep; merge that page into this one.","Healthy: "&N(K3)&" clicks"&IF(ISNUMBER(N3),", average position "&TEXT(N3,"0.0"),"")&". Keep and monitor.")))))))))) | AE3: =IF(A3="","",IF(AD3<>"",AD3,AA3))
A4: =IF(Crawl!A3="","",Crawl!A3) | B4: =IF(A4="","",Crawl!EC3) | C4: =IF(A4="","",IFERROR(INDEX(Crawl!$A3:$DZ3,1,Rules!$H$6),"")) | D4: =IF(A4="","",IFERROR(INDEX(Crawl!$A3:$DZ3,1,Rules!$H$7),"")&"") | E4: =IF(A4="","",IFERROR(INDEX(Crawl!$A3:$DZ3,1,Rules!$H$8),"")&"") | F4: =IF(A4="","",IFERROR(INDEX(Crawl!$A3:$DZ3,1,Rules!$H$9),"")) | G4: =IF(A4="","",IFERROR(INDEX(Crawl!$A3:$DZ3,1,Rules!$H$10),"")) | H4: =IF(A4="","",IFERROR(INDEX(Crawl!$A3:$DZ3,1,Rules!$H$12),"")) | I4: =IF(A4="","",IF(AND(N(H4)>0,IFERROR(INDEX(Crawl!$A3:$DZ3,1,Rules!$H$11),"")&""<>""),IFERROR(INDEX(Crawl!$A3:$DZ3,1,Rules!$H$11),"")&"",IF(AND(ISNUMBER(J4),N(J4)>=Rules!$B$12,IFERROR(INDEX(Crawl!$A3:$DZ3,1,Rules!$H$13),"")&""<>""),IFERROR(INDEX(Crawl!$A3:$DZ3,1,Rules!$H$13),"")&"",""))) | J4: =IF(A4="","",IF(IFERROR(INDEX(Crawl!$A3:$DZ3,1,Rules!$H$14),"")&""="","",IFERROR(INDEX(Crawl!$A3:$DZ3,1,Rules!$H$14),""))) | K4: =IF(A4="","",IFERROR(SUMIFS('GSC current'!$J$2:$J$2001,'GSC current'!$I$2:$I$2001,B4),0)) | L4: =IF(A4="","",IFERROR(SUMIFS('GSC current'!$K$2:$K$2001,'GSC current'!$I$2:$I$2001,B4),0)) | M4: =IF(A4="","",IF(N(L4)>0,K4/L4,"")) | N4: =IF(A4="","",IF(N(L4)>0,SUMIFS('GSC current'!$L$2:$L$2001,'GSC current'!$I$2:$I$2001,B4)/L4,"")) | O4: =IF(A4="","",IFERROR(SUMIFS('GSC previous'!$J$2:$J$2001,'GSC previous'!$I$2:$I$2001,B4),0)) | P4: =IF(A4="","",IF(N(O4)>0,(K4-O4)/O4,"")) | Q4: =IF(A4="","",IFERROR(SUMIFS(GA4!$P$2:$P$2001,GA4!$O$2:$O$2001,B4),0)) | R4: =IF(A4="","",IF(N(Q4)>0,SUMIFS(GA4!$Q$2:$Q$2001,GA4!$O$2:$O$2001,B4)/Q4,"")) | S4: =IF(A4="","",IFERROR(SUMIFS(GA4!$R$2:$R$2001,GA4!$O$2:$O$2001,B4),0)) | T4: =IF(A4="","",IF(AND(ISNUMBER(F4),LEFT(C4&"",1)="2"),IF(F4<Rules!$B$9,"Yes","No"),"No")) | U4: =IF(A4="","",IF(AND(N(O4)>=Rules!$B$8,ISNUMBER(P4)),IF(P4<=-Rules!$B$7,"Yes","No"),"No")) | V4: =IF(A4="","",IF(AND(N(L4)>=Rules!$B$6,ISNUMBER(N4)),IF(AND(N4>=Rules!$B$10,N4<=Rules!$B$11),"Yes","No"),"No")) | W4: =IF(A4="","",IF(I4<>"","Yes","No")) | X4: =IF(I4="","",IF(SUMIFS($K$3:$K$2002,$A$3:$A$2002,SUBSTITUTE(SUBSTITUTE(I4,"?","~?"),"*","~*"))>N(K4),"Yes","No")) | Y4: =IF(A4="","",IF(N(S4)>0,"Yes","No")) | Z4: =IF(A4="","",IF(AND(N(K4)<Rules!$B$5,N(L4)<Rules!$B$6,N(Q4)<Rules!$B$13,Y4="No"),"Yes","No")) | AA4: =IF(A4="","",IF(LEFT(C4&"",1)="3","Redirect",IF(OR(LEFT(C4&"",1)="4",LEFT(C4&"",1)="5"),IF(OR(N(K4)>0,N(AC4)>=Rules!$B$14),"Redirect","Prune"),IF(D4="Non-Indexable","Keep",IF(AND(W4="Yes",X4="Yes",Y4="No"),"Merge",IF(OR(U4="Yes",V4="Yes",AND(T4="Yes",N(L4)>=Rules!$B$6)),"Update",IF(Z4="Yes",IF(N(AC4)>=Rules!$B$14,"Redirect","Prune"),"Keep"))))))) | AB4: =IF(A4="","",IF(LEFT(C4&"",1)="3","Already redirects ("&C4&"). Update internal links to point at the final URL.",IF(OR(LEFT(C4&"",1)="4",LEFT(C4&"",1)="5"),IF(AA4="Redirect","Returns "&C4&" but still has "&N(K4)&" clicks and "&N(AC4)&" referring domains. 301 it to the closest live page.","Returns "&C4&" with no clicks or links. Remove internal links and let it 404 or 410."),IF(D4="Non-Indexable","Non-indexable ("&E4&"). Keep if that is intentional; otherwise fix the canonical or noindex.",IF(AA4="Merge","Overlaps with "&I4&IF(N(J4)>0," (similarity "&TEXT(J4,"0.00")&")","")&", which gets more clicks. Merge the useful parts into it and 301 this URL.",IF(AA4="Update",MID(IF(U4="Yes","; Clicks down "&TEXT(-P4,"0%")&" on the previous period","")&IF(V4="Yes","; Average position "&TEXT(N4,"0.0")&" on "&TEXT(L4,"#,##0")&" impressions (striking distance)","")&IF(AND(T4="Yes",N(L4)>=Rules!$B$6),"; Thin ("&F4&" words) but has search demand",""),3,400),IF(AA4="Prune","Low value: "&N(K4)&" clicks, "&N(L4)&" impressions, "&N(Q4)&" sessions, no key events. Remove or noindex it and update internal links.",IF(AA4="Redirect","Low value but "&N(AC4)&" referring domains. 301 it to the closest relevant page to keep those links.",IF(AND(Z4="No",Y4="Yes",N(K4)<Rules!$B$5),"Low search traffic but it converts (key events: "&S4&"). Keep it and link to it.",IF(W4="Yes","Stronger than the page it overlaps ("&I4&"). Keep; merge that page into this one.","Healthy: "&N(K4)&" clicks"&IF(ISNUMBER(N4),", average position "&TEXT(N4,"0.0"),"")&". Keep and monitor.")))))))))) | AE4: =IF(A4="","",IF(AD4<>"",AD4,AA4))
A5: =IF(Crawl!A4="","",Crawl!A4) | B5: =IF(A5="","",Crawl!EC4) | C5: =IF(A5="","",IFERROR(INDEX(Crawl!$A4:$DZ4,1,Rules!$H$6),"")) | D5: =IF(A5="","",IFERROR(INDEX(Crawl!$A4:$DZ4,1,Rules!$H$7),"")&"") | E5: =IF(A5="","",IFERROR(INDEX(Crawl!$A4:$DZ4,1,Rules!$H$8),"")&"") | F5: =IF(A5="","",IFERROR(INDEX(Crawl!$A4:$DZ4,1,Rules!$H$9),"")) | G5: =IF(A5="","",IFERROR(INDEX(Crawl!$A4:$DZ4,1,Rules!$H$10),"")) | H5: =IF(A5="","",IFERROR(INDEX(Crawl!$A4:$DZ4,1,Rules!$H$12),"")) | I5: =IF(A5="","",IF(AND(N(H5)>0,IFERROR(INDEX(Crawl!$A4:$DZ4,1,Rules!$H$11),"")&""<>""),IFERROR(INDEX(Crawl!$A4:$DZ4,1,Rules!$H$11),"")&"",IF(AND(ISNUMBER(J5),N(J5)>=Rules!$B$12,IFERROR(INDEX(Crawl!$A4:$DZ4,1,Rules!$H$13),"")&""<>""),IFERROR(INDEX(Crawl!$A4:$DZ4,1,Rules!$H$13),"")&"",""))) | J5: =IF(A5="","",IF(IFERROR(INDEX(Crawl!$A4:$DZ4,1,Rules!$H$14),"")&""="","",IFERROR(INDEX(Crawl!$A4:$DZ4,1,Rules!$H$14),""))) | K5: =IF(A5="","",IFERROR(SUMIFS('GSC current'!$J$2:$J$2001,'GSC current'!$I$2:$I$2001,B5),0)) | L5: =IF(A5="","",IFERROR(SUMIFS('GSC current'!$K$2:$K$2001,'GSC current'!$I$2:$I$2001,B5),0)) | M5: =IF(A5="","",IF(N(L5)>0,K5/L5,"")) | N5: =IF(A5="","",IF(N(L5)>0,SUMIFS('GSC current'!$L$2:$L$2001,'GSC current'!$I$2:$I$2001,B5)/L5,"")) | O5: =IF(A5="","",IFERROR(SUMIFS('GSC previous'!$J$2:$J$2001,'GSC previous'!$I$2:$I$2001,B5),0)) | P5: =IF(A5="","",IF(N(O5)>0,(K5-O5)/O5,"")) | Q5: =IF(A5="","",IFERROR(SUMIFS(GA4!$P$2:$P$2001,GA4!$O$2:$O$2001,B5),0)) | R5: =IF(A5="","",IF(N(Q5)>0,SUMIFS(GA4!$Q$2:$Q$2001,GA4!$O$2:$O$2001,B5)/Q5,"")) | S5: =IF(A5="","",IFERROR(SUMIFS(GA4!$R$2:$R$2001,GA4!$O$2:$O$2001,B5),0)) | T5: =IF(A5="","",IF(AND(ISNUMBER(F5),LEFT(C5&"",1)="2"),IF(F5<Rules!$B$9,"Yes","No"),"No")) | U5: =IF(A5="","",IF(AND(N(O5)>=Rules!$B$8,ISNUMBER(P5)),IF(P5<=-Rules!$B$7,"Yes","No"),"No")) | V5: =IF(A5="","",IF(AND(N(L5)>=Rules!$B$6,ISNUMBER(N5)),IF(AND(N5>=Rules!$B$10,N5<=Rules!$B$11),"Yes","No"),"No")) | W5: =IF(A5="","",IF(I5<>"","Yes","No")) | X5: =IF(I5="","",IF(SUMIFS($K$3:$K$2002,$A$3:$A$2002,SUBSTITUTE(SUBSTITUTE(I5,"?","~?"),"*","~*"))>N(K5),"Yes","No")) | Y5: =IF(A5="","",IF(N(S5)>0,"Yes","No")) | Z5: =IF(A5="","",IF(AND(N(K5)<Rules!$B$5,N(L5)<Rules!$B$6,N(Q5)<Rules!$B$13,Y5="No"),"Yes","No")) | AA5: =IF(A5="","",IF(LEFT(C5&"",1)="3","Redirect",IF(OR(LEFT(C5&"",1)="4",LEFT(C5&"",1)="5"),IF(OR(N(K5)>0,N(AC5)>=Rules!$B$14),"Redirect","Prune"),IF(D5="Non-Indexable","Keep",IF(AND(W5="Yes",X5="Yes",Y5="No"),"Merge",IF(OR(U5="Yes",V5="Yes",AND(T5="Yes",N(L5)>=Rules!$B$6)),"Update",IF(Z5="Yes",IF(N(AC5)>=Rules!$B$14,"Redirect","Prune"),"Keep"))))))) | AB5: =IF(A5="","",IF(LEFT(C5&"",1)="3","Already redirects ("&C5&"). Update internal links to point at the final URL.",IF(OR(LEFT(C5&"",1)="4",LEFT(C5&"",1)="5"),IF(AA5="Redirect","Returns "&C5&" but still has "&N(K5)&" clicks and "&N(AC5)&" referring domains. 301 it to the closest live page.","Returns "&C5&" with no clicks or links. Remove internal links and let it 404 or 410."),IF(D5="Non-Indexable","Non-indexable ("&E5&"). Keep if that is intentional; otherwise fix the canonical or noindex.",IF(AA5="Merge","Overlaps with "&I5&IF(N(J5)>0," (similarity "&TEXT(J5,"0.00")&")","")&", which gets more clicks. Merge the useful parts into it and 301 this URL.",IF(AA5="Update",MID(IF(U5="Yes","; Clicks down "&TEXT(-P5,"0%")&" on the previous period","")&IF(V5="Yes","; Average position "&TEXT(N5,"0.0")&" on "&TEXT(L5,"#,##0")&" impressions (striking distance)","")&IF(AND(T5="Yes",N(L5)>=Rules!$B$6),"; Thin ("&F5&" words) but has search demand",""),3,400),IF(AA5="Prune","Low value: "&N(K5)&" clicks, "&N(L5)&" impressions, "&N(Q5)&" sessions, no key events. Remove or noindex it and update internal links.",IF(AA5="Redirect","Low value but "&N(AC5)&" referring domains. 301 it to the closest relevant page to keep those links.",IF(AND(Z5="No",Y5="Yes",N(K5)<Rules!$B$5),"Low search traffic but it converts (key events: "&S5&"). Keep it and link to it.",IF(W5="Yes","Stronger than the page it overlaps ("&I5&"). Keep; merge that page into this one.","Healthy: "&N(K5)&" clicks"&IF(ISNUMBER(N5),", average position "&TEXT(N5,"0.0"),"")&". Keep and monitor.")))))))))) | AE5: =IF(A5="","",IF(AD5<>"",AD5,AA5))
A6: =IF(Crawl!A5="","",Crawl!A5) | B6: =IF(A6="","",Crawl!EC5) | C6: =IF(A6="","",IFERROR(INDEX(Crawl!$A5:$DZ5,1,Rules!$H$6),"")) | D6: =IF(A6="","",IFERROR(INDEX(Crawl!$A5:$DZ5,1,Rules!$H$7),"")&"") | E6: =IF(A6="","",IFERROR(INDEX(Crawl!$A5:$DZ5,1,Rules!$H$8),"")&"") | F6: =IF(A6="","",IFERROR(INDEX(Crawl!$A5:$DZ5,1,Rules!$H$9),"")) | G6: =IF(A6="","",IFERROR(INDEX(Crawl!$A5:$DZ5,1,Rules!$H$10),"")) | H6: =IF(A6="","",IFERROR(INDEX(Crawl!$A5:$DZ5,1,Rules!$H$12),"")) | I6: =IF(A6="","",IF(AND(N(H6)>0,IFERROR(INDEX(Crawl!$A5:$DZ5,1,Rules!$H$11),"")&""<>""),IFERROR(INDEX(Crawl!$A5:$DZ5,1,Rules!$H$11),"")&"",IF(AND(ISNUMBER(J6),N(J6)>=Rules!$B$12,IFERROR(INDEX(Crawl!$A5:$DZ5,1,Rules!$H$13),"")&""<>""),IFERROR(INDEX(Crawl!$A5:$DZ5,1,Rules!$H$13),"")&"",""))) | J6: =IF(A6="","",IF(IFERROR(INDEX(Crawl!$A5:$DZ5,1,Rules!$H$14),"")&""="","",IFERROR(INDEX(Crawl!$A5:$DZ5,1,Rules!$H$14),""))) | K6: =IF(A6="","",IFERROR(SUMIFS('GSC current'!$J$2:$J$2001,'GSC current'!$I$2:$I$2001,B6),0)) | L6: =IF(A6="","",IFERROR(SUMIFS('GSC current'!$K$2:$K$2001,'GSC current'!$I$2:$I$2001,B6),0)) | M6: =IF(A6="","",IF(N(L6)>0,K6/L6,"")) | N6: =IF(A6="","",IF(N(L6)>0,SUMIFS('GSC current'!$L$2:$L$2001,'GSC current'!$I$2:$I$2001,B6)/L6,"")) | O6: =IF(A6="","",IFERROR(SUMIFS('GSC previous'!$J$2:$J$2001,'GSC previous'!$I$2:$I$2001,B6),0)) | P6: =IF(A6="","",IF(N(O6)>0,(K6-O6)/O6,"")) | Q6: =IF(A6="","",IFERROR(SUMIFS(GA4!$P$2:$P$2001,GA4!$O$2:$O$2001,B6),0)) | R6: =IF(A6="","",IF(N(Q6)>0,SUMIFS(GA4!$Q$2:$Q$2001,GA4!$O$2:$O$2001,B6)/Q6,"")) | S6: =IF(A6="","",IFERROR(SUMIFS(GA4!$R$2:$R$2001,GA4!$O$2:$O$2001,B6),0)) | T6: =IF(A6="","",IF(AND(ISNUMBER(F6),LEFT(C6&"",1)="2"),IF(F6<Rules!$B$9,"Yes","No"),"No")) | U6: =IF(A6="","",IF(AND(N(O6)>=Rules!$B$8,ISNUMBER(P6)),IF(P6<=-Rules!$B$7,"Yes","No"),"No")) | V6: =IF(A6="","",IF(AND(N(L6)>=Rules!$B$6,ISNUMBER(N6)),IF(AND(N6>=Rules!$B$10,N6<=Rules!$B$11),"Yes","No"),"No")) | W6: =IF(A6="","",IF(I6<>"","Yes","No")) | X6: =IF(I6="","",IF(SUMIFS($K$3:$K$2002,$A$3:$A$2002,SUBSTITUTE(SUBSTITUTE(I6,"?","~?"),"*","~*"))>N(K6),"Yes","No")) | Y6: =IF(A6="","",IF(N(S6)>0,"Yes","No")) | Z6: =IF(A6="","",IF(AND(N(K6)<Rules!$B$5,N(L6)<Rules!$B$6,N(Q6)<Rules!$B$13,Y6="No"),"Yes","No")) | AA6: =IF(A6="","",IF(LEFT(C6&"",1)="3","Redirect",IF(OR(LEFT(C6&"",1)="4",LEFT(C6&"",1)="5"),IF(OR(N(K6)>0,N(AC6)>=Rules!$B$14),"Redirect","Prune"),IF(D6="Non-Indexable","Keep",IF(AND(W6="Yes",X6="Yes",Y6="No"),"Merge",IF(OR(U6="Yes",V6="Yes",AND(T6="Yes",N(L6)>=Rules!$B$6)),"Update",IF(Z6="Yes",IF(N(AC6)>=Rules!$B$14,"Redirect","Prune"),"Keep"))))))) | AB6: =IF(A6="","",IF(LEFT(C6&"",1)="3","Already redirects ("&C6&"). Update internal links to point at the final URL.",IF(OR(LEFT(C6&"",1)="4",LEFT(C6&"",1)="5"),IF(AA6="Redirect","Returns "&C6&" but still has "&N(K6)&" clicks and "&N(AC6)&" referring domains. 301 it to the closest live page.","Returns "&C6&" with no clicks or links. Remove internal links and let it 404 or 410."),IF(D6="Non-Indexable","Non-indexable ("&E6&"). Keep if that is intentional; otherwise fix the canonical or noindex.",IF(AA6="Merge","Overlaps with "&I6&IF(N(J6)>0," (similarity "&TEXT(J6,"0.00")&")","")&", which gets more clicks. Merge the useful parts into it and 301 this URL.",IF(AA6="Update",MID(IF(U6="Yes","; Clicks down "&TEXT(-P6,"0%")&" on the previous period","")&IF(V6="Yes","; Average position "&TEXT(N6,"0.0")&" on "&TEXT(L6,"#,##0")&" impressions (striking distance)","")&IF(AND(T6="Yes",N(L6)>=Rules!$B$6),"; Thin ("&F6&" words) but has search demand",""),3,400),IF(AA6="Prune","Low value: "&N(K6)&" clicks, "&N(L6)&" impressions, "&N(Q6)&" sessions, no key events. Remove or noindex it and update internal links.",IF(AA6="Redirect","Low value but "&N(AC6)&" referring domains. 301 it to the closest relevant page to keep those links.",IF(AND(Z6="No",Y6="Yes",N(K6)<Rules!$B$5),"Low search traffic but it converts (key events: "&S6&"). Keep it and link to it.",IF(W6="Yes","Stronger than the page it overlaps ("&I6&"). Keep; merge that page into this one.","Healthy: "&N(K6)&" clicks"&IF(ISNUMBER(N6),", average position "&TEXT(N6,"0.0"),"")&". Keep and monitor.")))))))))) | AE6: =IF(A6="","",IF(AD6<>"",AD6,AA6))
A7: =IF(Crawl!A6="","",Crawl!A6) | B7: =IF(A7="","",Crawl!EC6) | C7: =IF(A7="","",IFERROR(INDEX(Crawl!$A6:$DZ6,1,Rules!$H$6),"")) | D7: =IF(A7="","",IFERROR(INDEX(Crawl!$A6:$DZ6,1,Rules!$H$7),"")&"") | E7: =IF(A7="","",IFERROR(INDEX(Crawl!$A6:$DZ6,1,Rules!$H$8),"")&"") | F7: =IF(A7="","",IFERROR(INDEX(Crawl!$A6:$DZ6,1,Rules!$H$9),"")) | G7: =IF(A7="","",IFERROR(INDEX(Crawl!$A6:$DZ6,1,Rules!$H$10),"")) | H7: =IF(A7="","",IFERROR(INDEX(Crawl!$A6:$DZ6,1,Rules!$H$12),"")) | I7: =IF(A7="","",IF(AND(N(H7)>0,IFERROR(INDEX(Crawl!$A6:$DZ6,1,Rules!$H$11),"")&""<>""),IFERROR(INDEX(Crawl!$A6:$DZ6,1,Rules!$H$11),"")&"",IF(AND(ISNUMBER(J7),N(J7)>=Rules!$B$12,IFERROR(INDEX(Crawl!$A6:$DZ6,1,Rules!$H$13),"")&""<>""),IFERROR(INDEX(Crawl!$A6:$DZ6,1,Rules!$H$13),"")&"",""))) | J7: =IF(A7="","",IF(IFERROR(INDEX(Crawl!$A6:$DZ6,1,Rules!$H$14),"")&""="","",IFERROR(INDEX(Crawl!$A6:$DZ6,1,Rules!$H$14),""))) | K7: =IF(A7="","",IFERROR(SUMIFS('GSC current'!$J$2:$J$2001,'GSC current'!$I$2:$I$2001,B7),0)) | L7: =IF(A7="","",IFERROR(SUMIFS('GSC current'!$K$2:$K$2001,'GSC current'!$I$2:$I$2001,B7),0)) | M7: =IF(A7="","",IF(N(L7)>0,K7/L7,"")) | N7: =IF(A7="","",IF(N(L7)>0,SUMIFS('GSC current'!$L$2:$L$2001,'GSC current'!$I$2:$I$2001,B7)/L7,"")) | O7: =IF(A7="","",IFERROR(SUMIFS('GSC previous'!$J$2:$J$2001,'GSC previous'!$I$2:$I$2001,B7),0)) | P7: =IF(A7="","",IF(N(O7)>0,(K7-O7)/O7,"")) | Q7: =IF(A7="","",IFERROR(SUMIFS(GA4!$P$2:$P$2001,GA4!$O$2:$O$2001,B7),0)) | R7: =IF(A7="","",IF(N(Q7)>0,SUMIFS(GA4!$Q$2:$Q$2001,GA4!$O$2:$O$2001,B7)/Q7,"")) | S7: =IF(A7="","",IFERROR(SUMIFS(GA4!$R$2:$R$2001,GA4!$O$2:$O$2001,B7),0)) | T7: =IF(A7="","",IF(AND(ISNUMBER(F7),LEFT(C7&"",1)="2"),IF(F7<Rules!$B$9,"Yes","No"),"No")) | U7: =IF(A7="","",IF(AND(N(O7)>=Rules!$B$8,ISNUMBER(P7)),IF(P7<=-Rules!$B$7,"Yes","No"),"No")) | V7: =IF(A7="","",IF(AND(N(L7)>=Rules!$B$6,ISNUMBER(N7)),IF(AND(N7>=Rules!$B$10,N7<=Rules!$B$11),"Yes","No"),"No")) | W7: =IF(A7="","",IF(I7<>"","Yes","No")) | X7: =IF(I7="","",IF(SUMIFS($K$3:$K$2002,$A$3:$A$2002,SUBSTITUTE(SUBSTITUTE(I7,"?","~?"),"*","~*"))>N(K7),"Yes","No")) | Y7: =IF(A7="","",IF(N(S7)>0,"Yes","No")) | Z7: =IF(A7="","",IF(AND(N(K7)<Rules!$B$5,N(L7)<Rules!$B$6,N(Q7)<Rules!$B$13,Y7="No"),"Yes","No")) | AA7: =IF(A7="","",IF(LEFT(C7&"",1)="3","Redirect",IF(OR(LEFT(C7&"",1)="4",LEFT(C7&"",1)="5"),IF(OR(N(K7)>0,N(AC7)>=Rules!$B$14),"Redirect","Prune"),IF(D7="Non-Indexable","Keep",IF(AND(W7="Yes",X7="Yes",Y7="No"),"Merge",IF(OR(U7="Yes",V7="Yes",AND(T7="Yes",N(L7)>=Rules!$B$6)),"Update",IF(Z7="Yes",IF(N(AC7)>=Rules!$B$14,"Redirect","Prune"),"Keep"))))))) | AB7: =IF(A7="","",IF(LEFT(C7&"",1)="3","Already redirects ("&C7&"). Update internal links to point at the final URL.",IF(OR(LEFT(C7&"",1)="4",LEFT(C7&"",1)="5"),IF(AA7="Redirect","Returns "&C7&" but still has "&N(K7)&" clicks and "&N(AC7)&" referring domains. 301 it to the closest live page.","Returns "&C7&" with no clicks or links. Remove internal links and let it 404 or 410."),IF(D7="Non-Indexable","Non-indexable ("&E7&"). Keep if that is intentional; otherwise fix the canonical or noindex.",IF(AA7="Merge","Overlaps with "&I7&IF(N(J7)>0," (similarity "&TEXT(J7,"0.00")&")","")&", which gets more clicks. Merge the useful parts into it and 301 this URL.",IF(AA7="Update",MID(IF(U7="Yes","; Clicks down "&TEXT(-P7,"0%")&" on the previous period","")&IF(V7="Yes","; Average position "&TEXT(N7,"0.0")&" on "&TEXT(L7,"#,##0")&" impressions (striking distance)","")&IF(AND(T7="Yes",N(L7)>=Rules!$B$6),"; Thin ("&F7&" words) but has search demand",""),3,400),IF(AA7="Prune","Low value: "&N(K7)&" clicks, "&N(L7)&" impressions, "&N(Q7)&" sessions, no key events. Remove or noindex it and update internal links.",IF(AA7="Redirect","Low value but "&N(AC7)&" referring domains. 301 it to the closest relevant page to keep those links.",IF(AND(Z7="No",Y7="Yes",N(K7)<Rules!$B$5),"Low search traffic but it converts (key events: "&S7&"). Keep it and link to it.",IF(W7="Yes","Stronger than the page it overlaps ("&I7&"). Keep; merge that page into this one.","Healthy: "&N(K7)&" clicks"&IF(ISNUMBER(N7),", average position "&TEXT(N7,"0.0"),"")&". Keep and monitor.")))))))))) | AE7: =IF(A7="","",IF(AD7<>"",AD7,AA7))
A8: =IF(Crawl!A7="","",Crawl!A7) | B8: =IF(A8="","",Crawl!EC7) | C8: =IF(A8="","",IFERROR(INDEX(Crawl!$A7:$DZ7,1,Rules!$H$6),"")) | D8: =IF(A8="","",IFERROR(INDEX(Crawl!$A7:$DZ7,1,Rules!$H$7),"")&"") | E8: =IF(A8="","",IFERROR(INDEX(Crawl!$A7:$DZ7,1,Rules!$H$8),"")&"") | F8: =IF(A8="","",IFERROR(INDEX(Crawl!$A7:$DZ7,1,Rules!$H$9),"")) | G8: =IF(A8="","",IFERROR(INDEX(Crawl!$A7:$DZ7,1,Rules!$H$10),"")) | H8: =IF(A8="","",IFERROR(INDEX(Crawl!$A7:$DZ7,1,Rules!$H$12),"")) | I8: =IF(A8="","",IF(AND(N(H8)>0,IFERROR(INDEX(Crawl!$A7:$DZ7,1,Rules!$H$11),"")&""<>""),IFERROR(INDEX(Crawl!$A7:$DZ7,1,Rules!$H$11),"")&"",IF(AND(ISNUMBER(J8),N(J8)>=Rules!$B$12,IFERROR(INDEX(Crawl!$A7:$DZ7,1,Rules!$H$13),"")&""<>""),IFERROR(INDEX(Crawl!$A7:$DZ7,1,Rules!$H$13),"")&"",""))) | J8: =IF(A8="","",IF(IFERROR(INDEX(Crawl!$A7:$DZ7,1,Rules!$H$14),"")&""="","",IFERROR(INDEX(Crawl!$A7:$DZ7,1,Rules!$H$14),""))) | K8: =IF(A8="","",IFERROR(SUMIFS('GSC current'!$J$2:$J$2001,'GSC current'!$I$2:$I$2001,B8),0)) | L8: =IF(A8="","",IFERROR(SUMIFS('GSC current'!$K$2:$K$2001,'GSC current'!$I$2:$I$2001,B8),0)) | M8: =IF(A8="","",IF(N(L8)>0,K8/L8,"")) | N8: =IF(A8="","",IF(N(L8)>0,SUMIFS('GSC current'!$L$2:$L$2001,'GSC current'!$I$2:$I$2001,B8)/L8,"")) | O8: =IF(A8="","",IFERROR(SUMIFS('GSC previous'!$J$2:$J$2001,'GSC previous'!$I$2:$I$2001,B8),0)) | P8: =IF(A8="","",IF(N(O8)>0,(K8-O8)/O8,"")) | Q8: =IF(A8="","",IFERROR(SUMIFS(GA4!$P$2:$P$2001,GA4!$O$2:$O$2001,B8),0)) | R8: =IF(A8="","",IF(N(Q8)>0,SUMIFS(GA4!$Q$2:$Q$2001,GA4!$O$2:$O$2001,B8)/Q8,"")) | S8: =IF(A8="","",IFERROR(SUMIFS(GA4!$R$2:$R$2001,GA4!$O$2:$O$2001,B8),0)) | T8: =IF(A8="","",IF(AND(ISNUMBER(F8),LEFT(C8&"",1)="2"),IF(F8<Rules!$B$9,"Yes","No"),"No")) | U8: =IF(A8="","",IF(AND(N(O8)>=Rules!$B$8,ISNUMBER(P8)),IF(P8<=-Rules!$B$7,"Yes","No"),"No")) | V8: =IF(A8="","",IF(AND(N(L8)>=Rules!$B$6,ISNUMBER(N8)),IF(AND(N8>=Rules!$B$10,N8<=Rules!$B$11),"Yes","No"),"No")) | W8: =IF(A8="","",IF(I8<>"","Yes","No")) | X8: =IF(I8="","",IF(SUMIFS($K$3:$K$2002,$A$3:$A$2002,SUBSTITUTE(SUBSTITUTE(I8,"?","~?"),"*","~*"))>N(K8),"Yes","No")) | Y8: =IF(A8="","",IF(N(S8)>0,"Yes","No")) | Z8: =IF(A8="","",IF(AND(N(K8)<Rules!$B$5,N(L8)<Rules!$B$6,N(Q8)<Rules!$B$13,Y8="No"),"Yes","No")) | AA8: =IF(A8="","",IF(LEFT(C8&"",1)="3","Redirect",IF(OR(LEFT(C8&"",1)="4",LEFT(C8&"",1)="5"),IF(OR(N(K8)>0,N(AC8)>=Rules!$B$14),"Redirect","Prune"),IF(D8="Non-Indexable","Keep",IF(AND(W8="Yes",X8="Yes",Y8="No"),"Merge",IF(OR(U8="Yes",V8="Yes",AND(T8="Yes",N(L8)>=Rules!$B$6)),"Update",IF(Z8="Yes",IF(N(AC8)>=Rules!$B$14,"Redirect","Prune"),"Keep"))))))) | AB8: =IF(A8="","",IF(LEFT(C8&"",1)="3","Already redirects ("&C8&"). Update internal links to point at the final URL.",IF(OR(LEFT(C8&"",1)="4",LEFT(C8&"",1)="5"),IF(AA8="Redirect","Returns "&C8&" but still has "&N(K8)&" clicks and "&N(AC8)&" referring domains. 301 it to the closest live page.","Returns "&C8&" with no clicks or links. Remove internal links and let it 404 or 410."),IF(D8="Non-Indexable","Non-indexable ("&E8&"). Keep if that is intentional; otherwise fix the canonical or noindex.",IF(AA8="Merge","Overlaps with "&I8&IF(N(J8)>0," (similarity "&TEXT(J8,"0.00")&")","")&", which gets more clicks. Merge the useful parts into it and 301 this URL.",IF(AA8="Update",MID(IF(U8="Yes","; Clicks down "&TEXT(-P8,"0%")&" on the previous period","")&IF(V8="Yes","; Average position "&TEXT(N8,"0.0")&" on "&TEXT(L8,"#,##0")&" impressions (striking distance)","")&IF(AND(T8="Yes",N(L8)>=Rules!$B$6),"; Thin ("&F8&" words) but has search demand",""),3,400),IF(AA8="Prune","Low value: "&N(K8)&" clicks, "&N(L8)&" impressions, "&N(Q8)&" sessions, no key events. Remove or noindex it and update internal links.",IF(AA8="Redirect","Low value but "&N(AC8)&" referring domains. 301 it to the closest relevant page to keep those links.",IF(AND(Z8="No",Y8="Yes",N(K8)<Rules!$B$5),"Low search traffic but it converts (key events: "&S8&"). Keep it and link to it.",IF(W8="Yes","Stronger than the page it overlaps ("&I8&"). Keep; merge that page into this one.","Healthy: "&N(K8)&" clicks"&IF(ISNUMBER(N8),", average position "&TEXT(N8,"0.0"),"")&". Keep and monitor.")))))))))) | AE8: =IF(A8="","",IF(AD8<>"",AD8,AA8))
A9: =IF(Crawl!A8="","",Crawl!A8) | B9: =IF(A9="","",Crawl!EC8) | C9: =IF(A9="","",IFERROR(INDEX(Crawl!$A8:$DZ8,1,Rules!$H$6),"")) | D9: =IF(A9="","",IFERROR(INDEX(Crawl!$A8:$DZ8,1,Rules!$H$7),"")&"") | E9: =IF(A9="","",IFERROR(INDEX(Crawl!$A8:$DZ8,1,Rules!$H$8),"")&"") | F9: =IF(A9="","",IFERROR(INDEX(Crawl!$A8:$DZ8,1,Rules!$H$9),"")) | G9: =IF(A9="","",IFERROR(INDEX(Crawl!$A8:$DZ8,1,Rules!$H$10),"")) | H9: =IF(A9="","",IFERROR(INDEX(Crawl!$A8:$DZ8,1,Rules!$H$12),"")) | I9: =IF(A9="","",IF(AND(N(H9)>0,IFERROR(INDEX(Crawl!$A8:$DZ8,1,Rules!$H$11),"")&""<>""),IFERROR(INDEX(Crawl!$A8:$DZ8,1,Rules!$H$11),"")&"",IF(AND(ISNUMBER(J9),N(J9)>=Rules!$B$12,IFERROR(INDEX(Crawl!$A8:$DZ8,1,Rules!$H$13),"")&""<>""),IFERROR(INDEX(Crawl!$A8:$DZ8,1,Rules!$H$13),"")&"",""))) | J9: =IF(A9="","",IF(IFERROR(INDEX(Crawl!$A8:$DZ8,1,Rules!$H$14),"")&""="","",IFERROR(INDEX(Crawl!$A8:$DZ8,1,Rules!$H$14),""))) | K9: =IF(A9="","",IFERROR(SUMIFS('GSC current'!$J$2:$J$2001,'GSC current'!$I$2:$I$2001,B9),0)) | L9: =IF(A9="","",IFERROR(SUMIFS('GSC current'!$K$2:$K$2001,'GSC current'!$I$2:$I$2001,B9),0)) | M9: =IF(A9="","",IF(N(L9)>0,K9/L9,"")) | N9: =IF(A9="","",IF(N(L9)>0,SUMIFS('GSC current'!$L$2:$L$2001,'GSC current'!$I$2:$I$2001,B9)/L9,"")) | O9: =IF(A9="","",IFERROR(SUMIFS('GSC previous'!$J$2:$J$2001,'GSC previous'!$I$2:$I$2001,B9),0)) | P9: =IF(A9="","",IF(N(O9)>0,(K9-O9)/O9,"")) | Q9: =IF(A9="","",IFERROR(SUMIFS(GA4!$P$2:$P$2001,GA4!$O$2:$O$2001,B9),0)) | R9: =IF(A9="","",IF(N(Q9)>0,SUMIFS(GA4!$Q$2:$Q$2001,GA4!$O$2:$O$2001,B9)/Q9,"")) | S9: =IF(A9="","",IFERROR(SUMIFS(GA4!$R$2:$R$2001,GA4!$O$2:$O$2001,B9),0)) | T9: =IF(A9="","",IF(AND(ISNUMBER(F9),LEFT(C9&"",1)="2"),IF(F9<Rules!$B$9,"Yes","No"),"No")) | U9: =IF(A9="","",IF(AND(N(O9)>=Rules!$B$8,ISNUMBER(P9)),IF(P9<=-Rules!$B$7,"Yes","No"),"No")) | V9: =IF(A9="","",IF(AND(N(L9)>=Rules!$B$6,ISNUMBER(N9)),IF(AND(N9>=Rules!$B$10,N9<=Rules!$B$11),"Yes","No"),"No")) | W9: =IF(A9="","",IF(I9<>"","Yes","No")) | X9: =IF(I9="","",IF(SUMIFS($K$3:$K$2002,$A$3:$A$2002,SUBSTITUTE(SUBSTITUTE(I9,"?","~?"),"*","~*"))>N(K9),"Yes","No")) | Y9: =IF(A9="","",IF(N(S9)>0,"Yes","No")) | Z9: =IF(A9="","",IF(AND(N(K9)<Rules!$B$5,N(L9)<Rules!$B$6,N(Q9)<Rules!$B$13,Y9="No"),"Yes","No")) | AA9: =IF(A9="","",IF(LEFT(C9&"",1)="3","Redirect",IF(OR(LEFT(C9&"",1)="4",LEFT(C9&"",1)="5"),IF(OR(N(K9)>0,N(AC9)>=Rules!$B$14),"Redirect","Prune"),IF(D9="Non-Indexable","Keep",IF(AND(W9="Yes",X9="Yes",Y9="No"),"Merge",IF(OR(U9="Yes",V9="Yes",AND(T9="Yes",N(L9)>=Rules!$B$6)),"Update",IF(Z9="Yes",IF(N(AC9)>=Rules!$B$14,"Redirect","Prune"),"Keep"))))))) | AB9: =IF(A9="","",IF(LEFT(C9&"",1)="3","Already redirects ("&C9&"). Update internal links to point at the final URL.",IF(OR(LEFT(C9&"",1)="4",LEFT(C9&"",1)="5"),IF(AA9="Redirect","Returns "&C9&" but still has "&N(K9)&" clicks and "&N(AC9)&" referring domains. 301 it to the closest live page.","Returns "&C9&" with no clicks or links. Remove internal links and let it 404 or 410."),IF(D9="Non-Indexable","Non-indexable ("&E9&"). Keep if that is intentional; otherwise fix the canonical or noindex.",IF(AA9="Merge","Overlaps with "&I9&IF(N(J9)>0," (similarity "&TEXT(J9,"0.00")&")","")&", which gets more clicks. Merge the useful parts into it and 301 this URL.",IF(AA9="Update",MID(IF(U9="Yes","; Clicks down "&TEXT(-P9,"0%")&" on the previous period","")&IF(V9="Yes","; Average position "&TEXT(N9,"0.0")&" on "&TEXT(L9,"#,##0")&" impressions (striking distance)","")&IF(AND(T9="Yes",N(L9)>=Rules!$B$6),"; Thin ("&F9&" words) but has search demand",""),3,400),IF(AA9="Prune","Low value: "&N(K9)&" clicks, "&N(L9)&" impressions, "&N(Q9)&" sessions, no key events. Remove or noindex it and update internal links.",IF(AA9="Redirect","Low value but "&N(AC9)&" referring domains. 301 it to the closest relevant page to keep those links.",IF(AND(Z9="No",Y9="Yes",N(K9)<Rules!$B$5),"Low search traffic but it converts (key events: "&S9&"). Keep it and link to it.",IF(W9="Yes","Stronger than the page it overlaps ("&I9&"). Keep; merge that page into this one.","Healthy: "&N(K9)&" clicks"&IF(ISNUMBER(N9),", average position "&TEXT(N9,"0.0"),"")&". Keep and monitor.")))))))))) | AE9: =IF(A9="","",IF(AD9<>"",AD9,AA9))
A10: =IF(Crawl!A9="","",Crawl!A9) | B10: =IF(A10="","",Crawl!EC9) | C10: =IF(A10="","",IFERROR(INDEX(Crawl!$A9:$DZ9,1,Rules!$H$6),"")) | D10: =IF(A10="","",IFERROR(INDEX(Crawl!$A9:$DZ9,1,Rules!$H$7),"")&"") | E10: =IF(A10="","",IFERROR(INDEX(Crawl!$A9:$DZ9,1,Rules!$H$8),"")&"") | F10: =IF(A10="","",IFERROR(INDEX(Crawl!$A9:$DZ9,1,Rules!$H$9),"")) | G10: =IF(A10="","",IFERROR(INDEX(Crawl!$A9:$DZ9,1,Rules!$H$10),"")) | H10: =IF(A10="","",IFERROR(INDEX(Crawl!$A9:$DZ9,1,Rules!$H$12),"")) | I10: =IF(A10="","",IF(AND(N(H10)>0,IFERROR(INDEX(Crawl!$A9:$DZ9,1,Rules!$H$11),"")&""<>""),IFERROR(INDEX(Crawl!$A9:$DZ9,1,Rules!$H$11),"")&"",IF(AND(ISNUMBER(J10),N(J10)>=Rules!$B$12,IFERROR(INDEX(Crawl!$A9:$DZ9,1,Rules!$H$13),"")&""<>""),IFERROR(INDEX(Crawl!$A9:$DZ9,1,Rules!$H$13),"")&"",""))) | J10: =IF(A10="","",IF(IFERROR(INDEX(Crawl!$A9:$DZ9,1,Rules!$H$14),"")&""="","",IFERROR(INDEX(Crawl!$A9:$DZ9,1,Rules!$H$14),""))) | K10: =IF(A10="","",IFERROR(SUMIFS('GSC current'!$J$2:$J$2001,'GSC current'!$I$2:$I$2001,B10),0)) | L10: =IF(A10="","",IFERROR(SUMIFS('GSC current'!$K$2:$K$2001,'GSC current'!$I$2:$I$2001,B10),0)) | M10: =IF(A10="","",IF(N(L10)>0,K10/L10,"")) | N10: =IF(A10="","",IF(N(L10)>0,SUMIFS('GSC current'!$L$2:$L$2001,'GSC current'!$I$2:$I$2001,B10)/L10,"")) | O10: =IF(A10="","",IFERROR(SUMIFS('GSC previous'!$J$2:$J$2001,'GSC previous'!$I$2:$I$2001,B10),0)) | P10: =IF(A10="","",IF(N(O10)>0,(K10-O10)/O10,"")) | Q10: =IF(A10="","",IFERROR(SUMIFS(GA4!$P$2:$P$2001,GA4!$O$2:$O$2001,B10),0)) | R10: =IF(A10="","",IF(N(Q10)>0,SUMIFS(GA4!$Q$2:$Q$2001,GA4!$O$2:$O$2001,B10)/Q10,"")) | S10: =IF(A10="","",IFERROR(SUMIFS(GA4!$R$2:$R$2001,GA4!$O$2:$O$2001,B10),0)) | T10: =IF(A10="","",IF(AND(ISNUMBER(F10),LEFT(C10&"",1)="2"),IF(F10<Rules!$B$9,"Yes","No"),"No")) | U10: =IF(A10="","",IF(AND(N(O10)>=Rules!$B$8,ISNUMBER(P10)),IF(P10<=-Rules!$B$7,"Yes","No"),"No")) | V10: =IF(A10="","",IF(AND(N(L10)>=Rules!$B$6,ISNUMBER(N10)),IF(AND(N10>=Rules!$B$10,N10<=Rules!$B$11),"Yes","No"),"No")) | W10: =IF(A10="","",IF(I10<>"","Yes","No")) | X10: =IF(I10="","",IF(SUMIFS($K$3:$K$2002,$A$3:$A$2002,SUBSTITUTE(SUBSTITUTE(I10,"?","~?"),"*","~*"))>N(K10),"Yes","No")) | Y10: =IF(A10="","",IF(N(S10)>0,"Yes","No")) | Z10: =IF(A10="","",IF(AND(N(K10)<Rules!$B$5,N(L10)<Rules!$B$6,N(Q10)<Rules!$B$13,Y10="No"),"Yes","No")) | AA10: =IF(A10="","",IF(LEFT(C10&"",1)="3","Redirect",IF(OR(LEFT(C10&"",1)="4",LEFT(C10&"",1)="5"),IF(OR(N(K10)>0,N(AC10)>=Rules!$B$14),"Redirect","Prune"),IF(D10="Non-Indexable","Keep",IF(AND(W10="Yes",X10="Yes",Y10="No"),"Merge",IF(OR(U10="Yes",V10="Yes",AND(T10="Yes",N(L10)>=Rules!$B$6)),"Update",IF(Z10="Yes",IF(N(AC10)>=Rules!$B$14,"Redirect","Prune"),"Keep"))))))) | AB10: =IF(A10="","",IF(LEFT(C10&"",1)="3","Already redirects ("&C10&"). Update internal links to point at the final URL.",IF(OR(LEFT(C10&"",1)="4",LEFT(C10&"",1)="5"),IF(AA10="Redirect","Returns "&C10&" but still has "&N(K10)&" clicks and "&N(AC10)&" referring domains. 301 it to the closest live page.","Returns "&C10&" with no clicks or links. Remove internal links and let it 404 or 410."),IF(D10="Non-Indexable","Non-indexable ("&E10&"). Keep if that is intentional; otherwise fix the canonical or noindex.",IF(AA10="Merge","Overlaps with "&I10&IF(N(J10)>0," (similarity "&TEXT(J10,"0.00")&")","")&", which gets more clicks. Merge the useful parts into it and 301 this URL.",IF(AA10="Update",MID(IF(U10="Yes","; Clicks down "&TEXT(-P10,"0%")&" on the previous period","")&IF(V10="Yes","; Average position "&TEXT(N10,"0.0")&" on "&TEXT(L10,"#,##0")&" impressions (striking distance)","")&IF(AND(T10="Yes",N(L10)>=Rules!$B$6),"; Thin ("&F10&" words) but has search demand",""),3,400),IF(AA10="Prune","Low value: "&N(K10)&" clicks, "&N(L10)&" impressions, "&N(Q10)&" sessions, no key events. Remove or noindex it and update internal links.",IF(AA10="Redirect","Low value but "&N(AC10)&" referring domains. 301 it to the closest relevant page to keep those links.",IF(AND(Z10="No",Y10="Yes",N(K10)<Rules!$B$5),"Low search traffic but it converts (key events: "&S10&"). Keep it and link to it.",IF(W10="Yes","Stronger than the page it overlaps ("&I10&"). Keep; merge that page into this one.","Healthy: "&N(K10)&" clicks"&IF(ISNUMBER(N10),", average position "&TEXT(N10,"0.0"),"")&". Keep and monitor.")))))))))) | AE10: =IF(A10="","",IF(AD10<>"",AD10,AA10))
A11: =IF(Crawl!A10="","",Crawl!A10) | B11: =IF(A11="","",Crawl!EC10) | C11: =IF(A11="","",IFERROR(INDEX(Crawl!$A10:$DZ10,1,Rules!$H$6),"")) | D11: =IF(A11="","",IFERROR(INDEX(Crawl!$A10:$DZ10,1,Rules!$H$7),"")&"") | E11: =IF(A11="","",IFERROR(INDEX(Crawl!$A10:$DZ10,1,Rules!$H$8),"")&"") | F11: =IF(A11="","",IFERROR(INDEX(Crawl!$A10:$DZ10,1,Rules!$H$9),"")) | G11: =IF(A11="","",IFERROR(INDEX(Crawl!$A10:$DZ10,1,Rules!$H$10),"")) | H11: =IF(A11="","",IFERROR(INDEX(Crawl!$A10:$DZ10,1,Rules!$H$12),"")) | I11: =IF(A11="","",IF(AND(N(H11)>0,IFERROR(INDEX(Crawl!$A10:$DZ10,1,Rules!$H$11),"")&""<>""),IFERROR(INDEX(Crawl!$A10:$DZ10,1,Rules!$H$11),"")&"",IF(AND(ISNUMBER(J11),N(J11)>=Rules!$B$12,IFERROR(INDEX(Crawl!$A10:$DZ10,1,Rules!$H$13),"")&""<>""),IFERROR(INDEX(Crawl!$A10:$DZ10,1,Rules!$H$13),"")&"",""))) | J11: =IF(A11="","",IF(IFERROR(INDEX(Crawl!$A10:$DZ10,1,Rules!$H$14),"")&""="","",IFERROR(INDEX(Crawl!$A10:$DZ10,1,Rules!$H$14),""))) | K11: =IF(A11="","",IFERROR(SUMIFS('GSC current'!$J$2:$J$2001,'GSC current'!$I$2:$I$2001,B11),0)) | L11: =IF(A11="","",IFERROR(SUMIFS('GSC current'!$K$2:$K$2001,'GSC current'!$I$2:$I$2001,B11),0)) | M11: =IF(A11="","",IF(N(L11)>0,K11/L11,"")) | N11: =IF(A11="","",IF(N(L11)>0,SUMIFS('GSC current'!$L$2:$L$2001,'GSC current'!$I$2:$I$2001,B11)/L11,"")) | O11: =IF(A11="","",IFERROR(SUMIFS('GSC previous'!$J$2:$J$2001,'GSC previous'!$I$2:$I$2001,B11),0)) | P11: =IF(A11="","",IF(N(O11)>0,(K11-O11)/O11,"")) | Q11: =IF(A11="","",IFERROR(SUMIFS(GA4!$P$2:$P$2001,GA4!$O$2:$O$2001,B11),0)) | R11: =IF(A11="","",IF(N(Q11)>0,SUMIFS(GA4!$Q$2:$Q$2001,GA4!$O$2:$O$2001,B11)/Q11,"")) | S11: =IF(A11="","",IFERROR(SUMIFS(GA4!$R$2:$R$2001,GA4!$O$2:$O$2001,B11),0)) | T11: =IF(A11="","",IF(AND(ISNUMBER(F11),LEFT(C11&"",1)="2"),IF(F11<Rules!$B$9,"Yes","No"),"No")) | U11: =IF(A11="","",IF(AND(N(O11)>=Rules!$B$8,ISNUMBER(P11)),IF(P11<=-Rules!$B$7,"Yes","No"),"No")) | V11: =IF(A11="","",IF(AND(N(L11)>=Rules!$B$6,ISNUMBER(N11)),IF(AND(N11>=Rules!$B$10,N11<=Rules!$B$11),"Yes","No"),"No")) | W11: =IF(A11="","",IF(I11<>"","Yes","No")) | X11: =IF(I11="","",IF(SUMIFS($K$3:$K$2002,$A$3:$A$2002,SUBSTITUTE(SUBSTITUTE(I11,"?","~?"),"*","~*"))>N(K11),"Yes","No")) | Y11: =IF(A11="","",IF(N(S11)>0,"Yes","No")) | Z11: =IF(A11="","",IF(AND(N(K11)<Rules!$B$5,N(L11)<Rules!$B$6,N(Q11)<Rules!$B$13,Y11="No"),"Yes","No")) | AA11: =IF(A11="","",IF(LEFT(C11&"",1)="3","Redirect",IF(OR(LEFT(C11&"",1)="4",LEFT(C11&"",1)="5"),IF(OR(N(K11)>0,N(AC11)>=Rules!$B$14),"Redirect","Prune"),IF(D11="Non-Indexable","Keep",IF(AND(W11="Yes",X11="Yes",Y11="No"),"Merge",IF(OR(U11="Yes",V11="Yes",AND(T11="Yes",N(L11)>=Rules!$B$6)),"Update",IF(Z11="Yes",IF(N(AC11)>=Rules!$B$14,"Redirect","Prune"),"Keep"))))))) | AB11: =IF(A11="","",IF(LEFT(C11&"",1)="3","Already redirects ("&C11&"). Update internal links to point at the final URL.",IF(OR(LEFT(C11&"",1)="4",LEFT(C11&"",1)="5"),IF(AA11="Redirect","Returns "&C11&" but still has "&N(K11)&" clicks and "&N(AC11)&" referring domains. 301 it to the closest live page.","Returns "&C11&" with no clicks or links. Remove internal links and let it 404 or 410."),IF(D11="Non-Indexable","Non-indexable ("&E11&"). Keep if that is intentional; otherwise fix the canonical or noindex.",IF(AA11="Merge","Overlaps with "&I11&IF(N(J11)>0," (similarity "&TEXT(J11,"0.00")&")","")&", which gets more clicks. Merge the useful parts into it and 301 this URL.",IF(AA11="Update",MID(IF(U11="Yes","; Clicks down "&TEXT(-P11,"0%")&" on the previous period","")&IF(V11="Yes","; Average position "&TEXT(N11,"0.0")&" on "&TEXT(L11,"#,##0")&" impressions (striking distance)","")&IF(AND(T11="Yes",N(L11)>=Rules!$B$6),"; Thin ("&F11&" words) but has search demand",""),3,400),IF(AA11="Prune","Low value: "&N(K11)&" clicks, "&N(L11)&" impressions, "&N(Q11)&" sessions, no key events. Remove or noindex it and update internal links.",IF(AA11="Redirect","Low value but "&N(AC11)&" referring domains. 301 it to the closest relevant page to keep those links.",IF(AND(Z11="No",Y11="Yes",N(K11)<Rules!$B$5),"Low search traffic but it converts (key events: "&S11&"). Keep it and link to it.",IF(W11="Yes","Stronger than the page it overlaps ("&I11&"). Keep; merge that page into this one.","Healthy: "&N(K11)&" clicks"&IF(ISNUMBER(N11),", average position "&TEXT(N11,"0.0"),"")&". Keep and monitor.")))))))))) | AE11: =IF(A11="","",IF(AD11<>"",AD11,AA11))
A12: =IF(Crawl!A11="","",Crawl!A11) | B12: =IF(A12="","",Crawl!EC11) | C12: =IF(A12="","",IFERROR(INDEX(Crawl!$A11:$DZ11,1,Rules!$H$6),"")) | D12: =IF(A12="","",IFERROR(INDEX(Crawl!$A11:$DZ11,1,Rules!$H$7),"")&"") | E12: =IF(A12="","",IFERROR(INDEX(Crawl!$A11:$DZ11,1,Rules!$H$8),"")&"") | F12: =IF(A12="","",IFERROR(INDEX(Crawl!$A11:$DZ11,1,Rules!$H$9),"")) | G12: =IF(A12="","",IFERROR(INDEX(Crawl!$A11:$DZ11,1,Rules!$H$10),"")) | H12: =IF(A12="","",IFERROR(INDEX(Crawl!$A11:$DZ11,1,Rules!$H$12),"")) | I12: =IF(A12="","",IF(AND(N(H12)>0,IFERROR(INDEX(Crawl!$A11:$DZ11,1,Rules!$H$11),"")&""<>""),IFERROR(INDEX(Crawl!$A11:$DZ11,1,Rules!$H$11),"")&"",IF(AND(ISNUMBER(J12),N(J12)>=Rules!$B$12,IFERROR(INDEX(Crawl!$A11:$DZ11,1,Rules!$H$13),"")&""<>""),IFERROR(INDEX(Crawl!$A11:$DZ11,1,Rules!$H$13),"")&"",""))) | J12: =IF(A12="","",IF(IFERROR(INDEX(Crawl!$A11:$DZ11,1,Rules!$H$14),"")&""="","",IFERROR(INDEX(Crawl!$A11:$DZ11,1,Rules!$H$14),""))) | K12: =IF(A12="","",IFERROR(SUMIFS('GSC current'!$J$2:$J$2001,'GSC current'!$I$2:$I$2001,B12),0)) | L12: =IF(A12="","",IFERROR(SUMIFS('GSC current'!$K$2:$K$2001,'GSC current'!$I$2:$I$2001,B12),0)) | M12: =IF(A12="","",IF(N(L12)>0,K12/L12,"")) | N12: =IF(A12="","",IF(N(L12)>0,SUMIFS('GSC current'!$L$2:$L$2001,'GSC current'!$I$2:$I$2001,B12)/L12,"")) | O12: =IF(A12="","",IFERROR(SUMIFS('GSC previous'!$J$2:$J$2001,'GSC previous'!$I$2:$I$2001,B12),0)) | P12: =IF(A12="","",IF(N(O12)>0,(K12-O12)/O12,"")) | Q12: =IF(A12="","",IFERROR(SUMIFS(GA4!$P$2:$P$2001,GA4!$O$2:$O$2001,B12),0)) | R12: =IF(A12="","",IF(N(Q12)>0,SUMIFS(GA4!$Q$2:$Q$2001,GA4!$O$2:$O$2001,B12)/Q12,"")) | S12: =IF(A12="","",IFERROR(SUMIFS(GA4!$R$2:$R$2001,GA4!$O$2:$O$2001,B12),0)) | T12: =IF(A12="","",IF(AND(ISNUMBER(F12),LEFT(C12&"",1)="2"),IF(F12<Rules!$B$9,"Yes","No"),"No")) | U12: =IF(A12="","",IF(AND(N(O12)>=Rules!$B$8,ISNUMBER(P12)),IF(P12<=-Rules!$B$7,"Yes","No"),"No")) | V12: =IF(A12="","",IF(AND(N(L12)>=Rules!$B$6,ISNUMBER(N12)),IF(AND(N12>=Rules!$B$10,N12<=Rules!$B$11),"Yes","No"),"No")) | W12: =IF(A12="","",IF(I12<>"","Yes","No")) | X12: =IF(I12="","",IF(SUMIFS($K$3:$K$2002,$A$3:$A$2002,SUBSTITUTE(SUBSTITUTE(I12,"?","~?"),"*","~*"))>N(K12),"Yes","No")) | Y12: =IF(A12="","",IF(N(S12)>0,"Yes","No")) | Z12: =IF(A12="","",IF(AND(N(K12)<Rules!$B$5,N(L12)<Rules!$B$6,N(Q12)<Rules!$B$13,Y12="No"),"Yes","No")) | AA12: =IF(A12="","",IF(LEFT(C12&"",1)="3","Redirect",IF(OR(LEFT(C12&"",1)="4",LEFT(C12&"",1)="5"),IF(OR(N(K12)>0,N(AC12)>=Rules!$B$14),"Redirect","Prune"),IF(D12="Non-Indexable","Keep",IF(AND(W12="Yes",X12="Yes",Y12="No"),"Merge",IF(OR(U12="Yes",V12="Yes",AND(T12="Yes",N(L12)>=Rules!$B$6)),"Update",IF(Z12="Yes",IF(N(AC12)>=Rules!$B$14,"Redirect","Prune"),"Keep"))))))) | AB12: =IF(A12="","",IF(LEFT(C12&"",1)="3","Already redirects ("&C12&"). Update internal links to point at the final URL.",IF(OR(LEFT(C12&"",1)="4",LEFT(C12&"",1)="5"),IF(AA12="Redirect","Returns "&C12&" but still has "&N(K12)&" clicks and "&N(AC12)&" referring domains. 301 it to the closest live page.","Returns "&C12&" with no clicks or links. Remove internal links and let it 404 or 410."),IF(D12="Non-Indexable","Non-indexable ("&E12&"). Keep if that is intentional; otherwise fix the canonical or noindex.",IF(AA12="Merge","Overlaps with "&I12&IF(N(J12)>0," (similarity "&TEXT(J12,"0.00")&")","")&", which gets more clicks. Merge the useful parts into it and 301 this URL.",IF(AA12="Update",MID(IF(U12="Yes","; Clicks down "&TEXT(-P12,"0%")&" on the previous period","")&IF(V12="Yes","; Average position "&TEXT(N12,"0.0")&" on "&TEXT(L12,"#,##0")&" impressions (striking distance)","")&IF(AND(T12="Yes",N(L12)>=Rules!$B$6),"; Thin ("&F12&" words) but has search demand",""),3,400),IF(AA12="Prune","Low value: "&N(K12)&" clicks, "&N(L12)&" impressions, "&N(Q12)&" sessions, no key events. Remove or noindex it and update internal links.",IF(AA12="Redirect","Low value but "&N(AC12)&" referring domains. 301 it to the closest relevant page to keep those links.",IF(AND(Z12="No",Y12="Yes",N(K12)<Rules!$B$5),"Low search traffic but it converts (key events: "&S12&"). Keep it and link to it.",IF(W12="Yes","Stronger than the page it overlaps ("&I12&"). Keep; merge that page into this one.","Healthy: "&N(K12)&" clicks"&IF(ISNUMBER(N12),", average position "&TEXT(N12,"0.0"),"")&". Keep and monitor.")))))))))) | AE12: =IF(A12="","",IF(AD12<>"",AD12,AA12))
A13: =IF(Crawl!A12="","",Crawl!A12) | B13: =IF(A13="","",Crawl!EC12) | C13: =IF(A13="","",IFERROR(INDEX(Crawl!$A12:$DZ12,1,Rules!$H$6),"")) | D13: =IF(A13="","",IFERROR(INDEX(Crawl!$A12:$DZ12,1,Rules!$H$7),"")&"") | E13: =IF(A13="","",IFERROR(INDEX(Crawl!$A12:$DZ12,1,Rules!$H$8),"")&"") | F13: =IF(A13="","",IFERROR(INDEX(Crawl!$A12:$DZ12,1,Rules!$H$9),"")) | G13: =IF(A13="","",IFERROR(INDEX(Crawl!$A12:$DZ12,1,Rules!$H$10),"")) | H13: =IF(A13="","",IFERROR(INDEX(Crawl!$A12:$DZ12,1,Rules!$H$12),"")) | I13: =IF(A13="","",IF(AND(N(H13)>0,IFERROR(INDEX(Crawl!$A12:$DZ12,1,Rules!$H$11),"")&""<>""),IFERROR(INDEX(Crawl!$A12:$DZ12,1,Rules!$H$11),"")&"",IF(AND(ISNUMBER(J13),N(J13)>=Rules!$B$12,IFERROR(INDEX(Crawl!$A12:$DZ12,1,Rules!$H$13),"")&""<>""),IFERROR(INDEX(Crawl!$A12:$DZ12,1,Rules!$H$13),"")&"",""))) | J13: =IF(A13="","",IF(IFERROR(INDEX(Crawl!$A12:$DZ12,1,Rules!$H$14),"")&""="","",IFERROR(INDEX(Crawl!$A12:$DZ12,1,Rules!$H$14),""))) | K13: =IF(A13="","",IFERROR(SUMIFS('GSC current'!$J$2:$J$2001,'GSC current'!$I$2:$I$2001,B13),0)) | L13: =IF(A13="","",IFERROR(SUMIFS('GSC current'!$K$2:$K$2001,'GSC current'!$I$2:$I$2001,B13),0)) | M13: =IF(A13="","",IF(N(L13)>0,K13/L13,"")) | N13: =IF(A13="","",IF(N(L13)>0,SUMIFS('GSC current'!$L$2:$L$2001,'GSC current'!$I$2:$I$2001,B13)/L13,"")) | O13: =IF(A13="","",IFERROR(SUMIFS('GSC previous'!$J$2:$J$2001,'GSC previous'!$I$2:$I$2001,B13),0)) | P13: =IF(A13="","",IF(N(O13)>0,(K13-O13)/O13,"")) | Q13: =IF(A13="","",IFERROR(SUMIFS(GA4!$P$2:$P$2001,GA4!$O$2:$O$2001,B13),0)) | R13: =IF(A13="","",IF(N(Q13)>0,SUMIFS(GA4!$Q$2:$Q$2001,GA4!$O$2:$O$2001,B13)/Q13,"")) | S13: =IF(A13="","",IFERROR(SUMIFS(GA4!$R$2:$R$2001,GA4!$O$2:$O$2001,B13),0)) | T13: =IF(A13="","",IF(AND(ISNUMBER(F13),LEFT(C13&"",1)="2"),IF(F13<Rules!$B$9,"Yes","No"),"No")) | U13: =IF(A13="","",IF(AND(N(O13)>=Rules!$B$8,ISNUMBER(P13)),IF(P13<=-Rules!$B$7,"Yes","No"),"No")) | V13: =IF(A13="","",IF(AND(N(L13)>=Rules!$B$6,ISNUMBER(N13)),IF(AND(N13>=Rules!$B$10,N13<=Rules!$B$11),"Yes","No"),"No")) | W13: =IF(A13="","",IF(I13<>"","Yes","No")) | X13: =IF(I13="","",IF(SUMIFS($K$3:$K$2002,$A$3:$A$2002,SUBSTITUTE(SUBSTITUTE(I13,"?","~?"),"*","~*"))>N(K13),"Yes","No")) | Y13: =IF(A13="","",IF(N(S13)>0,"Yes","No")) | Z13: =IF(A13="","",IF(AND(N(K13)<Rules!$B$5,N(L13)<Rules!$B$6,N(Q13)<Rules!$B$13,Y13="No"),"Yes","No")) | AA13: =IF(A13="","",IF(LEFT(C13&"",1)="3","Redirect",IF(OR(LEFT(C13&"",1)="4",LEFT(C13&"",1)="5"),IF(OR(N(K13)>0,N(AC13)>=Rules!$B$14),"Redirect","Prune"),IF(D13="Non-Indexable","Keep",IF(AND(W13="Yes",X13="Yes",Y13="No"),"Merge",IF(OR(U13="Yes",V13="Yes",AND(T13="Yes",N(L13)>=Rules!$B$6)),"Update",IF(Z13="Yes",IF(N(AC13)>=Rules!$B$14,"Redirect","Prune"),"Keep"))))))) | AB13: =IF(A13="","",IF(LEFT(C13&"",1)="3","Already redirects ("&C13&"). Update internal links to point at the final URL.",IF(OR(LEFT(C13&"",1)="4",LEFT(C13&"",1)="5"),IF(AA13="Redirect","Returns "&C13&" but still has "&N(K13)&" clicks and "&N(AC13)&" referring domains. 301 it to the closest live page.","Returns "&C13&" with no clicks or links. Remove internal links and let it 404 or 410."),IF(D13="Non-Indexable","Non-indexable ("&E13&"). Keep if that is intentional; otherwise fix the canonical or noindex.",IF(AA13="Merge","Overlaps with "&I13&IF(N(J13)>0," (similarity "&TEXT(J13,"0.00")&")","")&", which gets more clicks. Merge the useful parts into it and 301 this URL.",IF(AA13="Update",MID(IF(U13="Yes","; Clicks down "&TEXT(-P13,"0%")&" on the previous period","")&IF(V13="Yes","; Average position "&TEXT(N13,"0.0")&" on "&TEXT(L13,"#,##0")&" impressions (striking distance)","")&IF(AND(T13="Yes",N(L13)>=Rules!$B$6),"; Thin ("&F13&" words) but has search demand",""),3,400),IF(AA13="Prune","Low value: "&N(K13)&" clicks, "&N(L13)&" impressions, "&N(Q13)&" sessions, no key events. Remove or noindex it and update internal links.",IF(AA13="Redirect","Low value but "&N(AC13)&" referring domains. 301 it to the closest relevant page to keep those links.",IF(AND(Z13="No",Y13="Yes",N(K13)<Rules!$B$5),"Low search traffic but it converts (key events: "&S13&"). Keep it and link to it.",IF(W13="Yes","Stronger than the page it overlaps ("&I13&"). Keep; merge that page into this one.","Healthy: "&N(K13)&" clicks"&IF(ISNUMBER(N13),", average position "&TEXT(N13,"0.0"),"")&". Keep and monitor.")))))))))) | AE13: =IF(A13="","",IF(AD13<>"",AD13,AA13))
A14: =IF(Crawl!A13="","",Crawl!A13) | B14: =IF(A14="","",Crawl!EC13) | C14: =IF(A14="","",IFERROR(INDEX(Crawl!$A13:$DZ13,1,Rules!$H$6),"")) | D14: =IF(A14="","",IFERROR(INDEX(Crawl!$A13:$DZ13,1,Rules!$H$7),"")&"") | E14: =IF(A14="","",IFERROR(INDEX(Crawl!$A13:$DZ13,1,Rules!$H$8),"")&"") | F14: =IF(A14="","",IFERROR(INDEX(Crawl!$A13:$DZ13,1,Rules!$H$9),"")) | G14: =IF(A14="","",IFERROR(INDEX(Crawl!$A13:$DZ13,1,Rules!$H$10),"")) | H14: =IF(A14="","",IFERROR(INDEX(Crawl!$A13:$DZ13,1,Rules!$H$12),"")) | I14: =IF(A14="","",IF(AND(N(H14)>0,IFERROR(INDEX(Crawl!$A13:$DZ13,1,Rules!$H$11),"")&""<>""),IFERROR(INDEX(Crawl!$A13:$DZ13,1,Rules!$H$11),"")&"",IF(AND(ISNUMBER(J14),N(J14)>=Rules!$B$12,IFERROR(INDEX(Crawl!$A13:$DZ13,1,Rules!$H$13),"")&""<>""),IFERROR(INDEX(Crawl!$A13:$DZ13,1,Rules!$H$13),"")&"",""))) | J14: =IF(A14="","",IF(IFERROR(INDEX(Crawl!$A13:$DZ13,1,Rules!$H$14),"")&""="","",IFERROR(INDEX(Crawl!$A13:$DZ13,1,Rules!$H$14),""))) | K14: =IF(A14="","",IFERROR(SUMIFS('GSC current'!$J$2:$J$2001,'GSC current'!$I$2:$I$2001,B14),0)) | L14: =IF(A14="","",IFERROR(SUMIFS('GSC current'!$K$2:$K$2001,'GSC current'!$I$2:$I$2001,B14),0)) | M14: =IF(A14="","",IF(N(L14)>0,K14/L14,"")) | N14: =IF(A14="","",IF(N(L14)>0,SUMIFS('GSC current'!$L$2:$L$2001,'GSC current'!$I$2:$I$2001,B14)/L14,"")) | O14: =IF(A14="","",IFERROR(SUMIFS('GSC previous'!$J$2:$J$2001,'GSC previous'!$I$2:$I$2001,B14),0)) | P14: =IF(A14="","",IF(N(O14)>0,(K14-O14)/O14,"")) | Q14: =IF(A14="","",IFERROR(SUMIFS(GA4!$P$2:$P$2001,GA4!$O$2:$O$2001,B14),0)) | R14: =IF(A14="","",IF(N(Q14)>0,SUMIFS(GA4!$Q$2:$Q$2001,GA4!$O$2:$O$2001,B14)/Q14,"")) | S14: =IF(A14="","",IFERROR(SUMIFS(GA4!$R$2:$R$2001,GA4!$O$2:$O$2001,B14),0)) | T14: =IF(A14="","",IF(AND(ISNUMBER(F14),LEFT(C14&"",1)="2"),IF(F14<Rules!$B$9,"Yes","No"),"No")) | U14: =IF(A14="","",IF(AND(N(O14)>=Rules!$B$8,ISNUMBER(P14)),IF(P14<=-Rules!$B$7,"Yes","No"),"No")) | V14: =IF(A14="","",IF(AND(N(L14)>=Rules!$B$6,ISNUMBER(N14)),IF(AND(N14>=Rules!$B$10,N14<=Rules!$B$11),"Yes","No"),"No")) | W14: =IF(A14="","",IF(I14<>"","Yes","No")) | X14: =IF(I14="","",IF(SUMIFS($K$3:$K$2002,$A$3:$A$2002,SUBSTITUTE(SUBSTITUTE(I14,"?","~?"),"*","~*"))>N(K14),"Yes","No")) | Y14: =IF(A14="","",IF(N(S14)>0,"Yes","No")) | Z14: =IF(A14="","",IF(AND(N(K14)<Rules!$B$5,N(L14)<Rules!$B$6,N(Q14)<Rules!$B$13,Y14="No"),"Yes","No")) | AA14: =IF(A14="","",IF(LEFT(C14&"",1)="3","Redirect",IF(OR(LEFT(C14&"",1)="4",LEFT(C14&"",1)="5"),IF(OR(N(K14)>0,N(AC14)>=Rules!$B$14),"Redirect","Prune"),IF(D14="Non-Indexable","Keep",IF(AND(W14="Yes",X14="Yes",Y14="No"),"Merge",IF(OR(U14="Yes",V14="Yes",AND(T14="Yes",N(L14)>=Rules!$B$6)),"Update",IF(Z14="Yes",IF(N(AC14)>=Rules!$B$14,"Redirect","Prune"),"Keep"))))))) | AB14: =IF(A14="","",IF(LEFT(C14&"",1)="3","Already redirects ("&C14&"). Update internal links to point at the final URL.",IF(OR(LEFT(C14&"",1)="4",LEFT(C14&"",1)="5"),IF(AA14="Redirect","Returns "&C14&" but still has "&N(K14)&" clicks and "&N(AC14)&" referring domains. 301 it to the closest live page.","Returns "&C14&" with no clicks or links. Remove internal links and let it 404 or 410."),IF(D14="Non-Indexable","Non-indexable ("&E14&"). Keep if that is intentional; otherwise fix the canonical or noindex.",IF(AA14="Merge","Overlaps with "&I14&IF(N(J14)>0," (similarity "&TEXT(J14,"0.00")&")","")&", which gets more clicks. Merge the useful parts into it and 301 this URL.",IF(AA14="Update",MID(IF(U14="Yes","; Clicks down "&TEXT(-P14,"0%")&" on the previous period","")&IF(V14="Yes","; Average position "&TEXT(N14,"0.0")&" on "&TEXT(L14,"#,##0")&" impressions (striking distance)","")&IF(AND(T14="Yes",N(L14)>=Rules!$B$6),"; Thin ("&F14&" words) but has search demand",""),3,400),IF(AA14="Prune","Low value: "&N(K14)&" clicks, "&N(L14)&" impressions, "&N(Q14)&" sessions, no key events. Remove or noindex it and update internal links.",IF(AA14="Redirect","Low value but "&N(AC14)&" referring domains. 301 it to the closest relevant page to keep those links.",IF(AND(Z14="No",Y14="Yes",N(K14)<Rules!$B$5),"Low search traffic but it converts (key events: "&S14&"). Keep it and link to it.",IF(W14="Yes","Stronger than the page it overlaps ("&I14&"). Keep; merge that page into this one.","Healthy: "&N(K14)&" clicks"&IF(ISNUMBER(N14),", average position "&TEXT(N14,"0.0"),"")&". Keep and monitor.")))))))))) | AE14: =IF(A14="","",IF(AD14<>"",AD14,AA14))
A15: =IF(Crawl!A14="","",Crawl!A14) | B15: =IF(A15="","",Crawl!EC14) | C15: =IF(A15="","",IFERROR(INDEX(Crawl!$A14:$DZ14,1,Rules!$H$6),"")) | D15: =IF(A15="","",IFERROR(INDEX(Crawl!$A14:$DZ14,1,Rules!$H$7),"")&"") | E15: =IF(A15="","",IFERROR(INDEX(Crawl!$A14:$DZ14,1,Rules!$H$8),"")&"") | F15: =IF(A15="","",IFERROR(INDEX(Crawl!$A14:$DZ14,1,Rules!$H$9),"")) | G15: =IF(A15="","",IFERROR(INDEX(Crawl!$A14:$DZ14,1,Rules!$H$10),"")) | H15: =IF(A15="","",IFERROR(INDEX(Crawl!$A14:$DZ14,1,Rules!$H$12),"")) | I15: =IF(A15="","",IF(AND(N(H15)>0,IFERROR(INDEX(Crawl!$A14:$DZ14,1,Rules!$H$11),"")&""<>""),IFERROR(INDEX(Crawl!$A14:$DZ14,1,Rules!$H$11),"")&"",IF(AND(ISNUMBER(J15),N(J15)>=Rules!$B$12,IFERROR(INDEX(Crawl!$A14:$DZ14,1,Rules!$H$13),"")&""<>""),IFERROR(INDEX(Crawl!$A14:$DZ14,1,Rules!$H$13),"")&"",""))) | J15: =IF(A15="","",IF(IFERROR(INDEX(Crawl!$A14:$DZ14,1,Rules!$H$14),"")&""="","",IFERROR(INDEX(Crawl!$A14:$DZ14,1,Rules!$H$14),""))) | K15: =IF(A15="","",IFERROR(SUMIFS('GSC current'!$J$2:$J$2001,'GSC current'!$I$2:$I$2001,B15),0)) | L15: =IF(A15="","",IFERROR(SUMIFS('GSC current'!$K$2:$K$2001,'GSC current'!$I$2:$I$2001,B15),0)) | M15: =IF(A15="","",IF(N(L15)>0,K15/L15,"")) | N15: =IF(A15="","",IF(N(L15)>0,SUMIFS('GSC current'!$L$2:$L$2001,'GSC current'!$I$2:$I$2001,B15)/L15,"")) | O15: =IF(A15="","",IFERROR(SUMIFS('GSC previous'!$J$2:$J$2001,'GSC previous'!$I$2:$I$2001,B15),0)) | P15: =IF(A15="","",IF(N(O15)>0,(K15-O15)/O15,"")) | Q15: =IF(A15="","",IFERROR(SUMIFS(GA4!$P$2:$P$2001,GA4!$O$2:$O$2001,B15),0)) | R15: =IF(A15="","",IF(N(Q15)>0,SUMIFS(GA4!$Q$2:$Q$2001,GA4!$O$2:$O$2001,B15)/Q15,"")) | S15: =IF(A15="","",IFERROR(SUMIFS(GA4!$R$2:$R$2001,GA4!$O$2:$O$2001,B15),0)) | T15: =IF(A15="","",IF(AND(ISNUMBER(F15),LEFT(C15&"",1)="2"),IF(F15<Rules!$B$9,"Yes","No"),"No")) | U15: =IF(A15="","",IF(AND(N(O15)>=Rules!$B$8,ISNUMBER(P15)),IF(P15<=-Rules!$B$7,"Yes","No"),"No")) | V15: =IF(A15="","",IF(AND(N(L15)>=Rules!$B$6,ISNUMBER(N15)),IF(AND(N15>=Rules!$B$10,N15<=Rules!$B$11),"Yes","No"),"No")) | W15: =IF(A15="","",IF(I15<>"","Yes","No")) | X15: =IF(I15="","",IF(SUMIFS($K$3:$K$2002,$A$3:$A$2002,SUBSTITUTE(SUBSTITUTE(I15,"?","~?"),"*","~*"))>N(K15),"Yes","No")) | Y15: =IF(A15="","",IF(N(S15)>0,"Yes","No")) | Z15: =IF(A15="","",IF(AND(N(K15)<Rules!$B$5,N(L15)<Rules!$B$6,N(Q15)<Rules!$B$13,Y15="No"),"Yes","No")) | AA15: =IF(A15="","",IF(LEFT(C15&"",1)="3","Redirect",IF(OR(LEFT(C15&"",1)="4",LEFT(C15&"",1)="5"),IF(OR(N(K15)>0,N(AC15)>=Rules!$B$14),"Redirect","Prune"),IF(D15="Non-Indexable","Keep",IF(AND(W15="Yes",X15="Yes",Y15="No"),"Merge",IF(OR(U15="Yes",V15="Yes",AND(T15="Yes",N(L15)>=Rules!$B$6)),"Update",IF(Z15="Yes",IF(N(AC15)>=Rules!$B$14,"Redirect","Prune"),"Keep"))))))) | AB15: =IF(A15="","",IF(LEFT(C15&"",1)="3","Already redirects ("&C15&"). Update internal links to point at the final URL.",IF(OR(LEFT(C15&"",1)="4",LEFT(C15&"",1)="5"),IF(AA15="Redirect","Returns "&C15&" but still has "&N(K15)&" clicks and "&N(AC15)&" referring domains. 301 it to the closest live page.","Returns "&C15&" with no clicks or links. Remove internal links and let it 404 or 410."),IF(D15="Non-Indexable","Non-indexable ("&E15&"). Keep if that is intentional; otherwise fix the canonical or noindex.",IF(AA15="Merge","Overlaps with "&I15&IF(N(J15)>0," (similarity "&TEXT(J15,"0.00")&")","")&", which gets more clicks. Merge the useful parts into it and 301 this URL.",IF(AA15="Update",MID(IF(U15="Yes","; Clicks down "&TEXT(-P15,"0%")&" on the previous period","")&IF(V15="Yes","; Average position "&TEXT(N15,"0.0")&" on "&TEXT(L15,"#,##0")&" impressions (striking distance)","")&IF(AND(T15="Yes",N(L15)>=Rules!$B$6),"; Thin ("&F15&" words) but has search demand",""),3,400),IF(AA15="Prune","Low value: "&N(K15)&" clicks, "&N(L15)&" impressions, "&N(Q15)&" sessions, no key events. Remove or noindex it and update internal links.",IF(AA15="Redirect","Low value but "&N(AC15)&" referring domains. 301 it to the closest relevant page to keep those links.",IF(AND(Z15="No",Y15="Yes",N(K15)<Rules!$B$5),"Low search traffic but it converts (key events: "&S15&"). Keep it and link to it.",IF(W15="Yes","Stronger than the page it overlaps ("&I15&"). Keep; merge that page into this one.","Healthy: "&N(K15)&" clicks"&IF(ISNUMBER(N15),", average position "&TEXT(N15,"0.0"),"")&". Keep and monitor.")))))))))) | AE15: =IF(A15="","",IF(AD15<>"",AD15,AA15))
