Workbook

Sheet Start here
B2: Knowledge Panel & Brand SERP Audit Checklist
B3: A step-by-step audit of your Google knowledge panel eligibility and brand SERP, ending with a prioritised action plan. Free from MLforSEO, October 2026.
B5: What this is
B6: Knowledge panels aren't something you apply for. Google generates them automatically when its Knowledge Graph holds enough consistent, verifiable information about an entity, and the same signals help AI assistants describe you correctly. This workbook walks you through 36 checks: what page one shows for your brand today, whether Google's Knowledge Graph recognises you, your Wikidata status, your own markup, cross-platform consistency, independent corroboration, claiming and managing a panel, and monitoring.
B7: It works for organisations and for people (founders, authors, consultants). Where a check says Organization, read Person or ProfilePage if you're auditing a person.
B9: How to use it
B10: Step 1 | C10: Make your own copy (File > Make a copy in Google Sheets).
B11: Step 2 | C11: Start with the Fact sheet tab: write the canonical version of each fact in column B. Everything else is compared against it.
B12: Step 3 | C12: Work through the Checklist tab in order. Log what you find in the Brand SERP log and KG lookup log tabs as the checks ask.
B13: Step 4 | C13: Fill in the platform columns of the Fact sheet. Any cell that differs from column B turns red.
B14: Step 5 | C14: Turn findings into the Action plan tab. Its order (own site first, then profiles, then panel claim, Wikidata and coverage) is the sequence we recommend.
B15: Step 6 | C15: Check the Progress tab for completion, owned share of page one and fact mismatches. Repeat monthly and quarterly (area 8).
B17: Tabs
B18: Checklist | C18: 36 checks with why each matters, how to check it, priority, evidence level, status, owner, notes and links.
B19: Fact sheet | C19: Your single source of truth, compared across nine platforms. Mismatches turn red and are counted.
B20: Brand SERP log | C20: One row per result on page one for each brand query you test.
B21: KG lookup log | C21: Dated Knowledge Graph Search API results: ID, name, type, description, resultScore and panel status.
B22: Action plan | C22: The prioritised sequence of fixes, with owners, dates and status.
B23: Progress | C23: Checklist completion by area and priority, plus brand SERP and fact-sheet summaries.
B25: Status
B26: Not started | C26: Default for every check.
B27: In progress | C27: Someone is working on it.
B28: Done | C28: Checked, and fixed if it needed fixing.
B29: N/A | C29: Does not apply to this site. N/A rows are left out of the % complete.
B31: Priority
B32: High | C32: Fix first. Contradictions, misidentification or missing foundations.
B33: Medium | C33: Do next. Strengthens recognition and corroboration.
B34: Low | C34: Monitor, or nice to have.
B36: Evidence levels
B37: Google-documented | C37: Stated in Google Search Central or Google Help documentation.
B38: Platform-documented | C38: Stated in another platform's own documentation (OpenAI, Anthropic, Perplexity, Microsoft Bing, Apple, Meta, Wikidata / Wikimedia, schema.org).
B39: Research-backed | C39: Supported by published research or a large public dataset. Results come from specific test conditions and may not carry over to every site.
B40: MLforSEO practice | C40: What we teach in MLforSEO courses and use in audits, based on how retrieval and entity systems work. Sensible and low-risk, but not confirmed by the platforms.
B41: Unconfirmed (optional) | C41: A cheap extra that no major platform has confirmed using. Do it last, if at all.
B43: Realistic expectations
B44: Google doesn't publish a threshold for showing a panel, and it can't be bought or requested. In MLforSEO's experience it takes six to eighteen months of consistent signals for most brands, faster if you already have strong press coverage. The same work makes you easier for AI assistants to recognise and describe accurately, so it pays off even before a panel appears.
B46: Credits
B47: Created by | C47: =HYPERLINK("https://www.mlforseo.com/experts/lazarina-stoy/","Lazarina Stoy · MLforSEO")
B48: Built on | C48: =HYPERLINK("https://www.mlforseo.com/experts/beatrice-gamba/","Beatrice Gamba's entity SEO articles on MLforSEO")
B49: Read first | C49: =HYPERLINK("https://www.mlforseo.com/knowledge-graph-strategy/what-it-takes-to-earn-a-google-knowledge-panel/","What it takes to earn a Google knowledge panel")
...

Sheet Checklist
A1: ID | B1: Area | C1: Check | D1: Why it matters | E1: How to check (tool / where) | F1: Priority | G1: Evidence | H1: Status | I1: Owner | J1: Notes | K1: Learn more | L1: Official source
A2: K01 | B2: 1. Brand SERP baseline | C2: Capture page one for your exact brand name, on desktop and mobile | D2: Your brand SERP is what people (and AI systems summarising the web) see when they look you up. You need a dated baseline before changing anything. | E2: Search your brand name in a private window, set to your main country and language. Screenshot page one on desktop and mobile, then log each result in the 'Brand SERP log' tab. | F2: High | G2: MLforSEO practice | H2: Not started | K2: =HYPERLINK("https://www.mlforseo.com/knowledge-graph-strategy/what-it-takes-to-earn-a-google-knowledge-panel/","What it takes to earn a Google knowledge panel")
A3: K02 | B3: 1. Brand SERP baseline | C3: Record which results you own or control | D3: Owned pages and official profiles are results you can keep accurate. Third-party results show how others describe you, for better or worse. | E3: In the Brand SERP log, mark each result as Owned site, Official profile, Third party (positive / neutral / negative) or Namesake. The Progress tab shows your owned share. | F3: Medium | G3: MLforSEO practice | H3: Not started | K3: =HYPERLINK("https://www.mlforseo.com/knowledge-graph-strategy/what-it-takes-to-earn-a-google-knowledge-panel/","What it takes to earn a Google knowledge panel")
A4: K03 | B4: 1. Brand SERP baseline | C4: Note which SERP features appear for your brand query and which kind of panel it is | D4: A knowledge panel (an entity in Google's Knowledge Graph) and a Business Profile (a local business listing) look alike but are managed in different ways. Sitelinks, AI Overviews, videos and People Also Ask also shape the page. | E4: List every feature on page one: knowledge panel, Business Profile, sitelinks, AI Overview, People Also Ask, Top stories, videos, images, social posts, reviews. Entity panels usually carry a short description (often sourced from a site such as Wikipedia) and may offer 'Claim this knowledge panel'; a panel with hours, directions and reviews is usually a Business Profile. | F4: Medium | G4: Google-documented | H4: Not started | K4: =HYPERLINK("https://www.mlforseo.com/knowledge-graph-strategy/what-it-takes-to-earn-a-google-knowledge-panel/","What it takes to earn a Google knowledge panel") | L4: =HYPERLINK("https://support.google.com/knowledgepanel/answer/9163198","Google Help: about knowledge panels")
A5: K04 | B5: 1. Brand SERP baseline | C5: Check the brand + modifier searches people actually run | D5: Searches like '[brand] reviews', '[brand] pricing', '[brand] vs [competitor]' and '[founder name]' are where wrong or negative information tends to surface. | E5: Pull branded queries from Search Console (filter queries containing the brand). Search the top five modifiers and log anything inaccurate or unowned. | F5: Medium | G5: MLforSEO practice | H5: Not started | K5: =HYPERLINK("https://www.mlforseo.com/knowledge-graph-strategy/what-it-takes-to-earn-a-google-knowledge-panel/","What it takes to earn a Google knowledge panel")
A6: K05 | B6: 1. Brand SERP baseline | C6: Ask AI assistants who you are and compare the answer with your canonical facts | D6: AI answers draw on the same records as your knowledge panel. Wrong founding dates, products or locations point to the sources you need to correct. | E6: Ask 'What is [brand]?' and 'Who founded [brand]?' in Google AI Mode, Gemini, ChatGPT and Perplexity. Compare against the Fact sheet tab and note every mismatch and the source cited. | F6: High | G6: MLforSEO practice | H6: Not started | K6: =HYPERLINK("https://www.mlforseo.com/machine-learning-implementation-guides/ai-search-optimisation/trust-is-not-a-schema-field/","Trust isn't a schema field")
A7: K06 | B7: 2. Knowledge Graph status | C7: Look up your brand (and founder) in the Knowledge Graph Search API | D7: The API shows whether Google's Knowledge Graph holds an entity for your name, its machine ID (kg:/m/... or kg:/g/...), type and description. No entity means a recognition problem comes before anything else. | E7: Use the API Explorer on Google's Knowledge Graph Search API page or the MLforSEO Knowledge Graph API notebook with your own API key. Log the ID, name, @type, description and resultScore in the 'KG lookup log' tab. Google now points new projects to Cloud Enterprise Knowledge Graph and says this API isn't for production-critical use; it is fine for audits. | F7: High | G7: Google-documented | H7: Not started | K7: =HYPERLINK("https://www.mlforseo.com/resource/knowledge-graph-api-extraction-and-entity-relationship-analysis-for-semantic-keyword-research-notebook/","Knowledge Graph API notebook") | L7: =HYPERLINK("https://developers.google.com/knowledge-graph","Google: Knowledge Graph Search API")
A8: K07 | B8: 2. Knowledge Graph status | C8: Confirm the entity returned is you, not a namesake | D8: If a famous person, place or another company with the same name comes back first, you have a disambiguation problem, and AI systems may attribute your content to the wrong entity. | E8: Read the description and type of the top results. Search the API with your full name plus category (for example 'Acme Software'). Record which entity wins. | F8: High | G8: MLforSEO practice | H8: Not started | K8: =HYPERLINK("https://www.mlforseo.com/machine-learning-tutorials/entity-analysis/entity-disambiguation-in-practice/","Entity disambiguation in practice")
A9: K08 | B9: 2. Knowledge Graph status | C9: Open your entity's ID in Google Search to see the panel tied to it | D9: Searching by machine ID shows the panel Google associates with that entity, even when your brand query shows something else. | E9: Search https://www.google.com/search?kgmid=/g/XXXX (use the ID from the API without the 'kg:' prefix). Screenshot the result. | F9: Medium | G9: MLforSEO practice | H9: Not started | K9: =HYPERLINK("https://www.mlforseo.com/knowledge-graph-strategy/what-it-takes-to-earn-a-google-knowledge-panel/","What it takes to earn a Google knowledge panel")
A10: K09 | B10: 2. Knowledge Graph status | C10: Look for duplicate or fragmented entities for your brand | D10: Name variants ('Acme', 'Acme Corp', 'Acme Corporation') can create several thin entities instead of one strong one. | E10: Query each name variant and your founder in the API. If more than one ID describes your organisation, note them all and make naming consistent everywhere (area 5). | F10: Medium | G10: MLforSEO practice | H10: Not started | K10: =HYPERLINK("https://www.mlforseo.com/machine-learning-implementation-guides/ai-search-optimisation/consistency-beats-completeness-structured-data/","Consistency beats completeness")
A11: K10 | B11: 2. Knowledge Graph status | C11: Treat resultScore as a relative signal only | D11: Google documents resultScore as an indicator of how well an entity matched the request and publishes no thresholds. It moves with the query, so compare it only with itself over time. | E11: Run the same query monthly and log the score in the KG lookup log. Rising scores and a stable ID are good signs; a changing ID is worth investigating. | F11: Low | G11: Google-documented | H11: Not started | K11: =HYPERLINK("https://www.mlforseo.com/machine-learning-tutorials/entity-analysis/entity-disambiguation-in-practice/","Entity disambiguation in practice") | L11: =HYPERLINK("https://developers.google.com/knowledge-graph","Google: Knowledge Graph Search API")
A12: K11 | B12: 3. Wikidata & Wikipedia | C12: Search Wikidata for an existing item before creating anything | D12: Duplicate items are the most common reason brand entries get deleted. Someone may already have created one for you. | E12: Search wikidata.org for your brand, legal name and founders. Record any Q-IDs in the Fact sheet. If one exists, improve it rather than starting again. | F12: High | G12: Platform-documented | H12: Not started | K12: =HYPERLINK("https://www.mlforseo.com/knowledge-graph-strategy/wikidata-for-brands-notability-criteria-and-a-realistic-path/","Wikidata for brands") | L12: =HYPERLINK("https://www.wikidata.org/wiki/Wikidata:Notability","Wikidata: notability policy")
A13: K12 | B13: 3. Wikidata & Wikipedia | C13: If an item exists, check it is accurate, neutral and referenced | D13: Wikidata is openly licensed and widely reused by search and AI systems, so errors there spread. Unreferenced statements are easy to challenge. | E13: Check label, description (short and neutral, no promotional language), instance of, country, official website, inception, founders, headquarters and social media IDs. Every statement should cite an external source. | F13: High | G13: Platform-documented | H13: Not started | K13: =HYPERLINK("https://www.mlforseo.com/knowledge-graph-strategy/wikidata-for-brands-notability-criteria-and-a-realistic-path/","Wikidata for brands") | L13: =HYPERLINK("https://www.wikidata.org/wiki/Wikidata:Notability","Wikidata: notability policy")
A14: K13 | B14: 3. Wikidata & Wikipedia | C14: If there is no item, check notability before creating one | D14: Wikidata accepts entities that can be described using serious, publicly available references: registries, authority records, databases and independent coverage. Your own website on its own isn't enough. | E14: List your external references (company registry, Crunchbase, trade press, conference programmes, industry databases). If you have two or three solid ones, you likely qualify; if not, earn coverage first (area 6). | F14: Medium | G14: Platform-documented | H14: Not started | K14: =HYPERLINK("https://www.mlforseo.com/knowledge-graph-strategy/wikidata-for-brands-notability-criteria-and-a-realistic-path/","Wikidata for brands") | L14: =HYPERLINK("https://www.wikidata.org/wiki/Wikidata:Notability","Wikidata: notability policy")
A15: K14 | B15: 3. Wikidata & Wikipedia | C15: Declare any conflict of interest when you or your agency edit | D15: Editing your own organisation's item or article is a conflict of interest. On Wikipedia, paid editing must be disclosed under the Wikimedia Terms of Use, and you should propose changes on the article's Talk page rather than editing directly. | E15: Use a personal, clearly identifiable account. Note your connection on your user page. For Wikipedia, request edits on the Talk page with independent sources. | F15: High | G15: Platform-documented | H15: Not started | K15: =HYPERLINK("https://www.mlforseo.com/knowledge-graph-strategy/wikidata-for-brands-notability-criteria-and-a-realistic-path/","Wikidata for brands") | L15: =HYPERLINK("https://en.wikipedia.org/wiki/Wikipedia:Conflict_of_interest","Wikipedia: conflict of interest guideline")
A16: K15 | B16: 3. Wikidata & Wikipedia | C16: Record whether a Wikipedia article exists and is accurate | D16: Wikipedia is a strong source for knowledge panels, but its notability bar (significant coverage in independent, reliable sources) excludes most small and mid-size brands. Not having one is normal. | E16: Search Wikipedia in your main languages. If an article exists, log factual errors and suggest corrections on its Talk page with sources. Don't write your own article. | F16: Low | G16: Platform-documented | H16: Not started | K16: =HYPERLINK("https://www.mlforseo.com/knowledge-graph-strategy/wikidata-for-brands-notability-criteria-and-a-realistic-path/","Wikidata for brands") | L16: =HYPERLINK("https://en.wikipedia.org/wiki/Wikipedia:Conflict_of_interest","Wikipedia: conflict of interest guideline")
A17: K16 | B17: 4. On-site entity markup | C17: Organization (or Person / ProfilePage) markup sits on your home or about page | D17: Google recommends placing Organization markup on the home page or a single page describing the organisation. It helps Google understand your details and which logo to show, including in knowledge panels. For a person, ProfilePage markup with a Person as mainEntity does the same job. | E17: View Source on the home and about pages. Check for name, alternateName, legalName, url, logo, description, foundingDate, founder, address, contactPoint and sameAs. Validate with the Rich Results Test and Schema Markup Validator. | F17: High | G17: Google-documented | H17: Not started | K17: =HYPERLINK("https://www.mlforseo.com/machine-learning-implementation-guides/structured-data-audit/how-structured-data-reinforces-entity-understanding-in-ai-search/","Structured data and entity understanding") | L17: =HYPERLINK("https://developers.google.com/search/docs/appearance/structured-data/organization","Google: Organization structured data")
A18: K17 | B18: 4. On-site entity markup | C18: The logo in your markup is a crawlable image of at least 112 x 112 px | D18: Google's Organization guidelines set this minimum and say the logo property helps Google choose the logo for Search results and knowledge panels. | E18: Open the logo URL from the markup: it should load directly (not blocked by robots.txt), be square-friendly and look right on a white background. | F18: Medium | G18: Google-documented | H18: Not started | K18: =HYPERLINK("https://www.mlforseo.com/machine-learning-implementation-guides/structured-data-audit/how-structured-data-reinforces-entity-understanding-in-ai-search/","Structured data and entity understanding") | L18: =HYPERLINK("https://developers.google.com/search/docs/appearance/structured-data/organization","Google: Organization structured data")
A19: K18 | B19: 4. On-site entity markup | C19: Organization and founders have stable @id values that other markup points to | D19: A stable @id lets every article, product and author page reference the same entity, so signals add up instead of scattering across separate declarations. | E19: Check the Organization @id never changes between pages, and that Article publisher, Person worksFor and Product brand reference it. | F19: Medium | G19: MLforSEO practice | H19: Not started | K19: =HYPERLINK("https://www.mlforseo.com/machine-learning-implementation-guides/structured-data-audit/what-schema-org-id-does-and-why-your-entity-graph-falls-apart-without-it/","What schema.org @id does")
A20: K19 | B20: 4. On-site entity markup | C20: Every sameAs link resolves to an official profile showing the same name | D20: schema.org defines sameAs as a page that unambiguously indicates the item's identity. A broken or mismatched link is a failed confirmation, which is worse than no link. | E20: Open each sameAs URL; log status code and displayed name in the Fact sheet. Include Wikidata, LinkedIn, Crunchbase, official social profiles and relevant industry directories. | F20: High | G20: MLforSEO practice | H20: Not started | K20: =HYPERLINK("https://www.mlforseo.com/machine-learning-implementation-guides/ai-search-optimisation/consistency-beats-completeness-structured-data/","Consistency beats completeness") | L20: =HYPERLINK("https://schema.org/sameAs","schema.org: sameAs")
A21: K20 | B21: 4. On-site entity markup | C21: Your about page states the canonical facts in plain text, matching the markup | D21: Structured data should describe what is visible on the page. Plain-text facts also give AI systems and journalists something to quote. | E21: Compare the about page text with the JSON-LD and the Fact sheet: name, founding date, founders, headquarters, what you do in one sentence. | F21: High | G21: Google-documented | H21: Not started | K21: =HYPERLINK("https://www.mlforseo.com/machine-learning-implementation-guides/ai-search-optimisation/consistency-beats-completeness-structured-data/","Consistency beats completeness") | L21: =HYPERLINK("https://developers.google.com/search/docs/appearance/structured-data/sd-policies","Google: structured data policies")
A22: K21 | B22: 4. On-site entity markup | C22: Your brand is the most prominent entity on your home and about pages | D22: If navigation labels or product names outscore your brand in entity extraction, the pages meant to define you send a weak signal. | E22: Run Google's Natural Language API (or the MLforSEO no-code template) on the full page and on the main content only. Your brand should lead on salience. Use <nav>, <main> and <footer> elements. | F22: Medium | G22: MLforSEO practice | H22: Not started | K22: =HYPERLINK("https://www.mlforseo.com/machine-learning-tutorials/entity-analysis/why-navigation-elements-outrank-your-brand-in-entity-analysis/","Why navigation outranks your brand")
A23: K22 | B23: 5. Cross-platform consistency | C23: Create a single source of truth for your canonical facts | D23: One agreed version of each fact makes every later update quick and consistent. Without it, teams rediscover the platform list each time and miss some. | E23: Fill in column B of the 'Fact sheet' tab: canonical name, legal name, founding date, founders, headquarters, website URL, one-sentence description, category, employee range, logo URL. | F23: High | G23: MLforSEO practice | H23: Not started | K23: =HYPERLINK("https://www.mlforseo.com/machine-learning-implementation-guides/ai-search-optimisation/cross-platform-entity-consistency-the-llm-era/","Cross-platform entity consistency")
A24: K23 | B24: 5. Cross-platform consistency | C24: Audit every profile against the fact sheet | D24: Each platform holding facts about you is a verification point for Google and AI systems. Consistent points add confidence; inconsistent ones subtract it. | E24: Fill the platform columns in the Fact sheet: website and schema, LinkedIn, Crunchbase, Wikidata, Business Profile, X, YouTube, industry directories, company registry. Cells that differ from column B turn red. | F24: High | G24: MLforSEO practice | H24: Not started | K24: =HYPERLINK("https://www.mlforseo.com/machine-learning-implementation-guides/ai-search-optimisation/cross-platform-entity-consistency-the-llm-era/","Cross-platform entity consistency")
A25: K24 | B25: 5. Cross-platform consistency | C25: Fix contradictions first, then fill gaps | D25: A missing fact is neutral. Conflicting facts (founded 2011 here, 2013 there) are a conflict systems can't resolve, so they may drop the fact or lower confidence in the whole entity. | E25: Sort the Fact sheet by red cells. Correct the platforms you control, then request corrections from third parties with a link to an authoritative source. | F25: High | G25: MLforSEO practice | H25: Not started | K25: =HYPERLINK("https://www.mlforseo.com/machine-learning-implementation-guides/ai-search-optimisation/trust-is-not-a-schema-field/","Trust isn't a schema field")
A26: K25 | B26: 5. Cross-platform consistency | C26: Founders and leaders have consistent, linked profiles | D26: People entities reinforce the organisation. Consistent names, titles and employers across author pages, speaker bios and LinkedIn give systems a second route to recognising you. | E26: Check each founder's LinkedIn, author page, speaker bios and Wikidata (if any) use the same name, title and employer. Link the person's markup to the Organization @id. | F26: Medium | G26: MLforSEO practice | H26: Not started | K26: =HYPERLINK("https://www.mlforseo.com/machine-learning-implementation-guides/ai-search-optimisation/trust-is-not-a-schema-field/","Trust isn't a schema field") | L26: =HYPERLINK("https://developers.google.com/search/docs/appearance/structured-data/profile-page","Google: ProfilePage structured data")
A27: K26 | B27: 6. Corroboration | C27: List the independent sources that already describe you | D27: Google cross-checks your claims against external sources. Five consistent mentions in respected publications do more than fifty thin directory listings. | E27: Search your brand in news, trade publications, podcasts, conference programmes, registries and databases. Log each source and whether its facts match the Fact sheet. | F27: Medium | G27: MLforSEO practice | H27: Not started | K27: =HYPERLINK("https://www.mlforseo.com/knowledge-graph-strategy/what-it-takes-to-earn-a-google-knowledge-panel/","What it takes to earn a Google knowledge panel")
A28: K27 | B28: 6. Corroboration | C28: Plan coverage that would make your key facts independently verifiable | D28: Panels appear when enough independent sources agree. Most brands need more third-party coverage before anything else moves. | E28: Pick realistic targets: industry publications, podcast interviews, conference talks, guest articles, partner pages, awards. Track them in the Action plan tab. | F28: Medium | G28: MLforSEO practice | H28: Not started | K28: =HYPERLINK("https://www.mlforseo.com/knowledge-graph-strategy/what-it-takes-to-earn-a-google-knowledge-panel/","What it takes to earn a Google knowledge panel")
A29: K28 | B29: 6. Corroboration | C29: Third-party mentions place you next to your category and peers | D29: Co-occurrence with category terms, partners and competitors tells systems which 'Acme' you are and what you're relevant for. | E29: Check how press and partner pages describe you. Ask for your full name plus a short category descriptor in bios and boilerplates. | F29: Low | G29: MLforSEO practice | H29: Not started | K29: =HYPERLINK("https://www.mlforseo.com/machine-learning-implementation-guides/ai-search-optimisation/how-llms-co-cite-building-authority-by-association/","How LLMs co-cite")
A30: K29 | B30: 7. Claim & manage | C30: If a knowledge panel shows, claim it through an official profile | D30: Verified representatives can suggest changes to their panel and choose a featured image. Not every panel is claimable yet, so check back if the option is missing. | E30: Signed in to a Google Account, search for the entity, click 'Claim this knowledge panel' at the bottom of the panel, then sign in to one of the listed official sites or profiles (such as Search Console, YouTube, X or Facebook). | F30: High | G30: Google-documented | H30: Not started | K30: =HYPERLINK("https://www.mlforseo.com/knowledge-graph-strategy/what-it-takes-to-earn-a-google-knowledge-panel/","What it takes to earn a Google knowledge panel") | L30: =HYPERLINK("https://support.google.com/knowledgepanel/answer/7534902","Google Help: get verified on Google")
A31: K30 | B31: 7. Claim & manage | C31: Once verified, suggest corrections with evidence and add team members | D31: Feedback from verified representatives is prioritised, and edits backed by links to verifying pages are more likely to be accepted. | E31: Use Feedback below the panel, flag the fact, describe the correction and link to pages that confirm it. Add colleagues as Contributors or Managers at google.com/search/contributions/manage. | F31: Medium | G31: Google-documented | H31: Not started | K31: =HYPERLINK("https://www.mlforseo.com/knowledge-graph-strategy/what-it-takes-to-earn-a-google-knowledge-panel/","What it takes to earn a Google knowledge panel") | L31: =HYPERLINK("https://support.google.com/knowledgepanel/answer/7534902","Google Help: get verified on Google")
A32: K31 | B32: 7. Claim & manage | C32: Local businesses: claim and verify your Business Profile separately | D32: Business Profiles look like knowledge panels but cover businesses serving customers at a location or in a service area, and are managed through Google Business Profile. | E32: Claim or create the profile in Google Business Profile, verify it, and make name, address, phone, hours and website match the Fact sheet. | F32: High | G32: Google-documented | H32: Not started | K32: =HYPERLINK("https://www.mlforseo.com/machine-learning-implementation-guides/ai-search-optimisation/cross-platform-entity-consistency-the-llm-era/","Cross-platform entity consistency") | L32: =HYPERLINK("https://support.google.com/knowledgepanel/answer/9163198","Google Help: about knowledge panels")
A33: K32 | B33: 7. Claim & manage | C33: If the panel mixes you up with someone else or shows the wrong profiles, contact support | D33: Google's knowledge panel help lists mixed-up entities and wrong websites or profiles as cases for its support team, and runs an account recovery process if someone else already manages your panel. | E33: Follow the troubleshooting steps in Google's 'Get verified on Google' help article. Keep screenshots and links to authoritative sources ready. | F33: Medium | G33: Google-documented | H33: Not started | K33: =HYPERLINK("https://www.mlforseo.com/machine-learning-tutorials/entity-analysis/entity-disambiguation-in-practice/","Entity disambiguation in practice") | L33: =HYPERLINK("https://support.google.com/knowledgepanel/answer/7534902","Google Help: get verified on Google")
A34: K33 | B34: 7. Claim & manage | C34: Own more of page one for brand and brand + modifier searches | D34: Official profiles, a clear site structure (for sitelinks) and pages answering pricing, reviews and comparison questions keep accurate information near the top. | E34: Fill gaps from the Brand SERP log: complete official profiles, add or improve pages for top branded modifiers, link profiles from the site and markup. | F34: Medium | G34: MLforSEO practice | H34: Not started | K34: =HYPERLINK("https://www.mlforseo.com/knowledge-graph-strategy/what-it-takes-to-earn-a-google-knowledge-panel/","What it takes to earn a Google knowledge panel")
A35: K34 | B35: 8. Monitor | C35: Monthly: check the top five platforms and rerun the brand SERP and KG lookups | D35: Third parties edit your records and Google updates panels automatically as the web changes. Small, regular checks stop drift. | E35: Each month: website, LinkedIn, Wikidata, Crunchbase, Business Profile against the Fact sheet; add a new row to the KG lookup log; note SERP changes in the Brand SERP log. | F35: Medium | G35: MLforSEO practice | H35: Not started | K35: =HYPERLINK("https://www.mlforseo.com/machine-learning-tutorials/entity-analysis/entity-audit-cadence-what-to-check-weekly-monthly-quarterly/","Entity audit cadence")
A36: K35 | B36: 8. Monitor | C36: Update every platform within a week of a material change | D36: New leadership, a move, an acquisition or a rebrand makes old facts wrong everywhere at once. Stale data on Wikidata and profiles propagates to other systems. | E36: Update the Fact sheet first, then work through every platform column. Add the change to the Action plan with an owner and date. | F36: Medium | G36: MLforSEO practice | H36: Not started | K36: =HYPERLINK("https://www.mlforseo.com/machine-learning-implementation-guides/ai-search-optimisation/cross-platform-entity-consistency-the-llm-era/","Cross-platform entity consistency")
A37: K36 | B37: 8. Monitor | C37: Quarterly: repeat the full audit and the AI answer check | D37: Panels usually take months of consistent signals to appear: six to eighteen months for most brands in MLforSEO's experience. Quarterly reviews show whether the work is moving the entity. | E37: Duplicate this sheet (or add a dated column to the logs), rerun every check, and compare KG ID, panel presence, owned share of page one and AI answer accuracy with last quarter. | F37: Low | G37: MLforSEO practice | H37: Not started | K37: =HYPERLINK("https://www.mlforseo.com/knowledge-graph-strategy/what-it-takes-to-earn-a-google-knowledge-panel/","What it takes to earn a Google knowledge panel")

Sheet Fact sheet
A1: Write the canonical value in column B, then what each platform currently shows. Leave a cell blank if that platform doesn't show the fact. Cells that differ from column B turn red (the comparison ignores upper and lower case). Add rows for any other facts you track.
A2: Fact | B2: Canonical value (your source of truth) | C2: Website & schema | D2: LinkedIn | E2: Crunchbase | F2: Wikidata | G2: Business Profile | H2: X / social | I2: YouTube | J2: Industry directory | K2: Company registry | L2: Mismatches | M2: Notes
A3: Canonical brand name | L3: =IF($B3="","",SUMPRODUCT((C3:K3<>"")*(C3:K3<>$B3)))
A4: Legal name | L4: =IF($B4="","",SUMPRODUCT((C4:K4<>"")*(C4:K4<>$B4)))
A5: Other names / abbreviations | L5: =IF($B5="","",SUMPRODUCT((C5:K5<>"")*(C5:K5<>$B5)))
A6: Website URL (exact) | L6: =IF($B6="","",SUMPRODUCT((C6:K6<>"")*(C6:K6<>$B6)))
A7: One-sentence description | L7: =IF($B7="","",SUMPRODUCT((C7:K7<>"")*(C7:K7<>$B7)))
A8: Category / industry | L8: =IF($B8="","",SUMPRODUCT((C8:K8<>"")*(C8:K8<>$B8)))
A9: Founding date | L9: =IF($B9="","",SUMPRODUCT((C9:K9<>"")*(C9:K9<>$B9)))
A10: Founders | L10: =IF($B10="","",SUMPRODUCT((C10:K10<>"")*(C10:K10<>$B10)))
A11: Current CEO / leader | L11: =IF($B11="","",SUMPRODUCT((C11:K11<>"")*(C11:K11<>$B11)))
A12: Headquarters address | L12: =IF($B12="","",SUMPRODUCT((C12:K12<>"")*(C12:K12<>$B12)))
A13: Phone | L13: =IF($B13="","",SUMPRODUCT((C13:K13<>"")*(C13:K13<>$B13)))
A14: Employee range | L14: =IF($B14="","",SUMPRODUCT((C14:K14<>"")*(C14:K14<>$B14)))
... A17: Knowledge Graph ID | L17: =IF($B17="","",SUMPRODUCT((C17:K17<>"")*(C17:K17<>$B17)))
L18: =IF($B18="","",SUMPRODUCT((C18:K18<>"")*(C18:K18<>$B18)))
L19: =IF($B19="","",SUMPRODUCT((C19:K19<>"")*(C19:K19<>$B19)))
L20: =IF($B20="","",SUMPRODUCT((C20:K20<>"")*(C20:K20<>$B20)))
L21: =IF($B21="","",SUMPRODUCT((C21:K21<>"")*(C21:K21<>$B21)))
L22: =IF($B22="","",SUMPRODUCT((C22:K22<>"")*(C22:K22<>$B22)))

Sheet Brand SERP log
A1: One row per result on page one, per query and device. Log the exact brand name first, then brand + modifier queries (reviews, pricing, vs competitor, founder name). Delete the example rows.
A2: Date | B2: Query | C2: Device | D2: Position | E2: URL | F2: Title / source | G2: Result type | H2: SERP feature | I2: Accurate? | J2: Notes
A3: 2026-10-01 | B3: acme software | C3: Desktop | D3: 1 | E3: https://www.example.com/ | F3: Acme Software: project management for remote teams | G3: Owned site | H3: Sitelinks | I3: Yes | J3: EXAMPLE ROW: delete.
A4: 2026-10-01 | B4: acme software | C4: Desktop | D4: 2 | E4: https://www.linkedin.com/company/example | F4: Acme Software | LinkedIn | G4: Official profile | H4: Organic result | I4: Partly | J4: EXAMPLE ROW: delete. Old HQ address.

Sheet KG lookup log
A1: Log a Knowledge Graph Search API lookup for your brand, its name variants and founders each month. resultScore has no official thresholds: compare it with your own earlier rows only.
A2: Date | B2: Query | C2: KG ID (kg:/m/... or kg:/g/...) | D2: Name | E2: @type | F2: Description | G2: resultScore | H2: Is it you? | I2: Panel for brand query | J2: Claimed? | K2: Notes

Sheet Action plan
A1: The recommended sequence: fix what you control first, then align profiles, then claim, then build external corroboration. Add your own actions from the checklist findings in the blank rows.
A2: Order | B2: Action | C2: Related checks | D2: Why this order | E2: Effort | F2: Owner | G2: Due date | H2: Status | I2: Notes
A3: 1 | B3: Agree the canonical facts and fill in the Fact sheet | C3: K22 | D3: Everything else is checked against it. | E3: Low | H3: Not started
A4: 2 | B4: Fix contradictions on your own site and markup (about page, Organization markup, @id, sameAs) | C4: K16 to K21, K24 | D4: You control these, and Google re-reads them at the next crawl. | E4: Low to medium | H4: Not started
A5: 3 | B5: Align the profiles you control (LinkedIn, Crunchbase, social profiles, directories, Business Profile) | C5: K23 to K25, K31 | D5: Removes conflicts across the verification points you can edit today. | E5: Medium | H5: Not started
A6: 4 | B6: Claim the knowledge panel if one exists and submit evidence-backed corrections | C6: K29, K30, K32 | D6: Verified feedback is prioritised. | E6: Low | H6: Not started
A7: 5 | B7: Improve or create the Wikidata item if you meet notability, declaring any conflict of interest | C7: K11 to K14 | D7: Adds a referenced, openly reused record of your entity. | E7: Medium | H7: Not started
A8: 6 | B8: Earn independent coverage that confirms your key facts | C8: K26 to K28 | D8: Panels and AI citations rely on agreement across independent sources. | E8: High (ongoing) | H8: Not started
A9: 7 | B9: Fill the gaps on page one for brand and brand + modifier searches | C9: K33 | D9: Keeps accurate, owned information in front of people. | E9: Medium | H9: Not started
A10: 8 | B10: Set the monthly and quarterly checks in your calendar | C10: K34 to K36 | D10: Stops drift and shows whether the work is moving the entity. | E10: Low | H10: Not started

Sheet Progress
B2: Progress
B3: Updates automatically as you change the Status column. Formulas use COUNTIF / COUNTIFS, so they work in Google Sheets and Excel.
B5: Checks | C5: =COUNTA('Checklist'!$C$2:$C$52)
B6: Done | C6: =COUNTIF('Checklist'!$H$2:$H$52,"Done")
B7: In progress | C7: =COUNTIF('Checklist'!$H$2:$H$52,"In progress")
B8: Not started | C8: =COUNTIF('Checklist'!$H$2:$H$52,"Not started")
B9: N/A | C9: =COUNTIF('Checklist'!$H$2:$H$52,"N/A")
B10: % complete (Done / applicable) | C10: =IFERROR(C6/(C5-C9),0) | D10: =REPT("█",ROUND(C10*20,0))&REPT("░",20-ROUND(C10*20,0))
B11: Open High-priority checks | C11: =COUNTIFS('Checklist'!$F$2:$F$52,"High",'Checklist'!$H$2:$H$52,"<>Done",'Checklist'!$H$2:$H$52,"<>N/A")
B13: Area | C13: Checks | D13: Done | E13: In progress | F13: Not started | G13: N/A | H13: % done | I13: Open High
B14: 1. Brand SERP baseline | C14: =COUNTIF('Checklist'!$B$2:$B$52,$B14) | D14: =COUNTIFS('Checklist'!$B$2:$B$52,$B14,'Checklist'!$H$2:$H$52,"Done") | E14: =COUNTIFS('Checklist'!$B$2:$B$52,$B14,'Checklist'!$H$2:$H$52,"In progress") | F14: =COUNTIFS('Checklist'!$B$2:$B$52,$B14,'Checklist'!$H$2:$H$52,"Not started") | G14: =COUNTIFS('Checklist'!$B$2:$B$52,$B14,'Checklist'!$H$2:$H$52,"N/A") | H14: =IFERROR(D14/(C14-G14),0) | I14: =COUNTIFS('Checklist'!$B$2:$B$52,$B14,'Checklist'!$F$2:$F$52,"High",'Checklist'!$H$2:$H$52,"<>Done",'Checklist'!$H$2:$H$52,"<>N/A") | J14: =REPT("█",ROUND(H14*10,0))&REPT("░",10-ROUND(H14*10,0))
B15: 2. Knowledge Graph status | C15: =COUNTIF('Checklist'!$B$2:$B$52,$B15) | D15: =COUNTIFS('Checklist'!$B$2:$B$52,$B15,'Checklist'!$H$2:$H$52,"Done") | E15: =COUNTIFS('Checklist'!$B$2:$B$52,$B15,'Checklist'!$H$2:$H$52,"In progress") | F15: =COUNTIFS('Checklist'!$B$2:$B$52,$B15,'Checklist'!$H$2:$H$52,"Not started") | G15: =COUNTIFS('Checklist'!$B$2:$B$52,$B15,'Checklist'!$H$2:$H$52,"N/A") | H15: =IFERROR(D15/(C15-G15),0) | I15: =COUNTIFS('Checklist'!$B$2:$B$52,$B15,'Checklist'!$F$2:$F$52,"High",'Checklist'!$H$2:$H$52,"<>Done",'Checklist'!$H$2:$H$52,"<>N/A") | J15: =REPT("█",ROUND(H15*10,0))&REPT("░",10-ROUND(H15*10,0))
B16: 3. Wikidata & Wikipedia | C16: =COUNTIF('Checklist'!$B$2:$B$52,$B16) | D16: =COUNTIFS('Checklist'!$B$2:$B$52,$B16,'Checklist'!$H$2:$H$52,"Done") | E16: =COUNTIFS('Checklist'!$B$2:$B$52,$B16,'Checklist'!$H$2:$H$52,"In progress") | F16: =COUNTIFS('Checklist'!$B$2:$B$52,$B16,'Checklist'!$H$2:$H$52,"Not started") | G16: =COUNTIFS('Checklist'!$B$2:$B$52,$B16,'Checklist'!$H$2:$H$52,"N/A") | H16: =IFERROR(D16/(C16-G16),0) | I16: =COUNTIFS('Checklist'!$B$2:$B$52,$B16,'Checklist'!$F$2:$F$52,"High",'Checklist'!$H$2:$H$52,"<>Done",'Checklist'!$H$2:$H$52,"<>N/A") | J16: =REPT("█",ROUND(H16*10,0))&REPT("░",10-ROUND(H16*10,0))
B17: 4. On-site entity markup | C17: =COUNTIF('Checklist'!$B$2:$B$52,$B17) | D17: =COUNTIFS('Checklist'!$B$2:$B$52,$B17,'Checklist'!$H$2:$H$52,"Done") | E17: =COUNTIFS('Checklist'!$B$2:$B$52,$B17,'Checklist'!$H$2:$H$52,"In progress") | F17: =COUNTIFS('Checklist'!$B$2:$B$52,$B17,'Checklist'!$H$2:$H$52,"Not started") | G17: =COUNTIFS('Checklist'!$B$2:$B$52,$B17,'Checklist'!$H$2:$H$52,"N/A") | H17: =IFERROR(D17/(C17-G17),0) | I17: =COUNTIFS('Checklist'!$B$2:$B$52,$B17,'Checklist'!$F$2:$F$52,"High",'Checklist'!$H$2:$H$52,"<>Done",'Checklist'!$H$2:$H$52,"<>N/A") | J17: =REPT("█",ROUND(H17*10,0))&REPT("░",10-ROUND(H17*10,0))
B18: 5. Cross-platform consistency | C18: =COUNTIF('Checklist'!$B$2:$B$52,$B18) | D18: =COUNTIFS('Checklist'!$B$2:$B$52,$B18,'Checklist'!$H$2:$H$52,"Done") | E18: =COUNTIFS('Checklist'!$B$2:$B$52,$B18,'Checklist'!$H$2:$H$52,"In progress") | F18: =COUNTIFS('Checklist'!$B$2:$B$52,$B18,'Checklist'!$H$2:$H$52,"Not started") | G18: =COUNTIFS('Checklist'!$B$2:$B$52,$B18,'Checklist'!$H$2:$H$52,"N/A") | H18: =IFERROR(D18/(C18-G18),0) | I18: =COUNTIFS('Checklist'!$B$2:$B$52,$B18,'Checklist'!$F$2:$F$52,"High",'Checklist'!$H$2:$H$52,"<>Done",'Checklist'!$H$2:$H$52,"<>N/A") | J18: =REPT("█",ROUND(H18*10,0))&REPT("░",10-ROUND(H18*10,0))
B19: 6. Corroboration | C19: =COUNTIF('Checklist'!$B$2:$B$52,$B19) | D19: =COUNTIFS('Checklist'!$B$2:$B$52,$B19,'Checklist'!$H$2:$H$52,"Done") | E19: =COUNTIFS('Checklist'!$B$2:$B$52,$B19,'Checklist'!$H$2:$H$52,"In progress") | F19: =COUNTIFS('Checklist'!$B$2:$B$52,$B19,'Checklist'!$H$2:$H$52,"Not started") | G19: =COUNTIFS('Checklist'!$B$2:$B$52,$B19,'Checklist'!$H$2:$H$52,"N/A") | H19: =IFERROR(D19/(C19-G19),0) | I19: =COUNTIFS('Checklist'!$B$2:$B$52,$B19,'Checklist'!$F$2:$F$52,"High",'Checklist'!$H$2:$H$52,"<>Done",'Checklist'!$H$2:$H$52,"<>N/A") | J19: =REPT("█",ROUND(H19*10,0))&REPT("░",10-ROUND(H19*10,0))
B20: 7. Claim & manage | C20: =COUNTIF('Checklist'!$B$2:$B$52,$B20) | D20: =COUNTIFS('Checklist'!$B$2:$B$52,$B20,'Checklist'!$H$2:$H$52,"Done") | E20: =COUNTIFS('Checklist'!$B$2:$B$52,$B20,'Checklist'!$H$2:$H$52,"In progress") | F20: =COUNTIFS('Checklist'!$B$2:$B$52,$B20,'Checklist'!$H$2:$H$52,"Not started") | G20: =COUNTIFS('Checklist'!$B$2:$B$52,$B20,'Checklist'!$H$2:$H$52,"N/A") | H20: =IFERROR(D20/(C20-G20),0) | I20: =COUNTIFS('Checklist'!$B$2:$B$52,$B20,'Checklist'!$F$2:$F$52,"High",'Checklist'!$H$2:$H$52,"<>Done",'Checklist'!$H$2:$H$52,"<>N/A") | J20: =REPT("█",ROUND(H20*10,0))&REPT("░",10-ROUND(H20*10,0))
B21: 8. Monitor | C21: =COUNTIF('Checklist'!$B$2:$B$52,$B21) | D21: =COUNTIFS('Checklist'!$B$2:$B$52,$B21,'Checklist'!$H$2:$H$52,"Done") | E21: =COUNTIFS('Checklist'!$B$2:$B$52,$B21,'Checklist'!$H$2:$H$52,"In progress") | F21: =COUNTIFS('Checklist'!$B$2:$B$52,$B21,'Checklist'!$H$2:$H$52,"Not started") | G21: =COUNTIFS('Checklist'!$B$2:$B$52,$B21,'Checklist'!$H$2:$H$52,"N/A") | H21: =IFERROR(D21/(C21-G21),0) | I21: =COUNTIFS('Checklist'!$B$2:$B$52,$B21,'Checklist'!$F$2:$F$52,"High",'Checklist'!$H$2:$H$52,"<>Done",'Checklist'!$H$2:$H$52,"<>N/A") | J21: =REPT("█",ROUND(H21*10,0))&REPT("░",10-ROUND(H21*10,0))
B23: Priority | C23: Checks | D23: Done | E23: Open | F23: % done
B24: High | C24: =COUNTIF('Checklist'!$F$2:$F$52,$B24) | D24: =COUNTIFS('Checklist'!$F$2:$F$52,$B24,'Checklist'!$H$2:$H$52,"Done") | E24: =COUNTIFS('Checklist'!$F$2:$F$52,$B24,'Checklist'!$H$2:$H$52,"<>Done",'Checklist'!$H$2:$H$52,"<>N/A") | F24: =IFERROR(D24/(C24-COUNTIFS('Checklist'!$F$2:$F$52,$B24,'Checklist'!$H$2:$H$52,"N/A")),0)
B25: Medium | C25: =COUNTIF('Checklist'!$F$2:$F$52,$B25) | D25: =COUNTIFS('Checklist'!$F$2:$F$52,$B25,'Checklist'!$H$2:$H$52,"Done") | E25: =COUNTIFS('Checklist'!$F$2:$F$52,$B25,'Checklist'!$H$2:$H$52,"<>Done",'Checklist'!$H$2:$H$52,"<>N/A") | F25: =IFERROR(D25/(C25-COUNTIFS('Checklist'!$F$2:$F$52,$B25,'Checklist'!$H$2:$H$52,"N/A")),0)
B26: Low | C26: =COUNTIF('Checklist'!$F$2:$F$52,$B26) | D26: =COUNTIFS('Checklist'!$F$2:$F$52,$B26,'Checklist'!$H$2:$H$52,"Done") | E26: =COUNTIFS('Checklist'!$F$2:$F$52,$B26,'Checklist'!$H$2:$H$52,"<>Done",'Checklist'!$H$2:$H$52,"<>N/A") | F26: =IFERROR(D26/(C26-COUNTIFS('Checklist'!$F$2:$F$52,$B26,'Checklist'!$H$2:$H$52,"N/A")),0)
B28: Brand SERP, facts and actions
B29: Results logged | C29: =COUNTA('Brand SERP log'!$G$3:$G$302)
B30: Owned site or official profile | C30: =COUNTIF('Brand SERP log'!$G$3:$G$302,"Owned site")+COUNTIF('Brand SERP log'!$G$3:$G$302,"Official profile")
B31: Owned share of logged results | C31: =IFERROR(C30/C29,0)
B32: Negative third-party results | C32: =COUNTIF('Brand SERP log'!$G$3:$G$302,"Third party: negative")
B33: Results with inaccurate information | C33: =COUNTIF('Brand SERP log'!$I$3:$I$302,"No")+COUNTIF('Brand SERP log'!$I$3:$I$302,"Partly")
B34: Fact-sheet mismatches (all platforms) | C34: =SUM('Fact sheet'!L3:L22)
B35: Facts with at least one mismatch | C35: =COUNTIF('Fact sheet'!L3:L22,">0")
B36: Action plan items done | C36: =COUNTIF('Action plan'!$H$3:$H$22,"Done")&" of "&COUNTA('Action plan'!$B$3:$B$22)
