Workbook

Sheet Start here
A1: Topical Map Template + Generator (EAV-based)
A2: Entity → attributes → values → pillar, cluster and supporting pages · by Lazarina Stoy · MLforSEO
A4: What it does
A5: You describe one central entity, the attributes people use to describe or filter it, and the values each attribute takes.
A6: The Topical Map tab turns that into a pillar page, one cluster (hub) page per attribute and one supporting page per value,
A7: with a suggested title, slug, intent, format, internal links (up, across and down), coverage against your existing URLs
A8: and a priority score. Combinations crosses two attributes for long-tail ideas.
A10: EAV (entity, attribute, variable or value) is a data-modelling pattern borrowed from database design. I use it here as a
A11: planning lens: a structured way to list what your audience wants to know about an entity and to spot gaps. It is not a
A12: claim about how any search engine ranks pages.
A14: How to use it
A15: 1. Entity: name the central entity and adjust the three title patterns ({entity}, {attribute}, {value}).
... A32: Legend
A33: Dark header | B33: Input column: paste or type here.
A34: Purple header | B34: Calculated column: formulas, please don't type over them.
A35: Lavender band | B35: Readability banding and paste zones.
A36: Yellow cell | B36: A flag that needs a human look, or an editable setting.
A37: Soft red | B37: A stronger warning (for example cannibalisation or a prune decision).
A38: Credits
A39: Template by Lazarina Stoy · MLforSEO (mlforseo.com). Free to use and adapt; please keep this credit.
A40: Read: What is the EAV model in SEO? (MLforSEO)
A41: Course: Semantic ML-enabled Keyword Research (MLforSEO Academy)
A42: Read: What does a good semantic keyword universe look like? (MLforSEO)
A43: Read: What is a knowledge graph? How to use it for keyword strategy (MLforSEO)

Sheet Entity
A1: 1. Entity: start with one central entity
A2: Yellow cells are yours. Patterns use {entity}, {attribute} and {value} as placeholders.
A3: Central entity | B3: Running shoes | C3: The one entity the map is about: your main product category, service or topic.
A4: Entity type | B4: Product | C4: Person, Place, Organisation, Product, Event, Creative work or Concept.
A5: Site root URL | B5: https://www.stride-example.com/ | C5: Used only for reference.
A6: Pillar page URL (if it exists) | B6: https://www.stride-example.com/running-shoes/ | C6: Leave blank if the pillar is still a gap.
A7: Pillar title pattern | B7: {entity}: the complete guide | C7: {entity} is replaced by the central entity.
A8: Cluster title pattern (default) | B8: {entity} by {attribute} | C8: Used when an attribute has no cluster title of its own.
A9: Supporting title pattern (default) | B9: {entity} for {value} | C9: Used when an attribute has no pattern of its own.
A10: Audience / notes | B10: Recreational and club runners in the UK
A13: Calculated
A14: Attributes included | B14: =MAX(Attributes!$P$3:$P$52)
A15: Values kept | B15: =MAX(Values!$J$3:$J$502)
A16: Rows on the topical map | B16: =1+B14+B15

Sheet Attributes
A1: 2. ATTRIBUTES: the ways people describe or filter the entity | K1: SAMPLE: fictional running shoe shop. Clear A-J and add your own.
A2: Attribute | B2: Attribute type | C2: Cutoff rule | D2: Typical intent | E2: Business relevance (1-3) | F2: Include? | G2: Cluster page title (optional) | H2: Supporting title pattern (optional) | I2: Cluster / hub page URL (if it exists) | J2: Notes | K2: Values listed | L2: Values kept | M2: Values covered | N2: Coverage | O2: Check | P2: Map order (helper)
A3: Terrain | B3: Finite | D3: Commercial | E3: 3 | F3: Yes | H3: {value} {entity} | K3: =IF(A3="","",COUNTIF(Values!$A$3:$A$502,SUBSTITUTE(SUBSTITUTE(A3,"?","~?"),"*","~*"))) | L3: =IF(A3="","",COUNTIFS(Values!$A$3:$A$502,SUBSTITUTE(SUBSTITUTE(A3,"?","~?"),"*","~*"),Values!$I$3:$I$502,"Yes")) | M3: =IF(A3="","",SUMPRODUCT((Values!$A$3:$A$502=A3)*(Values!$I$3:$I$502="Yes")*(LEN(Values!$F$3:$F$502)>0))) | N3: =IF(A3="","",IF(L3=0,"",M3/L3)) | O3: =IF(A3="","",IF(AND(B3="Infinite",F3="Yes"),"Infinite attribute included: add a cutoff or exclude it",IF(AND(B3="Finite with a cutoff",C3=""),"Add the cutoff rule",IF(AND(F3="Yes",L3=0),"No values kept yet","")))) | P3: =IF(AND(A3<>"",F3="Yes"),SUMPRODUCT(($F$3:F3="Yes")*(LEN($A$3:A3)>0)),"")
A4: Distance | B4: Finite | D4: Commercial | E4: 3 | F4: Yes | H4: {entity} for {value} | K4: =IF(A4="","",COUNTIF(Values!$A$3:$A$502,SUBSTITUTE(SUBSTITUTE(A4,"?","~?"),"*","~*"))) | L4: =IF(A4="","",COUNTIFS(Values!$A$3:$A$502,SUBSTITUTE(SUBSTITUTE(A4,"?","~?"),"*","~*"),Values!$I$3:$I$502,"Yes")) | M4: =IF(A4="","",SUMPRODUCT((Values!$A$3:$A$502=A4)*(Values!$I$3:$I$502="Yes")*(LEN(Values!$F$3:$F$502)>0))) | N4: =IF(A4="","",IF(L4=0,"",M4/L4)) | O4: =IF(A4="","",IF(AND(B4="Infinite",F4="Yes"),"Infinite attribute included: add a cutoff or exclude it",IF(AND(B4="Finite with a cutoff",C4=""),"Add the cutoff rule",IF(AND(F4="Yes",L4=0),"No values kept yet","")))) | P4: =IF(AND(A4<>"",F4="Yes"),SUMPRODUCT(($F$3:F4="Yes")*(LEN($A$3:A4)>0)),"")
A5: Foot type | B5: Finite | D5: Commercial | E5: 3 | F5: Yes | G5: Running shoes for every foot type | H5: {entity} for {value} | K5: =IF(A5="","",COUNTIF(Values!$A$3:$A$502,SUBSTITUTE(SUBSTITUTE(A5,"?","~?"),"*","~*"))) | L5: =IF(A5="","",COUNTIFS(Values!$A$3:$A$502,SUBSTITUTE(SUBSTITUTE(A5,"?","~?"),"*","~*"),Values!$I$3:$I$502,"Yes")) | M5: =IF(A5="","",SUMPRODUCT((Values!$A$3:$A$502=A5)*(Values!$I$3:$I$502="Yes")*(LEN(Values!$F$3:$F$502)>0))) | N5: =IF(A5="","",IF(L5=0,"",M5/L5)) | O5: =IF(A5="","",IF(AND(B5="Infinite",F5="Yes"),"Infinite attribute included: add a cutoff or exclude it",IF(AND(B5="Finite with a cutoff",C5=""),"Add the cutoff rule",IF(AND(F5="Yes",L5=0),"No values kept yet","")))) | P5: =IF(AND(A5<>"",F5="Yes"),SUMPRODUCT(($F$3:F5="Yes")*(LEN($A$3:A5)>0)),"")
A6: Cushioning | B6: Finite | D6: Informational | E6: 2 | F6: Yes | H6: {value} {entity} | K6: =IF(A6="","",COUNTIF(Values!$A$3:$A$502,SUBSTITUTE(SUBSTITUTE(A6,"?","~?"),"*","~*"))) | L6: =IF(A6="","",COUNTIFS(Values!$A$3:$A$502,SUBSTITUTE(SUBSTITUTE(A6,"?","~?"),"*","~*"),Values!$I$3:$I$502,"Yes")) | M6: =IF(A6="","",SUMPRODUCT((Values!$A$3:$A$502=A6)*(Values!$I$3:$I$502="Yes")*(LEN(Values!$F$3:$F$502)>0))) | N6: =IF(A6="","",IF(L6=0,"",M6/L6)) | O6: =IF(A6="","",IF(AND(B6="Infinite",F6="Yes"),"Infinite attribute included: add a cutoff or exclude it",IF(AND(B6="Finite with a cutoff",C6=""),"Add the cutoff rule",IF(AND(F6="Yes",L6=0),"No values kept yet","")))) | P6: =IF(AND(A6<>"",F6="Yes"),SUMPRODUCT(($F$3:F6="Yes")*(LEN($A$3:A6)>0)),"")
A7: Brand | B7: Finite with a cutoff | C7: Brands we stock (12) | D7: Commercial | E7: 2 | F7: Yes | G7: Running shoe brands | H7: {value} {entity} | I7: https://www.stride-example.com/brands/ | K7: =IF(A7="","",COUNTIF(Values!$A$3:$A$502,SUBSTITUTE(SUBSTITUTE(A7,"?","~?"),"*","~*"))) | L7: =IF(A7="","",COUNTIFS(Values!$A$3:$A$502,SUBSTITUTE(SUBSTITUTE(A7,"?","~?"),"*","~*"),Values!$I$3:$I$502,"Yes")) | M7: =IF(A7="","",SUMPRODUCT((Values!$A$3:$A$502=A7)*(Values!$I$3:$I$502="Yes")*(LEN(Values!$F$3:$F$502)>0))) | N7: =IF(A7="","",IF(L7=0,"",M7/L7)) | O7: =IF(A7="","",IF(AND(B7="Infinite",F7="Yes"),"Infinite attribute included: add a cutoff or exclude it",IF(AND(B7="Finite with a cutoff",C7=""),"Add the cutoff rule",IF(AND(F7="Yes",L7=0),"No values kept yet","")))) | P7: =IF(AND(A7<>"",F7="Yes"),SUMPRODUCT(($F$3:F7="Yes")*(LEN($A$3:A7)>0)),"")
A8: Runner level | B8: Finite | D8: Informational | E8: 2 | F8: Yes | H8: {entity} for {value} | K8: =IF(A8="","",COUNTIF(Values!$A$3:$A$502,SUBSTITUTE(SUBSTITUTE(A8,"?","~?"),"*","~*"))) | L8: =IF(A8="","",COUNTIFS(Values!$A$3:$A$502,SUBSTITUTE(SUBSTITUTE(A8,"?","~?"),"*","~*"),Values!$I$3:$I$502,"Yes")) | M8: =IF(A8="","",SUMPRODUCT((Values!$A$3:$A$502=A8)*(Values!$I$3:$I$502="Yes")*(LEN(Values!$F$3:$F$502)>0))) | N8: =IF(A8="","",IF(L8=0,"",M8/L8)) | O8: =IF(A8="","",IF(AND(B8="Infinite",F8="Yes"),"Infinite attribute included: add a cutoff or exclude it",IF(AND(B8="Finite with a cutoff",C8=""),"Add the cutoff rule",IF(AND(F8="Yes",L8=0),"No values kept yet","")))) | P8: =IF(AND(A8<>"",F8="Yes"),SUMPRODUCT(($F$3:F8="Yes")*(LEN($A$3:A8)>0)),"")
A9: Price | B9: Finite with a cutoff | C9: Three bands: under £80, £80-£140, over £140 | D9: Transactional | E9: 1 | F9: Yes | H9: {entity} {value} | K9: =IF(A9="","",COUNTIF(Values!$A$3:$A$502,SUBSTITUTE(SUBSTITUTE(A9,"?","~?"),"*","~*"))) | L9: =IF(A9="","",COUNTIFS(Values!$A$3:$A$502,SUBSTITUTE(SUBSTITUTE(A9,"?","~?"),"*","~*"),Values!$I$3:$I$502,"Yes")) | M9: =IF(A9="","",SUMPRODUCT((Values!$A$3:$A$502=A9)*(Values!$I$3:$I$502="Yes")*(LEN(Values!$F$3:$F$502)>0))) | N9: =IF(A9="","",IF(L9=0,"",M9/L9)) | O9: =IF(A9="","",IF(AND(B9="Infinite",F9="Yes"),"Infinite attribute included: add a cutoff or exclude it",IF(AND(B9="Finite with a cutoff",C9=""),"Add the cutoff rule",IF(AND(F9="Yes",L9=0),"No values kept yet","")))) | P9: =IF(AND(A9<>"",F9="Yes"),SUMPRODUCT(($F$3:F9="Yes")*(LEN($A$3:A9)>0)),"")
A10: Runner name | B10: Infinite | D10: Navigational | E10: 1 | F10: No | J10: Excluded: a page per runner has no reason to exist | K10: =IF(A10="","",COUNTIF(Values!$A$3:$A$502,SUBSTITUTE(SUBSTITUTE(A10,"?","~?"),"*","~*"))) | L10: =IF(A10="","",COUNTIFS(Values!$A$3:$A$502,SUBSTITUTE(SUBSTITUTE(A10,"?","~?"),"*","~*"),Values!$I$3:$I$502,"Yes")) | M10: =IF(A10="","",SUMPRODUCT((Values!$A$3:$A$502=A10)*(Values!$I$3:$I$502="Yes")*(LEN(Values!$F$3:$F$502)>0))) | N10: =IF(A10="","",IF(L10=0,"",M10/L10)) | O10: =IF(A10="","",IF(AND(B10="Infinite",F10="Yes"),"Infinite attribute included: add a cutoff or exclude it",IF(AND(B10="Finite with a cutoff",C10=""),"Add the cutoff rule",IF(AND(F10="Yes",L10=0),"No values kept yet","")))) | P10: =IF(AND(A10<>"",F10="Yes"),SUMPRODUCT(($F$3:F10="Yes")*(LEN($A$3:A10)>0)),"")
K11: =IF(A11="","",COUNTIF(Values!$A$3:$A$502,SUBSTITUTE(SUBSTITUTE(A11,"?","~?"),"*","~*"))) | L11: =IF(A11="","",COUNTIFS(Values!$A$3:$A$502,SUBSTITUTE(SUBSTITUTE(A11,"?","~?"),"*","~*"),Values!$I$3:$I$502,"Yes")) | M11: =IF(A11="","",SUMPRODUCT((Values!$A$3:$A$502=A11)*(Values!$I$3:$I$502="Yes")*(LEN(Values!$F$3:$F$502)>0))) | N11: =IF(A11="","",IF(L11=0,"",M11/L11)) | O11: =IF(A11="","",IF(AND(B11="Infinite",F11="Yes"),"Infinite attribute included: add a cutoff or exclude it",IF(AND(B11="Finite with a cutoff",C11=""),"Add the cutoff rule",IF(AND(F11="Yes",L11=0),"No values kept yet","")))) | P11: =IF(AND(A11<>"",F11="Yes"),SUMPRODUCT(($F$3:F11="Yes")*(LEN($A$3:A11)>0)),"")
K12: =IF(A12="","",COUNTIF(Values!$A$3:$A$502,SUBSTITUTE(SUBSTITUTE(A12,"?","~?"),"*","~*"))) | L12: =IF(A12="","",COUNTIFS(Values!$A$3:$A$502,SUBSTITUTE(SUBSTITUTE(A12,"?","~?"),"*","~*"),Values!$I$3:$I$502,"Yes")) | M12: =IF(A12="","",SUMPRODUCT((Values!$A$3:$A$502=A12)*(Values!$I$3:$I$502="Yes")*(LEN(Values!$F$3:$F$502)>0))) | N12: =IF(A12="","",IF(L12=0,"",M12/L12)) | O12: =IF(A12="","",IF(AND(B12="Infinite",F12="Yes"),"Infinite attribute included: add a cutoff or exclude it",IF(AND(B12="Finite with a cutoff",C12=""),"Add the cutoff rule",IF(AND(F12="Yes",L12=0),"No values kept yet","")))) | P12: =IF(AND(A12<>"",F12="Yes"),SUMPRODUCT(($F$3:F12="Yes")*(LEN($A$3:A12)>0)),"")
K13: =IF(A13="","",COUNTIF(Values!$A$3:$A$502,SUBSTITUTE(SUBSTITUTE(A13,"?","~?"),"*","~*"))) | L13: =IF(A13="","",COUNTIFS(Values!$A$3:$A$502,SUBSTITUTE(SUBSTITUTE(A13,"?","~?"),"*","~*"),Values!$I$3:$I$502,"Yes")) | M13: =IF(A13="","",SUMPRODUCT((Values!$A$3:$A$502=A13)*(Values!$I$3:$I$502="Yes")*(LEN(Values!$F$3:$F$502)>0))) | N13: =IF(A13="","",IF(L13=0,"",M13/L13)) | O13: =IF(A13="","",IF(AND(B13="Infinite",F13="Yes"),"Infinite attribute included: add a cutoff or exclude it",IF(AND(B13="Finite with a cutoff",C13=""),"Add the cutoff rule",IF(AND(F13="Yes",L13=0),"No values kept yet","")))) | P13: =IF(AND(A13<>"",F13="Yes"),SUMPRODUCT(($F$3:F13="Yes")*(LEN($A$3:A13)>0)),"")
K14: =IF(A14="","",COUNTIF(Values!$A$3:$A$502,SUBSTITUTE(SUBSTITUTE(A14,"?","~?"),"*","~*"))) | L14: =IF(A14="","",COUNTIFS(Values!$A$3:$A$502,SUBSTITUTE(SUBSTITUTE(A14,"?","~?"),"*","~*"),Values!$I$3:$I$502,"Yes")) | M14: =IF(A14="","",SUMPRODUCT((Values!$A$3:$A$502=A14)*(Values!$I$3:$I$502="Yes")*(LEN(Values!$F$3:$F$502)>0))) | N14: =IF(A14="","",IF(L14=0,"",M14/L14)) | O14: =IF(A14="","",IF(AND(B14="Infinite",F14="Yes"),"Infinite attribute included: add a cutoff or exclude it",IF(AND(B14="Finite with a cutoff",C14=""),"Add the cutoff rule",IF(AND(F14="Yes",L14=0),"No values kept yet","")))) | P14: =IF(AND(A14<>"",F14="Yes"),SUMPRODUCT(($F$3:F14="Yes")*(LEN($A$3:A14)>0)),"")
K15: =IF(A15="","",COUNTIF(Values!$A$3:$A$502,SUBSTITUTE(SUBSTITUTE(A15,"?","~?"),"*","~*"))) | L15: =IF(A15="","",COUNTIFS(Values!$A$3:$A$502,SUBSTITUTE(SUBSTITUTE(A15,"?","~?"),"*","~*"),Values!$I$3:$I$502,"Yes")) | M15: =IF(A15="","",SUMPRODUCT((Values!$A$3:$A$502=A15)*(Values!$I$3:$I$502="Yes")*(LEN(Values!$F$3:$F$502)>0))) | N15: =IF(A15="","",IF(L15=0,"",M15/L15)) | O15: =IF(A15="","",IF(AND(B15="Infinite",F15="Yes"),"Infinite attribute included: add a cutoff or exclude it",IF(AND(B15="Finite with a cutoff",C15=""),"Add the cutoff rule",IF(AND(F15="Yes",L15=0),"No values kept yet","")))) | P15: =IF(AND(A15<>"",F15="Yes"),SUMPRODUCT(($F$3:F15="Yes")*(LEN($A$3:A15)>0)),"")
K16: =IF(A16="","",COUNTIF(Values!$A$3:$A$502,SUBSTITUTE(SUBSTITUTE(A16,"?","~?"),"*","~*"))) | L16: =IF(A16="","",COUNTIFS(Values!$A$3:$A$502,SUBSTITUTE(SUBSTITUTE(A16,"?","~?"),"*","~*"),Values!$I$3:$I$502,"Yes")) | M16: =IF(A16="","",SUMPRODUCT((Values!$A$3:$A$502=A16)*(Values!$I$3:$I$502="Yes")*(LEN(Values!$F$3:$F$502)>0))) | N16: =IF(A16="","",IF(L16=0,"",M16/L16)) | O16: =IF(A16="","",IF(AND(B16="Infinite",F16="Yes"),"Infinite attribute included: add a cutoff or exclude it",IF(AND(B16="Finite with a cutoff",C16=""),"Add the cutoff rule",IF(AND(F16="Yes",L16=0),"No values kept yet","")))) | P16: =IF(AND(A16<>"",F16="Yes"),SUMPRODUCT(($F$3:F16="Yes")*(LEN($A$3:A16)>0)),"")
K17: =IF(A17="","",COUNTIF(Values!$A$3:$A$502,SUBSTITUTE(SUBSTITUTE(A17,"?","~?"),"*","~*"))) | L17: =IF(A17="","",COUNTIFS(Values!$A$3:$A$502,SUBSTITUTE(SUBSTITUTE(A17,"?","~?"),"*","~*"),Values!$I$3:$I$502,"Yes")) | M17: =IF(A17="","",SUMPRODUCT((Values!$A$3:$A$502=A17)*(Values!$I$3:$I$502="Yes")*(LEN(Values!$F$3:$F$502)>0))) | N17: =IF(A17="","",IF(L17=0,"",M17/L17)) | O17: =IF(A17="","",IF(AND(B17="Infinite",F17="Yes"),"Infinite attribute included: add a cutoff or exclude it",IF(AND(B17="Finite with a cutoff",C17=""),"Add the cutoff rule",IF(AND(F17="Yes",L17=0),"No values kept yet","")))) | P17: =IF(AND(A17<>"",F17="Yes"),SUMPRODUCT(($F$3:F17="Yes")*(LEN($A$3:A17)>0)),"")
K18: =IF(A18="","",COUNTIF(Values!$A$3:$A$502,SUBSTITUTE(SUBSTITUTE(A18,"?","~?"),"*","~*"))) | L18: =IF(A18="","",COUNTIFS(Values!$A$3:$A$502,SUBSTITUTE(SUBSTITUTE(A18,"?","~?"),"*","~*"),Values!$I$3:$I$502,"Yes")) | M18: =IF(A18="","",SUMPRODUCT((Values!$A$3:$A$502=A18)*(Values!$I$3:$I$502="Yes")*(LEN(Values!$F$3:$F$502)>0))) | N18: =IF(A18="","",IF(L18=0,"",M18/L18)) | O18: =IF(A18="","",IF(AND(B18="Infinite",F18="Yes"),"Infinite attribute included: add a cutoff or exclude it",IF(AND(B18="Finite with a cutoff",C18=""),"Add the cutoff rule",IF(AND(F18="Yes",L18=0),"No values kept yet","")))) | P18: =IF(AND(A18<>"",F18="Yes"),SUMPRODUCT(($F$3:F18="Yes")*(LEN($A$3:A18)>0)),"")
K19: =IF(A19="","",COUNTIF(Values!$A$3:$A$502,SUBSTITUTE(SUBSTITUTE(A19,"?","~?"),"*","~*"))) | L19: =IF(A19="","",COUNTIFS(Values!$A$3:$A$502,SUBSTITUTE(SUBSTITUTE(A19,"?","~?"),"*","~*"),Values!$I$3:$I$502,"Yes")) | M19: =IF(A19="","",SUMPRODUCT((Values!$A$3:$A$502=A19)*(Values!$I$3:$I$502="Yes")*(LEN(Values!$F$3:$F$502)>0))) | N19: =IF(A19="","",IF(L19=0,"",M19/L19)) | O19: =IF(A19="","",IF(AND(B19="Infinite",F19="Yes"),"Infinite attribute included: add a cutoff or exclude it",IF(AND(B19="Finite with a cutoff",C19=""),"Add the cutoff rule",IF(AND(F19="Yes",L19=0),"No values kept yet","")))) | P19: =IF(AND(A19<>"",F19="Yes"),SUMPRODUCT(($F$3:F19="Yes")*(LEN($A$3:A19)>0)),"")
K20: =IF(A20="","",COUNTIF(Values!$A$3:$A$502,SUBSTITUTE(SUBSTITUTE(A20,"?","~?"),"*","~*"))) | L20: =IF(A20="","",COUNTIFS(Values!$A$3:$A$502,SUBSTITUTE(SUBSTITUTE(A20,"?","~?"),"*","~*"),Values!$I$3:$I$502,"Yes")) | M20: =IF(A20="","",SUMPRODUCT((Values!$A$3:$A$502=A20)*(Values!$I$3:$I$502="Yes")*(LEN(Values!$F$3:$F$502)>0))) | N20: =IF(A20="","",IF(L20=0,"",M20/L20)) | O20: =IF(A20="","",IF(AND(B20="Infinite",F20="Yes"),"Infinite attribute included: add a cutoff or exclude it",IF(AND(B20="Finite with a cutoff",C20=""),"Add the cutoff rule",IF(AND(F20="Yes",L20=0),"No values kept yet","")))) | P20: =IF(AND(A20<>"",F20="Yes"),SUMPRODUCT(($F$3:F20="Yes")*(LEN($A$3:A20)>0)),"")
K21: =IF(A21="","",COUNTIF(Values!$A$3:$A$502,SUBSTITUTE(SUBSTITUTE(A21,"?","~?"),"*","~*"))) | L21: =IF(A21="","",COUNTIFS(Values!$A$3:$A$502,SUBSTITUTE(SUBSTITUTE(A21,"?","~?"),"*","~*"),Values!$I$3:$I$502,"Yes")) | M21: =IF(A21="","",SUMPRODUCT((Values!$A$3:$A$502=A21)*(Values!$I$3:$I$502="Yes")*(LEN(Values!$F$3:$F$502)>0))) | N21: =IF(A21="","",IF(L21=0,"",M21/L21)) | O21: =IF(A21="","",IF(AND(B21="Infinite",F21="Yes"),"Infinite attribute included: add a cutoff or exclude it",IF(AND(B21="Finite with a cutoff",C21=""),"Add the cutoff rule",IF(AND(F21="Yes",L21=0),"No values kept yet","")))) | P21: =IF(AND(A21<>"",F21="Yes"),SUMPRODUCT(($F$3:F21="Yes")*(LEN($A$3:A21)>0)),"")
K22: =IF(A22="","",COUNTIF(Values!$A$3:$A$502,SUBSTITUTE(SUBSTITUTE(A22,"?","~?"),"*","~*"))) | L22: =IF(A22="","",COUNTIFS(Values!$A$3:$A$502,SUBSTITUTE(SUBSTITUTE(A22,"?","~?"),"*","~*"),Values!$I$3:$I$502,"Yes")) | M22: =IF(A22="","",SUMPRODUCT((Values!$A$3:$A$502=A22)*(Values!$I$3:$I$502="Yes")*(LEN(Values!$F$3:$F$502)>0))) | N22: =IF(A22="","",IF(L22=0,"",M22/L22)) | O22: =IF(A22="","",IF(AND(B22="Infinite",F22="Yes"),"Infinite attribute included: add a cutoff or exclude it",IF(AND(B22="Finite with a cutoff",C22=""),"Add the cutoff rule",IF(AND(F22="Yes",L22=0),"No values kept yet","")))) | P22: =IF(AND(A22<>"",F22="Yes"),SUMPRODUCT(($F$3:F22="Yes")*(LEN($A$3:A22)>0)),"")
... K52: =IF(A52="","",COUNTIF(Values!$A$3:$A$502,SUBSTITUTE(SUBSTITUTE(A52,"?","~?"),"*","~*"))) | L52: =IF(A52="","",COUNTIFS(Values!$A$3:$A$502,SUBSTITUTE(SUBSTITUTE(A52,"?","~?"),"*","~*"),Values!$I$3:$I$502,"Yes")) | M52: =IF(A52="","",SUMPRODUCT((Values!$A$3:$A$502=A52)*(Values!$I$3:$I$502="Yes")*(LEN(Values!$F$3:$F$502)>0))) | N52: =IF(A52="","",IF(L52=0,"",M52/L52)) | O52: =IF(A52="","",IF(AND(B52="Infinite",F52="Yes"),"Infinite attribute included: add a cutoff or exclude it",IF(AND(B52="Finite with a cutoff",C52=""),"Add the cutoff rule",IF(AND(F52="Yes",L52=0),"No values kept yet","")))) | P52: =IF(AND(A52<>"",F52="Yes"),SUMPRODUCT(($F$3:F52="Yes")*(LEN($A$3:A52)>0)),"")

Sheet Values
A1: 3. VALUES: the specific values each attribute takes (sub-entities welcome) | H1: SAMPLE values. Clear A-G and add your own (one value per row).
A2: Attribute | B2: Value / sub-entity | C2: Is it an entity itself? | D2: Real user benefit? | E2: Search volume (optional) | F2: Existing URL (coverage) | G2: Notes | H2: Attribute included? | I2: Keep? | J2: Map order (helper) | K2: Position in attribute | L2: Key (helper) | M2: Kept in attribute | N2: Sibling value | O2: Sibling map order (helper)
A3: Terrain | B3: road | C3: No | D3: Yes | E3: 6600 | F3: https://www.stride-example.com/road-running-shoes/ | H3: =IF(A3="","",IFERROR(INDEX(Attributes!$F$3:$F$52,MATCH(A3,Attributes!$A$3:$A$52,0))&"","Unknown attribute")) | I3: =IF(OR(A3="",B3=""),"",IF(AND(H3="Yes",D3<>"No"),"Yes","No")) | J3: =IF(I3="Yes",COUNTIF($I$3:I3,"Yes"),"") | K3: =IF(I3<>"Yes","",COUNTIFS($A$3:A3,SUBSTITUTE(SUBSTITUTE(A3,"?","~?"),"*","~*"),$I$3:I3,"Yes")) | L3: =IF(K3="","",A3&"|"&K3) | M3: =IF(I3<>"Yes","",COUNTIFS(Values!$A$3:$A$502,SUBSTITUTE(SUBSTITUTE(A3,"?","~?"),"*","~*"),Values!$I$3:$I$502,"Yes")) | N3: =IF(I3<>"Yes","",IF(M3<2,"",INDEX(Values!$B$3:$B$502,MATCH(A3&"|"&IF(K3=M3,1,K3+1),Values!$L$3:$L$502,0)))) | O3: =IF(N3="","",INDEX(Values!$J$3:$J$502,MATCH(A3&"|"&IF(K3=M3,1,K3+1),Values!$L$3:$L$502,0)))
A4: Terrain | B4: trail | C4: No | D4: Yes | E4: 9900 | F4: https://www.stride-example.com/trail-running-shoes/ | H4: =IF(A4="","",IFERROR(INDEX(Attributes!$F$3:$F$52,MATCH(A4,Attributes!$A$3:$A$52,0))&"","Unknown attribute")) | I4: =IF(OR(A4="",B4=""),"",IF(AND(H4="Yes",D4<>"No"),"Yes","No")) | J4: =IF(I4="Yes",COUNTIF($I$3:I4,"Yes"),"") | K4: =IF(I4<>"Yes","",COUNTIFS($A$3:A4,SUBSTITUTE(SUBSTITUTE(A4,"?","~?"),"*","~*"),$I$3:I4,"Yes")) | L4: =IF(K4="","",A4&"|"&K4) | M4: =IF(I4<>"Yes","",COUNTIFS(Values!$A$3:$A$502,SUBSTITUTE(SUBSTITUTE(A4,"?","~?"),"*","~*"),Values!$I$3:$I$502,"Yes")) | N4: =IF(I4<>"Yes","",IF(M4<2,"",INDEX(Values!$B$3:$B$502,MATCH(A4&"|"&IF(K4=M4,1,K4+1),Values!$L$3:$L$502,0)))) | O4: =IF(N4="","",INDEX(Values!$J$3:$J$502,MATCH(A4&"|"&IF(K4=M4,1,K4+1),Values!$L$3:$L$502,0)))
A5: Terrain | B5: track | C5: No | D5: Yes | E5: 320 | H5: =IF(A5="","",IFERROR(INDEX(Attributes!$F$3:$F$52,MATCH(A5,Attributes!$A$3:$A$52,0))&"","Unknown attribute")) | I5: =IF(OR(A5="",B5=""),"",IF(AND(H5="Yes",D5<>"No"),"Yes","No")) | J5: =IF(I5="Yes",COUNTIF($I$3:I5,"Yes"),"") | K5: =IF(I5<>"Yes","",COUNTIFS($A$3:A5,SUBSTITUTE(SUBSTITUTE(A5,"?","~?"),"*","~*"),$I$3:I5,"Yes")) | L5: =IF(K5="","",A5&"|"&K5) | M5: =IF(I5<>"Yes","",COUNTIFS(Values!$A$3:$A$502,SUBSTITUTE(SUBSTITUTE(A5,"?","~?"),"*","~*"),Values!$I$3:$I$502,"Yes")) | N5: =IF(I5<>"Yes","",IF(M5<2,"",INDEX(Values!$B$3:$B$502,MATCH(A5&"|"&IF(K5=M5,1,K5+1),Values!$L$3:$L$502,0)))) | O5: =IF(N5="","",INDEX(Values!$J$3:$J$502,MATCH(A5&"|"&IF(K5=M5,1,K5+1),Values!$L$3:$L$502,0)))
A6: Terrain | B6: treadmill | C6: No | D6: Unsure | E6: 590 | G6: Check the SERP: mostly treadmill reviews? | H6: =IF(A6="","",IFERROR(INDEX(Attributes!$F$3:$F$52,MATCH(A6,Attributes!$A$3:$A$52,0))&"","Unknown attribute")) | I6: =IF(OR(A6="",B6=""),"",IF(AND(H6="Yes",D6<>"No"),"Yes","No")) | J6: =IF(I6="Yes",COUNTIF($I$3:I6,"Yes"),"") | K6: =IF(I6<>"Yes","",COUNTIFS($A$3:A6,SUBSTITUTE(SUBSTITUTE(A6,"?","~?"),"*","~*"),$I$3:I6,"Yes")) | L6: =IF(K6="","",A6&"|"&K6) | M6: =IF(I6<>"Yes","",COUNTIFS(Values!$A$3:$A$502,SUBSTITUTE(SUBSTITUTE(A6,"?","~?"),"*","~*"),Values!$I$3:$I$502,"Yes")) | N6: =IF(I6<>"Yes","",IF(M6<2,"",INDEX(Values!$B$3:$B$502,MATCH(A6&"|"&IF(K6=M6,1,K6+1),Values!$L$3:$L$502,0)))) | O6: =IF(N6="","",INDEX(Values!$J$3:$J$502,MATCH(A6&"|"&IF(K6=M6,1,K6+1),Values!$L$3:$L$502,0)))
A7: Distance | B7: 5K | C7: No | D7: Yes | E7: 210 | H7: =IF(A7="","",IFERROR(INDEX(Attributes!$F$3:$F$52,MATCH(A7,Attributes!$A$3:$A$52,0))&"","Unknown attribute")) | I7: =IF(OR(A7="",B7=""),"",IF(AND(H7="Yes",D7<>"No"),"Yes","No")) | J7: =IF(I7="Yes",COUNTIF($I$3:I7,"Yes"),"") | K7: =IF(I7<>"Yes","",COUNTIFS($A$3:A7,SUBSTITUTE(SUBSTITUTE(A7,"?","~?"),"*","~*"),$I$3:I7,"Yes")) | L7: =IF(K7="","",A7&"|"&K7) | M7: =IF(I7<>"Yes","",COUNTIFS(Values!$A$3:$A$502,SUBSTITUTE(SUBSTITUTE(A7,"?","~?"),"*","~*"),Values!$I$3:$I$502,"Yes")) | N7: =IF(I7<>"Yes","",IF(M7<2,"",INDEX(Values!$B$3:$B$502,MATCH(A7&"|"&IF(K7=M7,1,K7+1),Values!$L$3:$L$502,0)))) | O7: =IF(N7="","",INDEX(Values!$J$3:$J$502,MATCH(A7&"|"&IF(K7=M7,1,K7+1),Values!$L$3:$L$502,0)))
A8: Distance | B8: half marathon | C8: No | D8: Yes | E8: 480 | H8: =IF(A8="","",IFERROR(INDEX(Attributes!$F$3:$F$52,MATCH(A8,Attributes!$A$3:$A$52,0))&"","Unknown attribute")) | I8: =IF(OR(A8="",B8=""),"",IF(AND(H8="Yes",D8<>"No"),"Yes","No")) | J8: =IF(I8="Yes",COUNTIF($I$3:I8,"Yes"),"") | K8: =IF(I8<>"Yes","",COUNTIFS($A$3:A8,SUBSTITUTE(SUBSTITUTE(A8,"?","~?"),"*","~*"),$I$3:I8,"Yes")) | L8: =IF(K8="","",A8&"|"&K8) | M8: =IF(I8<>"Yes","",COUNTIFS(Values!$A$3:$A$502,SUBSTITUTE(SUBSTITUTE(A8,"?","~?"),"*","~*"),Values!$I$3:$I$502,"Yes")) | N8: =IF(I8<>"Yes","",IF(M8<2,"",INDEX(Values!$B$3:$B$502,MATCH(A8&"|"&IF(K8=M8,1,K8+1),Values!$L$3:$L$502,0)))) | O8: =IF(N8="","",INDEX(Values!$J$3:$J$502,MATCH(A8&"|"&IF(K8=M8,1,K8+1),Values!$L$3:$L$502,0)))
A9: Distance | B9: marathon | C9: No | D9: Yes | E9: 2400 | F9: https://www.stride-example.com/marathon-running-shoes/ | H9: =IF(A9="","",IFERROR(INDEX(Attributes!$F$3:$F$52,MATCH(A9,Attributes!$A$3:$A$52,0))&"","Unknown attribute")) | I9: =IF(OR(A9="",B9=""),"",IF(AND(H9="Yes",D9<>"No"),"Yes","No")) | J9: =IF(I9="Yes",COUNTIF($I$3:I9,"Yes"),"") | K9: =IF(I9<>"Yes","",COUNTIFS($A$3:A9,SUBSTITUTE(SUBSTITUTE(A9,"?","~?"),"*","~*"),$I$3:I9,"Yes")) | L9: =IF(K9="","",A9&"|"&K9) | M9: =IF(I9<>"Yes","",COUNTIFS(Values!$A$3:$A$502,SUBSTITUTE(SUBSTITUTE(A9,"?","~?"),"*","~*"),Values!$I$3:$I$502,"Yes")) | N9: =IF(I9<>"Yes","",IF(M9<2,"",INDEX(Values!$B$3:$B$502,MATCH(A9&"|"&IF(K9=M9,1,K9+1),Values!$L$3:$L$502,0)))) | O9: =IF(N9="","",INDEX(Values!$J$3:$J$502,MATCH(A9&"|"&IF(K9=M9,1,K9+1),Values!$L$3:$L$502,0)))
A10: Distance | B10: ultramarathon | C10: No | D10: Yes | E10: 390 | H10: =IF(A10="","",IFERROR(INDEX(Attributes!$F$3:$F$52,MATCH(A10,Attributes!$A$3:$A$52,0))&"","Unknown attribute")) | I10: =IF(OR(A10="",B10=""),"",IF(AND(H10="Yes",D10<>"No"),"Yes","No")) | J10: =IF(I10="Yes",COUNTIF($I$3:I10,"Yes"),"") | K10: =IF(I10<>"Yes","",COUNTIFS($A$3:A10,SUBSTITUTE(SUBSTITUTE(A10,"?","~?"),"*","~*"),$I$3:I10,"Yes")) | L10: =IF(K10="","",A10&"|"&K10) | M10: =IF(I10<>"Yes","",COUNTIFS(Values!$A$3:$A$502,SUBSTITUTE(SUBSTITUTE(A10,"?","~?"),"*","~*"),Values!$I$3:$I$502,"Yes")) | N10: =IF(I10<>"Yes","",IF(M10<2,"",INDEX(Values!$B$3:$B$502,MATCH(A10&"|"&IF(K10=M10,1,K10+1),Values!$L$3:$L$502,0)))) | O10: =IF(N10="","",INDEX(Values!$J$3:$J$502,MATCH(A10&"|"&IF(K10=M10,1,K10+1),Values!$L$3:$L$502,0)))
A11: Foot type | B11: wide feet | C11: No | D11: Yes | E11: 1900 | F11: https://www.stride-example.com/wide-fit-running-shoes/ | H11: =IF(A11="","",IFERROR(INDEX(Attributes!$F$3:$F$52,MATCH(A11,Attributes!$A$3:$A$52,0))&"","Unknown attribute")) | I11: =IF(OR(A11="",B11=""),"",IF(AND(H11="Yes",D11<>"No"),"Yes","No")) | J11: =IF(I11="Yes",COUNTIF($I$3:I11,"Yes"),"") | K11: =IF(I11<>"Yes","",COUNTIFS($A$3:A11,SUBSTITUTE(SUBSTITUTE(A11,"?","~?"),"*","~*"),$I$3:I11,"Yes")) | L11: =IF(K11="","",A11&"|"&K11) | M11: =IF(I11<>"Yes","",COUNTIFS(Values!$A$3:$A$502,SUBSTITUTE(SUBSTITUTE(A11,"?","~?"),"*","~*"),Values!$I$3:$I$502,"Yes")) | N11: =IF(I11<>"Yes","",IF(M11<2,"",INDEX(Values!$B$3:$B$502,MATCH(A11&"|"&IF(K11=M11,1,K11+1),Values!$L$3:$L$502,0)))) | O11: =IF(N11="","",INDEX(Values!$J$3:$J$502,MATCH(A11&"|"&IF(K11=M11,1,K11+1),Values!$L$3:$L$502,0)))
A12: Foot type | B12: narrow feet | C12: No | D12: Yes | E12: 590 | H12: =IF(A12="","",IFERROR(INDEX(Attributes!$F$3:$F$52,MATCH(A12,Attributes!$A$3:$A$52,0))&"","Unknown attribute")) | I12: =IF(OR(A12="",B12=""),"",IF(AND(H12="Yes",D12<>"No"),"Yes","No")) | J12: =IF(I12="Yes",COUNTIF($I$3:I12,"Yes"),"") | K12: =IF(I12<>"Yes","",COUNTIFS($A$3:A12,SUBSTITUTE(SUBSTITUTE(A12,"?","~?"),"*","~*"),$I$3:I12,"Yes")) | L12: =IF(K12="","",A12&"|"&K12) | M12: =IF(I12<>"Yes","",COUNTIFS(Values!$A$3:$A$502,SUBSTITUTE(SUBSTITUTE(A12,"?","~?"),"*","~*"),Values!$I$3:$I$502,"Yes")) | N12: =IF(I12<>"Yes","",IF(M12<2,"",INDEX(Values!$B$3:$B$502,MATCH(A12&"|"&IF(K12=M12,1,K12+1),Values!$L$3:$L$502,0)))) | O12: =IF(N12="","",INDEX(Values!$J$3:$J$502,MATCH(A12&"|"&IF(K12=M12,1,K12+1),Values!$L$3:$L$502,0)))
A13: Foot type | B13: flat feet | C13: No | D13: Yes | E13: 1600 | H13: =IF(A13="","",IFERROR(INDEX(Attributes!$F$3:$F$52,MATCH(A13,Attributes!$A$3:$A$52,0))&"","Unknown attribute")) | I13: =IF(OR(A13="",B13=""),"",IF(AND(H13="Yes",D13<>"No"),"Yes","No")) | J13: =IF(I13="Yes",COUNTIF($I$3:I13,"Yes"),"") | K13: =IF(I13<>"Yes","",COUNTIFS($A$3:A13,SUBSTITUTE(SUBSTITUTE(A13,"?","~?"),"*","~*"),$I$3:I13,"Yes")) | L13: =IF(K13="","",A13&"|"&K13) | M13: =IF(I13<>"Yes","",COUNTIFS(Values!$A$3:$A$502,SUBSTITUTE(SUBSTITUTE(A13,"?","~?"),"*","~*"),Values!$I$3:$I$502,"Yes")) | N13: =IF(I13<>"Yes","",IF(M13<2,"",INDEX(Values!$B$3:$B$502,MATCH(A13&"|"&IF(K13=M13,1,K13+1),Values!$L$3:$L$502,0)))) | O13: =IF(N13="","",INDEX(Values!$J$3:$J$502,MATCH(A13&"|"&IF(K13=M13,1,K13+1),Values!$L$3:$L$502,0)))
A14: Foot type | B14: high arches | C14: No | D14: Yes | E14: 880 | H14: =IF(A14="","",IFERROR(INDEX(Attributes!$F$3:$F$52,MATCH(A14,Attributes!$A$3:$A$52,0))&"","Unknown attribute")) | I14: =IF(OR(A14="",B14=""),"",IF(AND(H14="Yes",D14<>"No"),"Yes","No")) | J14: =IF(I14="Yes",COUNTIF($I$3:I14,"Yes"),"") | K14: =IF(I14<>"Yes","",COUNTIFS($A$3:A14,SUBSTITUTE(SUBSTITUTE(A14,"?","~?"),"*","~*"),$I$3:I14,"Yes")) | L14: =IF(K14="","",A14&"|"&K14) | M14: =IF(I14<>"Yes","",COUNTIFS(Values!$A$3:$A$502,SUBSTITUTE(SUBSTITUTE(A14,"?","~?"),"*","~*"),Values!$I$3:$I$502,"Yes")) | N14: =IF(I14<>"Yes","",IF(M14<2,"",INDEX(Values!$B$3:$B$502,MATCH(A14&"|"&IF(K14=M14,1,K14+1),Values!$L$3:$L$502,0)))) | O14: =IF(N14="","",INDEX(Values!$J$3:$J$502,MATCH(A14&"|"&IF(K14=M14,1,K14+1),Values!$L$3:$L$502,0)))
A15: Foot type | B15: overpronation | C15: Yes | D15: Yes | E15: 1300 | G15: A concept entity in its own right | H15: =IF(A15="","",IFERROR(INDEX(Attributes!$F$3:$F$52,MATCH(A15,Attributes!$A$3:$A$52,0))&"","Unknown attribute")) | I15: =IF(OR(A15="",B15=""),"",IF(AND(H15="Yes",D15<>"No"),"Yes","No")) | J15: =IF(I15="Yes",COUNTIF($I$3:I15,"Yes"),"") | K15: =IF(I15<>"Yes","",COUNTIFS($A$3:A15,SUBSTITUTE(SUBSTITUTE(A15,"?","~?"),"*","~*"),$I$3:I15,"Yes")) | L15: =IF(K15="","",A15&"|"&K15) | M15: =IF(I15<>"Yes","",COUNTIFS(Values!$A$3:$A$502,SUBSTITUTE(SUBSTITUTE(A15,"?","~?"),"*","~*"),Values!$I$3:$I$502,"Yes")) | N15: =IF(I15<>"Yes","",IF(M15<2,"",INDEX(Values!$B$3:$B$502,MATCH(A15&"|"&IF(K15=M15,1,K15+1),Values!$L$3:$L$502,0)))) | O15: =IF(N15="","",INDEX(Values!$J$3:$J$502,MATCH(A15&"|"&IF(K15=M15,1,K15+1),Values!$L$3:$L$502,0)))
A16: Cushioning | B16: minimalist | C16: No | D16: Yes | E16: 720 | H16: =IF(A16="","",IFERROR(INDEX(Attributes!$F$3:$F$52,MATCH(A16,Attributes!$A$3:$A$52,0))&"","Unknown attribute")) | I16: =IF(OR(A16="",B16=""),"",IF(AND(H16="Yes",D16<>"No"),"Yes","No")) | J16: =IF(I16="Yes",COUNTIF($I$3:I16,"Yes"),"") | K16: =IF(I16<>"Yes","",COUNTIFS($A$3:A16,SUBSTITUTE(SUBSTITUTE(A16,"?","~?"),"*","~*"),$I$3:I16,"Yes")) | L16: =IF(K16="","",A16&"|"&K16) | M16: =IF(I16<>"Yes","",COUNTIFS(Values!$A$3:$A$502,SUBSTITUTE(SUBSTITUTE(A16,"?","~?"),"*","~*"),Values!$I$3:$I$502,"Yes")) | N16: =IF(I16<>"Yes","",IF(M16<2,"",INDEX(Values!$B$3:$B$502,MATCH(A16&"|"&IF(K16=M16,1,K16+1),Values!$L$3:$L$502,0)))) | O16: =IF(N16="","",INDEX(Values!$J$3:$J$502,MATCH(A16&"|"&IF(K16=M16,1,K16+1),Values!$L$3:$L$502,0)))
A17: Cushioning | B17: max-cushion | C17: No | D17: Yes | E17: 1000 | H17: =IF(A17="","",IFERROR(INDEX(Attributes!$F$3:$F$52,MATCH(A17,Attributes!$A$3:$A$52,0))&"","Unknown attribute")) | I17: =IF(OR(A17="",B17=""),"",IF(AND(H17="Yes",D17<>"No"),"Yes","No")) | J17: =IF(I17="Yes",COUNTIF($I$3:I17,"Yes"),"") | K17: =IF(I17<>"Yes","",COUNTIFS($A$3:A17,SUBSTITUTE(SUBSTITUTE(A17,"?","~?"),"*","~*"),$I$3:I17,"Yes")) | L17: =IF(K17="","",A17&"|"&K17) | M17: =IF(I17<>"Yes","",COUNTIFS(Values!$A$3:$A$502,SUBSTITUTE(SUBSTITUTE(A17,"?","~?"),"*","~*"),Values!$I$3:$I$502,"Yes")) | N17: =IF(I17<>"Yes","",IF(M17<2,"",INDEX(Values!$B$3:$B$502,MATCH(A17&"|"&IF(K17=M17,1,K17+1),Values!$L$3:$L$502,0)))) | O17: =IF(N17="","",INDEX(Values!$J$3:$J$502,MATCH(A17&"|"&IF(K17=M17,1,K17+1),Values!$L$3:$L$502,0)))
A18: Cushioning | B18: carbon-plate | C18: Yes | D18: Yes | E18: 1000 | G18: Technology entity: explain what it is | H18: =IF(A18="","",IFERROR(INDEX(Attributes!$F$3:$F$52,MATCH(A18,Attributes!$A$3:$A$52,0))&"","Unknown attribute")) | I18: =IF(OR(A18="",B18=""),"",IF(AND(H18="Yes",D18<>"No"),"Yes","No")) | J18: =IF(I18="Yes",COUNTIF($I$3:I18,"Yes"),"") | K18: =IF(I18<>"Yes","",COUNTIFS($A$3:A18,SUBSTITUTE(SUBSTITUTE(A18,"?","~?"),"*","~*"),$I$3:I18,"Yes")) | L18: =IF(K18="","",A18&"|"&K18) | M18: =IF(I18<>"Yes","",COUNTIFS(Values!$A$3:$A$502,SUBSTITUTE(SUBSTITUTE(A18,"?","~?"),"*","~*"),Values!$I$3:$I$502,"Yes")) | N18: =IF(I18<>"Yes","",IF(M18<2,"",INDEX(Values!$B$3:$B$502,MATCH(A18&"|"&IF(K18=M18,1,K18+1),Values!$L$3:$L$502,0)))) | O18: =IF(N18="","",INDEX(Values!$J$3:$J$502,MATCH(A18&"|"&IF(K18=M18,1,K18+1),Values!$L$3:$L$502,0)))
A19: Brand | B19: Hoka | C19: Yes | D19: Yes | E19: 12100 | F19: https://www.stride-example.com/brands/hoka/ | H19: =IF(A19="","",IFERROR(INDEX(Attributes!$F$3:$F$52,MATCH(A19,Attributes!$A$3:$A$52,0))&"","Unknown attribute")) | I19: =IF(OR(A19="",B19=""),"",IF(AND(H19="Yes",D19<>"No"),"Yes","No")) | J19: =IF(I19="Yes",COUNTIF($I$3:I19,"Yes"),"") | K19: =IF(I19<>"Yes","",COUNTIFS($A$3:A19,SUBSTITUTE(SUBSTITUTE(A19,"?","~?"),"*","~*"),$I$3:I19,"Yes")) | L19: =IF(K19="","",A19&"|"&K19) | M19: =IF(I19<>"Yes","",COUNTIFS(Values!$A$3:$A$502,SUBSTITUTE(SUBSTITUTE(A19,"?","~?"),"*","~*"),Values!$I$3:$I$502,"Yes")) | N19: =IF(I19<>"Yes","",IF(M19<2,"",INDEX(Values!$B$3:$B$502,MATCH(A19&"|"&IF(K19=M19,1,K19+1),Values!$L$3:$L$502,0)))) | O19: =IF(N19="","",INDEX(Values!$J$3:$J$502,MATCH(A19&"|"&IF(K19=M19,1,K19+1),Values!$L$3:$L$502,0)))
A20: Brand | B20: Brooks | C20: Yes | D20: Yes | E20: 8100 | H20: =IF(A20="","",IFERROR(INDEX(Attributes!$F$3:$F$52,MATCH(A20,Attributes!$A$3:$A$52,0))&"","Unknown attribute")) | I20: =IF(OR(A20="",B20=""),"",IF(AND(H20="Yes",D20<>"No"),"Yes","No")) | J20: =IF(I20="Yes",COUNTIF($I$3:I20,"Yes"),"") | K20: =IF(I20<>"Yes","",COUNTIFS($A$3:A20,SUBSTITUTE(SUBSTITUTE(A20,"?","~?"),"*","~*"),$I$3:I20,"Yes")) | L20: =IF(K20="","",A20&"|"&K20) | M20: =IF(I20<>"Yes","",COUNTIFS(Values!$A$3:$A$502,SUBSTITUTE(SUBSTITUTE(A20,"?","~?"),"*","~*"),Values!$I$3:$I$502,"Yes")) | N20: =IF(I20<>"Yes","",IF(M20<2,"",INDEX(Values!$B$3:$B$502,MATCH(A20&"|"&IF(K20=M20,1,K20+1),Values!$L$3:$L$502,0)))) | O20: =IF(N20="","",INDEX(Values!$J$3:$J$502,MATCH(A20&"|"&IF(K20=M20,1,K20+1),Values!$L$3:$L$502,0)))
A21: Brand | B21: Asics | C21: Yes | D21: Yes | E21: 9900 | F21: https://www.stride-example.com/brands/asics/ | H21: =IF(A21="","",IFERROR(INDEX(Attributes!$F$3:$F$52,MATCH(A21,Attributes!$A$3:$A$52,0))&"","Unknown attribute")) | I21: =IF(OR(A21="",B21=""),"",IF(AND(H21="Yes",D21<>"No"),"Yes","No")) | J21: =IF(I21="Yes",COUNTIF($I$3:I21,"Yes"),"") | K21: =IF(I21<>"Yes","",COUNTIFS($A$3:A21,SUBSTITUTE(SUBSTITUTE(A21,"?","~?"),"*","~*"),$I$3:I21,"Yes")) | L21: =IF(K21="","",A21&"|"&K21) | M21: =IF(I21<>"Yes","",COUNTIFS(Values!$A$3:$A$502,SUBSTITUTE(SUBSTITUTE(A21,"?","~?"),"*","~*"),Values!$I$3:$I$502,"Yes")) | N21: =IF(I21<>"Yes","",IF(M21<2,"",INDEX(Values!$B$3:$B$502,MATCH(A21&"|"&IF(K21=M21,1,K21+1),Values!$L$3:$L$502,0)))) | O21: =IF(N21="","",INDEX(Values!$J$3:$J$502,MATCH(A21&"|"&IF(K21=M21,1,K21+1),Values!$L$3:$L$502,0)))
A22: Brand | B22: Saucony | C22: Yes | D22: Yes | E22: 4400 | H22: =IF(A22="","",IFERROR(INDEX(Attributes!$F$3:$F$52,MATCH(A22,Attributes!$A$3:$A$52,0))&"","Unknown attribute")) | I22: =IF(OR(A22="",B22=""),"",IF(AND(H22="Yes",D22<>"No"),"Yes","No")) | J22: =IF(I22="Yes",COUNTIF($I$3:I22,"Yes"),"") | K22: =IF(I22<>"Yes","",COUNTIFS($A$3:A22,SUBSTITUTE(SUBSTITUTE(A22,"?","~?"),"*","~*"),$I$3:I22,"Yes")) | L22: =IF(K22="","",A22&"|"&K22) | M22: =IF(I22<>"Yes","",COUNTIFS(Values!$A$3:$A$502,SUBSTITUTE(SUBSTITUTE(A22,"?","~?"),"*","~*"),Values!$I$3:$I$502,"Yes")) | N22: =IF(I22<>"Yes","",IF(M22<2,"",INDEX(Values!$B$3:$B$502,MATCH(A22&"|"&IF(K22=M22,1,K22+1),Values!$L$3:$L$502,0)))) | O22: =IF(N22="","",INDEX(Values!$J$3:$J$502,MATCH(A22&"|"&IF(K22=M22,1,K22+1),Values!$L$3:$L$502,0)))
A23: Brand | B23: On | C23: Yes | D23: Yes | E23: 6600 | H23: =IF(A23="","",IFERROR(INDEX(Attributes!$F$3:$F$52,MATCH(A23,Attributes!$A$3:$A$52,0))&"","Unknown attribute")) | I23: =IF(OR(A23="",B23=""),"",IF(AND(H23="Yes",D23<>"No"),"Yes","No")) | J23: =IF(I23="Yes",COUNTIF($I$3:I23,"Yes"),"") | K23: =IF(I23<>"Yes","",COUNTIFS($A$3:A23,SUBSTITUTE(SUBSTITUTE(A23,"?","~?"),"*","~*"),$I$3:I23,"Yes")) | L23: =IF(K23="","",A23&"|"&K23) | M23: =IF(I23<>"Yes","",COUNTIFS(Values!$A$3:$A$502,SUBSTITUTE(SUBSTITUTE(A23,"?","~?"),"*","~*"),Values!$I$3:$I$502,"Yes")) | N23: =IF(I23<>"Yes","",IF(M23<2,"",INDEX(Values!$B$3:$B$502,MATCH(A23&"|"&IF(K23=M23,1,K23+1),Values!$L$3:$L$502,0)))) | O23: =IF(N23="","",INDEX(Values!$J$3:$J$502,MATCH(A23&"|"&IF(K23=M23,1,K23+1),Values!$L$3:$L$502,0)))
A24: Runner level | B24: beginners | C24: No | D24: Yes | E24: 1300 | H24: =IF(A24="","",IFERROR(INDEX(Attributes!$F$3:$F$52,MATCH(A24,Attributes!$A$3:$A$52,0))&"","Unknown attribute")) | I24: =IF(OR(A24="",B24=""),"",IF(AND(H24="Yes",D24<>"No"),"Yes","No")) | J24: =IF(I24="Yes",COUNTIF($I$3:I24,"Yes"),"") | K24: =IF(I24<>"Yes","",COUNTIFS($A$3:A24,SUBSTITUTE(SUBSTITUTE(A24,"?","~?"),"*","~*"),$I$3:I24,"Yes")) | L24: =IF(K24="","",A24&"|"&K24) | M24: =IF(I24<>"Yes","",COUNTIFS(Values!$A$3:$A$502,SUBSTITUTE(SUBSTITUTE(A24,"?","~?"),"*","~*"),Values!$I$3:$I$502,"Yes")) | N24: =IF(I24<>"Yes","",IF(M24<2,"",INDEX(Values!$B$3:$B$502,MATCH(A24&"|"&IF(K24=M24,1,K24+1),Values!$L$3:$L$502,0)))) | O24: =IF(N24="","",INDEX(Values!$J$3:$J$502,MATCH(A24&"|"&IF(K24=M24,1,K24+1),Values!$L$3:$L$502,0)))
A25: Runner level | B25: returning from injury | C25: No | D25: Yes | E25: 90 | G25: Low volume, real need | H25: =IF(A25="","",IFERROR(INDEX(Attributes!$F$3:$F$52,MATCH(A25,Attributes!$A$3:$A$52,0))&"","Unknown attribute")) | I25: =IF(OR(A25="",B25=""),"",IF(AND(H25="Yes",D25<>"No"),"Yes","No")) | J25: =IF(I25="Yes",COUNTIF($I$3:I25,"Yes"),"") | K25: =IF(I25<>"Yes","",COUNTIFS($A$3:A25,SUBSTITUTE(SUBSTITUTE(A25,"?","~?"),"*","~*"),$I$3:I25,"Yes")) | L25: =IF(K25="","",A25&"|"&K25) | M25: =IF(I25<>"Yes","",COUNTIFS(Values!$A$3:$A$502,SUBSTITUTE(SUBSTITUTE(A25,"?","~?"),"*","~*"),Values!$I$3:$I$502,"Yes")) | N25: =IF(I25<>"Yes","",IF(M25<2,"",INDEX(Values!$B$3:$B$502,MATCH(A25&"|"&IF(K25=M25,1,K25+1),Values!$L$3:$L$502,0)))) | O25: =IF(N25="","",INDEX(Values!$J$3:$J$502,MATCH(A25&"|"&IF(K25=M25,1,K25+1),Values!$L$3:$L$502,0)))
A26: Runner level | B26: intermediate runners | C26: No | D26: Unsure | E26: 50 | H26: =IF(A26="","",IFERROR(INDEX(Attributes!$F$3:$F$52,MATCH(A26,Attributes!$A$3:$A$52,0))&"","Unknown attribute")) | I26: =IF(OR(A26="",B26=""),"",IF(AND(H26="Yes",D26<>"No"),"Yes","No")) | J26: =IF(I26="Yes",COUNTIF($I$3:I26,"Yes"),"") | K26: =IF(I26<>"Yes","",COUNTIFS($A$3:A26,SUBSTITUTE(SUBSTITUTE(A26,"?","~?"),"*","~*"),$I$3:I26,"Yes")) | L26: =IF(K26="","",A26&"|"&K26) | M26: =IF(I26<>"Yes","",COUNTIFS(Values!$A$3:$A$502,SUBSTITUTE(SUBSTITUTE(A26,"?","~?"),"*","~*"),Values!$I$3:$I$502,"Yes")) | N26: =IF(I26<>"Yes","",IF(M26<2,"",INDEX(Values!$B$3:$B$502,MATCH(A26&"|"&IF(K26=M26,1,K26+1),Values!$L$3:$L$502,0)))) | O26: =IF(N26="","",INDEX(Values!$J$3:$J$502,MATCH(A26&"|"&IF(K26=M26,1,K26+1),Values!$L$3:$L$502,0)))
A27: Price | B27: under £80 | C27: No | D27: Yes | E27: 880 | F27: https://www.stride-example.com/sale/ | H27: =IF(A27="","",IFERROR(INDEX(Attributes!$F$3:$F$52,MATCH(A27,Attributes!$A$3:$A$52,0))&"","Unknown attribute")) | I27: =IF(OR(A27="",B27=""),"",IF(AND(H27="Yes",D27<>"No"),"Yes","No")) | J27: =IF(I27="Yes",COUNTIF($I$3:I27,"Yes"),"") | K27: =IF(I27<>"Yes","",COUNTIFS($A$3:A27,SUBSTITUTE(SUBSTITUTE(A27,"?","~?"),"*","~*"),$I$3:I27,"Yes")) | L27: =IF(K27="","",A27&"|"&K27) | M27: =IF(I27<>"Yes","",COUNTIFS(Values!$A$3:$A$502,SUBSTITUTE(SUBSTITUTE(A27,"?","~?"),"*","~*"),Values!$I$3:$I$502,"Yes")) | N27: =IF(I27<>"Yes","",IF(M27<2,"",INDEX(Values!$B$3:$B$502,MATCH(A27&"|"&IF(K27=M27,1,K27+1),Values!$L$3:$L$502,0)))) | O27: =IF(N27="","",INDEX(Values!$J$3:$J$502,MATCH(A27&"|"&IF(K27=M27,1,K27+1),Values!$L$3:$L$502,0)))
A28: Price | B28: £80 to £140 | C28: No | D28: No | E28: 20 | G28: Nobody searches this band | H28: =IF(A28="","",IFERROR(INDEX(Attributes!$F$3:$F$52,MATCH(A28,Attributes!$A$3:$A$52,0))&"","Unknown attribute")) | I28: =IF(OR(A28="",B28=""),"",IF(AND(H28="Yes",D28<>"No"),"Yes","No")) | J28: =IF(I28="Yes",COUNTIF($I$3:I28,"Yes"),"") | K28: =IF(I28<>"Yes","",COUNTIFS($A$3:A28,SUBSTITUTE(SUBSTITUTE(A28,"?","~?"),"*","~*"),$I$3:I28,"Yes")) | L28: =IF(K28="","",A28&"|"&K28) | M28: =IF(I28<>"Yes","",COUNTIFS(Values!$A$3:$A$502,SUBSTITUTE(SUBSTITUTE(A28,"?","~?"),"*","~*"),Values!$I$3:$I$502,"Yes")) | N28: =IF(I28<>"Yes","",IF(M28<2,"",INDEX(Values!$B$3:$B$502,MATCH(A28&"|"&IF(K28=M28,1,K28+1),Values!$L$3:$L$502,0)))) | O28: =IF(N28="","",INDEX(Values!$J$3:$J$502,MATCH(A28&"|"&IF(K28=M28,1,K28+1),Values!$L$3:$L$502,0)))
A29: Price | B29: over £140 | C29: No | D29: Unsure | E29: 40 | H29: =IF(A29="","",IFERROR(INDEX(Attributes!$F$3:$F$52,MATCH(A29,Attributes!$A$3:$A$52,0))&"","Unknown attribute")) | I29: =IF(OR(A29="",B29=""),"",IF(AND(H29="Yes",D29<>"No"),"Yes","No")) | J29: =IF(I29="Yes",COUNTIF($I$3:I29,"Yes"),"") | K29: =IF(I29<>"Yes","",COUNTIFS($A$3:A29,SUBSTITUTE(SUBSTITUTE(A29,"?","~?"),"*","~*"),$I$3:I29,"Yes")) | L29: =IF(K29="","",A29&"|"&K29) | M29: =IF(I29<>"Yes","",COUNTIFS(Values!$A$3:$A$502,SUBSTITUTE(SUBSTITUTE(A29,"?","~?"),"*","~*"),Values!$I$3:$I$502,"Yes")) | N29: =IF(I29<>"Yes","",IF(M29<2,"",INDEX(Values!$B$3:$B$502,MATCH(A29&"|"&IF(K29=M29,1,K29+1),Values!$L$3:$L$502,0)))) | O29: =IF(N29="","",INDEX(Values!$J$3:$J$502,MATCH(A29&"|"&IF(K29=M29,1,K29+1),Values!$L$3:$L$502,0)))
A30: Runner name | B30: Eliud Kipchoge | C30: Yes | D30: No | E30: 2900 | G30: Infinite attribute, excluded | H30: =IF(A30="","",IFERROR(INDEX(Attributes!$F$3:$F$52,MATCH(A30,Attributes!$A$3:$A$52,0))&"","Unknown attribute")) | I30: =IF(OR(A30="",B30=""),"",IF(AND(H30="Yes",D30<>"No"),"Yes","No")) | J30: =IF(I30="Yes",COUNTIF($I$3:I30,"Yes"),"") | K30: =IF(I30<>"Yes","",COUNTIFS($A$3:A30,SUBSTITUTE(SUBSTITUTE(A30,"?","~?"),"*","~*"),$I$3:I30,"Yes")) | L30: =IF(K30="","",A30&"|"&K30) | M30: =IF(I30<>"Yes","",COUNTIFS(Values!$A$3:$A$502,SUBSTITUTE(SUBSTITUTE(A30,"?","~?"),"*","~*"),Values!$I$3:$I$502,"Yes")) | N30: =IF(I30<>"Yes","",IF(M30<2,"",INDEX(Values!$B$3:$B$502,MATCH(A30&"|"&IF(K30=M30,1,K30+1),Values!$L$3:$L$502,0)))) | O30: =IF(N30="","",INDEX(Values!$J$3:$J$502,MATCH(A30&"|"&IF(K30=M30,1,K30+1),Values!$L$3:$L$502,0)))
H31: =IF(A31="","",IFERROR(INDEX(Attributes!$F$3:$F$52,MATCH(A31,Attributes!$A$3:$A$52,0))&"","Unknown attribute")) | I31: =IF(OR(A31="",B31=""),"",IF(AND(H31="Yes",D31<>"No"),"Yes","No")) | J31: =IF(I31="Yes",COUNTIF($I$3:I31,"Yes"),"") | K31: =IF(I31<>"Yes","",COUNTIFS($A$3:A31,SUBSTITUTE(SUBSTITUTE(A31,"?","~?"),"*","~*"),$I$3:I31,"Yes")) | L31: =IF(K31="","",A31&"|"&K31) | M31: =IF(I31<>"Yes","",COUNTIFS(Values!$A$3:$A$502,SUBSTITUTE(SUBSTITUTE(A31,"?","~?"),"*","~*"),Values!$I$3:$I$502,"Yes")) | N31: =IF(I31<>"Yes","",IF(M31<2,"",INDEX(Values!$B$3:$B$502,MATCH(A31&"|"&IF(K31=M31,1,K31+1),Values!$L$3:$L$502,0)))) | O31: =IF(N31="","",INDEX(Values!$J$3:$J$502,MATCH(A31&"|"&IF(K31=M31,1,K31+1),Values!$L$3:$L$502,0)))
H32: =IF(A32="","",IFERROR(INDEX(Attributes!$F$3:$F$52,MATCH(A32,Attributes!$A$3:$A$52,0))&"","Unknown attribute")) | I32: =IF(OR(A32="",B32=""),"",IF(AND(H32="Yes",D32<>"No"),"Yes","No")) | J32: =IF(I32="Yes",COUNTIF($I$3:I32,"Yes"),"") | K32: =IF(I32<>"Yes","",COUNTIFS($A$3:A32,SUBSTITUTE(SUBSTITUTE(A32,"?","~?"),"*","~*"),$I$3:I32,"Yes")) | L32: =IF(K32="","",A32&"|"&K32) | M32: =IF(I32<>"Yes","",COUNTIFS(Values!$A$3:$A$502,SUBSTITUTE(SUBSTITUTE(A32,"?","~?"),"*","~*"),Values!$I$3:$I$502,"Yes")) | N32: =IF(I32<>"Yes","",IF(M32<2,"",INDEX(Values!$B$3:$B$502,MATCH(A32&"|"&IF(K32=M32,1,K32+1),Values!$L$3:$L$502,0)))) | O32: =IF(N32="","",INDEX(Values!$J$3:$J$502,MATCH(A32&"|"&IF(K32=M32,1,K32+1),Values!$L$3:$L$502,0)))
H33: =IF(A33="","",IFERROR(INDEX(Attributes!$F$3:$F$52,MATCH(A33,Attributes!$A$3:$A$52,0))&"","Unknown attribute")) | I33: =IF(OR(A33="",B33=""),"",IF(AND(H33="Yes",D33<>"No"),"Yes","No")) | J33: =IF(I33="Yes",COUNTIF($I$3:I33,"Yes"),"") | K33: =IF(I33<>"Yes","",COUNTIFS($A$3:A33,SUBSTITUTE(SUBSTITUTE(A33,"?","~?"),"*","~*"),$I$3:I33,"Yes")) | L33: =IF(K33="","",A33&"|"&K33) | M33: =IF(I33<>"Yes","",COUNTIFS(Values!$A$3:$A$502,SUBSTITUTE(SUBSTITUTE(A33,"?","~?"),"*","~*"),Values!$I$3:$I$502,"Yes")) | N33: =IF(I33<>"Yes","",IF(M33<2,"",INDEX(Values!$B$3:$B$502,MATCH(A33&"|"&IF(K33=M33,1,K33+1),Values!$L$3:$L$502,0)))) | O33: =IF(N33="","",INDEX(Values!$J$3:$J$502,MATCH(A33&"|"&IF(K33=M33,1,K33+1),Values!$L$3:$L$502,0)))
H34: =IF(A34="","",IFERROR(INDEX(Attributes!$F$3:$F$52,MATCH(A34,Attributes!$A$3:$A$52,0))&"","Unknown attribute")) | I34: =IF(OR(A34="",B34=""),"",IF(AND(H34="Yes",D34<>"No"),"Yes","No")) | J34: =IF(I34="Yes",COUNTIF($I$3:I34,"Yes"),"") | K34: =IF(I34<>"Yes","",COUNTIFS($A$3:A34,SUBSTITUTE(SUBSTITUTE(A34,"?","~?"),"*","~*"),$I$3:I34,"Yes")) | L34: =IF(K34="","",A34&"|"&K34) | M34: =IF(I34<>"Yes","",COUNTIFS(Values!$A$3:$A$502,SUBSTITUTE(SUBSTITUTE(A34,"?","~?"),"*","~*"),Values!$I$3:$I$502,"Yes")) | N34: =IF(I34<>"Yes","",IF(M34<2,"",INDEX(Values!$B$3:$B$502,MATCH(A34&"|"&IF(K34=M34,1,K34+1),Values!$L$3:$L$502,0)))) | O34: =IF(N34="","",INDEX(Values!$J$3:$J$502,MATCH(A34&"|"&IF(K34=M34,1,K34+1),Values!$L$3:$L$502,0)))
H35: =IF(A35="","",IFERROR(INDEX(Attributes!$F$3:$F$52,MATCH(A35,Attributes!$A$3:$A$52,0))&"","Unknown attribute")) | I35: =IF(OR(A35="",B35=""),"",IF(AND(H35="Yes",D35<>"No"),"Yes","No")) | J35: =IF(I35="Yes",COUNTIF($I$3:I35,"Yes"),"") | K35: =IF(I35<>"Yes","",COUNTIFS($A$3:A35,SUBSTITUTE(SUBSTITUTE(A35,"?","~?"),"*","~*"),$I$3:I35,"Yes")) | L35: =IF(K35="","",A35&"|"&K35) | M35: =IF(I35<>"Yes","",COUNTIFS(Values!$A$3:$A$502,SUBSTITUTE(SUBSTITUTE(A35,"?","~?"),"*","~*"),Values!$I$3:$I$502,"Yes")) | N35: =IF(I35<>"Yes","",IF(M35<2,"",INDEX(Values!$B$3:$B$502,MATCH(A35&"|"&IF(K35=M35,1,K35+1),Values!$L$3:$L$502,0)))) | O35: =IF(N35="","",INDEX(Values!$J$3:$J$502,MATCH(A35&"|"&IF(K35=M35,1,K35+1),Values!$L$3:$L$502,0)))
H36: =IF(A36="","",IFERROR(INDEX(Attributes!$F$3:$F$52,MATCH(A36,Attributes!$A$3:$A$52,0))&"","Unknown attribute")) | I36: =IF(OR(A36="",B36=""),"",IF(AND(H36="Yes",D36<>"No"),"Yes","No")) | J36: =IF(I36="Yes",COUNTIF($I$3:I36,"Yes"),"") | K36: =IF(I36<>"Yes","",COUNTIFS($A$3:A36,SUBSTITUTE(SUBSTITUTE(A36,"?","~?"),"*","~*"),$I$3:I36,"Yes")) | L36: =IF(K36="","",A36&"|"&K36) | M36: =IF(I36<>"Yes","",COUNTIFS(Values!$A$3:$A$502,SUBSTITUTE(SUBSTITUTE(A36,"?","~?"),"*","~*"),Values!$I$3:$I$502,"Yes")) | N36: =IF(I36<>"Yes","",IF(M36<2,"",INDEX(Values!$B$3:$B$502,MATCH(A36&"|"&IF(K36=M36,1,K36+1),Values!$L$3:$L$502,0)))) | O36: =IF(N36="","",INDEX(Values!$J$3:$J$502,MATCH(A36&"|"&IF(K36=M36,1,K36+1),Values!$L$3:$L$502,0)))
H37: =IF(A37="","",IFERROR(INDEX(Attributes!$F$3:$F$52,MATCH(A37,Attributes!$A$3:$A$52,0))&"","Unknown attribute")) | I37: =IF(OR(A37="",B37=""),"",IF(AND(H37="Yes",D37<>"No"),"Yes","No")) | J37: =IF(I37="Yes",COUNTIF($I$3:I37,"Yes"),"") | K37: =IF(I37<>"Yes","",COUNTIFS($A$3:A37,SUBSTITUTE(SUBSTITUTE(A37,"?","~?"),"*","~*"),$I$3:I37,"Yes")) | L37: =IF(K37="","",A37&"|"&K37) | M37: =IF(I37<>"Yes","",COUNTIFS(Values!$A$3:$A$502,SUBSTITUTE(SUBSTITUTE(A37,"?","~?"),"*","~*"),Values!$I$3:$I$502,"Yes")) | N37: =IF(I37<>"Yes","",IF(M37<2,"",INDEX(Values!$B$3:$B$502,MATCH(A37&"|"&IF(K37=M37,1,K37+1),Values!$L$3:$L$502,0)))) | O37: =IF(N37="","",INDEX(Values!$J$3:$J$502,MATCH(A37&"|"&IF(K37=M37,1,K37+1),Values!$L$3:$L$502,0)))
H38: =IF(A38="","",IFERROR(INDEX(Attributes!$F$3:$F$52,MATCH(A38,Attributes!$A$3:$A$52,0))&"","Unknown attribute")) | I38: =IF(OR(A38="",B38=""),"",IF(AND(H38="Yes",D38<>"No"),"Yes","No")) | J38: =IF(I38="Yes",COUNTIF($I$3:I38,"Yes"),"") | K38: =IF(I38<>"Yes","",COUNTIFS($A$3:A38,SUBSTITUTE(SUBSTITUTE(A38,"?","~?"),"*","~*"),$I$3:I38,"Yes")) | L38: =IF(K38="","",A38&"|"&K38) | M38: =IF(I38<>"Yes","",COUNTIFS(Values!$A$3:$A$502,SUBSTITUTE(SUBSTITUTE(A38,"?","~?"),"*","~*"),Values!$I$3:$I$502,"Yes")) | N38: =IF(I38<>"Yes","",IF(M38<2,"",INDEX(Values!$B$3:$B$502,MATCH(A38&"|"&IF(K38=M38,1,K38+1),Values!$L$3:$L$502,0)))) | O38: =IF(N38="","",INDEX(Values!$J$3:$J$502,MATCH(A38&"|"&IF(K38=M38,1,K38+1),Values!$L$3:$L$502,0)))
H39: =IF(A39="","",IFERROR(INDEX(Attributes!$F$3:$F$52,MATCH(A39,Attributes!$A$3:$A$52,0))&"","Unknown attribute")) | I39: =IF(OR(A39="",B39=""),"",IF(AND(H39="Yes",D39<>"No"),"Yes","No")) | J39: =IF(I39="Yes",COUNTIF($I$3:I39,"Yes"),"") | K39: =IF(I39<>"Yes","",COUNTIFS($A$3:A39,SUBSTITUTE(SUBSTITUTE(A39,"?","~?"),"*","~*"),$I$3:I39,"Yes")) | L39: =IF(K39="","",A39&"|"&K39) | M39: =IF(I39<>"Yes","",COUNTIFS(Values!$A$3:$A$502,SUBSTITUTE(SUBSTITUTE(A39,"?","~?"),"*","~*"),Values!$I$3:$I$502,"Yes")) | N39: =IF(I39<>"Yes","",IF(M39<2,"",INDEX(Values!$B$3:$B$502,MATCH(A39&"|"&IF(K39=M39,1,K39+1),Values!$L$3:$L$502,0)))) | O39: =IF(N39="","",INDEX(Values!$J$3:$J$502,MATCH(A39&"|"&IF(K39=M39,1,K39+1),Values!$L$3:$L$502,0)))
H40: =IF(A40="","",IFERROR(INDEX(Attributes!$F$3:$F$52,MATCH(A40,Attributes!$A$3:$A$52,0))&"","Unknown attribute")) | I40: =IF(OR(A40="",B40=""),"",IF(AND(H40="Yes",D40<>"No"),"Yes","No")) | J40: =IF(I40="Yes",COUNTIF($I$3:I40,"Yes"),"") | K40: =IF(I40<>"Yes","",COUNTIFS($A$3:A40,SUBSTITUTE(SUBSTITUTE(A40,"?","~?"),"*","~*"),$I$3:I40,"Yes")) | L40: =IF(K40="","",A40&"|"&K40) | M40: =IF(I40<>"Yes","",COUNTIFS(Values!$A$3:$A$502,SUBSTITUTE(SUBSTITUTE(A40,"?","~?"),"*","~*"),Values!$I$3:$I$502,"Yes")) | N40: =IF(I40<>"Yes","",IF(M40<2,"",INDEX(Values!$B$3:$B$502,MATCH(A40&"|"&IF(K40=M40,1,K40+1),Values!$L$3:$L$502,0)))) | O40: =IF(N40="","",INDEX(Values!$J$3:$J$502,MATCH(A40&"|"&IF(K40=M40,1,K40+1),Values!$L$3:$L$502,0)))
...

Sheet Topical Map
A1: 4. TOPICAL MAP: generated from Entity, Attributes and Values. Don't type here; copy it as values when you're happy.
A2: # | B2: Level | C2: Attribute | D2: Value / sub-entity | E2: Suggested title | F2: Suggested slug | G2: Links up to | H2: Links across to | I2: Links down to | J2: Primary intent | K2: Suggested format | L2: Existing URL | M2: Coverage | N2: Search volume | O2: Priority | P2: Value row (helper) | Q2: Attribute row (helper) | R2: Raw title (helper)
A3: =ROW()-2 | B3: =IF(A3=1,"Pillar",IF(A3<=1+Entity!$B$14,"Cluster",IF(A3<=1+Entity!$B$14+Entity!$B$15,"Supporting",""))) | C3: =IF(B3="Cluster",INDEX(Attributes!$A$3:$A$52,MATCH(A3-1,Attributes!$P$3:$P$52,0)),IF(B3="Supporting",INDEX(Values!$A$3:$A$502,P3),"")) | D3: =IF(B3="Supporting",INDEX(Values!$B$3:$B$502,P3),"") | E3: =IF(R3="","",UPPER(LEFT(R3,1))&MID(R3,2,500)) | F3: =IF(E3="","",LOWER(SUBSTITUTE(SUBSTITUTE(SUBSTITUTE(SUBSTITUTE(SUBSTITUTE(SUBSTITUTE(SUBSTITUTE(TRIM(E3),":",""),",",""),"'",""),"&","and"),"£","")," "," ")," ","-"))) | G3: =IF(B3="Cluster",$E$3,IF(B3="Supporting",INDEX($E$3:$E$553,MATCH(C3,$C$3:$C$553,0)),"")) | H3: =IF(B3="Supporting",IFERROR(INDEX($E$3:$E$553,1+Entity!$B$14+INDEX(Values!$O$3:$O$502,P3)),""),IF(B3="Cluster",IF(Entity!$B$14<2,"",INDEX($E$3:$E$553,IF(A3-1=Entity!$B$14,2,A3+1))),"")) | I3: =IF(B3="Pillar",Entity!$B$14&" cluster pages",IF(B3="Cluster",(COUNTIF($C$3:$C$553,SUBSTITUTE(SUBSTITUTE(C3,"?","~?"),"*","~*"))-1)&" supporting pages","")) | J3: =IF(B3="Pillar","Informational",IF(OR(B3="Cluster",B3="Supporting"),INDEX(Attributes!$D$3:$D$52,Q3)&"","")) | K3: =IF(B3="","",IF(B3="Pillar","Pillar guide (entity hub)",IF(B3="Cluster","Hub page for this attribute",IF(INDEX(Values!$C$3:$C$502,P3)="Yes","Entity page (profile of the sub-entity)",IFERROR(INDEX(Lists!$B$3:$B$6,MATCH(J3,Lists!$A$3:$A$6,0)),"Article"))))) | L3: =IF(B3="Pillar",Entity!$B$6&"",IF(B3="Cluster",INDEX(Attributes!$I$3:$I$52,Q3)&"",IF(B3="Supporting",INDEX(Values!$F$3:$F$502,P3)&"",""))) | M3: =IF(B3="","",IF(L3<>"","Covered","Gap")) | N3: =IF(B3="Pillar",SUMIFS(Values!$E$3:$E$502,Values!$I$3:$I$502,"Yes"),IF(B3="Cluster",SUMIFS(Values!$E$3:$E$502,Values!$A$3:$A$502,SUBSTITUTE(SUBSTITUTE(C3,"?","~?"),"*","~*"),Values!$I$3:$I$502,"Yes"),IF(B3="Supporting",N(INDEX(Values!$E$3:$E$502,P3)),""))) | O3: =IF(B3="","",IF(B3="Pillar",100,IF(B3="Cluster",N(INDEX(Attributes!$E$3:$E$52,Q3))*25+IF(M3="Gap",10,0),N(INDEX(Attributes!$E$3:$E$52,Q3))*20+MIN(20,ROUND(LOG10(N(N3)+1)*5,0))+IF(M3="Gap",10,0)+IF(INDEX(Values!$D$3:$D$502,P3)="Yes",5,0)))) | P3: =IF(B3="Supporting",MATCH(A3-1-Entity!$B$14,Values!$J$3:$J$502,0),"") | Q3: =IF(C3="","",MATCH(C3,Attributes!$A$3:$A$52,0)) | R3: =IF(B3="Pillar",SUBSTITUTE(Entity!$B$7,"{entity}",LOWER(Entity!$B$3)),IF(B3="Cluster",IF(INDEX(Attributes!$G$3:$G$52,Q3)<>"",INDEX(Attributes!$G$3:$G$52,Q3),SUBSTITUTE(SUBSTITUTE(Entity!$B$8,"{entity}",LOWER(Entity!$B$3)),"{attribute}",LOWER(C3))),IF(B3="Supporting",SUBSTITUTE(SUBSTITUTE(SUBSTITUTE(IF(INDEX(Attributes!$H$3:$H$52,Q3)<>"",INDEX(Attributes!$H$3:$H$52,Q3),Entity!$B$9),"{entity}",LOWER(Entity!$B$3)),"{value}",D3),"{attribute}",LOWER(C3)),"")))
A4: =ROW()-2 | B4: =IF(A4=1,"Pillar",IF(A4<=1+Entity!$B$14,"Cluster",IF(A4<=1+Entity!$B$14+Entity!$B$15,"Supporting",""))) | C4: =IF(B4="Cluster",INDEX(Attributes!$A$3:$A$52,MATCH(A4-1,Attributes!$P$3:$P$52,0)),IF(B4="Supporting",INDEX(Values!$A$3:$A$502,P4),"")) | D4: =IF(B4="Supporting",INDEX(Values!$B$3:$B$502,P4),"") | E4: =IF(R4="","",UPPER(LEFT(R4,1))&MID(R4,2,500)) | F4: =IF(E4="","",LOWER(SUBSTITUTE(SUBSTITUTE(SUBSTITUTE(SUBSTITUTE(SUBSTITUTE(SUBSTITUTE(SUBSTITUTE(TRIM(E4),":",""),",",""),"'",""),"&","and"),"£","")," "," ")," ","-"))) | G4: =IF(B4="Cluster",$E$3,IF(B4="Supporting",INDEX($E$3:$E$553,MATCH(C4,$C$3:$C$553,0)),"")) | H4: =IF(B4="Supporting",IFERROR(INDEX($E$3:$E$553,1+Entity!$B$14+INDEX(Values!$O$3:$O$502,P4)),""),IF(B4="Cluster",IF(Entity!$B$14<2,"",INDEX($E$3:$E$553,IF(A4-1=Entity!$B$14,2,A4+1))),"")) | I4: =IF(B4="Pillar",Entity!$B$14&" cluster pages",IF(B4="Cluster",(COUNTIF($C$3:$C$553,SUBSTITUTE(SUBSTITUTE(C4,"?","~?"),"*","~*"))-1)&" supporting pages","")) | J4: =IF(B4="Pillar","Informational",IF(OR(B4="Cluster",B4="Supporting"),INDEX(Attributes!$D$3:$D$52,Q4)&"","")) | K4: =IF(B4="","",IF(B4="Pillar","Pillar guide (entity hub)",IF(B4="Cluster","Hub page for this attribute",IF(INDEX(Values!$C$3:$C$502,P4)="Yes","Entity page (profile of the sub-entity)",IFERROR(INDEX(Lists!$B$3:$B$6,MATCH(J4,Lists!$A$3:$A$6,0)),"Article"))))) | L4: =IF(B4="Pillar",Entity!$B$6&"",IF(B4="Cluster",INDEX(Attributes!$I$3:$I$52,Q4)&"",IF(B4="Supporting",INDEX(Values!$F$3:$F$502,P4)&"",""))) | M4: =IF(B4="","",IF(L4<>"","Covered","Gap")) | N4: =IF(B4="Pillar",SUMIFS(Values!$E$3:$E$502,Values!$I$3:$I$502,"Yes"),IF(B4="Cluster",SUMIFS(Values!$E$3:$E$502,Values!$A$3:$A$502,SUBSTITUTE(SUBSTITUTE(C4,"?","~?"),"*","~*"),Values!$I$3:$I$502,"Yes"),IF(B4="Supporting",N(INDEX(Values!$E$3:$E$502,P4)),""))) | O4: =IF(B4="","",IF(B4="Pillar",100,IF(B4="Cluster",N(INDEX(Attributes!$E$3:$E$52,Q4))*25+IF(M4="Gap",10,0),N(INDEX(Attributes!$E$3:$E$52,Q4))*20+MIN(20,ROUND(LOG10(N(N4)+1)*5,0))+IF(M4="Gap",10,0)+IF(INDEX(Values!$D$3:$D$502,P4)="Yes",5,0)))) | P4: =IF(B4="Supporting",MATCH(A4-1-Entity!$B$14,Values!$J$3:$J$502,0),"") | Q4: =IF(C4="","",MATCH(C4,Attributes!$A$3:$A$52,0)) | R4: =IF(B4="Pillar",SUBSTITUTE(Entity!$B$7,"{entity}",LOWER(Entity!$B$3)),IF(B4="Cluster",IF(INDEX(Attributes!$G$3:$G$52,Q4)<>"",INDEX(Attributes!$G$3:$G$52,Q4),SUBSTITUTE(SUBSTITUTE(Entity!$B$8,"{entity}",LOWER(Entity!$B$3)),"{attribute}",LOWER(C4))),IF(B4="Supporting",SUBSTITUTE(SUBSTITUTE(SUBSTITUTE(IF(INDEX(Attributes!$H$3:$H$52,Q4)<>"",INDEX(Attributes!$H$3:$H$52,Q4),Entity!$B$9),"{entity}",LOWER(Entity!$B$3)),"{value}",D4),"{attribute}",LOWER(C4)),"")))
A5: =ROW()-2 | B5: =IF(A5=1,"Pillar",IF(A5<=1+Entity!$B$14,"Cluster",IF(A5<=1+Entity!$B$14+Entity!$B$15,"Supporting",""))) | C5: =IF(B5="Cluster",INDEX(Attributes!$A$3:$A$52,MATCH(A5-1,Attributes!$P$3:$P$52,0)),IF(B5="Supporting",INDEX(Values!$A$3:$A$502,P5),"")) | D5: =IF(B5="Supporting",INDEX(Values!$B$3:$B$502,P5),"") | E5: =IF(R5="","",UPPER(LEFT(R5,1))&MID(R5,2,500)) | F5: =IF(E5="","",LOWER(SUBSTITUTE(SUBSTITUTE(SUBSTITUTE(SUBSTITUTE(SUBSTITUTE(SUBSTITUTE(SUBSTITUTE(TRIM(E5),":",""),",",""),"'",""),"&","and"),"£","")," "," ")," ","-"))) | G5: =IF(B5="Cluster",$E$3,IF(B5="Supporting",INDEX($E$3:$E$553,MATCH(C5,$C$3:$C$553,0)),"")) | H5: =IF(B5="Supporting",IFERROR(INDEX($E$3:$E$553,1+Entity!$B$14+INDEX(Values!$O$3:$O$502,P5)),""),IF(B5="Cluster",IF(Entity!$B$14<2,"",INDEX($E$3:$E$553,IF(A5-1=Entity!$B$14,2,A5+1))),"")) | I5: =IF(B5="Pillar",Entity!$B$14&" cluster pages",IF(B5="Cluster",(COUNTIF($C$3:$C$553,SUBSTITUTE(SUBSTITUTE(C5,"?","~?"),"*","~*"))-1)&" supporting pages","")) | J5: =IF(B5="Pillar","Informational",IF(OR(B5="Cluster",B5="Supporting"),INDEX(Attributes!$D$3:$D$52,Q5)&"","")) | K5: =IF(B5="","",IF(B5="Pillar","Pillar guide (entity hub)",IF(B5="Cluster","Hub page for this attribute",IF(INDEX(Values!$C$3:$C$502,P5)="Yes","Entity page (profile of the sub-entity)",IFERROR(INDEX(Lists!$B$3:$B$6,MATCH(J5,Lists!$A$3:$A$6,0)),"Article"))))) | L5: =IF(B5="Pillar",Entity!$B$6&"",IF(B5="Cluster",INDEX(Attributes!$I$3:$I$52,Q5)&"",IF(B5="Supporting",INDEX(Values!$F$3:$F$502,P5)&"",""))) | M5: =IF(B5="","",IF(L5<>"","Covered","Gap")) | N5: =IF(B5="Pillar",SUMIFS(Values!$E$3:$E$502,Values!$I$3:$I$502,"Yes"),IF(B5="Cluster",SUMIFS(Values!$E$3:$E$502,Values!$A$3:$A$502,SUBSTITUTE(SUBSTITUTE(C5,"?","~?"),"*","~*"),Values!$I$3:$I$502,"Yes"),IF(B5="Supporting",N(INDEX(Values!$E$3:$E$502,P5)),""))) | O5: =IF(B5="","",IF(B5="Pillar",100,IF(B5="Cluster",N(INDEX(Attributes!$E$3:$E$52,Q5))*25+IF(M5="Gap",10,0),N(INDEX(Attributes!$E$3:$E$52,Q5))*20+MIN(20,ROUND(LOG10(N(N5)+1)*5,0))+IF(M5="Gap",10,0)+IF(INDEX(Values!$D$3:$D$502,P5)="Yes",5,0)))) | P5: =IF(B5="Supporting",MATCH(A5-1-Entity!$B$14,Values!$J$3:$J$502,0),"") | Q5: =IF(C5="","",MATCH(C5,Attributes!$A$3:$A$52,0)) | R5: =IF(B5="Pillar",SUBSTITUTE(Entity!$B$7,"{entity}",LOWER(Entity!$B$3)),IF(B5="Cluster",IF(INDEX(Attributes!$G$3:$G$52,Q5)<>"",INDEX(Attributes!$G$3:$G$52,Q5),SUBSTITUTE(SUBSTITUTE(Entity!$B$8,"{entity}",LOWER(Entity!$B$3)),"{attribute}",LOWER(C5))),IF(B5="Supporting",SUBSTITUTE(SUBSTITUTE(SUBSTITUTE(IF(INDEX(Attributes!$H$3:$H$52,Q5)<>"",INDEX(Attributes!$H$3:$H$52,Q5),Entity!$B$9),"{entity}",LOWER(Entity!$B$3)),"{value}",D5),"{attribute}",LOWER(C5)),"")))
