Workbook

Sheet Start here
B2: SEO Site Migration Checklist + Redirect Mapping Workbook
B3: 43 checks across seven phases, plus a redirect map that takes the output of MLforSEO's fuzzy-matching notebooks and tracks QA for every URL. Free from MLforSEO, October 2026.
B5: What this is
B6: A phase-by-phase migration checklist (scope, benchmark, redirect mapping, staging, launch day, first weeks, first year) built on Google's site move documentation, linked to a redirect mapping workbook. Draft your redirects with fuzzy matching, paste the results in, make a decision for each old URL, and the workbook builds the final destination, an Apache rule and warning flags (home page redirects, chains, self-redirects, low scores), then tracks QA through to 'Live and verified'.
B7: It covers domain changes, HTTP to HTTPS, URL structure changes and CMS replatforms. If your URLs aren't changing (a pure hosting move), follow Google's guide for moves without URL changes instead.
B9: How to use it
B10: Step 1 | C10: Make your own copy (File > Make a copy in Google Sheets).
B11: Step 2 | C11: Work through the Checklist tab phase by phase. Set Status, Owner and Notes as you go; mark anything that doesn't apply as N/A.
B12: Step 3 | C12: In phase 2, paste every old URL into column A of the Redirect map, with clicks and referring domains. Set your thresholds in the yellow cells at the top of that tab.
B13: Step 4 | C13: In phase 3, run a fuzzy-matching tool (see 'Which tool?' below) and paste its suggestions into columns E to J. Delete the example rows first.
B14: Step 5 | C14: Review each row and pick a Decision. Accepted rows use the suggestion; Override rows use the URL you type in column L. Columns M to P and T fill in automatically.
B15: Step 6 | C15: Before and after launch, crawl the old URLs in list mode and fill in Status code, Hops and 'Final URL returns 200?'. Move rows through QA status until they're 'Live and verified'.
B16: Step 7 | C16: Watch the Progress tab for open High-priority checks, undecided URLs and flags.
B18: Which fuzzy-matching tool?
B19: Under ~300 URLs | C19: Fuzzy Matching for SEO Google Sheets template (URL Redirection Mapping tab): www.mlforseo.com/resource/fuzzy-matching-for-seo-google-sheets-template/
B20: Old site vs new site | C20: Triple fuzzy matching redirect notebook: matches pre- and post-migration crawls on Address, Title 1, H1-1, H2-1, H2-2 and Meta Description 1 with three algorithms.
B21: 404s to live pages | C21: Mapping 404 URLs to live pages notebook: four algorithms on the URL path, outputs .htaccess rules (scores are 0 to 1, so multiply by 100 for column G).
B22: Python, free on GitHub | C22: fuzzy-matching-for-seo folder in lazarinastoy/mlforseo-code: redirect section outputs old_url, match, new_url, similarity, action.
B24: Pasting notebook output into the Redirect map
B25: Old URL (A) | C25: Pre-Migration value (triple notebook, Address rows) · 404 URL (404 notebook) · old_url (GitHub notebook) · old URL column (Sheets template)
B26: Matched on (E) | C26: The column that generated the match: Address, Title 1, H1-1, H2-1, H2-2 or Meta Description 1. For title or heading matches, look up the URL that belongs to the matched value in your crawl before pasting.
B27: Suggested new URL (F) | C27: Post-Migration match · live URL · new_url · most similar new URL
B28: Similarity (G) | C28: Similarity score on a 0 to 100 scale (multiply 0 to 1 scores by 100)
B29: Match type (H) | C29: Exact Match / Partial Match / No Suitable Match Found, or direct match / fuzzy match
B30: Algorithm (I), agreeing (J) | C30: PolyFuzz (TF-IDF), RapidFuzz, TheFuzz / FuzzyWuzzy, Levenshtein. Put the number of algorithms that suggested the same URL in J: agreement is a good sign.
B32: Status
B33: Not started | C33: Default for every check.
B34: In progress | C34: Someone is working on it.
B35: Done | C35: Checked, and fixed if it needed fixing.
B36: N/A | C36: Does not apply to this site. N/A rows are left out of the % complete.
B38: Priority
B39: High | C39: Skipping it risks lost traffic, broken indexing or lost link value.
B40: Medium | C40: Reduces risk and speeds up recovery.
B41: Low | C41: Tidy-up and documentation.
B43: Evidence levels
B44: Google-documented | C44: Stated in Google Search Central or Google Help documentation.
B45: Platform-documented | C45: Stated in another platform's own documentation (OpenAI, Anthropic, Perplexity, Microsoft Bing, Apple, Meta, Wikidata / Wikimedia, schema.org).
B46: Research-backed | C46: Supported by published research or a large public dataset. Results come from specific test conditions and may not carry over to every site.
B47: MLforSEO practice | C47: What we teach in MLforSEO courses and use in audits, based on how retrieval and entity systems work. Sensible and low-risk, but not confirmed by the platforms.
B48: Unconfirmed (optional) | C48: A cheap extra that no major platform has confirmed using. Do it last, if at all.
...

Sheet Checklist
A1: ID | B1: Phase | C1: Check | D1: Why it matters | E1: How to check (tool / where) | F1: Priority | G1: Evidence | H1: Status | I1: Owner | J1: Notes | K1: Learn more | L1: Official source
A2: M01 | B2: 1. Scope & plan | C2: Write down exactly what is changing: domain, protocol, URL structure, CMS, design, hosting | D2: Each kind of change carries different risks and needs different steps. A hosting move with no URL changes needs no redirects; a domain change needs redirects and the Change of Address tool. | E2: List every change in the Notes column. If URLs don't change, follow Google's 'moving hosting without URL changes' guide instead of this full process. | F2: High | G2: Google-documented | H2: Not started | L2: =HYPERLINK("https://developers.google.com/search/docs/crawling-indexing/site-move-with-url-changes","Google: how to move a site (URL changes)")
A3: M02 | B3: 1. Scope & plan | C3: Change one thing at a time where you can | D3: Google recommends moving domain first and redesigning later, for example. Stacking changes makes it hard to tell what caused a drop. | E3: Agree the order of changes with stakeholders. If everything must ship together, plan extra benchmarking and monitoring. | F3: Medium | G3: Google-documented | H3: Not started | L3: =HYPERLINK("https://developers.google.com/search/docs/crawling-indexing/site-move-with-url-changes","Google: how to move a site (URL changes)")
A4: M03 | B4: 1. Scope & plan | C4: Decide whether to move everything at once or in sections | D4: Google recommends moving small and medium sites all at once, and suggests large sites can move section by section to spot problems early. | E4: Size the site from a crawl and the sitemap. For large sites, pick a test section that changes rarely and isn't driven by unpredictable events. | F4: Medium | G4: Google-documented | H4: Not started | L4: =HYPERLINK("https://developers.google.com/search/docs/crawling-indexing/site-move-with-url-changes","Google: how to move a site (URL changes)")
A5: M04 | B5: 1. Scope & plan | C5: Pick a launch window in a quieter traffic period, with a freeze and a rollback plan | D5: Fewer users meet any problems, and more server capacity is left for Googlebot's extra crawling after the move. | E5: Check seasonality in analytics. Avoid launches before weekends or holidays. Agree a content and code freeze, who can sign off, and how to roll back. | F5: Medium | G5: Google-documented | H5: Not started | L5: =HYPERLINK("https://developers.google.com/search/docs/crawling-indexing/site-move-with-url-changes","Google: how to move a site (URL changes)")
A6: M05 | B6: 1. Scope & plan | C6: Set expectations: rankings fluctuate, and a medium site can take a few weeks or more to settle | D6: Google says visibility may fluctuate while it recrawls; medium sites can take a few weeks or more for new URLs to replace old ones, larger sites longer. Agreeing this upfront avoids panic decisions. | E6: Share the timeline and the KPIs you'll report on (indexed URLs, organic clicks by section, key conversions) with stakeholders before launch. | F6: Medium | G6: Google-documented | H6: Not started | L6: =HYPERLINK("https://developers.google.com/search/docs/crawling-indexing/site-move-with-url-changes","Google: how to move a site (URL changes)")
A7: M06 | B7: 1. Scope & plan | C7: Keep the old domain registered (at least a year, ideally for good) with a valid TLS certificate | D7: Google recommends paying for the old domain for at least a year so nobody else can buy and misuse it. Redirects from https:// URLs also need a working certificate on the old host. | E7: Check the registrar renewal date and auto-renew. Confirm the old host keeps serving HTTPS long enough to return the redirects. | F7: High | G7: Google-documented | H7: Not started | L7: =HYPERLINK("https://support.google.com/webmasters/answer/9370220","Google Help: Change of Address tool")
A8: M07 | B8: 2. Benchmark | C8: Crawl the old site in full and save the export | D8: The crawl is your record of what existed: URLs, status codes, titles, H1s, H2s, meta descriptions, canonicals, hreflang and structured data. It also feeds the fuzzy-matching notebook. | E8: Screaming Frog (or similar) with the Internal: HTML export; keep Address, Title 1, H1-1, H2-1, H2-2 and Meta Description 1 for redirect matching. Store the file with the launch date. | F8: High | G8: MLforSEO practice | H8: Not started | K8: =HYPERLINK("https://www.mlforseo.com/resource/automated-redirect-mapping-with-triple-fuzzy-matching-for-site-migrations-notebook/","Triple fuzzy matching redirect notebook")
A9: M08 | B9: 2. Benchmark | C9: Export Search Console and analytics data per URL | D9: You need before-and-after numbers by page and section, and the old property's data becomes harder to compare once URLs change. | E9: Search Console: page and query performance for the last 16 months, Page indexing report, Links report. GA4: landing pages with sessions and key events. | F9: High | G9: Google-documented | H9: Not started | L9: =HYPERLINK("https://developers.google.com/search/docs/crawling-indexing/site-move-with-url-changes","Google: how to move a site (URL changes)")
A10: M09 | B10: 2. Benchmark | C10: List every old URL that needs a decision, including images, PDFs and video | D10: Google suggests starting with your most important URLs and including embedded content such as images, videos, PDFs, JavaScript and CSS, which may be getting traffic or links. | E10: Combine sitemaps, the crawl, server logs, analytics landing pages, the Search Console Links report and a CMS export. Deduplicate into the Redirect map tab. | F10: High | G10: Google-documented | H10: Not started | K10: =HYPERLINK("https://www.mlforseo.com/machine-learning-tutorials/fuzzy-matching/404-and-redirect-mapping-with-fuzzy-matching-in-google-colab-python/","404 and redirect mapping with fuzzy matching") | L10: =HYPERLINK("https://developers.google.com/search/docs/crawling-indexing/site-move-with-url-changes","Google: how to move a site (URL changes)")
A11: M10 | B11: 2. Benchmark | C11: Export the pages with backlinks and save the list of linking sites | D11: Old URLs with links pass their value on through permanent redirects. You'll also contact the most valuable linking sites after launch. | E11: Search Console > Links (top linked pages and linking sites), plus Ahrefs or Semrush if you have them. Add referring domains to the Redirect map. | F11: High | G11: Google-documented | H11: Not started | L11: =HYPERLINK("https://developers.google.com/search/docs/crawling-indexing/site-move-with-url-changes","Google: how to move a site (URL changes)")
A12: M11 | B12: 2. Benchmark | C12: Record your AI search and SERP feature baseline | D12: Migrations can break the URLs AI assistants and SERP features cite. A baseline shows whether you lost citations, rich results or a knowledge panel link. | E12: Note rich results by type (Search Console Enhancements), AI Overview appearances for key queries, and a quick citation check in ChatGPT, Perplexity and Gemini for your top questions. | F12: Medium | G12: MLforSEO practice | H12: Not started | K12: =HYPERLINK("https://www.mlforseo.com/machine-learning-implementation-guides/ai-search-optimisation/rank-tracker-ai-search-measurement/","Your rank tracker is lying to you about AI search")
A13: M12 | B13: 3. Redirect mapping | C13: Map every old URL to its closest equivalent new URL, one to one where possible | D13: Relevant one-to-one redirects keep users and signals on the right page. Google recommends a full old-to-new mapping for any move beyond a simple domain swap. | E13: Use the Redirect map tab. For a straight domain change with identical paths, a wildcard rule may be enough; still test a sample. | F13: High | G13: Google-documented | H13: Not started | K13: =HYPERLINK("https://www.mlforseo.com/machine-learning-tutorials/fuzzy-matching/404-and-redirect-mapping-with-fuzzy-matching-in-google-colab-python/","404 and redirect mapping with fuzzy matching") | L13: =HYPERLINK("https://developers.google.com/search/docs/crawling-indexing/site-move-with-url-changes","Google: how to move a site (URL changes)")
A14: M13 | B14: 3. Redirect mapping | C14: Draft the map at scale with fuzzy matching, then review it | D14: Matching hundreds or thousands of URLs by hand takes days. Fuzzy matching on URL, title, H1, H2 and meta description shortlists the best candidates in minutes. | E14: Under about 300 URLs: the MLforSEO fuzzy matching Google Sheets template. Larger: the triple fuzzy matching notebook (old vs new crawl) or the 404 mapping notebook. Paste results into the Redirect map tab. | F14: Medium | G14: MLforSEO practice | H14: Not started | K14: =HYPERLINK("https://www.mlforseo.com/resource/automated-redirect-mapping-with-triple-fuzzy-matching-for-site-migrations-notebook/","Triple fuzzy matching redirect notebook") | L14: =HYPERLINK("https://www.mlforseo.com/resource/fuzzy-matching-for-seo-google-sheets-template/","Fuzzy matching Google Sheets template")
A15: M14 | B15: 3. Redirect mapping | C15: Review every partial or low-scoring match by hand | D15: String similarity has no understanding of meaning or intent. Two similar slugs can be different products; a strong score can still be wrong for the user. | E15: Sort the Redirect map by Similarity. Validate a sample to choose your own threshold, accept only above it, and set a Decision for everything below. Matches where several algorithms agree are safer. | F15: High | G15: MLforSEO practice | H15: Not started | K15: =HYPERLINK("https://www.mlforseo.com/machine-learning-tutorials/fuzzy-matching/404-and-redirect-mapping-with-fuzzy-matching-in-google-colab-python/","404 and redirect mapping with fuzzy matching")
A16: M15 | B16: 3. Redirect mapping | C16: Don't redirect lots of old URLs to the home page or an unrelated page | D16: Google may treat irrelevant redirects as soft 404s, and they confuse users. Redirecting several old pages to one new page that consolidates their content is fine. | E16: Check the Flags column in the Redirect map for 'Home page redirect'. For content with no equivalent, choose 410 or 404 instead. | F16: High | G16: Google-documented | H16: Not started | K16: =HYPERLINK("https://www.mlforseo.com/machine-learning-tutorials/fuzzy-matching/404-and-redirect-mapping-with-fuzzy-matching-in-google-colab-python/","404 and redirect mapping with fuzzy matching") | L16: =HYPERLINK("https://developers.google.com/search/docs/crawling-indexing/http-network-errors","Google: HTTP status codes and soft 404s")
A17: M16 | B17: 3. Redirect mapping | C17: Content you're retiring returns 404 or 410 | D17: Google's guide asks for a 404 or 410 on deleted content rather than a redirect to something unrelated. | E17: Set Decision to '410 Gone' or '404' in the Redirect map. Make sure the 404 page returns a real 404 status code. | F17: Medium | G17: Google-documented | H17: Not started | L17: =HYPERLINK("https://developers.google.com/search/docs/crawling-indexing/site-move-with-url-changes","Google: how to move a site (URL changes)")
A18: M17 | B18: 3. Redirect mapping | C18: Plan server-side permanent redirects (301 or 308) straight to the final URL | D18: Permanent redirects don't lose PageRank. Googlebot follows up to 10 hops, but Google advises redirecting to the final destination directly, and ideally no more than 3 hops. | E18: Agree the implementation with developers: server config (.htaccess, nginx), CDN rules or the CMS. Client-side (JavaScript or meta refresh) redirects are a last resort. | F18: High | G18: Google-documented | H18: Not started | L18: =HYPERLINK("https://developers.google.com/search/docs/crawling-indexing/301-redirects","Google: redirects and Google Search")
A19: M18 | B19: 3. Redirect mapping | C19: Update existing redirects so they point at the new final URLs | D19: Redirects from earlier migrations will otherwise chain through the old site (old > older > new). | E19: Export current redirect rules, run them through the same mapping, and rewrite each to point directly at the new destination. | F19: Medium | G19: Google-documented | H19: Not started | L19: =HYPERLINK("https://developers.google.com/search/docs/crawling-indexing/site-move-with-url-changes","Google: how to move a site (URL changes)")
A20: M19 | B20: 4. Pre-launch (staging) | C20: Keep staging out of search, and list exactly what to unblock at launch | D20: Staging sites get indexed by accident. Google's guide notes that if you block crawling or use noindex during development, you need a ready list of what to remove at launch. | E20: Password-protect staging (HTTP authentication) where possible. If you use noindex or robots.txt blocks, record each one in Notes so none are left behind. | F20: High | G20: Google-documented | H20: Not started | L20: =HYPERLINK("https://developers.google.com/search/docs/crawling-indexing/site-move-with-url-changes","Google: how to move a site (URL changes)")
A21: M20 | B21: 4. Pre-launch (staging) | C21: Crawl staging and compare it with the old-site crawl | D21: Missing pages, empty titles, lost H1s, dropped structured data or thinner content show up in a side-by-side comparison before they cost traffic. | E21: Crawl staging (with authentication) and compare URL counts, titles, H1s, meta descriptions, word counts and structured data by template with the benchmark crawl. | F21: High | G21: MLforSEO practice | H21: Not started | K21: =HYPERLINK("https://www.mlforseo.com/machine-learning-implementation-guides/content-audit/web-scraping-screaming-frog/","Web scraping with Screaming Frog")
A22: M21 | B22: 4. Pre-launch (staging) | C22: Every new URL has a self-referencing canonical, and hreflang uses the new URLs | D22: Canonicals or hreflang still pointing at old or staging URLs send mixed signals about which version to index. | E22: Crawl staging and check canonical and hreflang targets. None should point to the staging host or the old domain. | F22: High | G22: Google-documented | H22: Not started | L22: =HYPERLINK("https://developers.google.com/search/docs/crawling-indexing/consolidate-duplicate-urls","Google: canonical URLs")
A23: M22 | B23: 4. Pre-launch (staging) | C23: Internal links point straight at new URLs, not through redirects | D23: Updating internal links reduces redirect load and helps Google find the new URLs faster. | E23: Use the mapping to find-and-replace links in content, navigation, footers and templates. Crawl staging and filter internal links returning 3xx. | F23: High | G23: Google-documented | H23: Not started | L23: =HYPERLINK("https://developers.google.com/search/docs/crawling-indexing/site-move-with-url-changes","Google: how to move a site (URL changes)")
A24: M23 | B24: 4. Pre-launch (staging) | C24: A sitemap of the new URLs is ready, plus one of the old URLs | D24: Submitting the new sitemap helps Google discover the new URLs. Google's guide also suggests submitting the old-URL sitemap so you can watch old URLs drop out (redirect warnings there are expected). | E24: Generate the new XML sitemap (indexable 200 URLs only). Keep the old sitemap file from the benchmark. | F24: Medium | G24: Google-documented | H24: Not started | L24: =HYPERLINK("https://developers.google.com/search/docs/crawling-indexing/sitemaps/build-sitemap","Google: build a sitemap")
A25: M24 | B25: 4. Pre-launch (staging) | C25: The new robots.txt is ready and keeps your AI crawler decisions | D25: A robots.txt copied from staging can block the whole site. Rebuilds also tend to drop rules for AI search crawlers (OAI-SearchBot, PerplexityBot, Claude-SearchBot), or a CDN default may start blocking them. | E25: Prepare the production robots.txt in advance and diff it against the old one. Check CDN bot settings on the new setup. If you publish llms.txt, update its URLs. | F25: Medium | G25: Google-documented | H25: Not started | K25: =HYPERLINK("https://www.mlforseo.com/machine-learning-implementation-guides/ai-search-optimisation/robots-txt-silent-killer-ai-traffic/","Your robots.txt might be the silent killer of your AI traffic") | L25: =HYPERLINK("https://developers.google.com/search/docs/crawling-indexing/robots/intro","Google: robots.txt introduction")
A26: M25 | B26: 4. Pre-launch (staging) | C26: Structured data uses new URLs, and entity @id values stay stable | D26: Markup often hard-codes URLs (url, logo, sameAs, breadcrumbs, @id). If @id values change, the connections between your entities break. | E26: Search templates and the CMS for the old domain in JSON-LD. Keep @id values unchanged, or map them deliberately if they were built from page URLs. | F26: Medium | G26: MLforSEO practice | H26: Not started | K26: =HYPERLINK("https://www.mlforseo.com/machine-learning-implementation-guides/structured-data-audit/what-schema-org-id-does-and-why-your-entity-graph-falls-apart-without-it/","What schema.org @id does")
A27: M26 | B27: 4. Pre-launch (staging) | C27: Analytics, tag manager and Search Console verification work on the new templates | D27: Missing tracking on launch day leaves a hole in your data. Search Console verification can break if the HTML file or meta tag isn't carried over. | E27: Test tags on staging. Verify both old and new sites in Search Console, including all variants (www and non-www, http and https). | F27: High | G27: Google-documented | H27: Not started | L27: =HYPERLINK("https://developers.google.com/search/docs/crawling-indexing/site-move-with-url-changes","Google: how to move a site (URL changes)")
A28: M27 | B28: 4. Pre-launch (staging) | C28: The server and CDN can handle extra crawling | D28: Google says it will temporarily crawl the new site more heavily than usual after a move. Slow or failing responses slow down the whole migration. | E28: Warn your host for large sites. Make sure rate limits and WAF rules allow verified Googlebot and Bingbot. | F28: Medium | G28: Google-documented | H28: Not started | L28: =HYPERLINK("https://developers.google.com/search/docs/crawling-indexing/site-move-with-url-changes","Google: how to move a site (URL changes)")
A29: M28 | B29: 4. Pre-launch (staging) | C29: If the new domain was bought second-hand, check its history | D29: A previous owner may have left manual actions or URL removal requests in place. | E29: Verify the new domain in Search Console and check Manual actions and Removals before launch. | F29: Medium | G29: Google-documented | H29: Not started | L29: =HYPERLINK("https://developers.google.com/search/docs/crawling-indexing/site-move-with-url-changes","Google: how to move a site (URL changes)")
A30: M29 | B30: 4. Pre-launch (staging) | C30: Test the full redirect map on staging | D30: Mistakes in rules (wrong destinations, loops, chains, missing trailing slashes, lost query strings) are cheapest to fix before launch. | E30: Crawl the list of old URLs against staging in list mode with redirects followed. Fill in Status code, Hops and Final URL returns 200 in the Redirect map. | F30: High | G30: MLforSEO practice | H30: Not started | K30: =HYPERLINK("https://www.mlforseo.com/machine-learning-tutorials/fuzzy-matching/404-and-redirect-mapping-with-fuzzy-matching-in-google-colab-python/","404 and redirect mapping with fuzzy matching")
A31: M30 | B31: 5. Launch day | C31: Switch on the redirects and remove the staging blocks | D31: Leftover noindex tags or robots.txt blocks are one of the most common reasons a new site fails to get indexed. | E31: Deploy redirects; remove noindex and authentication; publish the production robots.txt. Spot-check with URL Inspection. | F31: High | G31: Google-documented | H31: Not started | L31: =HYPERLINK("https://developers.google.com/search/docs/crawling-indexing/site-move-with-url-changes","Google: how to move a site (URL changes)")
A32: M31 | B32: 5. Launch day | C32: Crawl every old URL: each returns 301 or 308 in one hop to a URL that returns 200 | D32: Google frequently sees redirects pointing to wrong or non-existent URLs. A list crawl catches them in minutes. | E32: List-mode crawl of all old URLs with redirects followed. Filter for chains, loops, 4xx and 5xx destinations and anything not matching the Final destination column. | F32: High | G32: Google-documented | H32: Not started | K32: =HYPERLINK("https://www.mlforseo.com/machine-learning-tutorials/fuzzy-matching/404-and-redirect-mapping-with-fuzzy-matching-in-google-colab-python/","404 and redirect mapping with fuzzy matching") | L32: =HYPERLINK("https://developers.google.com/search/docs/crawling-indexing/site-move-with-url-changes","Google: how to move a site (URL changes)")
A33: M32 | B33: 5. Launch day | C33: Domain or subdomain change: submit Change of Address for every verified variant | D33: The tool tells Google to prefer the new site and forwards signals for 180 days. You don't need it for HTTP to HTTPS, www to non-www, or path changes on the same domain. | E33: Search Console > Settings > Change of Address on the old domain-level property. Repeat for www, non-www and any subdomains, even unused ones. | F33: High | G33: Google-documented | H33: Not started | L33: =HYPERLINK("https://support.google.com/webmasters/answer/9370220","Google Help: Change of Address tool")
A34: M33 | B34: 5. Launch day | C34: Submit sitemaps in Search Console and Bing Webmaster Tools, and ping IndexNow | D34: Sitemaps speed up discovery in Google. Bing Webmaster Tools has its own site move tool, and IndexNow notifies Bing and other participating engines of changed URLs. | E34: Submit the new sitemap (and the old-URL sitemap) in both tools. Use Bing's site move tool for domain changes. Send old and new URLs through IndexNow. | F34: Medium | G34: Platform-documented | H34: Not started | K34: =HYPERLINK("https://www.mlforseo.com/machine-learning-implementation-guides/indexnow-api-python/","The IndexNow API guide") | L34: =HYPERLINK("https://www.bing.com/webmasters/","Bing Webmaster Tools")
A35: M34 | B35: 5. Launch day | C35: Re-upload any disavow file to the new property | D35: Google recommends re-uploading the old site's disavow file to the new Search Console property if you used one. | E35: Download it from the old property's disavow tool and upload to the new one. | F35: Low | G35: Google-documented | H35: Not started | L35: =HYPERLINK("https://developers.google.com/search/docs/crawling-indexing/site-move-with-url-changes","Google: how to move a site (URL changes)")
A36: M35 | B36: 5. Launch day | C36: Inspect one URL from each key template | D36: Confirms Googlebot sees the right rendered content, canonical and indexability on the live site. | E36: Search Console > URL Inspection > Test live URL for the home page, a category, a product or service page and an article. | F36: High | G36: Google-documented | H36: Not started | L36: =HYPERLINK("https://developers.google.com/search/docs/crawling-indexing/site-move-with-url-changes","Google: how to move a site (URL changes)")
A37: M36 | B37: 6. First weeks | C37: Monitor indexing, crawl stats and errors every day for the first two weeks | D37: Old URLs should drop out while new ones are indexed. Spikes in 404s, 5xx errors or 'Page with redirect' on new URLs need fixing fast. | E37: Search Console: Page indexing (old and new properties), Sitemaps, Crawl stats. Server logs: Googlebot status codes on old and new URLs. | F37: High | G37: Google-documented | H37: Not started | L37: =HYPERLINK("https://developers.google.com/search/docs/crawling-indexing/site-move-with-url-changes","Google: how to move a site (URL changes)")
A38: M37 | B38: 6. First weeks | C38: Fix 404s on old URLs that have traffic or links within days | D38: Each one is lost value and a broken journey. The 404 notebook can map a new batch of broken URLs to live pages quickly. | E38: Pull 404s from Search Console, logs and the analytics 404 page. Map them with the Redirect map tab or the 404 mapping notebook and deploy in batches. | F38: High | G38: MLforSEO practice | H38: Not started | K38: =HYPERLINK("https://www.mlforseo.com/resource/mapping-404-urls-to-live-pages-with-fuzzy-matching-guide/","Mapping 404s to live pages (notebook)")
A39: M38 | B39: 6. First weeks | C39: Update the links you control and ask for the important external ones to change | D39: Redirects are slow for users. Google suggests updating profile links, ad campaigns and high-value backlinks to point straight at new URLs. | E39: Update social profiles, Business Profile, Wikidata 'official website', Crunchbase, email templates, ads and partner pages. Contact the top linking sites from your benchmark list. | F39: Medium | G39: Google-documented | H39: Not started | K39: =HYPERLINK("https://www.mlforseo.com/machine-learning-implementation-guides/ai-search-optimisation/cross-platform-entity-consistency-the-llm-era/","Cross-platform entity consistency") | L39: =HYPERLINK("https://developers.google.com/search/docs/crawling-indexing/site-move-with-url-changes","Google: how to move a site (URL changes)")
A40: M39 | B40: 6. First weeks | C40: Compare organic traffic and conversions with the benchmark by section | D40: Sitewide totals hide problems. Section or template comparisons show exactly where something broke. | E40: Weekly: clicks, impressions and key events by section, against the same weeks last year and the pre-launch baseline. Annotate the launch date in GA4 and your reports. | F40: Medium | G40: MLforSEO practice | H40: Not started | L40: =HYPERLINK("https://developers.google.com/search/docs/crawling-indexing/site-move-with-url-changes","Google: how to move a site (URL changes)")
...

Sheet Redirect map
A1: Paste old URLs in column A and fuzzy-matching suggestions in E to J (see Start here for the column mapping). Pick a Decision in K. Grey-headed columns (D, M, N, O, P, T) are formulas: don't type over them. Delete the four example rows before you start.
A2: Settings (edit the yellow cells): | B2: High priority if clicks ≥ | C2: 100 | D2: or referring domains ≥ | E2: 5 | F2: Flag accepted matches with similarity below | G2: 70
A4: Old URL | B4: Clicks (last 12 months) | C4: Referring domains | D4: Old URL priority | E4: Matched on | F4: Suggested new URL (from notebook) | G4: Similarity (0 to 100) | H4: Match type (from notebook) | I4: Algorithm | J4: Algorithms agreeing | K4: Decision | L4: Override URL | M4: Final destination | N4: Redirect type | O4: Source path | P4: Apache rule (check before use) | Q4: Status code at test | R4: Hops | S4: Final URL returns 200? | T4: Flags | U4: QA status | V4: Reviewer | W4: Notes
A5: https://old.example.com/blog/how-to-choose-running-shoes/ | B5: 420 | C5: 12 | D5: =IF(A5="","",IF(OR(N(B5)>=$C$2,N(C5)>=$E$2),"High",IF(OR(N(B5)>0,N(C5)>0),"Medium","Low"))) | E5: Address | F5: https://www.example.com/guides/choosing-running-shoes/ | G5: 82 | H5: Partial Match | I5: RapidFuzz | J5: 3 | K5: Accept suggestion | M5: =IF(K5="Override",L5,IF(K5="Accept suggestion",F5,IF(K5="No change (same URL)",A5,""))) | N5: =IF(A5="","",IF(K5="410 Gone","410",IF(K5="404","404",IF(K5="No change (same URL)","none",IF(M5="","","301"))))) | O5: =IF(A5="","",IFERROR(MID(A5,FIND("/",A5,FIND("//",A5)+2),2000),A5)) | P5: =IF(OR(O5="",N5="",N5="none",N5="404"),"",IF(N5="410","Redirect gone "&O5,"Redirect "&N5&" "&O5&" "&M5)) | Q5: 301 | R5: 1 | S5: Yes | T5: =IF(A5="","",TRIM(IF(K5="","Needs decision; ","")&IF(AND(K5="Accept suggestion",F5=""),"No suggestion to accept; ","")&IF(AND(K5="Override",L5=""),"Override URL missing; ","")&IF(AND(K5="Accept suggestion",N(G5)<$G$2),"Below your threshold; ","")&IF(AND(M5<>"",M5=A5,K5<>"No change (same URL)"),"Redirects to itself; ","")&IF(AND(M5<>"",OR(M5="/",AND(LEFT(M5,4)="http",OR((LEN(M5)-LEN(SUBSTITUTE(M5,"/","")))=2,AND((LEN(M5)-LEN(SUBSTITUTE(M5,"/","")))=3,RIGHT(M5,1)="/"))))),"Home page redirect; ","")&IF(N(R5)>1,"Chain; ","")&IF(S5="No","Destination not 200; ",""))) | U5: Live and verified | V5: LS | W5: EXAMPLE ROW: delete.
A6: https://old.example.com/products/trail-runner-2/ | B6: 95 | C6: 3 | D6: =IF(A6="","",IF(OR(N(B6)>=$C$2,N(C6)>=$E$2),"High",IF(OR(N(B6)>0,N(C6)>0),"Medium","Low"))) | E6: Title 1 | F6: https://www.example.com/shop/trail-runner-3/ | G6: 71 | H6: Partial Match | I6: PolyFuzz (TF-IDF) | J6: 1 | K6: Override | L6: https://www.example.com/shop/trail-runners/ | M6: =IF(K6="Override",L6,IF(K6="Accept suggestion",F6,IF(K6="No change (same URL)",A6,""))) | N6: =IF(A6="","",IF(K6="410 Gone","410",IF(K6="404","404",IF(K6="No change (same URL)","none",IF(M6="","","301"))))) | O6: =IF(A6="","",IFERROR(MID(A6,FIND("/",A6,FIND("//",A6)+2),2000),A6)) | P6: =IF(OR(O6="",N6="",N6="none",N6="404"),"",IF(N6="410","Redirect gone "&O6,"Redirect "&N6&" "&O6&" "&M6)) | T6: =IF(A6="","",TRIM(IF(K6="","Needs decision; ","")&IF(AND(K6="Accept suggestion",F6=""),"No suggestion to accept; ","")&IF(AND(K6="Override",L6=""),"Override URL missing; ","")&IF(AND(K6="Accept suggestion",N(G6)<$G$2),"Below your threshold; ","")&IF(AND(M6<>"",M6=A6,K6<>"No change (same URL)"),"Redirects to itself; ","")&IF(AND(M6<>"",OR(M6="/",AND(LEFT(M6,4)="http",OR((LEN(M6)-LEN(SUBSTITUTE(M6,"/","")))=2,AND((LEN(M6)-LEN(SUBSTITUTE(M6,"/","")))=3,RIGHT(M6,1)="/"))))),"Home page redirect; ","")&IF(N(R6)>1,"Chain; ","")&IF(S6="No","Destination not 200; ",""))) | U6: Approved | V6: LS | W6: EXAMPLE ROW: delete. Model discontinued, category is the closest match.
A7: https://old.example.com/2019-summer-sale/ | B7: 0 | C7: 0 | D7: =IF(A7="","",IF(OR(N(B7)>=$C$2,N(C7)>=$E$2),"High",IF(OR(N(B7)>0,N(C7)>0),"Medium","Low"))) | E7: Address | F7: https://www.example.com/ | G7: 38 | H7: No Suitable Match Found | I7: RapidFuzz | J7: 1 | K7: 410 Gone | M7: =IF(K7="Override",L7,IF(K7="Accept suggestion",F7,IF(K7="No change (same URL)",A7,""))) | N7: =IF(A7="","",IF(K7="410 Gone","410",IF(K7="404","404",IF(K7="No change (same URL)","none",IF(M7="","","301"))))) | O7: =IF(A7="","",IFERROR(MID(A7,FIND("/",A7,FIND("//",A7)+2),2000),A7)) | P7: =IF(OR(O7="",N7="",N7="none",N7="404"),"",IF(N7="410","Redirect gone "&O7,"Redirect "&N7&" "&O7&" "&M7)) | T7: =IF(A7="","",TRIM(IF(K7="","Needs decision; ","")&IF(AND(K7="Accept suggestion",F7=""),"No suggestion to accept; ","")&IF(AND(K7="Override",L7=""),"Override URL missing; ","")&IF(AND(K7="Accept suggestion",N(G7)<$G$2),"Below your threshold; ","")&IF(AND(M7<>"",M7=A7,K7<>"No change (same URL)"),"Redirects to itself; ","")&IF(AND(M7<>"",OR(M7="/",AND(LEFT(M7,4)="http",OR((LEN(M7)-LEN(SUBSTITUTE(M7,"/","")))=2,AND((LEN(M7)-LEN(SUBSTITUTE(M7,"/","")))=3,RIGHT(M7,1)="/"))))),"Home page redirect; ","")&IF(N(R7)>1,"Chain; ","")&IF(S7="No","Destination not 200; ",""))) | U7: Approved | V7: LS | W7: EXAMPLE ROW: delete. Expired promotion.
A8: https://old.example.com/about-us/ | B8: 60 | C8: 25 | D8: =IF(A8="","",IF(OR(N(B8)>=$C$2,N(C8)>=$E$2),"High",IF(OR(N(B8)>0,N(C8)>0),"Medium","Low"))) | E8: H1-1 | F8: https://www.example.com/about/ | G8: 100 | H8: Exact Match | I8: TheFuzz | J8: 3 | M8: =IF(K8="Override",L8,IF(K8="Accept suggestion",F8,IF(K8="No change (same URL)",A8,""))) | N8: =IF(A8="","",IF(K8="410 Gone","410",IF(K8="404","404",IF(K8="No change (same URL)","none",IF(M8="","","301"))))) | O8: =IF(A8="","",IFERROR(MID(A8,FIND("/",A8,FIND("//",A8)+2),2000),A8)) | P8: =IF(OR(O8="",N8="",N8="none",N8="404"),"",IF(N8="410","Redirect gone "&O8,"Redirect "&N8&" "&O8&" "&M8)) | T8: =IF(A8="","",TRIM(IF(K8="","Needs decision; ","")&IF(AND(K8="Accept suggestion",F8=""),"No suggestion to accept; ","")&IF(AND(K8="Override",L8=""),"Override URL missing; ","")&IF(AND(K8="Accept suggestion",N(G8)<$G$2),"Below your threshold; ","")&IF(AND(M8<>"",M8=A8,K8<>"No change (same URL)"),"Redirects to itself; ","")&IF(AND(M8<>"",OR(M8="/",AND(LEFT(M8,4)="http",OR((LEN(M8)-LEN(SUBSTITUTE(M8,"/","")))=2,AND((LEN(M8)-LEN(SUBSTITUTE(M8,"/","")))=3,RIGHT(M8,1)="/"))))),"Home page redirect; ","")&IF(N(R8)>1,"Chain; ","")&IF(S8="No","Destination not 200; ",""))) | U8: To review | W8: EXAMPLE ROW: delete.
D9: =IF(A9="","",IF(OR(N(B9)>=$C$2,N(C9)>=$E$2),"High",IF(OR(N(B9)>0,N(C9)>0),"Medium","Low"))) | M9: =IF(K9="Override",L9,IF(K9="Accept suggestion",F9,IF(K9="No change (same URL)",A9,""))) | N9: =IF(A9="","",IF(K9="410 Gone","410",IF(K9="404","404",IF(K9="No change (same URL)","none",IF(M9="","","301"))))) | O9: =IF(A9="","",IFERROR(MID(A9,FIND("/",A9,FIND("//",A9)+2),2000),A9)) | P9: =IF(OR(O9="",N9="",N9="none",N9="404"),"",IF(N9="410","Redirect gone "&O9,"Redirect "&N9&" "&O9&" "&M9)) | T9: =IF(A9="","",TRIM(IF(K9="","Needs decision; ","")&IF(AND(K9="Accept suggestion",F9=""),"No suggestion to accept; ","")&IF(AND(K9="Override",L9=""),"Override URL missing; ","")&IF(AND(K9="Accept suggestion",N(G9)<$G$2),"Below your threshold; ","")&IF(AND(M9<>"",M9=A9,K9<>"No change (same URL)"),"Redirects to itself; ","")&IF(AND(M9<>"",OR(M9="/",AND(LEFT(M9,4)="http",OR((LEN(M9)-LEN(SUBSTITUTE(M9,"/","")))=2,AND((LEN(M9)-LEN(SUBSTITUTE(M9,"/","")))=3,RIGHT(M9,1)="/"))))),"Home page redirect; ","")&IF(N(R9)>1,"Chain; ","")&IF(S9="No","Destination not 200; ","")))
D10: =IF(A10="","",IF(OR(N(B10)>=$C$2,N(C10)>=$E$2),"High",IF(OR(N(B10)>0,N(C10)>0),"Medium","Low"))) | M10: =IF(K10="Override",L10,IF(K10="Accept suggestion",F10,IF(K10="No change (same URL)",A10,""))) | N10: =IF(A10="","",IF(K10="410 Gone","410",IF(K10="404","404",IF(K10="No change (same URL)","none",IF(M10="","","301"))))) | O10: =IF(A10="","",IFERROR(MID(A10,FIND("/",A10,FIND("//",A10)+2),2000),A10)) | P10: =IF(OR(O10="",N10="",N10="none",N10="404"),"",IF(N10="410","Redirect gone "&O10,"Redirect "&N10&" "&O10&" "&M10)) | T10: =IF(A10="","",TRIM(IF(K10="","Needs decision; ","")&IF(AND(K10="Accept suggestion",F10=""),"No suggestion to accept; ","")&IF(AND(K10="Override",L10=""),"Override URL missing; ","")&IF(AND(K10="Accept suggestion",N(G10)<$G$2),"Below your threshold; ","")&IF(AND(M10<>"",M10=A10,K10<>"No change (same URL)"),"Redirects to itself; ","")&IF(AND(M10<>"",OR(M10="/",AND(LEFT(M10,4)="http",OR((LEN(M10)-LEN(SUBSTITUTE(M10,"/","")))=2,AND((LEN(M10)-LEN(SUBSTITUTE(M10,"/","")))=3,RIGHT(M10,1)="/"))))),"Home page redirect; ","")&IF(N(R10)>1,"Chain; ","")&IF(S10="No","Destination not 200; ","")))
D11: =IF(A11="","",IF(OR(N(B11)>=$C$2,N(C11)>=$E$2),"High",IF(OR(N(B11)>0,N(C11)>0),"Medium","Low"))) | M11: =IF(K11="Override",L11,IF(K11="Accept suggestion",F11,IF(K11="No change (same URL)",A11,""))) | N11: =IF(A11="","",IF(K11="410 Gone","410",IF(K11="404","404",IF(K11="No change (same URL)","none",IF(M11="","","301"))))) | O11: =IF(A11="","",IFERROR(MID(A11,FIND("/",A11,FIND("//",A11)+2),2000),A11)) | P11: =IF(OR(O11="",N11="",N11="none",N11="404"),"",IF(N11="410","Redirect gone "&O11,"Redirect "&N11&" "&O11&" "&M11)) | T11: =IF(A11="","",TRIM(IF(K11="","Needs decision; ","")&IF(AND(K11="Accept suggestion",F11=""),"No suggestion to accept; ","")&IF(AND(K11="Override",L11=""),"Override URL missing; ","")&IF(AND(K11="Accept suggestion",N(G11)<$G$2),"Below your threshold; ","")&IF(AND(M11<>"",M11=A11,K11<>"No change (same URL)"),"Redirects to itself; ","")&IF(AND(M11<>"",OR(M11="/",AND(LEFT(M11,4)="http",OR((LEN(M11)-LEN(SUBSTITUTE(M11,"/","")))=2,AND((LEN(M11)-LEN(SUBSTITUTE(M11,"/","")))=3,RIGHT(M11,1)="/"))))),"Home page redirect; ","")&IF(N(R11)>1,"Chain; ","")&IF(S11="No","Destination not 200; ","")))
D12: =IF(A12="","",IF(OR(N(B12)>=$C$2,N(C12)>=$E$2),"High",IF(OR(N(B12)>0,N(C12)>0),"Medium","Low"))) | M12: =IF(K12="Override",L12,IF(K12="Accept suggestion",F12,IF(K12="No change (same URL)",A12,""))) | N12: =IF(A12="","",IF(K12="410 Gone","410",IF(K12="404","404",IF(K12="No change (same URL)","none",IF(M12="","","301"))))) | O12: =IF(A12="","",IFERROR(MID(A12,FIND("/",A12,FIND("//",A12)+2),2000),A12)) | P12: =IF(OR(O12="",N12="",N12="none",N12="404"),"",IF(N12="410","Redirect gone "&O12,"Redirect "&N12&" "&O12&" "&M12)) | T12: =IF(A12="","",TRIM(IF(K12="","Needs decision; ","")&IF(AND(K12="Accept suggestion",F12=""),"No suggestion to accept; ","")&IF(AND(K12="Override",L12=""),"Override URL missing; ","")&IF(AND(K12="Accept suggestion",N(G12)<$G$2),"Below your threshold; ","")&IF(AND(M12<>"",M12=A12,K12<>"No change (same URL)"),"Redirects to itself; ","")&IF(AND(M12<>"",OR(M12="/",AND(LEFT(M12,4)="http",OR((LEN(M12)-LEN(SUBSTITUTE(M12,"/","")))=2,AND((LEN(M12)-LEN(SUBSTITUTE(M12,"/","")))=3,RIGHT(M12,1)="/"))))),"Home page redirect; ","")&IF(N(R12)>1,"Chain; ","")&IF(S12="No","Destination not 200; ","")))
D13: =IF(A13="","",IF(OR(N(B13)>=$C$2,N(C13)>=$E$2),"High",IF(OR(N(B13)>0,N(C13)>0),"Medium","Low"))) | M13: =IF(K13="Override",L13,IF(K13="Accept suggestion",F13,IF(K13="No change (same URL)",A13,""))) | N13: =IF(A13="","",IF(K13="410 Gone","410",IF(K13="404","404",IF(K13="No change (same URL)","none",IF(M13="","","301"))))) | O13: =IF(A13="","",IFERROR(MID(A13,FIND("/",A13,FIND("//",A13)+2),2000),A13)) | P13: =IF(OR(O13="",N13="",N13="none",N13="404"),"",IF(N13="410","Redirect gone "&O13,"Redirect "&N13&" "&O13&" "&M13)) | T13: =IF(A13="","",TRIM(IF(K13="","Needs decision; ","")&IF(AND(K13="Accept suggestion",F13=""),"No suggestion to accept; ","")&IF(AND(K13="Override",L13=""),"Override URL missing; ","")&IF(AND(K13="Accept suggestion",N(G13)<$G$2),"Below your threshold; ","")&IF(AND(M13<>"",M13=A13,K13<>"No change (same URL)"),"Redirects to itself; ","")&IF(AND(M13<>"",OR(M13="/",AND(LEFT(M13,4)="http",OR((LEN(M13)-LEN(SUBSTITUTE(M13,"/","")))=2,AND((LEN(M13)-LEN(SUBSTITUTE(M13,"/","")))=3,RIGHT(M13,1)="/"))))),"Home page redirect; ","")&IF(N(R13)>1,"Chain; ","")&IF(S13="No","Destination not 200; ","")))
D14: =IF(A14="","",IF(OR(N(B14)>=$C$2,N(C14)>=$E$2),"High",IF(OR(N(B14)>0,N(C14)>0),"Medium","Low"))) | M14: =IF(K14="Override",L14,IF(K14="Accept suggestion",F14,IF(K14="No change (same URL)",A14,""))) | N14: =IF(A14="","",IF(K14="410 Gone","410",IF(K14="404","404",IF(K14="No change (same URL)","none",IF(M14="","","301"))))) | O14: =IF(A14="","",IFERROR(MID(A14,FIND("/",A14,FIND("//",A14)+2),2000),A14)) | P14: =IF(OR(O14="",N14="",N14="none",N14="404"),"",IF(N14="410","Redirect gone "&O14,"Redirect "&N14&" "&O14&" "&M14)) | T14: =IF(A14="","",TRIM(IF(K14="","Needs decision; ","")&IF(AND(K14="Accept suggestion",F14=""),"No suggestion to accept; ","")&IF(AND(K14="Override",L14=""),"Override URL missing; ","")&IF(AND(K14="Accept suggestion",N(G14)<$G$2),"Below your threshold; ","")&IF(AND(M14<>"",M14=A14,K14<>"No change (same URL)"),"Redirects to itself; ","")&IF(AND(M14<>"",OR(M14="/",AND(LEFT(M14,4)="http",OR((LEN(M14)-LEN(SUBSTITUTE(M14,"/","")))=2,AND((LEN(M14)-LEN(SUBSTITUTE(M14,"/","")))=3,RIGHT(M14,1)="/"))))),"Home page redirect; ","")&IF(N(R14)>1,"Chain; ","")&IF(S14="No","Destination not 200; ","")))
D15: =IF(A15="","",IF(OR(N(B15)>=$C$2,N(C15)>=$E$2),"High",IF(OR(N(B15)>0,N(C15)>0),"Medium","Low"))) | M15: =IF(K15="Override",L15,IF(K15="Accept suggestion",F15,IF(K15="No change (same URL)",A15,""))) | N15: =IF(A15="","",IF(K15="410 Gone","410",IF(K15="404","404",IF(K15="No change (same URL)","none",IF(M15="","","301"))))) | O15: =IF(A15="","",IFERROR(MID(A15,FIND("/",A15,FIND("//",A15)+2),2000),A15)) | P15: =IF(OR(O15="",N15="",N15="none",N15="404"),"",IF(N15="410","Redirect gone "&O15,"Redirect "&N15&" "&O15&" "&M15)) | T15: =IF(A15="","",TRIM(IF(K15="","Needs decision; ","")&IF(AND(K15="Accept suggestion",F15=""),"No suggestion to accept; ","")&IF(AND(K15="Override",L15=""),"Override URL missing; ","")&IF(AND(K15="Accept suggestion",N(G15)<$G$2),"Below your threshold; ","")&IF(AND(M15<>"",M15=A15,K15<>"No change (same URL)"),"Redirects to itself; ","")&IF(AND(M15<>"",OR(M15="/",AND(LEFT(M15,4)="http",OR((LEN(M15)-LEN(SUBSTITUTE(M15,"/","")))=2,AND((LEN(M15)-LEN(SUBSTITUTE(M15,"/","")))=3,RIGHT(M15,1)="/"))))),"Home page redirect; ","")&IF(N(R15)>1,"Chain; ","")&IF(S15="No","Destination not 200; ","")))
D16: =IF(A16="","",IF(OR(N(B16)>=$C$2,N(C16)>=$E$2),"High",IF(OR(N(B16)>0,N(C16)>0),"Medium","Low"))) | M16: =IF(K16="Override",L16,IF(K16="Accept suggestion",F16,IF(K16="No change (same URL)",A16,""))) | N16: =IF(A16="","",IF(K16="410 Gone","410",IF(K16="404","404",IF(K16="No change (same URL)","none",IF(M16="","","301"))))) | O16: =IF(A16="","",IFERROR(MID(A16,FIND("/",A16,FIND("//",A16)+2),2000),A16)) | P16: =IF(OR(O16="",N16="",N16="none",N16="404"),"",IF(N16="410","Redirect gone "&O16,"Redirect "&N16&" "&O16&" "&M16)) | T16: =IF(A16="","",TRIM(IF(K16="","Needs decision; ","")&IF(AND(K16="Accept suggestion",F16=""),"No suggestion to accept; ","")&IF(AND(K16="Override",L16=""),"Override URL missing; ","")&IF(AND(K16="Accept suggestion",N(G16)<$G$2),"Below your threshold; ","")&IF(AND(M16<>"",M16=A16,K16<>"No change (same URL)"),"Redirects to itself; ","")&IF(AND(M16<>"",OR(M16="/",AND(LEFT(M16,4)="http",OR((LEN(M16)-LEN(SUBSTITUTE(M16,"/","")))=2,AND((LEN(M16)-LEN(SUBSTITUTE(M16,"/","")))=3,RIGHT(M16,1)="/"))))),"Home page redirect; ","")&IF(N(R16)>1,"Chain; ","")&IF(S16="No","Destination not 200; ","")))
D17: =IF(A17="","",IF(OR(N(B17)>=$C$2,N(C17)>=$E$2),"High",IF(OR(N(B17)>0,N(C17)>0),"Medium","Low"))) | M17: =IF(K17="Override",L17,IF(K17="Accept suggestion",F17,IF(K17="No change (same URL)",A17,""))) | N17: =IF(A17="","",IF(K17="410 Gone","410",IF(K17="404","404",IF(K17="No change (same URL)","none",IF(M17="","","301"))))) | O17: =IF(A17="","",IFERROR(MID(A17,FIND("/",A17,FIND("//",A17)+2),2000),A17)) | P17: =IF(OR(O17="",N17="",N17="none",N17="404"),"",IF(N17="410","Redirect gone "&O17,"Redirect "&N17&" "&O17&" "&M17)) | T17: =IF(A17="","",TRIM(IF(K17="","Needs decision; ","")&IF(AND(K17="Accept suggestion",F17=""),"No suggestion to accept; ","")&IF(AND(K17="Override",L17=""),"Override URL missing; ","")&IF(AND(K17="Accept suggestion",N(G17)<$G$2),"Below your threshold; ","")&IF(AND(M17<>"",M17=A17,K17<>"No change (same URL)"),"Redirects to itself; ","")&IF(AND(M17<>"",OR(M17="/",AND(LEFT(M17,4)="http",OR((LEN(M17)-LEN(SUBSTITUTE(M17,"/","")))=2,AND((LEN(M17)-LEN(SUBSTITUTE(M17,"/","")))=3,RIGHT(M17,1)="/"))))),"Home page redirect; ","")&IF(N(R17)>1,"Chain; ","")&IF(S17="No","Destination not 200; ","")))
D18: =IF(A18="","",IF(OR(N(B18)>=$C$2,N(C18)>=$E$2),"High",IF(OR(N(B18)>0,N(C18)>0),"Medium","Low"))) | M18: =IF(K18="Override",L18,IF(K18="Accept suggestion",F18,IF(K18="No change (same URL)",A18,""))) | N18: =IF(A18="","",IF(K18="410 Gone","410",IF(K18="404","404",IF(K18="No change (same URL)","none",IF(M18="","","301"))))) | O18: =IF(A18="","",IFERROR(MID(A18,FIND("/",A18,FIND("//",A18)+2),2000),A18)) | P18: =IF(OR(O18="",N18="",N18="none",N18="404"),"",IF(N18="410","Redirect gone "&O18,"Redirect "&N18&" "&O18&" "&M18)) | T18: =IF(A18="","",TRIM(IF(K18="","Needs decision; ","")&IF(AND(K18="Accept suggestion",F18=""),"No suggestion to accept; ","")&IF(AND(K18="Override",L18=""),"Override URL missing; ","")&IF(AND(K18="Accept suggestion",N(G18)<$G$2),"Below your threshold; ","")&IF(AND(M18<>"",M18=A18,K18<>"No change (same URL)"),"Redirects to itself; ","")&IF(AND(M18<>"",OR(M18="/",AND(LEFT(M18,4)="http",OR((LEN(M18)-LEN(SUBSTITUTE(M18,"/","")))=2,AND((LEN(M18)-LEN(SUBSTITUTE(M18,"/","")))=3,RIGHT(M18,1)="/"))))),"Home page redirect; ","")&IF(N(R18)>1,"Chain; ","")&IF(S18="No","Destination not 200; ","")))
D19: =IF(A19="","",IF(OR(N(B19)>=$C$2,N(C19)>=$E$2),"High",IF(OR(N(B19)>0,N(C19)>0),"Medium","Low"))) | M19: =IF(K19="Override",L19,IF(K19="Accept suggestion",F19,IF(K19="No change (same URL)",A19,""))) | N19: =IF(A19="","",IF(K19="410 Gone","410",IF(K19="404","404",IF(K19="No change (same URL)","none",IF(M19="","","301"))))) | O19: =IF(A19="","",IFERROR(MID(A19,FIND("/",A19,FIND("//",A19)+2),2000),A19)) | P19: =IF(OR(O19="",N19="",N19="none",N19="404"),"",IF(N19="410","Redirect gone "&O19,"Redirect "&N19&" "&O19&" "&M19)) | T19: =IF(A19="","",TRIM(IF(K19="","Needs decision; ","")&IF(AND(K19="Accept suggestion",F19=""),"No suggestion to accept; ","")&IF(AND(K19="Override",L19=""),"Override URL missing; ","")&IF(AND(K19="Accept suggestion",N(G19)<$G$2),"Below your threshold; ","")&IF(AND(M19<>"",M19=A19,K19<>"No change (same URL)"),"Redirects to itself; ","")&IF(AND(M19<>"",OR(M19="/",AND(LEFT(M19,4)="http",OR((LEN(M19)-LEN(SUBSTITUTE(M19,"/","")))=2,AND((LEN(M19)-LEN(SUBSTITUTE(M19,"/","")))=3,RIGHT(M19,1)="/"))))),"Home page redirect; ","")&IF(N(R19)>1,"Chain; ","")&IF(S19="No","Destination not 200; ","")))
D20: =IF(A20="","",IF(OR(N(B20)>=$C$2,N(C20)>=$E$2),"High",IF(OR(N(B20)>0,N(C20)>0),"Medium","Low"))) | M20: =IF(K20="Override",L20,IF(K20="Accept suggestion",F20,IF(K20="No change (same URL)",A20,""))) | N20: =IF(A20="","",IF(K20="410 Gone","410",IF(K20="404","404",IF(K20="No change (same URL)","none",IF(M20="","","301"))))) | O20: =IF(A20="","",IFERROR(MID(A20,FIND("/",A20,FIND("//",A20)+2),2000),A20)) | P20: =IF(OR(O20="",N20="",N20="none",N20="404"),"",IF(N20="410","Redirect gone "&O20,"Redirect "&N20&" "&O20&" "&M20)) | T20: =IF(A20="","",TRIM(IF(K20="","Needs decision; ","")&IF(AND(K20="Accept suggestion",F20=""),"No suggestion to accept; ","")&IF(AND(K20="Override",L20=""),"Override URL missing; ","")&IF(AND(K20="Accept suggestion",N(G20)<$G$2),"Below your threshold; ","")&IF(AND(M20<>"",M20=A20,K20<>"No change (same URL)"),"Redirects to itself; ","")&IF(AND(M20<>"",OR(M20="/",AND(LEFT(M20,4)="http",OR((LEN(M20)-LEN(SUBSTITUTE(M20,"/","")))=2,AND((LEN(M20)-LEN(SUBSTITUTE(M20,"/","")))=3,RIGHT(M20,1)="/"))))),"Home page redirect; ","")&IF(N(R20)>1,"Chain; ","")&IF(S20="No","Destination not 200; ","")))
... D2004: =IF(A2004="","",IF(OR(N(B2004)>=$C$2,N(C2004)>=$E$2),"High",IF(OR(N(B2004)>0,N(C2004)>0),"Medium","Low"))) | M2004: =IF(K2004="Override",L2004,IF(K2004="Accept suggestion",F2004,IF(K2004="No change (same URL)",A2004,""))) | N2004: =IF(A2004="","",IF(K2004="410 Gone","410",IF(K2004="404","404",IF(K2004="No change (same URL)","none",IF(M2004="","","301"))))) | O2004: =IF(A2004="","",IFERROR(MID(A2004,FIND("/",A2004,FIND("//",A2004)+2),2000),A2004)) | P2004: =IF(OR(O2004="",N2004="",N2004="none",N2004="404"),"",IF(N2004="410","Redirect gone "&O2004,"Redirect "&N2004&" "&O2004&" "&M2004)) | T2004: =IF(A2004="","",TRIM(IF(K2004="","Needs decision; ","")&IF(AND(K2004="Accept suggestion",F2004=""),"No suggestion to accept; ","")&IF(AND(K2004="Override",L2004=""),"Override URL missing; ","")&IF(AND(K2004="Accept suggestion",N(G2004)<$G$2),"Below your threshold; ","")&IF(AND(M2004<>"",M2004=A2004,K2004<>"No change (same URL)"),"Redirects to itself; ","")&IF(AND(M2004<>"",OR(M2004="/",AND(LEFT(M2004,4)="http",OR((LEN(M2004)-LEN(SUBSTITUTE(M2004,"/","")))=2,AND((LEN(M2004)-LEN(SUBSTITUTE(M2004,"/","")))=3,RIGHT(M2004,1)="/"))))),"Home page redirect; ","")&IF(N(R2004)>1,"Chain; ","")&IF(S2004="No","Destination not 200; ","")))

Sheet Progress
B2: Progress
B3: Updates automatically as you change the Status column. Formulas use COUNTIF / COUNTIFS, so they work in Google Sheets and Excel.
B5: Checks | C5: =COUNTA('Checklist'!$C$2:$C$59)
B6: Done | C6: =COUNTIF('Checklist'!$H$2:$H$59,"Done")
B7: In progress | C7: =COUNTIF('Checklist'!$H$2:$H$59,"In progress")
B8: Not started | C8: =COUNTIF('Checklist'!$H$2:$H$59,"Not started")
B9: N/A | C9: =COUNTIF('Checklist'!$H$2:$H$59,"N/A")
B10: % complete (Done / applicable) | C10: =IFERROR(C6/(C5-C9),0) | D10: =REPT("█",ROUND(C10*20,0))&REPT("░",20-ROUND(C10*20,0))
B11: Open High-priority checks | C11: =COUNTIFS('Checklist'!$F$2:$F$59,"High",'Checklist'!$H$2:$H$59,"<>Done",'Checklist'!$H$2:$H$59,"<>N/A")
B13: Phase | C13: Checks | D13: Done | E13: In progress | F13: Not started | G13: N/A | H13: % done | I13: Open High
B14: 1. Scope & plan | C14: =COUNTIF('Checklist'!$B$2:$B$59,$B14) | D14: =COUNTIFS('Checklist'!$B$2:$B$59,$B14,'Checklist'!$H$2:$H$59,"Done") | E14: =COUNTIFS('Checklist'!$B$2:$B$59,$B14,'Checklist'!$H$2:$H$59,"In progress") | F14: =COUNTIFS('Checklist'!$B$2:$B$59,$B14,'Checklist'!$H$2:$H$59,"Not started") | G14: =COUNTIFS('Checklist'!$B$2:$B$59,$B14,'Checklist'!$H$2:$H$59,"N/A") | H14: =IFERROR(D14/(C14-G14),0) | I14: =COUNTIFS('Checklist'!$B$2:$B$59,$B14,'Checklist'!$F$2:$F$59,"High",'Checklist'!$H$2:$H$59,"<>Done",'Checklist'!$H$2:$H$59,"<>N/A") | J14: =REPT("█",ROUND(H14*10,0))&REPT("░",10-ROUND(H14*10,0))
B15: 2. Benchmark | C15: =COUNTIF('Checklist'!$B$2:$B$59,$B15) | D15: =COUNTIFS('Checklist'!$B$2:$B$59,$B15,'Checklist'!$H$2:$H$59,"Done") | E15: =COUNTIFS('Checklist'!$B$2:$B$59,$B15,'Checklist'!$H$2:$H$59,"In progress") | F15: =COUNTIFS('Checklist'!$B$2:$B$59,$B15,'Checklist'!$H$2:$H$59,"Not started") | G15: =COUNTIFS('Checklist'!$B$2:$B$59,$B15,'Checklist'!$H$2:$H$59,"N/A") | H15: =IFERROR(D15/(C15-G15),0) | I15: =COUNTIFS('Checklist'!$B$2:$B$59,$B15,'Checklist'!$F$2:$F$59,"High",'Checklist'!$H$2:$H$59,"<>Done",'Checklist'!$H$2:$H$59,"<>N/A") | J15: =REPT("█",ROUND(H15*10,0))&REPT("░",10-ROUND(H15*10,0))
B16: 3. Redirect mapping | C16: =COUNTIF('Checklist'!$B$2:$B$59,$B16) | D16: =COUNTIFS('Checklist'!$B$2:$B$59,$B16,'Checklist'!$H$2:$H$59,"Done") | E16: =COUNTIFS('Checklist'!$B$2:$B$59,$B16,'Checklist'!$H$2:$H$59,"In progress") | F16: =COUNTIFS('Checklist'!$B$2:$B$59,$B16,'Checklist'!$H$2:$H$59,"Not started") | G16: =COUNTIFS('Checklist'!$B$2:$B$59,$B16,'Checklist'!$H$2:$H$59,"N/A") | H16: =IFERROR(D16/(C16-G16),0) | I16: =COUNTIFS('Checklist'!$B$2:$B$59,$B16,'Checklist'!$F$2:$F$59,"High",'Checklist'!$H$2:$H$59,"<>Done",'Checklist'!$H$2:$H$59,"<>N/A") | J16: =REPT("█",ROUND(H16*10,0))&REPT("░",10-ROUND(H16*10,0))
B17: 4. Pre-launch (staging) | C17: =COUNTIF('Checklist'!$B$2:$B$59,$B17) | D17: =COUNTIFS('Checklist'!$B$2:$B$59,$B17,'Checklist'!$H$2:$H$59,"Done") | E17: =COUNTIFS('Checklist'!$B$2:$B$59,$B17,'Checklist'!$H$2:$H$59,"In progress") | F17: =COUNTIFS('Checklist'!$B$2:$B$59,$B17,'Checklist'!$H$2:$H$59,"Not started") | G17: =COUNTIFS('Checklist'!$B$2:$B$59,$B17,'Checklist'!$H$2:$H$59,"N/A") | H17: =IFERROR(D17/(C17-G17),0) | I17: =COUNTIFS('Checklist'!$B$2:$B$59,$B17,'Checklist'!$F$2:$F$59,"High",'Checklist'!$H$2:$H$59,"<>Done",'Checklist'!$H$2:$H$59,"<>N/A") | J17: =REPT("█",ROUND(H17*10,0))&REPT("░",10-ROUND(H17*10,0))
B18: 5. Launch day | C18: =COUNTIF('Checklist'!$B$2:$B$59,$B18) | D18: =COUNTIFS('Checklist'!$B$2:$B$59,$B18,'Checklist'!$H$2:$H$59,"Done") | E18: =COUNTIFS('Checklist'!$B$2:$B$59,$B18,'Checklist'!$H$2:$H$59,"In progress") | F18: =COUNTIFS('Checklist'!$B$2:$B$59,$B18,'Checklist'!$H$2:$H$59,"Not started") | G18: =COUNTIFS('Checklist'!$B$2:$B$59,$B18,'Checklist'!$H$2:$H$59,"N/A") | H18: =IFERROR(D18/(C18-G18),0) | I18: =COUNTIFS('Checklist'!$B$2:$B$59,$B18,'Checklist'!$F$2:$F$59,"High",'Checklist'!$H$2:$H$59,"<>Done",'Checklist'!$H$2:$H$59,"<>N/A") | J18: =REPT("█",ROUND(H18*10,0))&REPT("░",10-ROUND(H18*10,0))
B19: 6. First weeks | C19: =COUNTIF('Checklist'!$B$2:$B$59,$B19) | D19: =COUNTIFS('Checklist'!$B$2:$B$59,$B19,'Checklist'!$H$2:$H$59,"Done") | E19: =COUNTIFS('Checklist'!$B$2:$B$59,$B19,'Checklist'!$H$2:$H$59,"In progress") | F19: =COUNTIFS('Checklist'!$B$2:$B$59,$B19,'Checklist'!$H$2:$H$59,"Not started") | G19: =COUNTIFS('Checklist'!$B$2:$B$59,$B19,'Checklist'!$H$2:$H$59,"N/A") | H19: =IFERROR(D19/(C19-G19),0) | I19: =COUNTIFS('Checklist'!$B$2:$B$59,$B19,'Checklist'!$F$2:$F$59,"High",'Checklist'!$H$2:$H$59,"<>Done",'Checklist'!$H$2:$H$59,"<>N/A") | J19: =REPT("█",ROUND(H19*10,0))&REPT("░",10-ROUND(H19*10,0))
B20: 7. Months 1 to 12 | C20: =COUNTIF('Checklist'!$B$2:$B$59,$B20) | D20: =COUNTIFS('Checklist'!$B$2:$B$59,$B20,'Checklist'!$H$2:$H$59,"Done") | E20: =COUNTIFS('Checklist'!$B$2:$B$59,$B20,'Checklist'!$H$2:$H$59,"In progress") | F20: =COUNTIFS('Checklist'!$B$2:$B$59,$B20,'Checklist'!$H$2:$H$59,"Not started") | G20: =COUNTIFS('Checklist'!$B$2:$B$59,$B20,'Checklist'!$H$2:$H$59,"N/A") | H20: =IFERROR(D20/(C20-G20),0) | I20: =COUNTIFS('Checklist'!$B$2:$B$59,$B20,'Checklist'!$F$2:$F$59,"High",'Checklist'!$H$2:$H$59,"<>Done",'Checklist'!$H$2:$H$59,"<>N/A") | J20: =REPT("█",ROUND(H20*10,0))&REPT("░",10-ROUND(H20*10,0))
B22: Priority | C22: Checks | D22: Done | E22: Open | F22: % done
B23: High | C23: =COUNTIF('Checklist'!$F$2:$F$59,$B23) | D23: =COUNTIFS('Checklist'!$F$2:$F$59,$B23,'Checklist'!$H$2:$H$59,"Done") | E23: =COUNTIFS('Checklist'!$F$2:$F$59,$B23,'Checklist'!$H$2:$H$59,"<>Done",'Checklist'!$H$2:$H$59,"<>N/A") | F23: =IFERROR(D23/(C23-COUNTIFS('Checklist'!$F$2:$F$59,$B23,'Checklist'!$H$2:$H$59,"N/A")),0)
B24: Medium | C24: =COUNTIF('Checklist'!$F$2:$F$59,$B24) | D24: =COUNTIFS('Checklist'!$F$2:$F$59,$B24,'Checklist'!$H$2:$H$59,"Done") | E24: =COUNTIFS('Checklist'!$F$2:$F$59,$B24,'Checklist'!$H$2:$H$59,"<>Done",'Checklist'!$H$2:$H$59,"<>N/A") | F24: =IFERROR(D24/(C24-COUNTIFS('Checklist'!$F$2:$F$59,$B24,'Checklist'!$H$2:$H$59,"N/A")),0)
B25: Low | C25: =COUNTIF('Checklist'!$F$2:$F$59,$B25) | D25: =COUNTIFS('Checklist'!$F$2:$F$59,$B25,'Checklist'!$H$2:$H$59,"Done") | E25: =COUNTIFS('Checklist'!$F$2:$F$59,$B25,'Checklist'!$H$2:$H$59,"<>Done",'Checklist'!$H$2:$H$59,"<>N/A") | F25: =IFERROR(D25/(C25-COUNTIFS('Checklist'!$F$2:$F$59,$B25,'Checklist'!$H$2:$H$59,"N/A")),0)
B27: Redirect map
B28: Old URLs listed | C28: =COUNTA('Redirect map'!$A$5:$A$2004)
B29: High-priority old URLs | C29: =COUNTIF('Redirect map'!$D$5:$D$2004,"High")
B30: Decision made | C30: =COUNTA('Redirect map'!$K$5:$K$2004)
B31: Needs decision | C31: =COUNTIF('Redirect map'!$T$5:$T$2004,"*Needs decision*")
B32: High-priority URLs still undecided | C32: =COUNTIFS('Redirect map'!$D$5:$D$2004,"High",'Redirect map'!$K$5:$K$2004,"")
B33: Accepted suggestion | C33: =COUNTIF('Redirect map'!$K$5:$K$2004,"Accept suggestion")
B34: Overridden | C34: =COUNTIF('Redirect map'!$K$5:$K$2004,"Override")
B35: 410 or 404 | C35: =COUNTIF('Redirect map'!$K$5:$K$2004,"410 Gone")+COUNTIF('Redirect map'!$K$5:$K$2004,"404")
B36: Flag: home page redirect | C36: =COUNTIF('Redirect map'!$T$5:$T$2004,"*Home page*")
B37: Flag: below your similarity threshold | C37: =COUNTIF('Redirect map'!$T$5:$T$2004,"*Below your threshold*")
B38: Flag: chain (more than one hop) | C38: =COUNTIF('Redirect map'!$T$5:$T$2004,"*Chain*")
B39: Flag: destination not 200 | C39: =COUNTIF('Redirect map'!$T$5:$T$2004,"*not 200*")
B40: Flag: redirects to itself | C40: =COUNTIF('Redirect map'!$T$5:$T$2004,"*to itself*")
B41: QA: approved | C41: =COUNTIF('Redirect map'!$U$5:$U$2004,"Approved")
B42: QA: live and verified | C42: =COUNTIF('Redirect map'!$U$5:$U$2004,"Live and verified")
B43: QA: problem | C43: =COUNTIF('Redirect map'!$U$5:$U$2004,"Problem")
B44: % of old URLs live and verified | C44: =IFERROR(C42/C28,0) | D44: =REPT("█",ROUND(C44*20,0))&REPT("░",20-ROUND(C44*20,0))
